Workbook
Name ________________GEN1: [1]D!#REF!
Name ________________GEN1: [1]D!#REF!
Name ________________GEN1: [1]D!#REF!
Name ________________GEN1: [1]D!#REF!
Name ________________GEN1: [1]D!#REF!
Name ________________GEN1: [1]D!#REF!
Name ________________GEN1: [1]D!#REF!
Name ________________GEN1: [1]D!#REF!
Name ________________GEN1: [1]D!#REF!
Name ________________GEN1: [1]D!#REF!
Name ________________GEN1: [1]D!#REF!
Name ________________GEN1: [1]D!#REF!
Name ________________GEN1: [1]D!#REF!
Name ________________GEN1: [1]D!#REF!
Name ________________GEN1: [1]D!#REF!
Name ________________GEN1: [1]D!#REF!
Name ________________GEN1: [1]D!#REF!
Name ________________GEN1: [1]D!#REF!
Name ________________GEN1: [1]D!#REF!
Name ________________GEN1: [1]D!#REF!
Name ________________GEN1: [1]D!#REF!
Name ________________GEN1: [1]D!#REF!
Name ________________GEN1: [1]D!#REF!
Name ________________GEN1: [1]D!#REF!
Name ________________GEN1: [1]D!#REF!
Name ________________GEN1: [1]D!#REF!
Name ________________GEN1: [1]D!#REF!
Name ________________GEN1: [1]D!#REF!
Name ________________GEN1: [1]D!#REF!
Name ________________GEN1: [1]D!#REF!
Name ________________GEN1: [1]D!#REF!
Name ________________GEN1: [1]D!#REF!
Name ________________GEN1: [1]D!#REF!
Name ________________GEN1: [1]D!#REF!
Name ________________GEN1: [1]D!#REF!
Name ________________GEN1: [1]D!#REF!
Name ________________GEN1: [1]D!#REF!
Name ________________GEN1: [1]D!#REF!
Name ________________GEN1: [1]D!#REF!
Name ________________GEN1: [1]D!#REF!
Name ________________GEN1: [1]D!#REF!
Name ________________GEN1: [1]D!#REF!
Name ________________GEN1: [1]D!#REF!
Name ________________GEN1: [1]D!#REF!
Name ________________GEN1: [1]D!#REF!
Name ________________GEN1: [1]D!#REF!
Name ________________GEN1: [1]D!#REF!
Name ________________GEN1: [1]D!#REF!
Name ________________GEN1: [1]D!#REF!
Name ________________GEN1: [1]D!#REF!
Name ________________GEN1: [1]D!#REF!
Name ________________GEN1: [1]D!#REF!
Name ________________GEN1: [1]D!#REF!
Name ________________GEN1: [1]D!#REF!
Name ________________GEN1: [1]D!#REF!
Name ________________GEN1: [1]D!#REF!
Name ________________GEN1: [1]D!#REF!
Name ________________GEN1: [1]D!#REF!
Name ________________GEN1: [1]D!#REF!
Name ________________GEN1: [1]D!#REF!

Sheet Cover
L1: Basic Design Study and FEED Package Preparation for Construct New KOOPAL (ASMARI & BANGESTAN) Desalting Unit
A5: Hirgan Energy Eng. Co. | AE5: NISOC
A7: Project No.: 53-51-91215 | L7: Document Title : MECH. BASIC DESIGN MTO & COST ESTIMATION REPORT | AE7: Contract No.: 53-73-1264
A10: Consult. Proj. No.: 9104 | L10: Proj. | P10: Loc. | S10: Disc. | V10: Type | Y10: Seq. | AB10: Rev. | AE10: Page No: 1 of 109
L11: 91215 | P11: KPL | S11: ME | V11: RE | Y11: 476 | AB11: R03
A13: DOCUMENT TITLE: MECHANICAL BASIC DESIGN MTO & COST ESTIMATION REPORT
A70: R03 | D70: JAN. 2016 | I70: 91215-TN-ME-0596 | P70: IBB | U70: M.F. | Z70: M.Kh. | AE70: M.M.
A71: R02 | D71: FEB. 2015 | I71: 91215-TN-ME-0586 | P71: IBB | U71: M.F. | Z71: M.Kh. | AE71: M.M.
A72: R01 | D72: SEP. 2014 | I72: 91215-TN-ME-0568 | P72: IBB | U72: M.F. | Z72: M.Kh. | AE72: M.M.
A73: R00 | D73: JUN. 2014 | I73: 91215-TN-ME-0544 | P73: IFC | U73: M.F. | Z73: M.Kh. | AE73: M.M.
A74: REV. | D74: DATE | I74: TRANS. No. | P74: P.O.I. | U74: PREPARED | Z74: CHECKED | AE74: APPROVED | AJ74: AUTHORIZED

Sheet Record Sheet
L1: Basic Design Study and FEED Package Preparation for Construct New KOOPAL (ASMARI & BANGESTAN) Desalting Unit
A5: Hirgan Energy Eng. Co. | AE5: NISOC
A7: Project No.: 53-51-91215 | L7: Document Title : MECH. BASIC DESIGN MTO & COST ESTIMATION REPORT | AE7: Contract No.: 53-73-1264
A10: Consult. Proj. No.: 9104 | L10: Proj. | P10: Loc. | S10: Disc. | V10: Type | Y10: Seq. | AB10: Rev. | AE10: Page No: 2 of 109
L11: 91215 | P11: KPL | S11: ME | V11: RE | Y11: 476 | AB11: R03
P15: CHANGE RECORD SHEET
C17: PAGE | E17: R01 | H17: R02 | K17: R03 | P17: PAGE | R17: R01 | U17: R02 | X17: R03 | AC17: PAGE | AE17: R01 | AH17: R02 | AK17: R03
C18: 1 | E18: X | P18: 51 | R18: X | AC18: 101 | AE18: X
C19: 2 | E19: X | P19: 52 | R19: X | AC19: 102 | AE19: X
C20: 3 | E20: X | P20: 53 | R20: X | AC20: 103 | AE20: X
C21: 4 | E21: X | P21: 54 | R21: X | AC21: 104 | AE21: X
C22: 5 | E22: X | P22: 55 | R22: X | AC22: 105 | AE22: X
C23: 6 | E23: X | P23: 56 | R23: X | AC23: 106
C24: 7 | E24: X | P24: 57 | R24: X | AC24: 107
C25: 8 | E25: X | P25: 58 | R25: X | AC25: 108
C26: 9 | E26: X | P26: 59 | R26: X | AC26: 109
C27: 10 | E27: X | P27: 60 | R27: X | AC27: 110
C28: 11 | E28: X | P28: 61 | R28: X | AC28: 111
C29: 12 | E29: X | P29: 62 | R29: X | AC29: 112
C30: 13 | E30: X | P30: 63 | R30: X | AC30: 113
C31: 14 | E31: X | P31: 64 | R31: X | AC31: 114
C32: 15 | E32: X | P32: 65 | R32: X | AC32: 115
C33: 16 | E33: X | P33: 66 | R33: X | AC33: 116
C34: 17 | E34: X | P34: 67 | R34: X | AC34: 117
... C67: 50 | E67: X | P67: 100 | R67: X | AC67: 150

Sheet PROC-TITLE
N1: Basic Design Study and FEED Package Preparation for Construct New KOOPAL (ASMARI & BANGESTAN) Desalting Unit
A5: Hirgan Energy Eng. Co. | AW5: NISOC
A7: Project No.: 53-51-91215 | N7: Document Title : MECH. BASIC DESIGN MTO & COST ESTIMATION REPORT | AW7: Contract No.: 53-73-1264
A10: Consult. Proj. No.: 9104 | N10: Proj. | T10: Loc. | Z10: Disc. | AF10: Type | AL10: Seq. | AR10: Rev. | AW10: Page No: | BB10: 3 | BD10: of | BF10: 109
N11: 91215 | T11: KPL | Z11: ME | AF11: RE | AL11: 476 | AR11: R03
A13: PROCUREMENT MTO & COST ESTIMATION

Sheet DESALTERS-A
N1: Basic Design Study and FEED Package Preparation for Construct New KOOPAL (ASMARI & BANGESTAN) Desalting Unit
A5: Hirgan Energy Eng. Co. | AW5: NISOC
A7: Project No.: 53-51-91215 | N7: Document Title : MECH. BASIC DESIGN MTO & COST ESTIMATION REPORT | AW7: Contract No.: 53-73-1264
A10: Consult. Proj. No.: 9104 | N10: Proj. | T10: Loc. | Z10: Disc. | AF10: Type | AL10: Seq. | AR10: Rev. | AW10: Page No: | BB10: 4 | BD10: of | BF10: 109
N11: 91215 | T11: KPL | Z11: ME | AF11: RE | AL11: 476 | AR11: R03
A13: DESALTING PACKAGES
A14: ASMARI TRAIN
A16: Item No. | F16: Description | R16: Qty. (Set) | U16: Unit Price (Rials) | AC16: Total Price (Rials) | AK16: Unit Price (Euros) | AQ16: Total Price (Euros) | AW16: Remarks
A19: PK-111 | F19: Desalting Package | R19: 1 | AC19: =R19*U19 -> 0 | AK19: 3500000 | AQ19: =R19*AK19 -> 3500000
F20: Type: Electrostatic - AC / DC
F21: Including 1st & 2nd Stage Desalters
F22: (W/ 3 x 50% Transformer), Recycle Pumps,
F23: Related Piping, Instruments, etc.
F24: Desalter Vessels Tag Nos.: DE-111 / 112
F25: Vessels Dim. (ID x TL-TL):4267x30480 mm
F26: Vessels Design Pressure: 20.3 Barg
F27: Vessels Design Temperature: -2 / 95 oC
F28: Vessels Mat. (Shell/Heads): SA 516 Gr. 70
F29: Vessel Design Code & Standard:
F30: ASME VIII, DIV.1 & IPS-G-ME-150
F31: Recycle Pumps Tag Nos.: P-113 A/B
... F37: & IPS-G-PM-105
U38: Total Price (Rials) | AC38: =SUM(AC19:AJ37) -> 0 | AK38: Total Price (Euros) | AQ38: =SUM(AQ19:AV37) -> 3500000

Sheet DESALTERS-B
N1: Basic Design Study and FEED Package Preparation for Construct New KOOPAL (ASMARI & BANGESTAN) Desalting Unit
A5: Hirgan Energy Eng. Co. | AW5: NISOC
A7: Project No.: 53-51-91215 | N7: Document Title : MECH. BASIC DESIGN MTO & COST ESTIMATION REPORT | AW7: Contract No.: 53-73-1264
A10: Consult. Proj. No.: 9104 | N10: Proj. | T10: Loc. | Z10: Disc. | AF10: Type | AL10: Seq. | AR10: Rev. | AW10: Page No: | BB10: 5 | BD10: of | BF10: 109
N11: 91215 | T11: KPL | Z11: ME | AF11: RE | AL11: 476 | AR11: R03
A13: DESALTING PACKAGES
A14: BANGESTAN TRAIN
A16: Item No. | F16: Description | R16: Qty. (Set) | U16: Unit Price (Rials) | AC16: Total Price (Rials) | AK16: Unit Price (Euros) | AQ16: Total Price (Euros) | AW16: Remarks
A19: PK-121 | F19: Desalting Package | R19: 1 | AC19: =R19*U19 -> 0 | AK19: 2500000 | AQ19: =R19*AK19 -> 2500000
F20: Type: Electrostatic - AC / DC
F21: Including 1st & 2nd Stage Desalters
F22: (W/ 3 x 50% Transformer), Recycle Pumps,
F23: Related Piping, Instruments, etc.
F24: Desalter Vessels Tag Nos.: DE-121 / 122
F25: Vessels Dim. (ID x TL-TL):3352x16764mm
F26: Vessels Design Pressure: 21.4 Barg
F27: Vessels Design Temperature: -2 / 95 oC
F28: Vessels Mat. (Shell/Heads): SA 516 Gr. 70
F29: NACE 'MR-0175' Required: Yes
F30: Vessel Design Code & Standard:
F31: ASME VIII, DIV.1 & IPS-G-ME-150
... F39: & IPS-G-PM-105
U40: Total Price (Rials) | AC40: =SUM(AC19:AJ39) -> 0 | AK40: Total Price (Euros) | AQ40: =SUM(AQ19:AV39) -> 2500000

Sheet HEATERS-A
N1: Basic Design Study and FEED Package Preparation for Construct New KOOPAL (ASMARI & BANGESTAN) Desalting Unit
A5: Hirgan Energy Eng. Co. | AW5: NISOC
A7: Project No.: 53-51-91215 | N7: Document Title : MECH. BASIC DESIGN MTO & COST ESTIMATION REPORT | AW7: Contract No.: 53-73-1264
A10: Consult. Proj. No.: 9104 | N10: Proj. | T10: Loc. | Z10: Disc. | AF10: Type | AL10: Seq. | AR10: Rev. | AW10: Page No: | BB10: 6 | BD10: of | BF10: 109
N11: 91215 | T11: KPL | Z11: ME | AF11: RE | AL11: 476 | AR11: R03
A13: INDIRECT FIRED HEATER PACKAGES
A14: ASMARI TRAIN
A16: Item No. | F16: Description | R16: Qty. (Set) | U16: Unit Price (Rials) | AC16: Total Price (Rials) | AK16: Unit Price (Euros) | AQ16: Total Price (Euros) | AW16: Remarks
A19: H-111 A/B | F19: Oil Indirect Fired Heater Packages | R19: 2 | AC19: =R19*U19 -> 0 | AK19: 780000 | AQ19: =R19*AK19 -> 1560000
F20: Rated Heat Exchanged (KW): 8844
F21: Shell Dim. (ID x TL-TL): 3700 x 12000 mm
F22: Design Press. (Shell/Coils): 0.3/20.3 Barg
F23: Design Temperature: -2 / 120 oC
F24: Material (Shell/Heads): SA 516 Gr. 70
F25: Material (Coils): SA 106 Gr. B
F26: Design Code & Standard: API Spec.12K
F27: , ASME VIII, DIV.1 & IPS-G-ME-200
A28: H-112 | F28: Water Indirect Fired Heater Packages | R28: 1 | AC28: =R28*U28 -> 0 | AK28: 650000 | AQ28: =R28*AK28 -> 650000
F29: Rated Heat Exchanged (KW): 3649
F30: Dimsion (ID x TL-TL): 2600 x 10500 mm
F31: Design Press. (Shell/Coils): 0.3/17.7 Barg
F32: Design Temperature: -2 / 120 oC
F33: Material (Shell/Heads): SA 516 Gr. 70
F34: Material (Coils): SA 106 Gr. B
F35: Design Code & Standard: API Spec.12K
F36: , ASME VIII, DIV.1 & IPS-G-ME-200
U37: Total Price (Rials) | AC37: =SUM(AC19:AJ36) -> 0 | AK37: Total Price (Euros) | AQ37: =SUM(AQ19:AV36) -> 2210000

Sheet HEATERS-B
N1: Basic Design Study and FEED Package Preparation for Construct New KOOPAL (ASMARI & BANGESTAN) Desalting Unit
A5: Hirgan Energy Eng. Co. | AW5: NISOC
A7: Project No.: 53-51-91215 | N7: Document Title : MECH. BASIC DESIGN MTO & COST ESTIMATION REPORT | AW7: Contract No.: 53-73-1264
A10: Consult. Proj. No.: 9104 | N10: Proj. | T10: Loc. | Z10: Disc. | AF10: Type | AL10: Seq. | AR10: Rev. | AW10: Page No: | BB10: 7 | BD10: of | BF10: 109
N11: 91215 | T11: KPL | Z11: ME | AF11: RE | AL11: 476 | AR11: R03
A13: INDIRECT FIRED HEATER PACKAGES
A14: BANGESTAN TRAIN
A16: Item No. | F16: Description | R16: Qty. (Set) | U16: Unit Price (Rials) | AC16: Total Price (Rials) | AK16: Unit Price (Euros) | AQ16: Total Price (Euros) | AW16: Remarks
A19: H-121 A/B | F19: Oil Indirect Fired Heater Packages | R19: 2 | AC19: =R19*U19 -> 0 | AK19: 780000 | AQ19: =R19*AK19 -> 1560000
F20: Rated Heat Exchanged (KW): 5571
F21: Dimsion (ID x TL-TL): 3400 x 11000mm
F22: Design Press. (Shell/Coils): 0.3/21.4 Barg
F23: Design Temperature: -2 / 120 oC
F24: Material (Shell/Heads): SA 516 Gr. 70
F25: Material (Coils): SA 106 Gr. B
F26: NACE 'MR-0175' Required: Yes (for Coils)
F27: Design Code & Standard: API Spec.12K
F28: , ASME VIII, DIV.1 & IPS-G-ME-200
A29: H-122 | F29: Water Indirect Fired Heater Packages | R29: 1 | AC29: =R29*U29 -> 0 | AK29: 620000 | AQ29: =R29*AK29 -> 620000
F30: Rated Heat Exchanged (KW): 2653
F31: Dimsion (ID x TL-TL): 2400 x 9500 mm
F32: Design Press. (Shell/Coils): 0.3/17.7 Barg
F33: Design Temperature: -2 / 120 oC
F34: Material (Shell/Heads): SA 516 Gr. 70
F35: Material (Coils): SA 106 Gr. B
F36: Design Code & Standard: API Spec.12K
F37: , ASME VIII, DIV.1 & IPS-G-ME-200
U38: Total Price (Rials) | AC38: =SUM(AC19:AJ37) -> 0 | AK38: Total Price (Euros) | AQ38: =SUM(AQ19:AV37) -> 2180000

Sheet VESSELS-A
N1: Basic Design Study and FEED Package Preparation for Construct New KOOPAL (ASMARI & BANGESTAN) Desalting Unit
A5: Hirgan Energy Eng. Co. | AW5: NISOC
A7: Project No.: 53-51-91215 | N7: Document Title : MECH. BASIC DESIGN MTO & COST ESTIMATION REPORT | AW7: Contract No.: 53-73-1264
A10: Consult. Proj. No.: 9104 | N10: Proj. | T10: Loc. | Z10: Disc. | AF10: Type | AL10: Seq. | AR10: Rev. | AW10: Page No: | BB10: 8 | BD10: of | BF10: 109
N11: 91215 | T11: KPL | Z11: ME | AF11: RE | AL11: 476 | AR11: R03
A13: VESSELS
A14: ASMARI TRAIN
A16: Item No. | F16: Description | R16: Qty. (Set) | U16: Unit Price (Rials) | AC16: Total Price (Rials) | AK16: Unit Price (Euros) | AQ16: Total Price (Euros) | AW16: Remarks
A19: V-171 | F19: Flare K.O. Drum | R19: 1 | U19: 800000000 | AC19: =R19*U19 -> 800000000 | AQ19: =R19*AK19 -> 0
F20: Size (ID x TL-TL): 1500 x 4500 mm
F21: Installation Position: Horizontal
F22: Design Pressure: 3.5 (F.V.) Barg
F23: Design Temperature: -2 / 95 oC
F24: Material (Shell/Heads): SA 516 Gr. 70
F25: Design Code & Standard: ASME VIII, DIV.1
F26: & IPS-G-ME-150
A27: V-231 | F27: Closed Drain Drum | R27: 1 | U27: 1300000000 | AC27: =R27*U27 -> 1300000000 | AQ27: =R27*AK27 -> 0
F28: Size (ID x TL-TL): 2000 x 8000 mm
F29: Installation Position: Horizontal
F30: Design Pressure: 3.5 (F.V.) Barg
F31: Design Temperature: -2 / 95 oC
F32: Material (Shell/Heads): SA 516 Gr. 70
F33: Design Code & Standard: ASME VIII, DIV.1
F34: & IPS-G-ME-150
U35: Total Price (Rials) | AC35: =SUM(AC19:AJ32) -> 2100000000 | AK35: Total Price (Euros) | AQ35: =SUM(AQ19:AV32) -> 0

Sheet VESSELS-B
N1: Basic Design Study and FEED Package Preparation for Construct New KOOPAL (ASMARI & BANGESTAN) Desalting Unit
A5: Hirgan Energy Eng. Co. | AW5: NISOC
A7: Project No.: 53-51-91215 | N7: Document Title : MECH. BASIC DESIGN MTO & COST ESTIMATION REPORT | AW7: Contract No.: 53-73-1264
A10: Consult. Proj. No.: 9104 | N10: Proj. | T10: Loc. | Z10: Disc. | AF10: Type | AL10: Seq. | AR10: Rev. | AW10: Page No: | BB10: 9 | BD10: of | BF10: 109
N11: 91215 | T11: KPL | Z11: ME | AF11: RE | AL11: 476 | AR11: R03
A13: VESSELS
A14: BANGESTAN TRAIN
A16: Item No. | F16: Description | R16: Qty. (Set) | U16: Unit Price (Rials) | AC16: Total Price (Rials) | AK16: Unit Price (Euros) | AQ16: Total Price (Euros) | AW16: Remarks
A19: V-181 | F19: Flare K.O. Drum | R19: 1 | U19: 850000000 | AC19: =R19*U19 -> 850000000 | AQ19: =R19*AK19 -> 0
F20: Size (ID x TL-TL): 1500 x 4500 mm
F21: Installation Position: Horizontal
F22: Design Pressure: 3.5 (F.V.) Barg
F23: Design Temperature: -2 / 95 oC
F24: Material (Shell/Heads): SA 516 Gr. 70
F25: NACE 'MR-0175' Required: Yes
F26: Design Code & Standard: ASME VIII, DIV.1
F27: & IPS-G-ME-150
A28: V-241 | F28: Closed Drain Drum | R28: 1 | U28: 1500000000 | AC28: =R28*U28 -> 1500000000 | AQ28: =R28*AK28 -> 0
F29: Size (ID x TL-TL): 2000 x 8000 mm
F30: Installation Position: Horizontal
F31: Design Pressure: 3.5 (F.V.) Barg
F32: Design Temperature: -2 / 95 oC
F33: Material (Shell/Heads): SA 516 Gr. 70
F34: NACE 'MR-0175' Required: Yes
F35: Design Code & Standard: ASME VIII, DIV.1
F36: & IPS-G-ME-150
U37: Total Price (Rials) | AC37: =SUM(AC21:AJ36) -> 1500000000 | AK37: Total Price (Euros) | AQ37: =SUM(AQ21:AV36) -> 0

Sheet VESSELS-C
N1: Basic Design Study and FEED Package Preparation for Construct New KOOPAL (ASMARI & BANGESTAN) Desalting Unit
A5: Hirgan Energy Eng. Co. | AW5: NISOC
A7: Project No.: 53-51-91215 | N7: Document Title : MECH. BASIC DESIGN MTO & COST ESTIMATION REPORT | AW7: Contract No.: 53-73-1264
A10: Consult. Proj. No.: 9104 | N10: Proj. | T10: Loc. | Z10: Disc. | AF10: Type | AL10: Seq. | AR10: Rev. | AW10: Page No: | BB10: 10 | BD10: of | BF10: 109
N11: 91215 | T11: KPL | Z11: ME | AF11: RE | AL11: 476 | AR11: R03
A13: VESSELS
A14: COMMON (ASMARI & BANGESTAN TRAINS)
A16: Item No. | F16: Description | R16: Qty. (Set) | U16: Unit Price (Rials) | AC16: Total Price (Rials) | AK16: Unit Price (Euros) | AQ16: Total Price (Euros) | AW16: Remarks
A19: V-191 | F19: Fuel Gas K.O. Drum | R19: 1 | U19: 500000000 | AC19: =R19*U19 -> 500000000 | AQ19: =R19*AK19 -> 0
F20: Size (ID x TL-TL): 1200 x 2600 mm
F21: Installation Position: Vertical
F22: Design Pressure: 7 Barg
F23: Design Temperature: -5 / 85 oC
F24: Material (Shell/Heads): SA 516 Gr. 70
F25: Design Code & Standard: ASME VIII, DIV.1
F26: & IPS-G-ME-150
A27: V-201 | F27: Fuel Oil Storage Drum | R27: 1 | U27: 850000000 | AC27: =R27*U27 -> 850000000 | AQ27: =R27*AK27 -> 0
F28: Size (ID x TL-TL): 2400 x 7500 mm
F29: Installation Position: Horizontal
F30: Design Pressure: Atm. + Full of Liquid
F31: Design Temperature: -2 / 85 oC
F32: Material (Shell/Heads): SA 285 Gr. C
F33: Design Code & Standard: ASME VIII, DIV.1
F34: & IPS-G-ME-150
A35: V-211 | F35: Air Receiver | R35: 1 | U35: 3000000000 | AC35: =R35*U35 -> 3000000000 | AQ35: =R35*AK35 -> 0
F36: Size (ID x TL-TL): 3000 x 7500 mm
F37: Installation Position: Vertical
F38: Design Pressure: 13 Barg
F39: Design Temperature: -2 / 85 oC
F40: Material (Shell/Heads): SA 516 Gr. 70
F41: Design Code & Standard: ASME VIII, DIV.1
F42: & IPS-G-ME-150

Sheet VESSELS-C (2)
N1: Basic Design Study and FEED Package Preparation for Construct New KOOPAL (ASMARI & BANGESTAN) Desalting Unit
A5: Hirgan Energy Eng. Co. | AW5: NISOC
A7: Project No.: 53-51-91215 | N7: Document Title : MECH. BASIC DESIGN MTO & COST ESTIMATION REPORT | AW7: Contract No.: 53-73-1264
A10: Consult. Proj. No.: 9104 | N10: Proj. | T10: Loc. | Z10: Disc. | AF10: Type | AL10: Seq. | AR10: Rev. | AW10: Page No: | BB10: 11 | BD10: of | BF10: 109
N11: 91215 | T11: KPL | Z11: ME | AF11: RE | AL11: 476 | AR11: R03
A13: VESSELS
A14: COMMON (ASMARI & BANGESTAN TRAINS)
A16: Item No. | F16: Description | R16: Qty. (Set) | U16: Unit Price (Rials) | AC16: Total Price (Rials) | AK16: Unit Price (Euros) | AQ16: Total Price (Euros) | AW16: Remarks
A19: V-153 | F19: Recycle Water Vessel | R19: 1 | U19: 500000000 | AC19: =U19*R19 -> 500000000 | AQ19: 0 | AW19: The mentioned size shall be confirmed & finalized by Deaerator Vendor.
F20: (Deaeration System)
F21: Size (ID x TL-TL): 1200 x 2600 mm
F22: Installation Position: Vertical
F23: Design Pressure: 3.5 Barg
F24: Design Temperature: -2 / 85 oC
F25: Material (Shell/Heads): SA 516 Gr. 70
F26: Design Code & Standard: ASME VIII, DIV.1
F27: & IPS-G-ME-150
U28: Total Price (Rials) | AC28: =SUM('VESSELS-C'!AC19:AJ42)+SUM('VESSELS-C (2)'!AC19:AJ27) -> 4850000000 | AK28: Total Price (Euros) | AQ28: =SUM('VESSELS-C'!AQ19:AV42)+SUM('VESSELS-C (2)'!AQ19:AV27) -> 0

Sheet TANKS-A (1)
N1: Basic Design Study and FEED Package Preparation for Construct New KOOPAL (ASMARI & BANGESTAN) Desalting Unit
A5: Hirgan Energy Eng. Co. | AW5: NISOC
A7: Project No.: 53-51-91215 | N7: Document Title : MECH. BASIC DESIGN MTO & COST ESTIMATION REPORT | AW7: Contract No.: 53-73-1264
A10: Consult. Proj. No.: 9104 | N10: Proj. | T10: Loc. | Z10: Disc. | AF10: Type | AL10: Seq. | AR10: Rev. | AW10: Page No: | BB10: 12 | BD10: of | BF10: 109
N11: 91215 | T11: KPL | Z11: ME | AF11: RE | AL11: 476 | AR11: R03
A13: TANKS
A14: ASMARI TRAIN
A16: Item No. | F16: Description | R16: Qty. (Set) | U16: Unit Price (Rials) # | AC16: Total Price (Rials) | AK16: Unit Price (Euros) | AQ16: Total Price (Euros) | AW16: Remarks
A19: TK-111 | F19: Gunbarrel Tank (Settling Tank) | R19: 1 | U19: 16000000000 | AC19: =R19*U19 -> 16000000000 | AQ19: =R19*AK19 -> 0 | AW19: #: The mentioned cost is only for design & procurement of raw material. The construction & installation cost is noted in next section (Construction & Installation Cost).
F20: Size (D x H): 25000 x 15000 mm
F21: Roof Type: Dome
F22: Design Pressure: -0.4 / 25 Kpa(g)
F23: Design Temperature: -2 / 85 oC
F24: Material (Shell/Bottom/Roof): A 283 Gr. C
F25: Design Code & Standard: API 620
F26: & IPS-G-ME-110
A27: TK-112 | F27: Surge Tank | R27: 1 | U27: 4500000000 | AC27: =R27*U27 -> 4500000000 | AQ27: =R27*AK27 -> 0 | AW27: #: The mentioned cost is only for design & procurement of raw material. The construction & installation cost is noted in next section (Construction & Installation Cost).
F28: Size (D x H): 10000 x 12000 mm
F29: Roof Type: Dome
F30: Design Pressure: -0.4 / 25 Kpa(g)
F31: Design Temperature: -2 / 85 oC
F32: Material (Shell/Bottom/Roof): A 283 Gr. C
F33: Design Code & Standard: API 620
F34: & IPS-G-ME-110
A35: TK-131 | F35: Dirty Oil Tank | R35: 1 | U35: 500000000 | AC35: =R35*U35 -> 500000000 | AQ35: =R35*AK35 -> 0 | AW35: #: The mentioned cost is only for design & procurement of raw material. The construction & installation cost is noted in next section (Construction & Installation Cost).
F36: Size (D x H): 3000 x 3000 mm
F37: Roof Type: Dome
F38: Design Pressure: -0.4 / 25 Kpa(g)
F39: Design Temperature: -2 / 85 oC
F40: Material (Shell/Bottom/Roof): A 283 Gr. C
F41: Design Code & Standard: API 620
F42: & IPS-G-ME-110
A43: TK-132 | F43: Skimmer Tank | R43: 1 | U43: 3000000000 | AC43: =R43*U43 -> 3000000000 | AQ43: =R43*AK43 -> 0 | AW43: #: The mentioned cost is only for design & procurement of raw material. The construction & installation cost is noted in next section (Construction & Installation Cost).
F44: Size (D x H): 10000 x 5000 mm
F45: Roof Type: Dome
F46: Design Pressure: -0.4 / 25 Kpa(g)
F47: Design Temperature: -2 / 85 oC
F48: Material (Shell/Bottom/Roof): A 283 Gr. C
F49: Design Code & Standard: API 620
F50: & IPS-G-ME-110

Sheet TANKS-A (2)
N1: Basic Design Study and FEED Package Preparation for Construct New KOOPAL (ASMARI & BANGESTAN) Desalting Unit
A5: Hirgan Energy Eng. Co. | AW5: NISOC
A7: Project No.: 53-51-91215 | N7: Document Title : MECH. BASIC DESIGN MTO & COST ESTIMATION REPORT | AW7: Contract No.: 53-73-1264
A10: Consult. Proj. No.: 9104 | N10: Proj. | T10: Loc. | Z10: Disc. | AF10: Type | AL10: Seq. | AR10: Rev. | AW10: Page No: | BB10: 13 | BD10: of | BF10: 109
N11: 91215 | T11: KPL | Z11: ME | AF11: RE | AL11: 476 | AR11: R03
A13: TANKS (Cont'd)
A14: ASMARI TRAIN
A16: Item No. | F16: Description | R16: Qty. (Set) | U16: Unit Price (Rials) # | AC16: Total Price (Rials) | AK16: Unit Price (Euros) | AQ16: Total Price (Euros) | AW16: Remarks
A19: TK-133 | F19: Disposal Water Tank | R19: 1 | U19: 3000000000 | AC19: =R19*U19 -> 3000000000 | AQ19: =R19*AK19 -> 0 | AW19: #: The mentioned cost is only for design & procurement of raw material. The construction & installation cost is noted in next section (Construction & Installation Cost).
F20: Size (D x H): 8000 x 10000 mm
F21: Roof Type: Dome
F22: Design Pressure: -0.4 / 25 Kpa(g)
F23: Design Temperature: -2 / 85 oC
F24: Material (Shell/Bottom/Roof): A 283 Gr. C
F25: Design Code & Standard: API 620
F26: & IPS-G-ME-110
A27: TK-151 | F27: Dilution Water Tank | R27: 1 | U27: 3000000000 | AC27: =R27*U27 -> 3000000000 | AQ27: =R27*AK27 -> 0 | AW27: #: The mentioned cost is only for design & procurement of raw material. The construction & installation cost is noted in next section (Construction & Installation Cost).
F28: Size (D x H): 8000 x 10000 mm
F29: Roof Type: Dome
F30: Design Pressure: -0.4 / 25 Kpa(g)
F31: Design Temperature: -2 / 85 oC
F32: Material (Shell/Bottom/Roof): A 283 Gr. C
F33: Design Code & Standard: API 620
F34: & IPS-G-ME-110
U35: Total Price (Rials) | AC35: =SUM('TANKS-A (1)'!AC19:AJ50)+SUM('TANKS-A (2)'!AC19:AJ34) -> 30000000000 | AK35: Total Price (Euros) | AQ35: =SUM('TANKS-A (1)'!AQ19:AV50)+SUM('TANKS-A (2)'!AQ19:AV34) -> 0

Sheet TANKS-B
N1: Basic Design Study and FEED Package Preparation for Construct New KOOPAL (ASMARI & BANGESTAN) Desalting Unit
A5: Hirgan Energy Eng. Co. | AW5: NISOC
A7: Project No.: 53-51-91215 | N7: Document Title : MECH. BASIC DESIGN MTO & COST ESTIMATION REPORT | AW7: Contract No.: 53-73-1264
A10: Consult. Proj. No.: 9104 | N10: Proj. | T10: Loc. | Z10: Disc. | AF10: Type | AL10: Seq. | AR10: Rev. | AW10: Page No: | BB10: 14 | BD10: of | BF10: 109
N11: 91215 | T11: KPL | Z11: ME | AF11: RE | AL11: 476 | AR11: R03
A13: TANKS
A14: BANGESTAN TRAIN
A16: Item No. | F16: Description | R16: Qty. (Set) | U16: Unit Price (Rials) # | AC16: Total Price (Rials) | AK16: Unit Price (Euros) | AQ16: Total Price (Euros) | AW16: Remarks
A19: TK-121 | F19: Gunbarrel Tank | R19: 1 | U19: 14500000000 | AC19: =R19*U19 -> 14500000000 | AQ19: =R19*AK19 -> 0 | AW19: #: The mentioned cost is only for design & procurement of raw material. The construction & installation cost is noted in next section (Construction & Installation Cost).
F20: Size (D x H): 20000 x 15000 mm
F21: Roof Type: Dome
F22: Design Pressure: -0.4 / 25 Kpa(g)
F23: Design Temperature: -2 / 85 oC
F24: Material (Shell/Bottom/Roof): A 283 Gr. C
F25: NACE 'MR-0175' Required: Yes
F26: Design Code & Standard: API 620
F27: & IPS-G-ME-110
A28: TK-122 | F28: Surge Tank | R28: 1 | U28: 5000000000 | AC28: =R28*U28 -> 5000000000 | AQ28: =R28*AK28 -> 0 | AW28: #: The mentioned cost is only for design & procurement of raw material. The construction & installation cost is noted in next section (Construction & Installation Cost).
F29: Size (D x H): 10000 x 12000 mm
F30: Roof Type: Dome
F31: Design Pressure: -0.4 / 25 Kpa(g)
F32: Design Temperature: -2 / 85 oC
F33: Material (Shell/Bottom/Roof): A 283 Gr. C
F34: NACE 'MR-0175' Required: Yes
F35: Design Code & Standard: API 620
F36: & IPS-G-ME-110
A37: TK-123 | F37: Off Spec. Tank | R37: 1 | U37: 13000000000 | AC37: =R37*U37 -> 13000000000 | AQ37: =R37*AK37 -> 0 | AW37: #: The mentioned cost is only for design & procurement of raw material. The construction & installation cost is noted in next section (Construction & Installation Cost).
F38: Size (D x H): 22500 x 14000 mm
F39: Roof Type: Dome
F40: Design Pressure: -0.4 / 25 Kpa(g)
F41: Design Temperature: -2 / 85 oC
F42: Material (Shell/Bottom/Roof): A 283 Gr. C
F43: NACE 'MR-0175' Required: Yes
F44: Design Code & Standard: API 620
F45: & IPS-G-ME-110

Sheet TANKS-B (2)
N1: Basic Design Study and FEED Package Preparation for Construct New KOOPAL (ASMARI & BANGESTAN) Desalting Unit
A5: Hirgan Energy Eng. Co. | AW5: NISOC
A7: Project No.: 53-51-91215 | N7: Document Title : MECH. BASIC DESIGN MTO & COST ESTIMATION REPORT | AW7: Contract No.: 53-73-1264
A10: Consult. Proj. No.: 9104 | N10: Proj. | T10: Loc. | Z10: Disc. | AF10: Type | AL10: Seq. | AR10: Rev. | AW10: Page No: | BB10: 15 | BD10: of | BF10: 109
N11: 91215 | T11: KPL | Z11: ME | AF11: RE | AL11: 476 | AR11: R03
A13: TANKS (Cont'd)
A14: BANGESTAN TRAIN
A16: Item No. | F16: Description | R16: Qty. (Set) | U16: Unit Price (Rials) # | AC16: Total Price (Rials) | AK16: Unit Price (Euros) | AQ16: Total Price (Euros) | AW16: Remarks
A19: TK-141 | F19: Dirty Oil Tank | R19: 1 | U19: 500000000 | AC19: =R19*U19 -> 500000000 | AQ19: =R19*AK19 -> 0 | AW19: #: The mentioned cost is only for design & procurement of raw material. The construction & installation cost is noted in next section (Construction & Installation Cost).
F20: Size (D x H): 3000 x 3000 mm
F21: Roof Type: Dome
F22: Design Pressure: -0.4 / 25 Kpa(g)
F23: Design Temperature: -2 / 85 oC
F24: Material (Shell/Bottom/Roof): A 283 Gr. C
F25: Design Code & Standard: API 620
F26: & IPS-G-ME-110
A27: TK-142 | F27: Skimmer Tank | R27: 1 | U27: 3000000000 | AC27: =R27*U27 -> 3000000000 | AQ27: =R27*AK27 -> 0 | AW27: #: The mentioned cost is only for design & procurement of raw material. The construction & installation cost is noted in next section (Construction & Installation Cost).
F28: Size (D x H): 10000 x 5000 mm
F29: Roof Type: Dome
F30: Design Pressure: -0.4 / 25 Kpa(g)
F31: Design Temperature: -2 / 85 oC
F32: Material (Shell/Bottom/Roof): A 283 Gr. C
F33: Design Code & Standard: API 620
F34: & IPS-G-ME-110
A35: TK-143 | F35: Disposal Water Tank | R35: 1 | U35: 3000000000 | AC35: =R35*U35 -> 3000000000 | AQ35: =R35*AK35 -> 0 | AW35: #: The mentioned cost is only for design & procurement of raw material. The construction & installation cost is noted in next section (Construction & Installation Cost).
F36: Size (D x H): 8000 x 10000 mm
F37: Roof Type: Dome
F38: Design Pressure: -0.4 / 25 Kpa(g)
F39: Design Temperature: -2 / 85 oC
F40: Material (Shell/Bottom/Roof): A 283 Gr. C
F41: Design Code & Standard: API 620
F42: & IPS-G-ME-110
A43: TK-161 | F43: Dilution Water Tank | R43: 1 | U43: 3000000000 | AC43: =R43*U43 -> 3000000000 | AQ43: =R43*AK43 -> 0 | AW43: #: The mentioned cost is only for design & procurement of raw material. The construction & installation cost is noted in next section (Construction & Installation Cost).
F44: Size (D x H): 8000 x 10000 mm
F45: Roof Type: Dome
F46: Design Pressure: -0.4 / 25 Kpa(g)
F47: Design Temperature: -2 / 85 oC
F48: Material (Shell/Bottom/Roof): A 283 Gr. C
F49: Des. Standards: API 620 & IPS-G-ME-110
U50: Total Price (Rials) | AC50: =SUM('TANKS-B'!AC19:AJ45)+SUM('TANKS-B (2)'!AC19:AJ49) -> 42000000000 | AK50: Total Price (Euros) | AQ50: =SUM('TANKS-B'!AQ19:AV45)+SUM('TANKS-B (2)'!AQ19:AV49) -> 0

Sheet TANKS-C
N1: Basic Design Study and FEED Package Preparation for Construct New KOOPAL (ASMARI & BANGESTAN) Desalting Unit
A5: Hirgan Energy Eng. Co. | AW5: NISOC
A7: Project No.: 53-51-91215 | N7: Document Title : MECH. BASIC DESIGN MTO & COST ESTIMATION REPORT | AW7: Contract No.: 53-73-1264
A10: Consult. Proj. No.: 9104 | N10: Proj. | T10: Loc. | Z10: Disc. | AF10: Type | AL10: Seq. | AR10: Rev. | AW10: Page No: | BB10: 16 | BD10: of | BF10: 109
N11: 91215 | T11: KPL | Z11: ME | AF11: RE | AL11: 476 | AR11: R03
A13: TANKS
A14: COMMON (ASMARI & BANGESTAN TRAINS)
A16: Item No. | F16: Description | R16: Qty. (Set) | U16: Unit Price (Rials) # | AC16: Total Price (Rials) | AK16: Unit Price (Euros) | AQ16: Total Price (Euros) | AW16: Remarks
A19: TK-152 | F19: Elevated Potable Water Tank | R19: 1 | U19: 1000000000 | AC19: =R19*U19 -> 1000000000 | AQ19: =R19*AK19 -> 0 | AW19: #: The mentioned cost is only for design & procurement of raw material. The construction & installation cost is noted in next section (Construction & Installation Cost).
F20: Size (D x H): 6000 x 4000 mm
F21: Roof Type: Cone
F22: Design Pressure: Atm.+Full of Water
F23: Design Temperature: -2 / 85 oC
F24: Material (Shell/Bottom/Roof): A 283 Gr. C
F25: Design Code & Standard: AWWA D-100
F26: & IPS-G-ME-100
A27: TK-270 A/B | F27: Fire Water Tank | R27: 2 | U27: 6000000000 | AC27: =R27*U27 -> 12000000000 | AQ27: =R27*AK27 -> 0 | AW27: #: The mentioned cost is only for design & procurement of raw material. The construction & installation cost is noted in next section (Construction & Installation Cost).
F28: Size (D x H): 15000 x 10000 mm
F29: Roof Type: Cone
F30: Design Pressure: Atm.
F31: Design Temperature: -2 / 85 oC
F32: Material (Shell/Bottom/Roof): A 283 Gr. C
F33: Design Code & Standard: API 650
F34: & IPS-G-ME-100
A35: TK-154 | F35: Cooling Water (Pumps Sealing System) | R35: 1 | U35: 200000000 | AC35: =U35*R35 -> 200000000 | AQ35: 0 | AW35: #: The mentioned cost is only for design & procurement of raw material. The construction & installation cost is noted in next section (Construction & Installation Cost).
F36: Tank
F37: (For Pumps 'Plan 53B' Sealing System)
F38: Size (D x H): 2000 x 1600 mm
F39: Roof Type: Cone
F40: Design Pressure: Atm.+Full of Water
F41: Design Temperature: -2 / 85 oC
F42: Material: S.S. Typ. 316
F43: Design Code & Standard: API 650
F44: & IPS-G-ME-100
U45: Total Price (Rials) | AC45: =SUM(AC19:AJ44) -> 13200000000 | AK45: Total Price (Euros) | AQ45: =SUM(AQ19:AV44) -> 0

Sheet PLATE H.E.-A
N1: Basic Design Study and FEED Package Preparation for Construct New KOOPAL (ASMARI & BANGESTAN) Desalting Unit
A5: Hirgan Energy Eng. Co. | AW5: NISOC
A7: Project No.: 53-51-91215 | N7: Document Title : MECH. BASIC DESIGN MTO & COST ESTIMATION REPORT | AW7: Contract No.: 53-73-1264
A10: Consult. Proj. No.: 9104 | N10: Proj. | T10: Loc. | Z10: Disc. | AF10: Type | AL10: Seq. | AR10: Rev. | AW10: Page No: | BB10: 17 | BD10: of | BF10: 109
N11: 91215 | T11: KPL | Z11: ME | AF11: RE | AL11: 476 | AR11: R03
A13: PLATE & FRAME HEAT EXCHANGERS
A14: ASMARI TRAIN
A16: Item No. | F16: Description | R16: Qty. (Set) | U16: Unit Price (Rials) | AC16: Total Price (Rials) | AK16: Unit Price (Euros) | AQ16: Total Price (Euros) | AW16: Remarks
A19: E-111 | F19: Salty Crude / Desalted Crude H.E. | R19: 1 | AC19: =R19*U19 -> 0 | AK19: 120000 | AQ19: =R19*AK19 -> 120000
F20: Heat Exchanged (KW): 6710 (Dirty Cond.)
F21: Design Pressure: 20.3 Barg
F22: Design Temperature: -2 / 95 oC
F23: Material (Plates/Gaskets): Titanium / HNBR
F24: Design Code & Standard: API 662
F25: & ASME VIII, DIV.1
A26: E-112 | F26: Dilution Water / Waste Water H.E. | R26: 1 | AC26: =R26*U26 -> 0 | AK26: 25000 | AQ26: =R26*AK26 -> 25000
F27: Heat Exchanged (KW): 2761 (Dirty Cond.)
F28: Design Pressure: 17.7 Barg
F29: Design Temperature: -2 / 95 oC
F30: Material (Plates/Gaskets): Titanium / HNBR
F31: Design Code & Standard: API 662
F32: & ASME VIII, DIV.1
U33: Total Price (Rials) | AC33: =SUM(AC19:AJ32) -> 0 | AK33: Total Price (Euros) | AQ33: =SUM(AQ19:AV32) -> 145000

Sheet PLATE H.E.-B
N1: Basic Design Study and FEED Package Preparation for Construct New KOOPAL (ASMARI & BANGESTAN) Desalting Unit
A5: Hirgan Energy Eng. Co. | AW5: NISOC
A7: Project No.: 53-51-91215 | N7: Document Title : MECH. BASIC DESIGN MTO & COST ESTIMATION REPORT | AW7: Contract No.: 53-73-1264
A10: Consult. Proj. No.: 9104 | N10: Proj. | T10: Loc. | Z10: Disc. | AF10: Type | AL10: Seq. | AR10: Rev. | AW10: Page No: | BB10: 18 | BD10: of | BF10: 109
N11: 91215 | T11: KPL | Z11: ME | AF11: RE | AL11: 476 | AR11: R03
A13: PLATE & FRAME HEAT EXCHANGERS
A14: BANGESTAN TRAIN
A16: Item No. | F16: Description | R16: Qty. (Set) | U16: Unit Price (Rials) | AC16: Total Price (Rials) | AK16: Unit Price (Euros) | AQ16: Total Price (Euros) | AW16: Remarks
A19: E-121 | F19: Salty Crude / Desalted Crude H.E. | R19: 1 | AC19: =R19*U19 -> 0 | AK19: 65000 | AQ19: =R19*AK19 -> 65000
F20: Heat Exchanged (KW): 4216 (Dirty Cond.)
F21: Design Pressure: 21.4 Barg
F22: Design Temperature: -2 / 95 oC
F23: Material (Plates/Gaskets): Titanium / HNBR
F24: Design Code & Standard: API 662
F25: & ASME VIII, DIV.1
A26: E-122 | F26: Dilution Water / Waste Water H.E. | R26: 1 | AC26: =R26*U26 -> 0 | AK26: 25000 | AQ26: =R26*AK26 -> 25000
F27: Heat Exchanged (KW): 2009 (Dirty Cond.)
F28: Design Pressure: 17.3 Barg
F29: Design Temperature: -2 / 95 oC
F30: Material (Plates/Gaskets): Titanium / HNBR
F31: Design Code & Standard: API 662
F32: & ASME VIII, DIV.1
U33: Total Price (Rials) | AC33: =SUM(AC19:AJ32) -> 0 | AK33: Total Price (Euros) | AQ33: =SUM(AQ19:AV32) -> 90000

Sheet PUMPS-A (1)
N1: Basic Design Study and FEED Package Preparation for Construct New KOOPAL (ASMARI & BANGESTAN) Desalting Unit
A5: Hirgan Energy Eng. Co. | AW5: NISOC
A7: Project No.: 53-51-91215 | N7: Document Title : MECH. BASIC DESIGN MTO & COST ESTIMATION REPORT | AW7: Contract No.: 53-73-1264
A10: Consult. Proj. No.: 9104 | N10: Proj. | T10: Loc. | Z10: Disc. | AF10: Type | AL10: Seq. | AR10: Rev. | AW10: Page No: | BB10: 19 | BD10: of | BF10: 109
N11: 91215 | T11: KPL | Z11: ME | AF11: RE | AL11: 476 | AR11: R03
A13: PUMPS
A14: ASMARI TRAIN
A16: Item No. | F16: Description | R16: Qty. (Set) | U16: Unit Price (Rials) | AC16: Total Price (Rials) | AK16: Unit Price (Euros) | AQ16: Total Price (Euros) | AW16: Remarks
A19: P-111 A/B/C | F19: Salty Crude Transfer Pumps | R19: 3 | AC19: =R19*U19 -> 0 | AK19: 55000 | AQ19: =R19*AK19 -> 165000
F20: Type: Centrifugal (OH2)
F21: Rated Flow (m3/hr): 354
F22: Differential Head (m): 31.2
F23: Discharge Pressure (Barg): 4
F24: Material Class(Acc. to API 610): D1
F25: Design Code & Standard: API 610
F26: & IPS-G-PM-105
A27: P-114 A/B/C | F27: Salty Crude Booster Pumps | R27: 3 | AC27: =R27*U27 -> 0 | AK27: 60000 | AQ27: =R27*AK27 -> 180000
F28: Type: Centrifugal (OH2)
F29: Rated Flow (m3/hr): 255
F30: Differential Head (m): 170
F31: Discharge Pressure (Barg): 17.2
F32: Material Class(Acc. to API 610): D1
F33: Design Code & Standard: API 610
F34: & IPS-G-PM-105
A35: P-135 A/B | F35: Dirty Oil Pumps | R35: 2 | AC35: =R35*U35 -> 0 | AK35: 10000 | AQ35: =R35*AK35 -> 20000
F36: Type: P.D.-Rotary (Ext. Gear)
F37: Rated Flow (m3/hr): 5
F38: Discharge Pressure (Barg): 5.3
F39: Material Class(Acc. to API 610): D1
F40: Design Code & Standard: API 676
F41: & IPS-M-PM-140
A42: P-136 A/B | F42: Free Water Transfer Pumps | R42: 2 | AC42: =R42*U42 -> 0 | AK42: 30000 | AQ42: =R42*AK42 -> 60000
F43: Type: Centrifugal (OH2)
F44: Rated Flow (m3/hr): 21
F45: Differential Head (m): 27.6
F46: Discharge Pressure (Barg): 4
F47: Material Class(Acc. to API 610): D2
F48: Design Code & Standard: API 610
F49: & IPS-G-PM-105

Sheet PUMPS-A (2)
N1: Basic Design Study and FEED Package Preparation for Construct New KOOPAL (ASMARI & BANGESTAN) Desalting Unit
A5: Hirgan Energy Eng. Co. | AW5: NISOC
A7: Project No.: 53-51-91215 | N7: Document Title : MECH. BASIC DESIGN MTO & COST ESTIMATION REPORT | AW7: Contract No.: 53-73-1264
A10: Consult. Proj. No.: 9104 | N10: Proj. | T10: Loc. | Z10: Disc. | AF10: Type | AL10: Seq. | AR10: Rev. | AW10: Page No: | BB10: 20 | BD10: of | BF10: 109
N11: 91215 | T11: KPL | Z11: ME | AF11: RE | AL11: 476 | AR11: R03
A13: PUMPS (Cont'd)
A14: ASMARI TRAIN
A16: Item No. | F16: Description | R16: Qty. (Set) | U16: Unit Price (Rials) | AC16: Total Price (Rials) | AK16: Unit Price (Euros) | AQ16: Total Price (Euros) | AW16: Remarks
A19: P-137 A/B | F19: Disposal Water InjectionPumps | R19: 2 | AC19: =R19*U19 -> 0 | AK19: 210000 | AQ19: =R19*AK19 -> 420000
F20: Type: Centrifugal (BB3)
F21: Rated Flow (m3/hr): 73
F22: Differential Head (m): 607.4
F23: Discharge Pressure (Barg): 74.4
F24: Material Class(Acc. to API 610): D2
F25: Design Code & Standard: API 610
F26: & IPS-G-PM-105
A27: P-139 A/B | F27: Disposal Water InjectionPumps | R27: 2 | AC27: =R27*U27 -> 0 | AK27: 150000 | AQ27: =R27*AK27 -> 300000
F28: Type: Centrifugal (BB3)
F29: Rated Flow (m3/hr): 36
F30: Differential Head (m): 331
F31: Discharge Pressure (Barg): 37.4
F32: Material Class(Acc. to API 610): D2
F33: Design Code & Standard: API 610
F34: & IPS-G-PM-105
A35: P-151 A/B | F35: Dilution Water Pumps | R35: 2 | AC35: =R35*U35 -> 0 | AK35: 16500 | AQ35: =R35*AK35 -> 33000
F36: Type: Centrifugal (OH2)
F37: Rated Flow (m3/hr): 23
F38: Differential Head (m): 158
F39: Discharge Pressure (Barg): 16.7
F40: Material Class(Acc. to API 610): S5
F41: Design Code & Standard: API 610
F42: & IPS-G-PM-105
A43: P-152 | F43: Dilution Water Pump | R43: 1 | AC43: =R43*U43 -> 0 | AK43: 17500 | AQ43: =R43*AK43 -> 17500
F44: Type: Centrifugal (OH2)
F45: Rated Flow (m3/hr): 43
F46: Differential Head (m): 158
F47: Discharge Pressure (Barg): 16.7
F48: Material Class(Acc. to API 610): S5
F49: Design Code & Standard: API 610
F50: & IPS-G-PM-105

Sheet PUMPS-A (3)
N1: Basic Design Study and FEED Package Preparation for Construct New KOOPAL (ASMARI & BANGESTAN) Desalting Unit
A5: Hirgan Energy Eng. Co. | AW5: NISOC
A7: Project No.: 53-51-91215 | N7: Document Title : MECH. BASIC DESIGN MTO & COST ESTIMATION REPORT | AW7: Contract No.: 53-73-1264
A10: Consult. Proj. No.: 9104 | N10: Proj. | T10: Loc. | Z10: Disc. | AF10: Type | AL10: Seq. | AR10: Rev. | AW10: Page No: | BB10: 21 | BD10: of | BF10: 109
N11: 91215 | T11: KPL | Z11: ME | AF11: RE | AL11: 476 | AR11: R03
A13: PUMPS (Cont'd)
A14: ASMARI TRAIN
A16: Item No. | F16: Description | R16: Qty. (Set) | U16: Unit Price (Rials) | AC16: Total Price (Rials) | AK16: Unit Price (Euros) | AQ16: Total Price (Euros) | AW16: Remarks
A19: P-171 A/B | F19: Flare K.O. Drum Pumps | R19: 2 | AC19: =R19*U19 -> 0 | AK19: 10000 | AQ19: =R19*AK19 -> 20000
F20: Type: Centrifugal (OH2)
F21: Rated Flow (m3/hr): 15
F22: Differential Head (m): 50
F23: Discharge Pressure (Barg): 7.4
F24: Material Class(Acc. to API 610): S6
F25: Design Code & Standard: API 610
F26: & IPS-G-PM-105
A27: P-231 A/B | F27: O.W.S. Oil Pumps | R27: 2 | AC27: =R27*U27 -> 0 | AK27: 25000 | AQ27: =R27*AK27 -> 50000
F28: Type: P.D.-Rotary (Progressing Cavity)
F29: Rated Flow (m3/hr): 6
F30: Discharge Pressure (Barg): 3.6
F31: Material Class(Acc. to API 610): D1
F32: Design Code & Standard: API 676
F33: & IPS-M-PM-140
A34: P-232 A/B | F34: O.W.S. Water Pumps | R34: 2 | AC34: =R34*U34 -> 0 | AK34: 20000 | AQ34: =R34*AK34 -> 40000
F35: Type: Centrifugal (OH2)
F36: Rated Flow (m3/hr): 11
F37: Differential Head (m): 27.6
F38: Discharge Pressure (Barg): 3
F39: Material Class(Acc. to API 610): D2
F40: Design Code & Standard: API 610
F41: & IPS-G-PM-105
A42: P-234 A/B | F42: Closed Drain Drum Pumps | R42: 2 | AC42: =R42*U42 -> 0 | AK42: 15000 | AQ42: =R42*AK42 -> 30000
F43: Type: Centrifugal (OH2)
F44: Rated Flow (m3/hr): 15
F45: Differential Head (m): 46.81
F46: Discharge Pressure (Barg): 8.5
F47: Material Class(Acc. to API 610): D2
F48: Design Code & Standard: API 610
F49: & IPS-G-PM-105

Sheet PUMPS-A (4)
N1: Basic Design Study and FEED Package Preparation for Construct New KOOPAL (ASMARI & BANGESTAN) Desalting Unit
A5: Hirgan Energy Eng. Co. | AW5: NISOC
A7: Project No.: 53-51-91215 | N7: Document Title : MECH. BASIC DESIGN MTO & COST ESTIMATION REPORT | AW7: Contract No.: 53-73-1264
A10: Consult. Proj. No.: 9104 | N10: Proj. | T10: Loc. | Z10: Disc. | AF10: Type | AL10: Seq. | AR10: Rev. | AW10: Page No: | BB10: 22 | BD10: of | BF10: 109
N11: 91215 | T11: KPL | Z11: ME | AF11: RE | AL11: 476 | AR11: R03
A13: PUMPS (Cont'd)
A14: COMMON (ASMARI & BANGESTAN TRAINS)
A16: Item No. | F16: Description | R16: Qty. (Set) | U16: Unit Price (Rials) | AC16: Total Price (Rials) | AK16: Unit Price (Euros) | AQ16: Total Price (Euros) | AW16: Remarks
A19: P-236 | F19: Evaporation Pond Portable Pump | R19: 1 | AC19: =R19*U19 -> 0 | AK19: 20000 | AQ19: =R19*AK19 -> 20000
F20: Type: Centrifugal , Submersible
F21: Electrical Motor Driven, Explosion Proof
F22: IP68
F23: Rated Flow (m3/hr): 6
F24: Differential Pressure (Barg): 2
F25: Material Class(Acc. to API 610): D2
F26: Design Code & Standard: JIS B 8325
U27: Total Price (Rials) | AC27: =SUM('PUMPS-A (1)'!AC19:AJ49)+SUM('PUMPS-A (2)'!AC19:AJ50)+SUM('PUMPS-A (3)'!AC19:AJ49)+SUM('PUMPS-A (4)'!AC19:AJ26) -> 0 | AK27: Total Price (Euros) | AQ27: =SUM('PUMPS-A (1)'!AQ19:AV49)+SUM('PUMPS-A (2)'!AQ19:AV50)+SUM('PUMPS-A (3)'!AQ19:AV49)+SUM('PUMPS-A (4)'!AQ19:AV26) -> 1355500

Sheet PUMPS-B
N1: Basic Design Study and FEED Package Preparation for Construct New KOOPAL (ASMARI & BANGESTAN) Desalting Unit
A5: Hirgan Energy Eng. Co. | AW5: NISOC
A7: Project No.: 53-51-91215 | N7: Document Title : MECH. BASIC DESIGN MTO & COST ESTIMATION REPORT | AW7: Contract No.: 53-73-1264
A10: Consult. Proj. No.: 9104 | N10: Proj. | T10: Loc. | Z10: Disc. | AF10: Type | AL10: Seq. | AR10: Rev. | AW10: Page No: | BB10: 23 | BD10: of | BF10: 109
N11: 91215 | T11: KPL | Z11: ME | AF11: RE | AL11: 476 | AR11: R03
A13: PUMPS
A14: BANGESTAN TRAIN
A16: Item No. | F16: Description | R16: Qty. (Set) | U16: Unit Price (Rials) | AC16: Total Price (Rials) | AK16: Unit Price (Euros) | AQ16: Total Price (Euros) | AW16: Remarks
A19: P-121 A/B/C | F19: Salty Crude Transfer Pumps | R19: 3 | AC19: =R19*U19 -> 0 | AK19: 55000 | AQ19: =R19*AK19 -> 165000
F20: Type: Centrifugal (OH2)
F21: Rated Flow (m3/hr): 186
F22: Differential Head (m): 33.4
F23: Discharge Pressure (Barg): 3.9
F24: Material Class(Acc. to API 610): D1
F25: NACE 'MR-0175' Required: Yes
F26: Design Code & Standard: API 610
F27: & IPS-G-PM-105
A28: P-122 A/B | F28: Off Spec. Crude Pumps | R28: 2 | AC28: =R28*U28 -> 0 | AK28: 15000 | AQ28: =R28*AK28 -> 30000
F29: Type: Centrifugal (OH2)
F30: Rated Flow (m3/hr): 37
F31: Differential Head (m): 39
F32: Discharge Pressure (Barg): 5.4
F33: Material Class(Acc. to API 610): D1
F34: NACE 'MR-0175' Required: Yes
F35: Design Code & Standard: API 610
F36: & IPS-G-PM-105
A37: P-124 A/B/C | F37: Salty Crude Booster Pumps | R37: 3 | AC37: =R37*U37 -> 0 | AK37: 60000 | AQ37: =R37*AK37 -> 180000
F38: Type: Centrifugal (OH2)
F39: Rated Flow (m3/hr): 173
F40: Differential Head (m): 186.3
F41: Discharge Pressure (Barg): 18
F42: Material Class(Acc. to API 610): D1
F43: NACE 'MR-0175' Required: Yes
F44: Design Code & Standard: API 610
F45: & IPS-G-PM-105

Sheet PUMPS-B (2)
N1: Basic Design Study and FEED Package Preparation for Construct New KOOPAL (ASMARI & BANGESTAN) Desalting Unit
A5: Hirgan Energy Eng. Co. | AW5: NISOC
A7: Project No.: 53-51-91215 | N7: Document Title : MECH. BASIC DESIGN MTO & COST ESTIMATION REPORT | AW7: Contract No.: 53-73-1264
A10: Consult. Proj. No.: 9104 | N10: Proj. | T10: Loc. | Z10: Disc. | AF10: Type | AL10: Seq. | AR10: Rev. | AW10: Page No: | BB10: 24 | BD10: of | BF10: 109
N11: 91215 | T11: KPL | Z11: ME | AF11: RE | AL11: 476 | AR11: R03
A13: PUMPS (Cont'd)
A14: BANGESTAN TRAIN
A16: Item No. | F16: Description | R16: Qty. (Set) | U16: Unit Price (Rials) | AC16: Total Price (Rials) | AK16: Unit Price (Euros) | AQ16: Total Price (Euros) | AW16: Remarks
A19: P-145 A/B | F19: Dirty Oil Pumps | R19: 2 | AC19: =R19*U19 -> 0 | AK19: 10000 | AQ19: =R19*AK19 -> 20000
F20: Type: P.D.-Rotary (Ext. Gear)
F21: Rated Flow (m3/hr): 5
F22: Discharge Pressure (Barg): 6.5
F23: Material Class(Acc. to API 610): D1
F24: NACE 'MR-0175' Required: Yes
F25: Design Code & Standard: API 676
F26: & IPS-M-PM-140
A27: P-146 A/B | F27: Free Water Transfer Pumps | R27: 2 | AC27: =R27*U27 -> 0 | AK27: 35000 | AQ27: =R27*AK27 -> 70000
F28: Type: Centrifugal (OH2)
F29: Rated Flow (m3/hr): 14.5
F30: Differential Head (m): 27.6
F31: Discharge Pressure (Barg): 4
F32: Material Class(Acc. to API 610): D2
F33: NACE 'MR-0175' Required: Yes
F34: Design Code & Standard: API 610
F35: & IPS-G-PM-105
A36: P-147 A/B | F36: Disposal Water InjectionPumps | R36: 2 | AC36: =R36*U36 -> 0 | AK36: 230000 | AQ36: =R36*AK36 -> 460000
F37: Type: Centrifugal (BB3)
F38: Rated Flow (m3/hr): 44
F39: Differential Head (m): 670
F40: Discharge Pressure (Barg): 74.4
F41: Material Class(Acc. to API 610): D2
F42: NACE 'MR-0175' Required: Yes
F43: Design Code & Standard: API 610
F44: & IPS-G-PM-105

Sheet PUMPS-B (3)
N1: Basic Design Study and FEED Package Preparation for Construct New KOOPAL (ASMARI & BANGESTAN) Desalting Unit
A5: Hirgan Energy Eng. Co. | AW5: NISOC
A7: Project No.: 53-51-91215 | N7: Document Title : MECH. BASIC DESIGN MTO & COST ESTIMATION REPORT | AW7: Contract No.: 53-73-1264
A10: Consult. Proj. No.: 9104 | N10: Proj. | T10: Loc. | Z10: Disc. | AF10: Type | AL10: Seq. | AR10: Rev. | AW10: Page No: | BB10: 25 | BD10: of | BF10: 109
N11: 91215 | T11: KPL | Z11: ME | AF11: RE | AL11: 476 | AR11: R03
A13: PUMPS (Cont'd)
A14: BANGESTAN TRAIN
A16: Item No. | F16: Description | R16: Qty. (Set) | U16: Unit Price (Rials) | AC16: Total Price (Rials) | AK16: Unit Price (Euros) | AQ16: Total Price (Euros) | AW16: Remarks
A19: P-149 A/B | F19: Disposal Water InjectionPumps | R19: 2 | AC19: =R19*U19 -> 0 | AK19: 160000 | AQ19: =R19*AK19 -> 320000
F20: Type: Centrifugal (BB3)
F21: Rated Flow (m3/hr): 22
F22: Differential Head (m): 331
F23: Discharge Pressure (Barg): 37.4
F24: Material Class(Acc. to API 610): D2
F25: NACE 'MR-0175' Required: Yes
F26: Design Code & Standard: API 610
F27: & IPS-G-PM-105
A28: P-161 A/B | F28: Dilution Water Pumps | R28: 2 | AC28: =R28*U28 -> 0 | AK28: 16500 | AQ28: =R28*AK28 -> 33000
F29: Type: Centrifugal (OH2)
F30: Rated Flow (m3/hr): 19
F31: Differential Head (m): 168
F32: Discharge Pressure (Barg): 17.8
F33: Material Class(Acc. to API 610): S5
F34: Design Code & Standard: API 610
F35: & IPS-G-PM-105
A36: P-162 | F36: Dilution Water Pump | R36: 1 | AC36: =R36*U36 -> 0 | AK36: 17500 | AQ36: =R36*AK36 -> 17500
F37: Type: Centrifugal (OH2)
F38: Rated Flow (m3/hr): 33
F39: Differential Head (m): 168
F40: Discharge Pressure (Barg): 17.8
F41: Material Class(Acc. to API 610): S5
F42: Design Code & Standard: API 610
F43: & IPS-G-PM-105

Sheet PUMPS-B (4)
N1: Basic Design Study and FEED Package Preparation for Construct New KOOPAL (ASMARI & BANGESTAN) Desalting Unit
A5: Hirgan Energy Eng. Co. | AW5: NISOC
A7: Project No.: 53-51-91215 | N7: Document Title : MECH. BASIC DESIGN MTO & COST ESTIMATION REPORT | AW7: Contract No.: 53-73-1264
A10: Consult. Proj. No.: 9104 | N10: Proj. | T10: Loc. | Z10: Disc. | AF10: Type | AL10: Seq. | AR10: Rev. | AW10: Page No: | BB10: 26 | BD10: of | BF10: 109
N11: 91215 | T11: KPL | Z11: ME | AF11: RE | AL11: 476 | AR11: R03
A13: PUMPS (Cont'd)
A14: BANGESTAN TRAIN
A16: Item No. | F16: Description | R16: Qty. (Set) | U16: Unit Price (Rials) | AC16: Total Price (Rials) | AK16: Unit Price (Euros) | AQ16: Total Price (Euros) | AW16: Remarks
A19: P-181 A/B | F19: Flare K.O. Drum Pumps | R19: 2 | AC19: =R19*U19 -> 0 | AK19: 10000 | AQ19: =R19*AK19 -> 20000
F20: Type: Centrifugal (OH2)
F21: Rated Flow (m3/hr): 15
F22: Differential Head (m): 52
F23: Discharge Pressure (Barg): 7.3
F24: Material Class(Acc. to API 610): S6
F25: Design Code & Standard: API 610
F26: & IPS-G-PM-105
A27: P-241 A/B | F27: O.W.S. Oil Pumps | R27: 2 | AC27: =R27*U27 -> 0 | AK27: 25000 | AQ27: =R27*AK27 -> 50000
F28: Type: P.D.-Rotary (Progressing Cavity)
F29: Rated Flow (m3/hr): 5.5
F30: Discharge Pressure (Barg): 3.6
F31: Material Class(Acc. to API 610): D1
F32: NACE 'MR-0175' Required: Yes
F33: Design Code & Standard: API 676
F34: & IPS-M-PM-140
A35: P-242 A/B | F35: O.W.S. Water Pumps | R35: 2 | AC35: =R35*U35 -> 0 | AK35: 20000 | AQ35: =R35*AK35 -> 40000
F36: Type: Centrifugal (OH2)
F37: Rated Flow (m3/hr): 11
F38: Differential Head (m): 28
F39: Discharge Pressure (Barg): 3
F40: Material Class(Acc. to API 610): D2
F41: NACE 'MR-0175' Required: Yes
F42: Design Code & Standard: API 610
F43: & IPS-G-PM-105

Sheet PUMPS-B (5)
N1: Basic Design Study and FEED Package Preparation for Construct New KOOPAL (ASMARI & BANGESTAN) Desalting Unit
A5: Hirgan Energy Eng. Co. | AW5: NISOC
A7: Project No.: 53-51-91215 | N7: Document Title : MECH. BASIC DESIGN MTO & COST ESTIMATION REPORT | AW7: Contract No.: 53-73-1264
A10: Consult. Proj. No.: 9104 | N10: Proj. | T10: Loc. | Z10: Disc. | AF10: Type | AL10: Seq. | AR10: Rev. | AW10: Page No: | BB10: 27 | BD10: of | BF10: 109
N11: 91215 | T11: KPL | Z11: ME | AF11: RE | AL11: 476 | AR11: R03
A13: PUMPS (Cont'd)
A14: BANGESTAN TRAIN
A16: Item No. | F16: Description | R16: Qty. (Set) | U16: Unit Price (Rials) | AC16: Total Price (Rials) | AK16: Unit Price (Euros) | AQ16: Total Price (Euros) | AW16: Remarks
A19: P-244 A/B | F19: Closed Drain Drum Pumps | R19: 2 | AC19: =R19*U19 -> 0 | AK19: 17500 | AQ19: =R19*AK19 -> 35000
F20: Type: Centrifugal (OH2)
F21: Rated Flow (m3/hr): 15
F22: Differential Head (m): 61
F23: Discharge Pressure (Barg): 9
F24: Material Class(Acc. to API 610): D2
F25: NACE 'MR-0175' Required: Yes
F26: Design Code & Standard: API 610
F27: & IPS-G-PM-105
A28: P-246 | F28: Evaporation Pond Portable Pump | R28: 1 | AC28: =R28*U28 -> 0 | AK28: 20000 | AQ28: =R28*AK28 -> 20000
F29: Type: Centrifugal , Submersible
F30: Electrical Motor Driven, Explosion Proof
F31: IP68
F32: Rated Flow (m3/hr): 6
F33: Differential Pressure (Barg): 2
F34: Material Class(Acc. to API 610): D2
F35: Design Code & Standard: JIS B 8325
U36: Total Price (Rials) | AC36: =SUM('PUMPS-B'!AC19:AJ45)+SUM('PUMPS-B (2)'!AC19:AJ44)+SUM('PUMPS-B (3)'!AC19:AJ43)+SUM('PUMPS-B (4)'!AC19:AJ43)+SUM(AC19:AJ35) -> 0 | AK36: Total Price (Euros) | AQ36: =SUM('PUMPS-B'!AQ19:AV45)+SUM('PUMPS-B (2)'!AQ19:AV44)+SUM('PUMPS-B (3)'!AQ19:AV43)+SUM('PUMPS-B (4)'!AQ19:AV43)+SUM('PUMPS-B (5)'!AQ19:AV35) -> 1460500

Sheet PUMPS-C
N1: Basic Design Study and FEED Package Preparation for Construct New KOOPAL (ASMARI & BANGESTAN) Desalting Unit
A5: Hirgan Energy Eng. Co. | AW5: NISOC
A7: Project No.: 53-51-91215 | N7: Document Title : MECH. BASIC DESIGN MTO & COST ESTIMATION REPORT | AW7: Contract No.: 53-73-1264
A10: Consult. Proj. No.: 9104 | N10: Proj. | T10: Loc. | Z10: Disc. | AF10: Type | AL10: Seq. | AR10: Rev. | AW10: Page No: | BB10: 28 | BD10: of | BF10: 109
N11: 91215 | T11: KPL | Z11: ME | AF11: RE | AL11: 476 | AR11: R03
A13: PUMPS
A14: COMMON (ASMARI & BANGESTAN TRAINS)
A16: Item No. | F16: Description | R16: Qty. (Set) | U16: Unit Price (Rials) | AC16: Total Price (Rials) | AK16: Unit Price (Euros) | AQ16: Total Price (Euros) | AW16: Remarks
A19: P-153 A/B | F19: Deaerated Water Pumps | R19: 2 | AC19: =R19*U19 -> 0 | AK19: 6500 | AQ19: =R19*AK19 -> 13000
F20: Type: Centrifugal (Horizontal)
F21: Rated Flow (m3/hr): 48
F22: Differential Head (m): 36
F23: Discharge Pressure (Barg): 3
F24: Material Class(Acc. to API 610): I2
F25: Design Code & Standard: ISO 5199
F26: & IPS-M-PM-115
A27: P-158 | F27: Potable Water Loading Pump | R27: 1 | AC27: =R27*U27 -> 0 | AK27: 6500 | AQ27: =R27*AK27 -> 6500
F28: Type: Centrifugal (Horizontal)
F29: Rated Flow (m3/hr): 33
F30: Differential Head (m): 31
F31: Discharge Pressure (Barg): 2.9
F32: Material Class(Acc. to API 610): I2
F33: Design Code & Standard: ISO 5199
F34: & IPS-M-PM-115
A35: P-172 | F35: Flare K.O. Drums Sump Pump | R35: 1 | AC35: =R35*U35 -> 0 | AK35: 10000 | AQ35: =R35*AK35 -> 10000
F36: Type: Centrifugal (VS4)
F37: Rated Flow (m3/hr): 5.5
F38: Differential Head (m): 43
F39: Discharge Pressure (Barg): 3.03
F40: Material Class(Acc. to API 610): S6
F41: Design Code & Standard: API 610
F42: & IPS-G-PM-105
A43: P-201 | F43: Fuel Oil Pump | R43: 1 | AC43: =R43*U43 -> 0 | AK43: 7000 | AQ43: =R43*AK43 -> 7000
F44: Type: Centrifugal (Horizontal)
F45: Rated Flow (m3/hr): 10
F46: Differential Head (m): 41
F47: Discharge Pressure (Barg): 3.1
F48: Material Class(Acc. to API 610): S1
F49: Design Code & Standard: ISO 5199
F50: & IPS-M-PM-115

Sheet PUMPS-C (2)
N1: Basic Design Study and FEED Package Preparation for Construct New KOOPAL (ASMARI & BANGESTAN) Desalting Unit
A5: Hirgan Energy Eng. Co. | AW5: NISOC
A7: Project No.: 53-51-91215 | N7: Document Title : MECH. BASIC DESIGN MTO & COST ESTIMATION REPORT | AW7: Contract No.: 53-73-1264
A10: Consult. Proj. No.: 9104 | N10: Proj. | T10: Loc. | Z10: Disc. | AF10: Type | AL10: Seq. | AR10: Rev. | AW10: Page No: | BB10: 29 | BD10: of | BF10: 109
N11: 91215 | T11: KPL | Z11: ME | AF11: RE | AL11: 476 | AR11: R03
A13: PUMPS (Cont'd)
A14: COMMON (ASMARI & BANGESTAN TRAINS)
A16: Item No. | F16: Description | R16: Qty. (Set) | U16: Unit Price (Rials) | AC16: Total Price (Rials) | AK16: Unit Price (Euros) | AQ16: Total Price (Euros) | AW16: Remarks
A19: P-235 | F19: Closed Drain Drums Sump Pump | R19: 1 | AC19: =R19*U19 -> 0 | AK19: 10000 | AQ19: =R19*AK19 -> 10000
F20: Type: Centrifugal (VS4)
F21: Rated Flow (m3/hr): 5.5
F22: Differential Head (m): 31
F23: Discharge Pressure (Barg): 3.4
F24: Material Class(Acc. to API 610): S6
F25: Design Code & Standard: API 610
F26: & IPS-G-PM-105
A27: P-270 | F27: Fire Water Pump-Elect. Motor Driven | R27: 1 | AC27: =R27*U27 -> 0 | AK27: 70000 | AQ27: =R27*AK27 -> 70000
F28: Type: Centrifugal (Horizontal,
F29: Impeller Between Bearings Design)
F30: Rated Flow (m3/hr): 770
F31: Differential Head (m): 107
F32: Discharge Pressure (Barg): 11.3
F33: Material Class(Acc. to API 610): I2
F34: Design Code & Standard: NFPA 20
F35: & IPS-M-PM-125
A36: P-271 | F36: Fire Water Pump-Diesel Engine Driven | R36: 1 | AC36: =R36*U36 -> 0 | AK36: 90000 | AQ36: =R36*AK36 -> 90000
F37: Type: Centrifugal (Horizontal,
F38: Impeller Between Bearings Design)
F39: Rated Flow (m3/hr): 770
F40: Differential Head (m): 88.7
F41: Discharge Pressure (Barg): 9.5
F42: Material Class(Acc. to API 610): I2
F43: Design Code & Standard: NFPA 20
F44: & IPS-M-PM-125

Sheet PUMPS-C (3)
N1: Basic Design Study and FEED Package Preparation for Construct New KOOPAL (ASMARI & BANGESTAN) Desalting Unit
A5: Hirgan Energy Eng. Co. | AW5: NISOC
A7: Project No.: 53-51-91215 | N7: Document Title : MECH. BASIC DESIGN MTO & COST ESTIMATION REPORT | AW7: Contract No.: 53-73-1264
A10: Consult. Proj. No.: 9104 | N10: Proj. | T10: Loc. | Z10: Disc. | AF10: Type | AL10: Seq. | AR10: Rev. | AW10: Page No: | BB10: 30 | BD10: of | BF10: 109
N11: 91215 | T11: KPL | Z11: ME | AF11: RE | AL11: 476 | AR11: R03
A13: PUMPS (Cont'd)
A14: COMMON (ASMARI & BANGESTAN TRAINS)
A16: Item No. | F16: Description | R16: Qty. (Set) | U16: Unit Price (Rials) | AC16: Total Price (Rials) | AK16: Unit Price (Euros) | AQ16: Total Price (Euros) | AW16: Remarks
A19: P-272 A/B | F19: Fire Water Jockey Pumps | R19: 2 | AC19: =R19*U19 -> 0 | AK19: 15000 | AQ19: =R19*AK19 -> 30000
F20: Type: Centrifugal
F21: (Horizontal, Overhung Impeller Design)
F22: Rated Flow (m3/hr): 16.5
F23: Differential Head (m): 107
F24: Discharge Pressure (Barg): 11.3
F25: Material Class(Acc. to API 610): I2
F26: Design Code & Standard: NFPA 20
F27: & IPS-M-PM-125
A28: P-273 | F28: Fire Water Loading Pump | R28: 1 | AC28: =R28*U28 -> 0 | AK28: 6500 | AQ28: =R28*AK28 -> 6500
F29: Type: Centrifugal (Horizontal)
F30: Rated Flow (m3/hr): 33
F31: Differential Head (m): 30.6
F32: Discharge Pressure (Barg): 2.9
F33: Material Class(Acc. to API 610): I2
F34: Design Code & Standard: ISO 5199
F35: & IPS-M-PM-115
A36: P-220 A/B/C/D/E | F36: Chemical Loading Pumps | R36: 5 | U36: 100000000 | AC36: =R36*U36 -> 500000000 | AQ36: =R36*AK36 -> 0
F37: Type: Portable Barrel Pump
F38: Rated Flow (Lit/min): 160
F39: Differential Pressure (Bar): 2
F40: Material: S.S. 316 L
A41: P-154 A/B | F41: Cooling Water (Sealing System) | R41: 2 | U41: 300000000 | AC41: =R41*U41 -> 600000000 | AQ41: =R41*AK41 -> 0
F42: Recycle Pumps
F43: (For Pumps 'Plan 53B' Sealing System)
F44: Type: Centrifugal (Horizontal)
F45: Rated Flow (m3/hr): 3
F46: Differential Pressure (Bar): 3
F47: Material Class(Acc. to API 610): I2
F48: Design Code & Standard: ISO 5199
F49: & IPS-M-PM-115

Sheet PUMPS-C (4)
N1: Basic Design Study and FEED Package Preparation for Construct New KOOPAL (ASMARI & BANGESTAN) Desalting Unit
A5: Hirgan Energy Eng. Co. | AW5: NISOC
A7: Project No.: 53-51-91215 | N7: Document Title : MECH. BASIC DESIGN MTO & COST ESTIMATION REPORT | AW7: Contract No.: 53-73-1264
A10: Consult. Proj. No.: 9104 | N10: Proj. | T10: Loc. | Z10: Disc. | AF10: Type | AL10: Seq. | AR10: Rev. | AW10: Page No: | BB10: 31 | BD10: of | BF10: 109
N11: 91215 | T11: KPL | Z11: ME | AF11: RE | AL11: 476 | AR11: R03
A13: PUMPS (Cont'd)
A14: COMMON (ASMARI & BANGESTAN TRAINS)
A16: Item No. | F16: Description | R16: Qty. (Set) | U16: Unit Price (Rials) | AC16: Total Price (Rials) | AK16: Unit Price (Euros) | AQ16: Total Price (Euros) | AW16: Remarks
A19: P-157 A/B | F19: Water Liquid Return Pumps | R19: 2 | U19: 250000000 | AC19: =R19*U19 -> 500000000 | AQ19: =R19*AK19 -> 0 | AW19: The mentioned capacity shall be confirmed & finalized by Deaerator Vendor.
F20: (Deaeration System)
F21: Type: Centrifugal (Horizontal)
F22: Rated Flow (m3/hr): 2
F23: Differential Pressure (Bar): 3
F24: Material Class(Acc. to API 610): I2
F25: Design Code & Standard: ISO 5199
F26: & IPS-M-PM-115
A27: P-116 | F27: Water Glycol Loading Pump | R27: 1 | U27: 100000000 | AC27: =R27*U27 -> 100000000 | AQ27: =R27*AK27 -> 0
F28: Type: Portable Barrel Pump
F29: Rated Flow (m3/hr): 9.6
F30: Differential Pressure (Bar): 2
F31: Material: S.S. 316 L
U32: Total Price (Rials) | AC32: =SUM('PUMPS-C'!AC19:AJ50)+SUM('PUMPS-C (2)'!AC19:AJ44)+SUM('PUMPS-C (3)'!AC19:AJ49)+SUM('PUMPS-C (4)'!AC19:AJ31) -> 1700000000 | AK32: Total Price (Euros) | AQ32: =SUM('PUMPS-C'!AQ19:AV50)+SUM('PUMPS-C (2)'!AQ19:AV44)+SUM('PUMPS-C (3)'!AQ19:AV49)+SUM('PUMPS-C (4)'!AQ19:AV31) -> 243000

Sheet C.I.P.-A (1)
N1: Basic Design Study and FEED Package Preparation for Construct New KOOPAL (ASMARI & BANGESTAN) Desalting Unit
A5: Hirgan Energy Eng. Co. | AW5: NISOC
A7: Project No.: 53-51-91215 | N7: Document Title : MECH. BASIC DESIGN MTO & COST ESTIMATION REPORT | AW7: Contract No.: 53-73-1264
A10: Consult. Proj. No.: 9104 | N10: Proj. | T10: Loc. | Z10: Disc. | AF10: Type | AL10: Seq. | AR10: Rev. | AW10: Page No: | BB10: 32 | BD10: of | BF10: 109
