Workbook

Sheet Executive Dashboard
A1: EXECUTIVE SUMMARY DASHBOARD – Misc Database
A2: Counts include only records with Include in Totals = Y. Category rollups and untagged price-list items (Tag No. in parentheses) are excluded from Active Tags. No currency totals are shown.
A4: ACTIVE TAGS | C4: PACKAGES / RECORDS | E4: EQUIPMENT UNITS | G4: TOTAL RECORDS (incl. excluded)
A5: =SUMPRODUCT(('Master Database'!$AB$5:$AB$100="Y")*(LEFT('Master Database'!$D$5:$D$100,1)<>"(")) -> 15 | C5: =COUNTIF('Master Database'!$AB$5:$AB$100,"Y") -> 60 | E5: =SUMIF('Master Database'!$AB$5:$AB$100,"Y",'Master Database'!$G$5:$G$100) -> 586 | G5: =COUNTA('Master Database'!$A$5:$A$100) -> 69
A12: SUB-CATEGORY BREAKDOWN
A13: Sub-Category | B13: Sub-Category Name | C13: Active Tags | D13: Records | E13: Total Units | F13: Records Excluded
A14: PKG-STR | B14: Stripping Packages (Stripper Towers T-143 A/B) | C14: =SUMPRODUCT(('Master Database'!$F$5:$F$100=A14)*('Master Database'!$AB$5:$AB$100="Y")*(LEFT('Master Database'!$D$5:$D$100,1)<>"(")) -> 1 | D14: =COUNTIFS('Master Database'!$F$5:$F$100,A14,'Master Database'!$AB$5:$AB$100,"Y") -> 1 | E14: =SUMIFS('Master Database'!$G$5:$G$100,'Master Database'!$F$5:$F$100,A14,'Master Database'!$AB$5:$AB$100,"Y") -> 1 | F14: =COUNTIFS('Master Database'!$F$5:$F$100,A14,'Master Database'!$AB$5:$AB$100,"N") -> 1
A15: PKG-RO | B15: Reverse Osmosis Packages | C15: =SUMPRODUCT(('Master Database'!$F$5:$F$100=A15)*('Master Database'!$AB$5:$AB$100="Y")*(LEFT('Master Database'!$D$5:$D$100,1)<>"(")) -> 1 | D15: =COUNTIFS('Master Database'!$F$5:$F$100,A15,'Master Database'!$AB$5:$AB$100,"Y") -> 1 | E15: =SUMIFS('Master Database'!$G$5:$G$100,'Master Database'!$F$5:$F$100,A15,'Master Database'!$AB$5:$AB$100,"Y") -> 1 | F15: =COUNTIFS('Master Database'!$F$5:$F$100,A15,'Master Database'!$AB$5:$AB$100,"N") -> 0
A16: PKG-PIG | B16: Pig Launcher & Receiver | C16: =SUMPRODUCT(('Master Database'!$F$5:$F$100=A16)*('Master Database'!$AB$5:$AB$100="Y")*(LEFT('Master Database'!$D$5:$D$100,1)<>"(")) -> 0 | D16: =COUNTIFS('Master Database'!$F$5:$F$100,A16,'Master Database'!$AB$5:$AB$100,"Y") -> 2 | E16: =SUMIFS('Master Database'!$G$5:$G$100,'Master Database'!$F$5:$F$100,A16,'Master Database'!$AB$5:$AB$100,"Y") -> 1 | F16: =COUNTIFS('Master Database'!$F$5:$F$100,A16,'Master Database'!$AB$5:$AB$100,"N") -> 1
A17: SEP-OWS | B17: Oily Water / API Separators | C17: =SUMPRODUCT(('Master Database'!$F$5:$F$100=A17)*('Master Database'!$AB$5:$AB$100="Y")*(LEFT('Master Database'!$D$5:$D$100,1)<>"(")) -> 1 | D17: =COUNTIFS('Master Database'!$F$5:$F$100,A17,'Master Database'!$AB$5:$AB$100,"Y") -> 1 | E17: =SUMIFS('Master Database'!$G$5:$G$100,'Master Database'!$F$5:$F$100,A17,'Master Database'!$AB$5:$AB$100,"Y") -> 0 | F17: =COUNTIFS('Master Database'!$F$5:$F$100,A17,'Master Database'!$AB$5:$AB$100,"N") -> 0
A18: SEP-SKM | B18: Portable Skimmers | C18: =SUMPRODUCT(('Master Database'!$F$5:$F$100=A18)*('Master Database'!$AB$5:$AB$100="Y")*(LEFT('Master Database'!$D$5:$D$100,1)<>"(")) -> 1 | D18: =COUNTIFS('Master Database'!$F$5:$F$100,A18,'Master Database'!$AB$5:$AB$100,"Y") -> 1 | E18: =SUMIFS('Master Database'!$G$5:$G$100,'Master Database'!$F$5:$F$100,A18,'Master Database'!$AB$5:$AB$100,"Y") -> 0 | F18: =COUNTIFS('Master Database'!$F$5:$F$100,A18,'Master Database'!$AB$5:$AB$100,"N") -> 0
A19: ACX-AIR | B19: Air Coolers (Air-Cooled Heat Exchangers) | C19: =SUMPRODUCT(('Master Database'!$F$5:$F$100=A19)*('Master Database'!$AB$5:$AB$100="Y")*(LEFT('Master Database'!$D$5:$D$100,1)<>"(")) -> 0 | D19: =COUNTIFS('Master Database'!$F$5:$F$100,A19,'Master Database'!$AB$5:$AB$100,"Y") -> 1 | E19: =SUMIFS('Master Database'!$G$5:$G$100,'Master Database'!$F$5:$F$100,A19,'Master Database'!$AB$5:$AB$100,"Y") -> 0 | F19: =COUNTIFS('Master Database'!$F$5:$F$100,A19,'Master Database'!$AB$5:$AB$100,"N") -> 0
A20: HVAC-SYS | B20: HVAC Systems (incl. category rollups) | C20: =SUMPRODUCT(('Master Database'!$F$5:$F$100=A20)*('Master Database'!$AB$5:$AB$100="Y")*(LEFT('Master Database'!$D$5:$D$100,1)<>"(")) -> 0 | D20: =COUNTIFS('Master Database'!$F$5:$F$100,A20,'Master Database'!$AB$5:$AB$100,"Y") -> 10 | E20: =SUMIFS('Master Database'!$G$5:$G$100,'Master Database'!$F$5:$F$100,A20,'Master Database'!$AB$5:$AB$100,"Y") -> 8 | F20: =COUNTIFS('Master Database'!$F$5:$F$100,A20,'Master Database'!$AB$5:$AB$100,"N") -> 2
A21: SAF-SHW | B21: Safety Shower & Eye Wash | C21: =SUMPRODUCT(('Master Database'!$F$5:$F$100=A21)*('Master Database'!$AB$5:$AB$100="Y")*(LEFT('Master Database'!$D$5:$D$100,1)<>"(")) -> 0 | D21: =COUNTIFS('Master Database'!$F$5:$F$100,A21,'Master Database'!$AB$5:$AB$100,"Y") -> 2 | E21: =SUMIFS('Master Database'!$G$5:$G$100,'Master Database'!$F$5:$F$100,A21,'Master Database'!$AB$5:$AB$100,"Y") -> 12 | F21: =COUNTIFS('Master Database'!$F$5:$F$100,A21,'Master Database'!$AB$5:$AB$100,"N") -> 2
A22: PKG-EFF | B22: Effluent / Waste Water Treatment Packages | C22: =SUMPRODUCT(('Master Database'!$F$5:$F$100=A22)*('Master Database'!$AB$5:$AB$100="Y")*(LEFT('Master Database'!$D$5:$D$100,1)<>"(")) -> 0 | D22: =COUNTIFS('Master Database'!$F$5:$F$100,A22,'Master Database'!$AB$5:$AB$100,"Y") -> 1 | E22: =SUMIFS('Master Database'!$G$5:$G$100,'Master Database'!$F$5:$F$100,A22,'Master Database'!$AB$5:$AB$100,"Y") -> 0 | F22: =COUNTIFS('Master Database'!$F$5:$F$100,A22,'Master Database'!$AB$5:$AB$100,"N") -> 0
A23: PKG-WTR | B23: Water Treatment Packages | C23: =SUMPRODUCT(('Master Database'!$F$5:$F$100=A23)*('Master Database'!$AB$5:$AB$100="Y")*(LEFT('Master Database'!$D$5:$D$100,1)<>"(")) -> 0 | D23: =COUNTIFS('Master Database'!$F$5:$F$100,A23,'Master Database'!$AB$5:$AB$100,"Y") -> 1 | E23: =SUMIFS('Master Database'!$G$5:$G$100,'Master Database'!$F$5:$F$100,A23,'Master Database'!$AB$5:$AB$100,"Y") -> 0 | F23: =COUNTIFS('Master Database'!$F$5:$F$100,A23,'Master Database'!$AB$5:$AB$100,"N") -> 0
A24: PMP-WWP | B24: Waste Water & OWS Pumps | C24: =SUMPRODUCT(('Master Database'!$F$5:$F$100=A24)*('Master Database'!$AB$5:$AB$100="Y")*(LEFT('Master Database'!$D$5:$D$100,1)<>"(")) -> 3 | D24: =COUNTIFS('Master Database'!$F$5:$F$100,A24,'Master Database'!$AB$5:$AB$100,"Y") -> 3 | E24: =SUMIFS('Master Database'!$G$5:$G$100,'Master Database'!$F$5:$F$100,A24,'Master Database'!$AB$5:$AB$100,"Y") -> 5 | F24: =COUNTIFS('Master Database'!$F$5:$F$100,A24,'Master Database'!$AB$5:$AB$100,"N") -> 1
A25: TNK-SKM | B25: Oil Skimmer Tanks | C25: =SUMPRODUCT(('Master Database'!$F$5:$F$100=A25)*('Master Database'!$AB$5:$AB$100="Y")*(LEFT('Master Database'!$D$5:$D$100,1)<>"(")) -> 2 | D25: =COUNTIFS('Master Database'!$F$5:$F$100,A25,'Master Database'!$AB$5:$AB$100,"Y") -> 2 | E25: =SUMIFS('Master Database'!$G$5:$G$100,'Master Database'!$F$5:$F$100,A25,'Master Database'!$AB$5:$AB$100,"Y") -> 3 | F25: =COUNTIFS('Master Database'!$F$5:$F$100,A25,'Master Database'!$AB$5:$AB$100,"N") -> 0
... A33: CRN-FWP | B33: Fire Water Pumps Shelter Crane | C33: =SUMPRODUCT(('Master Database'!$F$5:$F$100=A33)*('Master Database'!$AB$5:$AB$100="Y")*(LEFT('Master Database'!$D$5:$D$100,1)<>"(")) -> 1 | D33: =COUNTIFS('Master Database'!$F$5:$F$100,A33,'Master Database'!$AB$5:$AB$100,"Y") -> 1 | E33: =SUMIFS('Master Database'!$G$5:$G$100,'Master Database'!$F$5:$F$100,A33,'Master Database'!$AB$5:$AB$100,"Y") -> 1 | F33: =COUNTIFS('Master Database'!$F$5:$F$100,A33,'Master Database'!$AB$5:$AB$100,"N") -> 0
A34: Total | C34: =SUM(C14:C33) -> 15 | D34: =SUM(D14:D33) -> 60 | E34: =SUM(E14:E33) -> 586 | F34: =SUM(F14:F33) -> 9
A36: NOTES & DATA GAPS
A37: • FX table has verified rates for 1392 (EUR only), 1393 (EUR only), 1402 (USD only), 1404 and 1405 only (reused from the Flare / Desalting Price Banks). 1394 (KPL stripping and RO packages, Rev. R03/Jan 2016) has no documented rate, so their converted price columns show "FX rate not entered for this year". Gachsaran 4 (1402) records convert to USD only; Maroon 3 1392 records convert to EUR only.
A38: • Unit Price (EUR/USD/IRR) in Master Database are formulas keyed off Cost Year; Unit Price (Reference) sits immediately next to Reference Currency in every sheet.
A39: • No Total Price / currency sums appear on this dashboard, per the same instruction used for the Flare database.
A40: • Category (PKG / SEP / ACX / HVAC / SAF / PMP / TNK / VSL) and Sub-Category codes carry cell comments spelling out the full names.
A41: • Tag No. in parentheses marks a project-wide category rollup or an untagged item taken from a price list. These are excluded from Active Tags but included in Records and Total Records. Real tags counted as Active Tags: PK-143, PK-152, SU-701, X-704 and OS-201.
A42: • SU-701 (Oily Water Separator) and X-704 (Portable Skimmer), Gachsaran 4, have process data sheets only: no price exists in P.ME, so their price cells are Not Stated; no value was invented.
A43: • v2 additions (from Change Log section C): effluent / water treatment packages 66.9 and 66.10, OS-201 tank, pumps P-148 and OWS pumps, safety & fire fighting package, HVAC / safety / pig group rollups. Records marked 'TO BE FILLED' in Remarks need prices from the project files (not opened in this pass). Pumps and the HVAC rollup are Include = N.
A44: • Air Cooler and Pig Launcher (price sample) are reference prices in USD with no cost year or quantity; they sit in Master Database (not on a separate sheet) because they are equipment. No air cooler, pig launcher, HVAC or safety shower record exists in the KPL or Pazanan 2 files.
A45: • v3 additions (stages 1-4 plus KPL fire water system; project reference files opened, installation costs excluded): OWS pumps P-703/P-704/P-750, KPL skimmer tanks, First Stage Separator price, rollup amounts, safety items P.ME 67.1-67.19 (Gachsaran 4, 1402) and priced items of SEFTY.p.1392 (Maroon 3, 1392), and KPL fire water tanks, pumps and crane (1394, pumps in EUR). KPL and Pazanan 2 OWS pumps were intentionally not added.

Sheet Master Database
A1: MASTER MISC EQUIPMENT & PRICE DATABASE (28-COLUMN AUDIT STRUCTURE)
A2: All extracted Misc records: stripping, reverse osmosis, pig launcher/receiver, oily water separator / skimmer, air cooler, HVAC and safety shower. Grey text = not stated in source. Unit Price (EUR/USD/IRR) are formulas keyed off Cost Year and the FX table; a year with no FX rate shows a message, not a number.
A4: Row | B4: Equipment Name | C4: Project Name | D4: Tag No. | E4: Category | F4: Sub-Category | G4: Quantity | H4: Unit | I4: Service Description | J4: Capacity / Flow Rate | K4: Design Pressure (Barg) | L4: Design Temp (°C) | M4: Material Class | N4: Design Code & Standard | O4: Weight / Power | P4: Manufacturer / Supplier | Q4: Cost Year / Date | R4: Reference Currency | S4: Unit Price (Reference) | T4: Unit Price (EUR) | U4: Unit Price (USD) | V4: Unit Price (IRR) | W4: Price Basis | X4: Estimate Class | Y4: Project Phase | Z4: Source Document / Sheet | AA4: Remarks & Scope Notes | AB4: Include in Totals (Y/N)
A5: 1 | B5: Stripping Package (Bangestan Train) | C5: Koopal Asmari/Bangestan Desalting Unit (Proj No. 53-51-91215) | D5: PK-143 | E5: PKG | F5: PKG-STR | G5: 1 | H5: Set | I5: Stripping Package including Stripper Towers T-143 A/B, Stripped Waste Water Pumps P-148 A/B/C, related piping, instruments, etc. | J5: Towers: lower section 2000 x 2500 mm (ID x L), upper section 800 x 5000 mm (ID x L), total length 9000 mm; internals: packing. Pumps (P-148 A/B/C): 50 m3/hr, 3 barg differential | K5: 5 (F.V.) | L5: -2 / 95 | M5: Shell/Heads: SA 516 Gr. 70; removable internals: Duplex S.S.; pumps API 610 material class D2 | N5: ASME VIII Div.1 & IPS-G-ME-150; pumps: API 610 & IPS-G-PM-105 | O5: Not Stated | P5: Not Stated | Q5: 1394 | R5: IRR | S5: 9000000000 | T5: =IF(NOT(ISNUMBER(S5)),"(Not stated)",IF(NOT(ISNUMBER(Q5)),"(Cost year not stated / not a Jalali year)",IFERROR(IF(N(IF(R5="EUR",S5,IF(R5="IRR",S5/INDEX('Assumptions & FX Reference'!$C$5:$C$25,MATCH(Q5,'Assumptions & FX Reference'!$A$5:$A$25,0)),IF(R5="USD",S5*INDEX('Assumptions & FX Reference'!$B$5:$B$25,MATCH(Q5,'Assumptions & FX Reference'!$A$5:$A$25,0))/INDEX('Assumptions & FX Reference'!$C$5:$C$25,MATCH(Q5,'Assumptions & FX Reference'!$A$5:$A$25,0)),"(Not stated)"))))>0,IF(R5="EUR",S5,IF(R5="IRR",S5/INDEX('Assumptions & FX Reference'!$C$5:$C$25,MATCH(Q5,'Assumptions & FX Reference'!$A$5:$A$25,0)),IF(R5="USD",S5*INDEX('Assumptions & FX Reference'!$B$5:$B$25,MATCH(Q5,'Assumptions & FX Reference'!$A$5:$A$25,0))/INDEX('Assumptions & FX Reference'!$C$5:$C$25,MATCH(Q5,'Assumptions & FX Reference'!$A$5:$A$25,0)),"(Not stated)"))),"(FX rate not entered for this year)"),"(FX rate not entered for this year)"))) -> 244897.96 | U5: =IF(NOT(ISNUMBER(S5)),"(Not stated)",IF(NOT(ISNUMBER(Q5)),"(Cost year not stated / not a Jalali year)",IFERROR(IF(N(IF(R5="USD",S5,IF(R5="IRR",S5/INDEX('Assumptions & FX Reference'!$B$5:$B$25,MATCH(Q5,'Assumptions & FX Reference'!$A$5:$A$25,0)),IF(R5="EUR",S5*INDEX('Assumptions & FX Reference'!$C$5:$C$25,MATCH(Q5,'Assumptions & FX Reference'!$A$5:$A$25,0))/INDEX('Assumptions & FX Reference'!$B$5:$B$25,MATCH(Q5,'Assumptions & FX Reference'!$A$5:$A$25,0)),"(Not stated)"))))>0,IF(R5="USD",S5,IF(R5="IRR",S5/INDEX('Assumptions & FX Reference'!$B$5:$B$25,MATCH(Q5,'Assumptions & FX Reference'!$A$5:$A$25,0)),IF(R5="EUR",S5*INDEX('Assumptions & FX Reference'!$C$5:$C$25,MATCH(Q5,'Assumptions & FX Reference'!$A$5:$A$25,0))/INDEX('Assumptions & FX Reference'!$B$5:$B$25,MATCH(Q5,'Assumptions & FX Reference'!$A$5:$A$25,0)),"(Not stated)"))),"(FX rate not entered for this year)"),"(FX rate not entered for this year)"))) -> 268256.33 | V5: =IF(NOT(ISNUMBER(S5)),"(Not stated)",IF(NOT(ISNUMBER(Q5)),"(Cost year not stated / not a Jalali year)",IFERROR(IF(N(IF(R5="IRR",S5,IF(R5="USD",S5*INDEX('Assumptions & FX Reference'!$B$5:$B$25,MATCH(Q5,'Assumptions & FX Reference'!$A$5:$A$25,0)),IF(R5="EUR",S5*INDEX('Assumptions & FX Reference'!$C$5:$C$25,MATCH(Q5,'Assumptions & FX Reference'!$A$5:$A$25,0)),"(Not stated)"))))>0,IF(R5="IRR",S5,IF(R5="USD",S5*INDEX('Assumptions & FX Reference'!$B$5:$B$25,MATCH(Q5,'Assumptions & FX Reference'!$A$5:$A$25,0)),IF(R5="EUR",S5*INDEX('Assumptions & FX Reference'!$C$5:$C$25,MATCH(Q5,'Assumptions & FX Reference'!$A$5:$A$25,0)),"(Not stated)"))),"(FX rate not entered for this year)"),"(FX rate not entered for this year)"))) -> 9000000000 | W5: Not Stated | X5: Class 2 (FEED) | Y5: FEED Package | Z5: 91215-KPL-ME-RE-476_R03_MTO_and_Cost_Estimation_Report.xlsx (Sheet STRIPPER-B) | AA5: Rev. R03 dated Jan. 2016 (~1394). Total Price (Euros) = 0 in source (no EUR quote). Lump-sum package price covers the two stripper towers, the stripped waste water pumps P-148 A/B/C (centrifugal, OH2), related piping and instruments; none of these is priced separately. Source sheet is headed BANGESTAN TRAIN; the report has no Asmari stripping sheet. Price basis not labelled in the source. | AB5: Y
A6: 2 | B6: Stripper Towers (Bangestan Train) | C6: Koopal Asmari/Bangestan Desalting Unit (Proj No. 53-51-91215) | D6: T-143 A/B | E6: PKG | F6: PKG-STR | G6: 2 | H6: No. | I6: Packed stripper towers T-143 A/B, supplied inside Stripping Package PK-143 | J6: Lower section 2000 x 2500 mm (ID x L); upper section 800 x 5000 mm (ID x L); total length 9000 mm; internals: packing | K6: 5 (F.V.) | L6: -2 / 95 | M6: Shell/Heads: SA 516 Gr. 70; removable internals: Duplex S.S. | N6: ASME VIII Div.1 & IPS-G-ME-150 | O6: Not Stated | P6: Not Stated | Q6: 1394 | R6: IRR | S6: Not Stated | T6: =IF(NOT(ISNUMBER(S6)),"(Not stated)",IF(NOT(ISNUMBER(Q6)),"(Cost year not stated / not a Jalali year)",IFERROR(IF(N(IF(R6="EUR",S6,IF(R6="IRR",S6/INDEX('Assumptions & FX Reference'!$C$5:$C$25,MATCH(Q6,'Assumptions & FX Reference'!$A$5:$A$25,0)),IF(R6="USD",S6*INDEX('Assumptions & FX Reference'!$B$5:$B$25,MATCH(Q6,'Assumptions & FX Reference'!$A$5:$A$25,0))/INDEX('Assumptions & FX Reference'!$C$5:$C$25,MATCH(Q6,'Assumptions & FX Reference'!$A$5:$A$25,0)),"(Not stated)"))))>0,IF(R6="EUR",S6,IF(R6="IRR",S6/INDEX('Assumptions & FX Reference'!$C$5:$C$25,MATCH(Q6,'Assumptions & FX Reference'!$A$5:$A$25,0)),IF(R6="USD",S6*INDEX('Assumptions & FX Reference'!$B$5:$B$25,MATCH(Q6,'Assumptions & FX Reference'!$A$5:$A$25,0))/INDEX('Assumptions & FX Reference'!$C$5:$C$25,MATCH(Q6,'Assumptions & FX Reference'!$A$5:$A$25,0)),"(Not stated)"))),"(FX rate not entered for this year)"),"(FX rate not entered for this year)"))) -> (Not stated) | U6: =IF(NOT(ISNUMBER(S6)),"(Not stated)",IF(NOT(ISNUMBER(Q6)),"(Cost year not stated / not a Jalali year)",IFERROR(IF(N(IF(R6="USD",S6,IF(R6="IRR",S6/INDEX('Assumptions & FX Reference'!$B$5:$B$25,MATCH(Q6,'Assumptions & FX Reference'!$A$5:$A$25,0)),IF(R6="EUR",S6*INDEX('Assumptions & FX Reference'!$C$5:$C$25,MATCH(Q6,'Assumptions & FX Reference'!$A$5:$A$25,0))/INDEX('Assumptions & FX Reference'!$B$5:$B$25,MATCH(Q6,'Assumptions & FX Reference'!$A$5:$A$25,0)),"(Not stated)"))))>0,IF(R6="USD",S6,IF(R6="IRR",S6/INDEX('Assumptions & FX Reference'!$B$5:$B$25,MATCH(Q6,'Assumptions & FX Reference'!$A$5:$A$25,0)),IF(R6="EUR",S6*INDEX('Assumptions & FX Reference'!$C$5:$C$25,MATCH(Q6,'Assumptions & FX Reference'!$A$5:$A$25,0))/INDEX('Assumptions & FX Reference'!$B$5:$B$25,MATCH(Q6,'Assumptions & FX Reference'!$A$5:$A$25,0)),"(Not stated)"))),"(FX rate not entered for this year)"),"(FX rate not entered for this year)"))) -> (Not stated) | V6: =IF(NOT(ISNUMBER(S6)),"(Not stated)",IF(NOT(ISNUMBER(Q6)),"(Cost year not stated / not a Jalali year)",IFERROR(IF(N(IF(R6="IRR",S6,IF(R6="USD",S6*INDEX('Assumptions & FX Reference'!$B$5:$B$25,MATCH(Q6,'Assumptions & FX Reference'!$A$5:$A$25,0)),IF(R6="EUR",S6*INDEX('Assumptions & FX Reference'!$C$5:$C$25,MATCH(Q6,'Assumptions & FX Reference'!$A$5:$A$25,0)),"(Not stated)"))))>0,IF(R6="IRR",S6,IF(R6="USD",S6*INDEX('Assumptions & FX Reference'!$B$5:$B$25,MATCH(Q6,'Assumptions & FX Reference'!$A$5:$A$25,0)),IF(R6="EUR",S6*INDEX('Assumptions & FX Reference'!$C$5:$C$25,MATCH(Q6,'Assumptions & FX Reference'!$A$5:$A$25,0)),"(Not stated)"))),"(FX rate not entered for this year)"),"(FX rate not entered for this year)"))) -> (Not stated) | W6: Not Stated | X6: Class 2 (FEED) | Y6: FEED Package | Z6: 91215-KPL-ME-RE-476_R03_MTO_and_Cost_Estimation_Report.xlsx (Sheet STRIPPER-B, row 23) | AA6: No separate price: the towers are inside the PK-143 lump sum (9,000,000,000 IRR). Record kept only so that tag T-143 A/B (MASTER_TAGS category Tower) stays traceable; excluded from totals to avoid double counting. | AB6: N
A7: 3 | B7: Reverse Osmosis Package (Asmari & Bangestan Trains) | C7: Koopal Asmari/Bangestan Desalting Unit (Proj No. 53-51-91215) | D7: PK-152 | E7: PKG | F7: PKG-RO | G7: 1 | H7: Set | I7: Reverse Osmosis Packages including Back Filters, R.O. Unit, C.I.P., Chemical Injection System & U.V. Lamp | J7: 1 m3/hr | K7: Not Stated | L7: Not Stated | M7: Not Stated | N7: Not Stated | O7: Not Stated | P7: Not Stated | Q7: 1394 | R7: IRR | S7: 800000000 | T7: =IF(NOT(ISNUMBER(S7)),"(Not stated)",IF(NOT(ISNUMBER(Q7)),"(Cost year not stated / not a Jalali year)",IFERROR(IF(N(IF(R7="EUR",S7,IF(R7="IRR",S7/INDEX('Assumptions & FX Reference'!$C$5:$C$25,MATCH(Q7,'Assumptions & FX Reference'!$A$5:$A$25,0)),IF(R7="USD",S7*INDEX('Assumptions & FX Reference'!$B$5:$B$25,MATCH(Q7,'Assumptions & FX Reference'!$A$5:$A$25,0))/INDEX('Assumptions & FX Reference'!$C$5:$C$25,MATCH(Q7,'Assumptions & FX Reference'!$A$5:$A$25,0)),"(Not stated)"))))>0,IF(R7="EUR",S7,IF(R7="IRR",S7/INDEX('Assumptions & FX Reference'!$C$5:$C$25,MATCH(Q7,'Assumptions & FX Reference'!$A$5:$A$25,0)),IF(R7="USD",S7*INDEX('Assumptions & FX Reference'!$B$5:$B$25,MATCH(Q7,'Assumptions & FX Reference'!$A$5:$A$25,0))/INDEX('Assumptions & FX Reference'!$C$5:$C$25,MATCH(Q7,'Assumptions & FX Reference'!$A$5:$A$25,0)),"(Not stated)"))),"(FX rate not entered for this year)"),"(FX rate not entered for this year)"))) -> 21768.707 | U7: =IF(NOT(ISNUMBER(S7)),"(Not stated)",IF(NOT(ISNUMBER(Q7)),"(Cost year not stated / not a Jalali year)",IFERROR(IF(N(IF(R7="USD",S7,IF(R7="IRR",S7/INDEX('Assumptions & FX Reference'!$B$5:$B$25,MATCH(Q7,'Assumptions & FX Reference'!$A$5:$A$25,0)),IF(R7="EUR",S7*INDEX('Assumptions & FX Reference'!$C$5:$C$25,MATCH(Q7,'Assumptions & FX Reference'!$A$5:$A$25,0))/INDEX('Assumptions & FX Reference'!$B$5:$B$25,MATCH(Q7,'Assumptions & FX Reference'!$A$5:$A$25,0)),"(Not stated)"))))>0,IF(R7="USD",S7,IF(R7="IRR",S7/INDEX('Assumptions & FX Reference'!$B$5:$B$25,MATCH(Q7,'Assumptions & FX Reference'!$A$5:$A$25,0)),IF(R7="EUR",S7*INDEX('Assumptions & FX Reference'!$C$5:$C$25,MATCH(Q7,'Assumptions & FX Reference'!$A$5:$A$25,0))/INDEX('Assumptions & FX Reference'!$B$5:$B$25,MATCH(Q7,'Assumptions & FX Reference'!$A$5:$A$25,0)),"(Not stated)"))),"(FX rate not entered for this year)"),"(FX rate not entered for this year)"))) -> 23845.007 | V7: =IF(NOT(ISNUMBER(S7)),"(Not stated)",IF(NOT(ISNUMBER(Q7)),"(Cost year not stated / not a Jalali year)",IFERROR(IF(N(IF(R7="IRR",S7,IF(R7="USD",S7*INDEX('Assumptions & FX Reference'!$B$5:$B$25,MATCH(Q7,'Assumptions & FX Reference'!$A$5:$A$25,0)),IF(R7="EUR",S7*INDEX('Assumptions & FX Reference'!$C$5:$C$25,MATCH(Q7,'Assumptions & FX Reference'!$A$5:$A$25,0)),"(Not stated)"))))>0,IF(R7="IRR",S7,IF(R7="USD",S7*INDEX('Assumptions & FX Reference'!$B$5:$B$25,MATCH(Q7,'Assumptions & FX Reference'!$A$5:$A$25,0)),IF(R7="EUR",S7*INDEX('Assumptions & FX Reference'!$C$5:$C$25,MATCH(Q7,'Assumptions & FX Reference'!$A$5:$A$25,0)),"(Not stated)"))),"(FX rate not entered for this year)"),"(FX rate not entered for this year)"))) -> 800000000 | W7: Not Stated | X7: Class 2 (FEED) | Y7: FEED Package | Z7: 91215-KPL-ME-RE-476_R03_MTO_and_Cost_Estimation_Report.xlsx (Sheet R.O.) | AA7: Rev. R03 dated Jan. 2016 (~1394). Total Price (Euros) = 0 in source (no EUR quote). One package serves both trains (sheet heading 'ASMARI & BANGESTAN TRAINS'), qty 1 Set. Installation sheet INS-PACK-C lists the same tag PK-152. Price basis not labelled in the source. | AB7: Y
A8: 4 | B8: Pig Launcher & Receiver | C8: Gachsaran 4 Development Plan (Proj No. 591111) | D8: (No Tag - P.ME item 68) | E8: PKG | F8: PKG-PIG | G8: 1 | H8: SET | I8: Pig Launcher & Receiver (pipeline pigging facilities) | J8: Not Stated | K8: Not Stated | L8: Not Stated | M8: Not Stated | N8: Not Stated | O8: Not Stated | P8: Not Stated | Q8: 1402 | R8: IRR | S8: 94500000000 | T8: =IF(NOT(ISNUMBER(S8)),"(Not stated)",IF(NOT(ISNUMBER(Q8)),"(Cost year not stated / not a Jalali year)",IFERROR(IF(N(IF(R8="EUR",S8,IF(R8="IRR",S8/INDEX('Assumptions & FX Reference'!$C$5:$C$25,MATCH(Q8,'Assumptions & FX Reference'!$A$5:$A$25,0)),IF(R8="USD",S8*INDEX('Assumptions & FX Reference'!$B$5:$B$25,MATCH(Q8,'Assumptions & FX Reference'!$A$5:$A$25,0))/INDEX('Assumptions & FX Reference'!$C$5:$C$25,MATCH(Q8,'Assumptions & FX Reference'!$A$5:$A$25,0)),"(Not stated)"))))>0,IF(R8="EUR",S8,IF(R8="IRR",S8/INDEX('Assumptions & FX Reference'!$C$5:$C$25,MATCH(Q8,'Assumptions & FX Reference'!$A$5:$A$25,0)),IF(R8="USD",S8*INDEX('Assumptions & FX Reference'!$B$5:$B$25,MATCH(Q8,'Assumptions & FX Reference'!$A$5:$A$25,0))/INDEX('Assumptions & FX Reference'!$C$5:$C$25,MATCH(Q8,'Assumptions & FX Reference'!$A$5:$A$25,0)),"(Not stated)"))),"(FX rate not entered for this year)"),"(FX rate not entered for this year)"))) -> 178470.25 | U8: =IF(NOT(ISNUMBER(S8)),"(Not stated)",IF(NOT(ISNUMBER(Q8)),"(Cost year not stated / not a Jalali year)",IFERROR(IF(N(IF(R8="USD",S8,IF(R8="IRR",S8/INDEX('Assumptions & FX Reference'!$B$5:$B$25,MATCH(Q8,'Assumptions & FX Reference'!$A$5:$A$25,0)),IF(R8="EUR",S8*INDEX('Assumptions & FX Reference'!$C$5:$C$25,MATCH(Q8,'Assumptions & FX Reference'!$A$5:$A$25,0))/INDEX('Assumptions & FX Reference'!$B$5:$B$25,MATCH(Q8,'Assumptions & FX Reference'!$A$5:$A$25,0)),"(Not stated)"))))>0,IF(R8="USD",S8,IF(R8="IRR",S8/INDEX('Assumptions & FX Reference'!$B$5:$B$25,MATCH(Q8,'Assumptions & FX Reference'!$A$5:$A$25,0)),IF(R8="EUR",S8*INDEX('Assumptions & FX Reference'!$C$5:$C$25,MATCH(Q8,'Assumptions & FX Reference'!$A$5:$A$25,0))/INDEX('Assumptions & FX Reference'!$B$5:$B$25,MATCH(Q8,'Assumptions & FX Reference'!$A$5:$A$25,0)),"(Not stated)"))),"(FX rate not entered for this year)"),"(FX rate not entered for this year)"))) -> 225000 | V8: =IF(NOT(ISNUMBER(S8)),"(Not stated)",IF(NOT(ISNUMBER(Q8)),"(Cost year not stated / not a Jalali year)",IFERROR(IF(N(IF(R8="IRR",S8,IF(R8="USD",S8*INDEX('Assumptions & FX Reference'!$B$5:$B$25,MATCH(Q8,'Assumptions & FX Reference'!$A$5:$A$25,0)),IF(R8="EUR",S8*INDEX('Assumptions & FX Reference'!$C$5:$C$25,MATCH(Q8,'Assumptions & FX Reference'!$A$5:$A$25,0)),"(Not stated)"))))>0,IF(R8="IRR",S8,IF(R8="USD",S8*INDEX('Assumptions & FX Reference'!$B$5:$B$25,MATCH(Q8,'Assumptions & FX Reference'!$A$5:$A$25,0)),IF(R8="EUR",S8*INDEX('Assumptions & FX Reference'!$C$5:$C$25,MATCH(Q8,'Assumptions & FX Reference'!$A$5:$A$25,0)),"(Not stated)"))),"(FX rate not entered for this year)"),"(FX rate not entered for this year)"))) -> 94500000000 | W8: FOB | X8: Class 3 (Basic) | Y8: Basic Engineering | Z8: PEP-Rev.140205_عزيزيان_Gachsaran_4.xlsx (Sheet P.ME, row 113) | AA8: Unit cost without overhead factor (هزینه واحد بدون ضریب). Source formula = 225,000 USD x USD_Change_IRR (420,000 IRR/USD) = 94,500,000,000 IRR. Freight allocation 241,488,427.26 IRR (P.ME col N; = 13,000,000 x IRR_Inflation_Factor) not included in Unit Price Reference; Customs clearance not stated. Same amount appears in the P.ME summary table row 141 (گیرنده و فرستنده توپک). Installation is a separate construction item (C.mECHANICAL 'LUNCHER AND RECEIVER') and is not included. | AB8: Y
A9: 5 | B9: Pig Launcher (Reference Price Sample) | C9: Not Stated (reference price sample, file نمونه_قیمتی_نمک_زدایی_overall.xlsx) | D9: (No Tag - price sample item 8) | E9: PKG | F9: PKG-PIG | G9: Not Stated | H9: Not Stated | I9: PIG Launcher (Type: Piping), from packages list of the price sample | J9: Length 4356 mm; diameters 16 / 12 inches | K9: 8 | L9: Not Stated | M9: C.S | N9: Not Stated | O9: Not Stated | P9: Not Stated | Q9: Not Stated | R9: USD | S9: 15000 | T9: =IF(NOT(ISNUMBER(S9)),"(Not stated)",IF(NOT(ISNUMBER(Q9)),"(Cost year not stated / not a Jalali year)",IFERROR(IF(N(IF(R9="EUR",S9,IF(R9="IRR",S9/INDEX('Assumptions & FX Reference'!$C$5:$C$25,MATCH(Q9,'Assumptions & FX Reference'!$A$5:$A$25,0)),IF(R9="USD",S9*INDEX('Assumptions & FX Reference'!$B$5:$B$25,MATCH(Q9,'Assumptions & FX Reference'!$A$5:$A$25,0))/INDEX('Assumptions & FX Reference'!$C$5:$C$25,MATCH(Q9,'Assumptions & FX Reference'!$A$5:$A$25,0)),"(Not stated)"))))>0,IF(R9="EUR",S9,IF(R9="IRR",S9/INDEX('Assumptions & FX Reference'!$C$5:$C$25,MATCH(Q9,'Assumptions & FX Reference'!$A$5:$A$25,0)),IF(R9="USD",S9*INDEX('Assumptions & FX Reference'!$B$5:$B$25,MATCH(Q9,'Assumptions & FX Reference'!$A$5:$A$25,0))/INDEX('Assumptions & FX Reference'!$C$5:$C$25,MATCH(Q9,'Assumptions & FX Reference'!$A$5:$A$25,0)),"(Not stated)"))),"(FX rate not entered for this year)"),"(FX rate not entered for this year)"))) -> (Cost year not stated / not a Jalali year) | U9: =IF(NOT(ISNUMBER(S9)),"(Not stated)",IF(NOT(ISNUMBER(Q9)),"(Cost year not stated / not a Jalali year)",IFERROR(IF(N(IF(R9="USD",S9,IF(R9="IRR",S9/INDEX('Assumptions & FX Reference'!$B$5:$B$25,MATCH(Q9,'Assumptions & FX Reference'!$A$5:$A$25,0)),IF(R9="EUR",S9*INDEX('Assumptions & FX Reference'!$C$5:$C$25,MATCH(Q9,'Assumptions & FX Reference'!$A$5:$A$25,0))/INDEX('Assumptions & FX Reference'!$B$5:$B$25,MATCH(Q9,'Assumptions & FX Reference'!$A$5:$A$25,0)),"(Not stated)"))))>0,IF(R9="USD",S9,IF(R9="IRR",S9/INDEX('Assumptions & FX Reference'!$B$5:$B$25,MATCH(Q9,'Assumptions & FX Reference'!$A$5:$A$25,0)),IF(R9="EUR",S9*INDEX('Assumptions & FX Reference'!$C$5:$C$25,MATCH(Q9,'Assumptions & FX Reference'!$A$5:$A$25,0))/INDEX('Assumptions & FX Reference'!$B$5:$B$25,MATCH(Q9,'Assumptions & FX Reference'!$A$5:$A$25,0)),"(Not stated)"))),"(FX rate not entered for this year)"),"(FX rate not entered for this year)"))) -> (Cost year not stated / not a Jalali year) | V9: =IF(NOT(ISNUMBER(S9)),"(Not stated)",IF(NOT(ISNUMBER(Q9)),"(Cost year not stated / not a Jalali year)",IFERROR(IF(N(IF(R9="IRR",S9,IF(R9="USD",S9*INDEX('Assumptions & FX Reference'!$B$5:$B$25,MATCH(Q9,'Assumptions & FX Reference'!$A$5:$A$25,0)),IF(R9="EUR",S9*INDEX('Assumptions & FX Reference'!$C$5:$C$25,MATCH(Q9,'Assumptions & FX Reference'!$A$5:$A$25,0)),"(Not stated)"))))>0,IF(R9="IRR",S9,IF(R9="USD",S9*INDEX('Assumptions & FX Reference'!$B$5:$B$25,MATCH(Q9,'Assumptions & FX Reference'!$A$5:$A$25,0)),IF(R9="EUR",S9*INDEX('Assumptions & FX Reference'!$C$5:$C$25,MATCH(Q9,'Assumptions & FX Reference'!$A$5:$A$25,0)),"(Not stated)"))),"(FX rate not entered for this year)"),"(FX rate not entered for this year)"))) -> (Cost year not stated / not a Jalali year) | W9: Not Stated | X9: Not Stated | Y9: Not Stated | Z9: نمونه_قیمتی_نمک_زدایی_overall.xlsx (Sheet packages, item 8, row 10) | AA9: Price ($) = 15,000 USD. Same figure in 18061405_Pump_only_CSV.csv (section packages, item 8, file row 65), where a separate 'Customs and transportation ($)' column = 900 USD (not included in Unit Price Reference). Sample lists a launcher only (no receiver); quantity, cost year and basis not stated. | AB9: Y
A10: 6 | B10: Oily Water Separator (API Separator) | C10: Gachsaran 4 Development Plan (Proj No. 591111) | D10: SU-701 | E10: SEP | F10: SEP-OWS | G10: Not Stated | H10: Not Stated | I10: Oily Water Separator SU-701 (Process Data Sheet, E.Process item 7.40) | J10: Not Stated | K10: Not Stated | L10: Not Stated | M10: Not Stated | N10: Not Stated | O10: Not Stated | P10: Not Stated | Q10: 1402 | R10: IRR | S10: Not Stated | T10: =IF(NOT(ISNUMBER(S10)),"(Not stated)",IF(NOT(ISNUMBER(Q10)),"(Cost year not stated / not a Jalali year)",IFERROR(IF(N(IF(R10="EUR",S10,IF(R10="IRR",S10/INDEX('Assumptions & FX Reference'!$C$5:$C$25,MATCH(Q10,'Assumptions & FX Reference'!$A$5:$A$25,0)),IF(R10="USD",S10*INDEX('Assumptions & FX Reference'!$B$5:$B$25,MATCH(Q10,'Assumptions & FX Reference'!$A$5:$A$25,0))/INDEX('Assumptions & FX Reference'!$C$5:$C$25,MATCH(Q10,'Assumptions & FX Reference'!$A$5:$A$25,0)),"(Not stated)"))))>0,IF(R10="EUR",S10,IF(R10="IRR",S10/INDEX('Assumptions & FX Reference'!$C$5:$C$25,MATCH(Q10,'Assumptions & FX Reference'!$A$5:$A$25,0)),IF(R10="USD",S10*INDEX('Assumptions & FX Reference'!$B$5:$B$25,MATCH(Q10,'Assumptions & FX Reference'!$A$5:$A$25,0))/INDEX('Assumptions & FX Reference'!$C$5:$C$25,MATCH(Q10,'Assumptions & FX Reference'!$A$5:$A$25,0)),"(Not stated)"))),"(FX rate not entered for this year)"),"(FX rate not entered for this year)"))) -> (Not stated) | U10: =IF(NOT(ISNUMBER(S10)),"(Not stated)",IF(NOT(ISNUMBER(Q10)),"(Cost year not stated / not a Jalali year)",IFERROR(IF(N(IF(R10="USD",S10,IF(R10="IRR",S10/INDEX('Assumptions & FX Reference'!$B$5:$B$25,MATCH(Q10,'Assumptions & FX Reference'!$A$5:$A$25,0)),IF(R10="EUR",S10*INDEX('Assumptions & FX Reference'!$C$5:$C$25,MATCH(Q10,'Assumptions & FX Reference'!$A$5:$A$25,0))/INDEX('Assumptions & FX Reference'!$B$5:$B$25,MATCH(Q10,'Assumptions & FX Reference'!$A$5:$A$25,0)),"(Not stated)"))))>0,IF(R10="USD",S10,IF(R10="IRR",S10/INDEX('Assumptions & FX Reference'!$B$5:$B$25,MATCH(Q10,'Assumptions & FX Reference'!$A$5:$A$25,0)),IF(R10="EUR",S10*INDEX('Assumptions & FX Reference'!$C$5:$C$25,MATCH(Q10,'Assumptions & FX Reference'!$A$5:$A$25,0))/INDEX('Assumptions & FX Reference'!$B$5:$B$25,MATCH(Q10,'Assumptions & FX Reference'!$A$5:$A$25,0)),"(Not stated)"))),"(FX rate not entered for this year)"),"(FX rate not entered for this year)"))) -> (Not stated) | V10: =IF(NOT(ISNUMBER(S10)),"(Not stated)",IF(NOT(ISNUMBER(Q10)),"(Cost year not stated / not a Jalali year)",IFERROR(IF(N(IF(R10="IRR",S10,IF(R10="USD",S10*INDEX('Assumptions & FX Reference'!$B$5:$B$25,MATCH(Q10,'Assumptions & FX Reference'!$A$5:$A$25,0)),IF(R10="EUR",S10*INDEX('Assumptions & FX Reference'!$C$5:$C$25,MATCH(Q10,'Assumptions & FX Reference'!$A$5:$A$25,0)),"(Not stated)"))))>0,IF(R10="IRR",S10,IF(R10="USD",S10*INDEX('Assumptions & FX Reference'!$B$5:$B$25,MATCH(Q10,'Assumptions & FX Reference'!$A$5:$A$25,0)),IF(R10="EUR",S10*INDEX('Assumptions & FX Reference'!$C$5:$C$25,MATCH(Q10,'Assumptions & FX Reference'!$A$5:$A$25,0)),"(Not stated)"))),"(FX rate not entered for this year)"),"(FX rate not entered for this year)"))) -> (Not stated) | W10: Not Stated | X10: Class 3 (Basic) | Y10: Basic Engineering | Z10: PEP-Rev.140205_عزيزيان_Gachsaran_4.xlsx (Sheet E.Process, row 110) | AA10: No price in the Gachsaran 4 procurement table. P.ME lists only the Oily Water Separator Pump P-750 (row 55; a pump, out of scope). The separator appears elsewhere only as civil work: C.OTHERS-1 row 18 (API SEPARATOR, civil quantities), E.Civil row 95 (Oily Water Separator Section And Details) and, in Maroon 3, CV1405 row 30 ('OILY WTER SEPARATOR', 12 m x 6 m, 75 m2, 500,000,000 IRR civil base). Those are civil scope, so no price is entered here to avoid inventing one. No mechanical data sheet exists for SU-701 in E.Mechanic. Tag is not present in MASTER_TAGS / SOURCES; found by searching the source workbook. | AB10: Y
A11: 7 | B11: Portable Skimmer | C11: Gachsaran 4 Development Plan (Proj No. 591111) | D11: X-704 | E11: SEP | F11: SEP-SKM | G11: Not Stated | H11: Not Stated | I11: Portable Skimmer X-704 (Process Data Sheet, E.Process item 7.57) | J11: Not Stated | K11: Not Stated | L11: Not Stated | M11: Not Stated | N11: Not Stated | O11: Not Stated | P11: Not Stated | Q11: 1402 | R11: IRR | S11: Not Stated | T11: =IF(NOT(ISNUMBER(S11)),"(Not stated)",IF(NOT(ISNUMBER(Q11)),"(Cost year not stated / not a Jalali year)",IFERROR(IF(N(IF(R11="EUR",S11,IF(R11="IRR",S11/INDEX('Assumptions & FX Reference'!$C$5:$C$25,MATCH(Q11,'Assumptions & FX Reference'!$A$5:$A$25,0)),IF(R11="USD",S11*INDEX('Assumptions & FX Reference'!$B$5:$B$25,MATCH(Q11,'Assumptions & FX Reference'!$A$5:$A$25,0))/INDEX('Assumptions & FX Reference'!$C$5:$C$25,MATCH(Q11,'Assumptions & FX Reference'!$A$5:$A$25,0)),"(Not stated)"))))>0,IF(R11="EUR",S11,IF(R11="IRR",S11/INDEX('Assumptions & FX Reference'!$C$5:$C$25,MATCH(Q11,'Assumptions & FX Reference'!$A$5:$A$25,0)),IF(R11="USD",S11*INDEX('Assumptions & FX Reference'!$B$5:$B$25,MATCH(Q11,'Assumptions & FX Reference'!$A$5:$A$25,0))/INDEX('Assumptions & FX Reference'!$C$5:$C$25,MATCH(Q11,'Assumptions & FX Reference'!$A$5:$A$25,0)),"(Not stated)"))),"(FX rate not entered for this year)"),"(FX rate not entered for this year)"))) -> (Not stated) | U11: =IF(NOT(ISNUMBER(S11)),"(Not stated)",IF(NOT(ISNUMBER(Q11)),"(Cost year not stated / not a Jalali year)",IFERROR(IF(N(IF(R11="USD",S11,IF(R11="IRR",S11/INDEX('Assumptions & FX Reference'!$B$5:$B$25,MATCH(Q11,'Assumptions & FX Reference'!$A$5:$A$25,0)),IF(R11="EUR",S11*INDEX('Assumptions & FX Reference'!$C$5:$C$25,MATCH(Q11,'Assumptions & FX Reference'!$A$5:$A$25,0))/INDEX('Assumptions & FX Reference'!$B$5:$B$25,MATCH(Q11,'Assumptions & FX Reference'!$A$5:$A$25,0)),"(Not stated)"))))>0,IF(R11="USD",S11,IF(R11="IRR",S11/INDEX('Assumptions & FX Reference'!$B$5:$B$25,MATCH(Q11,'Assumptions & FX Reference'!$A$5:$A$25,0)),IF(R11="EUR",S11*INDEX('Assumptions & FX Reference'!$C$5:$C$25,MATCH(Q11,'Assumptions & FX Reference'!$A$5:$A$25,0))/INDEX('Assumptions & FX Reference'!$B$5:$B$25,MATCH(Q11,'Assumptions & FX Reference'!$A$5:$A$25,0)),"(Not stated)"))),"(FX rate not entered for this year)"),"(FX rate not entered for this year)"))) -> (Not stated) | V11: =IF(NOT(ISNUMBER(S11)),"(Not stated)",IF(NOT(ISNUMBER(Q11)),"(Cost year not stated / not a Jalali year)",IFERROR(IF(N(IF(R11="IRR",S11,IF(R11="USD",S11*INDEX('Assumptions & FX Reference'!$B$5:$B$25,MATCH(Q11,'Assumptions & FX Reference'!$A$5:$A$25,0)),IF(R11="EUR",S11*INDEX('Assumptions & FX Reference'!$C$5:$C$25,MATCH(Q11,'Assumptions & FX Reference'!$A$5:$A$25,0)),"(Not stated)"))))>0,IF(R11="IRR",S11,IF(R11="USD",S11*INDEX('Assumptions & FX Reference'!$B$5:$B$25,MATCH(Q11,'Assumptions & FX Reference'!$A$5:$A$25,0)),IF(R11="EUR",S11*INDEX('Assumptions & FX Reference'!$C$5:$C$25,MATCH(Q11,'Assumptions & FX Reference'!$A$5:$A$25,0)),"(Not stated)"))),"(FX rate not entered for this year)"),"(FX rate not entered for this year)"))) -> (Not stated) | W11: Not Stated | X11: Class 3 (Basic) | Y11: Basic Engineering | Z11: PEP-Rev.140205_عزيزيان_Gachsaran_4.xlsx (Sheet E.Process, row 127) | AA11: No price in the Gachsaran 4 procurement table. Only a process data sheet is listed (no mechanical data sheet, no P.ME row). Not to be confused with Oil Skimmer Tank OS-201 (P.ME row 26, a tank priced per kg), which is excluded per the tank/drum scope. Tag is not present in MASTER_TAGS / SOURCES; found by searching the source workbook. | AB11: Y
A12: 8 | B12: Crude Aerial Cooler (Air Cooler) | C12: Not Stated (reference price sample, file نمونه_قیمتی_نمک_زدایی_overall.xlsx) | D12: (No Tag - price sample item 1) | E12: ACX | F12: ACX-AIR | G12: Not Stated | H12: Not Stated | I12: Air-cooled heat exchanger (crude service); Draft: Forced; fixed pitch, TEFC fan motors, speed control by VFD (per CSV) | J12: Duty 2.9 x 1.1 MW; bare area 475.7 m2/unit; 2 bays/unit; 4 fans/unit | K12: 7 | L12: 100 | M12: Header: C.S; Tube: C.S | N12: Not Stated | O12: 104.8 kW total consumed power per unit | P12: Not Stated | Q12: Not Stated | R12: USD | S12: 2200000 | T12: =IF(NOT(ISNUMBER(S12)),"(Not stated)",IF(NOT(ISNUMBER(Q12)),"(Cost year not stated / not a Jalali year)",IFERROR(IF(N(IF(R12="EUR",S12,IF(R12="IRR",S12/INDEX('Assumptions & FX Reference'!$C$5:$C$25,MATCH(Q12,'Assumptions & FX Reference'!$A$5:$A$25,0)),IF(R12="USD",S12*INDEX('Assumptions & FX Reference'!$B$5:$B$25,MATCH(Q12,'Assumptions & FX Reference'!$A$5:$A$25,0))/INDEX('Assumptions & FX Reference'!$C$5:$C$25,MATCH(Q12,'Assumptions & FX Reference'!$A$5:$A$25,0)),"(Not stated)"))))>0,IF(R12="EUR",S12,IF(R12="IRR",S12/INDEX('Assumptions & FX Reference'!$C$5:$C$25,MATCH(Q12,'Assumptions & FX Reference'!$A$5:$A$25,0)),IF(R12="USD",S12*INDEX('Assumptions & FX Reference'!$B$5:$B$25,MATCH(Q12,'Assumptions & FX Reference'!$A$5:$A$25,0))/INDEX('Assumptions & FX Reference'!$C$5:$C$25,MATCH(Q12,'Assumptions & FX Reference'!$A$5:$A$25,0)),"(Not stated)"))),"(FX rate not entered for this year)"),"(FX rate not entered for this year)"))) -> (Cost year not stated / not a Jalali year) | U12: =IF(NOT(ISNUMBER(S12)),"(Not stated)",IF(NOT(ISNUMBER(Q12)),"(Cost year not stated / not a Jalali year)",IFERROR(IF(N(IF(R12="USD",S12,IF(R12="IRR",S12/INDEX('Assumptions & FX Reference'!$B$5:$B$25,MATCH(Q12,'Assumptions & FX Reference'!$A$5:$A$25,0)),IF(R12="EUR",S12*INDEX('Assumptions & FX Reference'!$C$5:$C$25,MATCH(Q12,'Assumptions & FX Reference'!$A$5:$A$25,0))/INDEX('Assumptions & FX Reference'!$B$5:$B$25,MATCH(Q12,'Assumptions & FX Reference'!$A$5:$A$25,0)),"(Not stated)"))))>0,IF(R12="USD",S12,IF(R12="IRR",S12/INDEX('Assumptions & FX Reference'!$B$5:$B$25,MATCH(Q12,'Assumptions & FX Reference'!$A$5:$A$25,0)),IF(R12="EUR",S12*INDEX('Assumptions & FX Reference'!$C$5:$C$25,MATCH(Q12,'Assumptions & FX Reference'!$A$5:$A$25,0))/INDEX('Assumptions & FX Reference'!$B$5:$B$25,MATCH(Q12,'Assumptions & FX Reference'!$A$5:$A$25,0)),"(Not stated)"))),"(FX rate not entered for this year)"),"(FX rate not entered for this year)"))) -> (Cost year not stated / not a Jalali year) | V12: =IF(NOT(ISNUMBER(S12)),"(Not stated)",IF(NOT(ISNUMBER(Q12)),"(Cost year not stated / not a Jalali year)",IFERROR(IF(N(IF(R12="IRR",S12,IF(R12="USD",S12*INDEX('Assumptions & FX Reference'!$B$5:$B$25,MATCH(Q12,'Assumptions & FX Reference'!$A$5:$A$25,0)),IF(R12="EUR",S12*INDEX('Assumptions & FX Reference'!$C$5:$C$25,MATCH(Q12,'Assumptions & FX Reference'!$A$5:$A$25,0)),"(Not stated)"))))>0,IF(R12="IRR",S12,IF(R12="USD",S12*INDEX('Assumptions & FX Reference'!$B$5:$B$25,MATCH(Q12,'Assumptions & FX Reference'!$A$5:$A$25,0)),IF(R12="EUR",S12*INDEX('Assumptions & FX Reference'!$C$5:$C$25,MATCH(Q12,'Assumptions & FX Reference'!$A$5:$A$25,0)),"(Not stated)"))),"(FX rate not entered for this year)"),"(FX rate not entered for this year)"))) -> (Cost year not stated / not a Jalali year) | W12: Not Stated | X12: Not Stated | Y12: Not Stated | Z12: نمونه_قیمتی_نمک_زدایی_overall.xlsx (Sheet AIR COOLERS, item 1, row 3) | AA12: Price ($) = 2,200,000 USD. Same row in 18061405_Pump_only_CSV.csv (section AIR COOLERS, file row 43; area 476 m2, 105 kW rounded) with 'Customs and transportation ($)' = 132,000 USD (not included). The 'fixed pitch-TEFC-speed control by VFD' text sits under the Header Type column in the CSV and is blank in the xlsx, so it is recorded as a service note. Duty printed as '2.9 x 1.1' in source. Quantity, cost year and basis not stated. No air cooler found in KPL, Pazanan 2, Gachsaran 4 or Maroon 3 files. | AB12: Y
A13: 9 | B13: HVAC for Accommodation | C13: Gachsaran 4 Development Plan (Proj No. 591111) | D13: (No Tag - P.ME item 66.1) | E13: HVAC | F13: HVAC-SYS | G13: 1 | H13: SET | I13: HVAC for Accommodation (P.ME item 66.1 under HVAC group item 66) | J13: Not Stated | K13: Not Stated | L13: Not Stated | M13: Not Stated | N13: Not Stated | O13: Not Stated | P13: Not Stated | Q13: 1402 | R13: IRR | S13: 1300000000 | T13: =IF(NOT(ISNUMBER(S13)),"(Not stated)",IF(NOT(ISNUMBER(Q13)),"(Cost year not stated / not a Jalali year)",IFERROR(IF(N(IF(R13="EUR",S13,IF(R13="IRR",S13/INDEX('Assumptions & FX Reference'!$C$5:$C$25,MATCH(Q13,'Assumptions & FX Reference'!$A$5:$A$25,0)),IF(R13="USD",S13*INDEX('Assumptions & FX Reference'!$B$5:$B$25,MATCH(Q13,'Assumptions & FX Reference'!$A$5:$A$25,0))/INDEX('Assumptions & FX Reference'!$C$5:$C$25,MATCH(Q13,'Assumptions & FX Reference'!$A$5:$A$25,0)),"(Not stated)"))))>0,IF(R13="EUR",S13,IF(R13="IRR",S13/INDEX('Assumptions & FX Reference'!$C$5:$C$25,MATCH(Q13,'Assumptions & FX Reference'!$A$5:$A$25,0)),IF(R13="USD",S13*INDEX('Assumptions & FX Reference'!$B$5:$B$25,MATCH(Q13,'Assumptions & FX Reference'!$A$5:$A$25,0))/INDEX('Assumptions & FX Reference'!$C$5:$C$25,MATCH(Q13,'Assumptions & FX Reference'!$A$5:$A$25,0)),"(Not stated)"))),"(FX rate not entered for this year)"),"(FX rate not entered for this year)"))) -> 2455.1464 | U13: =IF(NOT(ISNUMBER(S13)),"(Not stated)",IF(NOT(ISNUMBER(Q13)),"(Cost year not stated / not a Jalali year)",IFERROR(IF(N(IF(R13="USD",S13,IF(R13="IRR",S13/INDEX('Assumptions & FX Reference'!$B$5:$B$25,MATCH(Q13,'Assumptions & FX Reference'!$A$5:$A$25,0)),IF(R13="EUR",S13*INDEX('Assumptions & FX Reference'!$C$5:$C$25,MATCH(Q13,'Assumptions & FX Reference'!$A$5:$A$25,0))/INDEX('Assumptions & FX Reference'!$B$5:$B$25,MATCH(Q13,'Assumptions & FX Reference'!$A$5:$A$25,0)),"(Not stated)"))))>0,IF(R13="USD",S13,IF(R13="IRR",S13/INDEX('Assumptions & FX Reference'!$B$5:$B$25,MATCH(Q13,'Assumptions & FX Reference'!$A$5:$A$25,0)),IF(R13="EUR",S13*INDEX('Assumptions & FX Reference'!$C$5:$C$25,MATCH(Q13,'Assumptions & FX Reference'!$A$5:$A$25,0))/INDEX('Assumptions & FX Reference'!$B$5:$B$25,MATCH(Q13,'Assumptions & FX Reference'!$A$5:$A$25,0)),"(Not stated)"))),"(FX rate not entered for this year)"),"(FX rate not entered for this year)"))) -> 3095.2381 | V13: =IF(NOT(ISNUMBER(S13)),"(Not stated)",IF(NOT(ISNUMBER(Q13)),"(Cost year not stated / not a Jalali year)",IFERROR(IF(N(IF(R13="IRR",S13,IF(R13="USD",S13*INDEX('Assumptions & FX Reference'!$B$5:$B$25,MATCH(Q13,'Assumptions & FX Reference'!$A$5:$A$25,0)),IF(R13="EUR",S13*INDEX('Assumptions & FX Reference'!$C$5:$C$25,MATCH(Q13,'Assumptions & FX Reference'!$A$5:$A$25,0)),"(Not stated)"))))>0,IF(R13="IRR",S13,IF(R13="USD",S13*INDEX('Assumptions & FX Reference'!$B$5:$B$25,MATCH(Q13,'Assumptions & FX Reference'!$A$5:$A$25,0)),IF(R13="EUR",S13*INDEX('Assumptions & FX Reference'!$C$5:$C$25,MATCH(Q13,'Assumptions & FX Reference'!$A$5:$A$25,0)),"(Not stated)"))),"(FX rate not entered for this year)"),"(FX rate not entered for this year)"))) -> 1300000000 | W13: FOB | X13: Class 3 (Basic) | Y13: Basic Engineering | Z13: PEP-Rev.140205_عزيزيان_Gachsaran_4.xlsx (Sheet P.ME, row 84) | AA13: Unit cost without overhead factor (هزینه واحد بدون ضریب). HVAC group header row 83 carries its own freight allocation of 1,207,442,136.32 IRR (not included); Customs clearance not stated. Equipment list / data sheets are in the E.HVAC document set. | AB13: Y
A14: 10 | B14: HVAC for DE4 Switchgear Room | C14: Gachsaran 4 Development Plan (Proj No. 591111) | D14: (No Tag - P.ME item 66.2) | E14: HVAC | F14: HVAC-SYS | G14: 1 | H14: SET | I14: HVAC for DE4 Switchgear Room (P.ME item 66.2 under HVAC group item 66) | J14: Not Stated | K14: Not Stated | L14: Not Stated | M14: Not Stated | N14: Not Stated | O14: Not Stated | P14: Not Stated | Q14: 1402 | R14: IRR | S14: 115920000000 | T14: =IF(NOT(ISNUMBER(S14)),"(Not stated)",IF(NOT(ISNUMBER(Q14)),"(Cost year not stated / not a Jalali year)",IFERROR(IF(N(IF(R14="EUR",S14,IF(R14="IRR",S14/INDEX('Assumptions & FX Reference'!$C$5:$C$25,MATCH(Q14,'Assumptions & FX Reference'!$A$5:$A$25,0)),IF(R14="USD",S14*INDEX('Assumptions & FX Reference'!$B$5:$B$25,MATCH(Q14,'Assumptions & FX Reference'!$A$5:$A$25,0))/INDEX('Assumptions & FX Reference'!$C$5:$C$25,MATCH(Q14,'Assumptions & FX Reference'!$A$5:$A$25,0)),"(Not stated)"))))>0,IF(R14="EUR",S14,IF(R14="IRR",S14/INDEX('Assumptions & FX Reference'!$C$5:$C$25,MATCH(Q14,'Assumptions & FX Reference'!$A$5:$A$25,0)),IF(R14="USD",S14*INDEX('Assumptions & FX Reference'!$B$5:$B$25,MATCH(Q14,'Assumptions & FX Reference'!$A$5:$A$25,0))/INDEX('Assumptions & FX Reference'!$C$5:$C$25,MATCH(Q14,'Assumptions & FX Reference'!$A$5:$A$25,0)),"(Not stated)"))),"(FX rate not entered for this year)"),"(FX rate not entered for this year)"))) -> 218923.51 | U14: =IF(NOT(ISNUMBER(S14)),"(Not stated)",IF(NOT(ISNUMBER(Q14)),"(Cost year not stated / not a Jalali year)",IFERROR(IF(N(IF(R14="USD",S14,IF(R14="IRR",S14/INDEX('Assumptions & FX Reference'!$B$5:$B$25,MATCH(Q14,'Assumptions & FX Reference'!$A$5:$A$25,0)),IF(R14="EUR",S14*INDEX('Assumptions & FX Reference'!$C$5:$C$25,MATCH(Q14,'Assumptions & FX Reference'!$A$5:$A$25,0))/INDEX('Assumptions & FX Reference'!$B$5:$B$25,MATCH(Q14,'Assumptions & FX Reference'!$A$5:$A$25,0)),"(Not stated)"))))>0,IF(R14="USD",S14,IF(R14="IRR",S14/INDEX('Assumptions & FX Reference'!$B$5:$B$25,MATCH(Q14,'Assumptions & FX Reference'!$A$5:$A$25,0)),IF(R14="EUR",S14*INDEX('Assumptions & FX Reference'!$C$5:$C$25,MATCH(Q14,'Assumptions & FX Reference'!$A$5:$A$25,0))/INDEX('Assumptions & FX Reference'!$B$5:$B$25,MATCH(Q14,'Assumptions & FX Reference'!$A$5:$A$25,0)),"(Not stated)"))),"(FX rate not entered for this year)"),"(FX rate not entered for this year)"))) -> 276000 | V14: =IF(NOT(ISNUMBER(S14)),"(Not stated)",IF(NOT(ISNUMBER(Q14)),"(Cost year not stated / not a Jalali year)",IFERROR(IF(N(IF(R14="IRR",S14,IF(R14="USD",S14*INDEX('Assumptions & FX Reference'!$B$5:$B$25,MATCH(Q14,'Assumptions & FX Reference'!$A$5:$A$25,0)),IF(R14="EUR",S14*INDEX('Assumptions & FX Reference'!$C$5:$C$25,MATCH(Q14,'Assumptions & FX Reference'!$A$5:$A$25,0)),"(Not stated)"))))>0,IF(R14="IRR",S14,IF(R14="USD",S14*INDEX('Assumptions & FX Reference'!$B$5:$B$25,MATCH(Q14,'Assumptions & FX Reference'!$A$5:$A$25,0)),IF(R14="EUR",S14*INDEX('Assumptions & FX Reference'!$C$5:$C$25,MATCH(Q14,'Assumptions & FX Reference'!$A$5:$A$25,0)),"(Not stated)"))),"(FX rate not entered for this year)"),"(FX rate not entered for this year)"))) -> 115920000000 | W14: FOB | X14: Class 3 (Basic) | Y14: Basic Engineering | Z14: PEP-Rev.140205_عزيزيان_Gachsaran_4.xlsx (Sheet P.ME, row 85) | AA14: Unit cost without overhead factor (هزینه واحد بدون ضریب). Source formula = 276,000 USD x USD_Change_IRR (420,000 IRR/USD) = 115,920,000,000 IRR. HVAC group header row 83 carries its own freight allocation of 1,207,442,136.32 IRR (not included); Customs clearance not stated. Equipment list / data sheets are in the E.HVAC document set. | AB14: Y
A15: 11 | B15: HVAC for DE4 Control Room | C15: Gachsaran 4 Development Plan (Proj No. 591111) | D15: (No Tag - P.ME item 66.3) | E15: HVAC | F15: HVAC-SYS | G15: 1 | H15: SET | I15: HVAC for DE4 Control Room (P.ME item 66.3 under HVAC group item 66) | J15: Not Stated | K15: Not Stated | L15: Not Stated | M15: Not Stated | N15: Not Stated | O15: Not Stated | P15: Not Stated | Q15: 1402 | R15: IRR | S15: 141120000000 | T15: =IF(NOT(ISNUMBER(S15)),"(Not stated)",IF(NOT(ISNUMBER(Q15)),"(Cost year not stated / not a Jalali year)",IFERROR(IF(N(IF(R15="EUR",S15,IF(R15="IRR",S15/INDEX('Assumptions & FX Reference'!$C$5:$C$25,MATCH(Q15,'Assumptions & FX Reference'!$A$5:$A$25,0)),IF(R15="USD",S15*INDEX('Assumptions & FX Reference'!$B$5:$B$25,MATCH(Q15,'Assumptions & FX Reference'!$A$5:$A$25,0))/INDEX('Assumptions & FX Reference'!$C$5:$C$25,MATCH(Q15,'Assumptions & FX Reference'!$A$5:$A$25,0)),"(Not stated)"))))>0,IF(R15="EUR",S15,IF(R15="IRR",S15/INDEX('Assumptions & FX Reference'!$C$5:$C$25,MATCH(Q15,'Assumptions & FX Reference'!$A$5:$A$25,0)),IF(R15="USD",S15*INDEX('Assumptions & FX Reference'!$B$5:$B$25,MATCH(Q15,'Assumptions & FX Reference'!$A$5:$A$25,0))/INDEX('Assumptions & FX Reference'!$C$5:$C$25,MATCH(Q15,'Assumptions & FX Reference'!$A$5:$A$25,0)),"(Not stated)"))),"(FX rate not entered for this year)"),"(FX rate not entered for this year)"))) -> 266515.58 | U15: =IF(NOT(ISNUMBER(S15)),"(Not stated)",IF(NOT(ISNUMBER(Q15)),"(Cost year not stated / not a Jalali year)",IFERROR(IF(N(IF(R15="USD",S15,IF(R15="IRR",S15/INDEX('Assumptions & FX Reference'!$B$5:$B$25,MATCH(Q15,'Assumptions & FX Reference'!$A$5:$A$25,0)),IF(R15="EUR",S15*INDEX('Assumptions & FX Reference'!$C$5:$C$25,MATCH(Q15,'Assumptions & FX Reference'!$A$5:$A$25,0))/INDEX('Assumptions & FX Reference'!$B$5:$B$25,MATCH(Q15,'Assumptions & FX Reference'!$A$5:$A$25,0)),"(Not stated)"))))>0,IF(R15="USD",S15,IF(R15="IRR",S15/INDEX('Assumptions & FX Reference'!$B$5:$B$25,MATCH(Q15,'Assumptions & FX Reference'!$A$5:$A$25,0)),IF(R15="EUR",S15*INDEX('Assumptions & FX Reference'!$C$5:$C$25,MATCH(Q15,'Assumptions & FX Reference'!$A$5:$A$25,0))/INDEX('Assumptions & FX Reference'!$B$5:$B$25,MATCH(Q15,'Assumptions & FX Reference'!$A$5:$A$25,0)),"(Not stated)"))),"(FX rate not entered for this year)"),"(FX rate not entered for this year)"))) -> 336000 | V15: =IF(NOT(ISNUMBER(S15)),"(Not stated)",IF(NOT(ISNUMBER(Q15)),"(Cost year not stated / not a Jalali year)",IFERROR(IF(N(IF(R15="IRR",S15,IF(R15="USD",S15*INDEX('Assumptions & FX Reference'!$B$5:$B$25,MATCH(Q15,'Assumptions & FX Reference'!$A$5:$A$25,0)),IF(R15="EUR",S15*INDEX('Assumptions & FX Reference'!$C$5:$C$25,MATCH(Q15,'Assumptions & FX Reference'!$A$5:$A$25,0)),"(Not stated)"))))>0,IF(R15="IRR",S15,IF(R15="USD",S15*INDEX('Assumptions & FX Reference'!$B$5:$B$25,MATCH(Q15,'Assumptions & FX Reference'!$A$5:$A$25,0)),IF(R15="EUR",S15*INDEX('Assumptions & FX Reference'!$C$5:$C$25,MATCH(Q15,'Assumptions & FX Reference'!$A$5:$A$25,0)),"(Not stated)"))),"(FX rate not entered for this year)"),"(FX rate not entered for this year)"))) -> 141120000000 | W15: FOB | X15: Class 3 (Basic) | Y15: Basic Engineering | Z15: PEP-Rev.140205_عزيزيان_Gachsaran_4.xlsx (Sheet P.ME, row 86) | AA15: Unit cost without overhead factor (هزینه واحد بدون ضریب). Source formula = 336,000 USD x USD_Change_IRR (420,000 IRR/USD) = 141,120,000,000 IRR. HVAC group header row 83 carries its own freight allocation of 1,207,442,136.32 IRR (not included); Customs clearance not stated. Equipment list / data sheets are in the E.HVAC document set. | AB15: Y
A16: 12 | B16: HVAC for 33 kV Station | C16: Gachsaran 4 Development Plan (Proj No. 591111) | D16: (No Tag - P.ME item 66.4) | E16: HVAC | F16: HVAC-SYS | G16: 1 | H16: SET | I16: HVAC for 33 kV Station (P.ME item 66.4 under HVAC group item 66) | J16: Not Stated | K16: Not Stated | L16: Not Stated | M16: Not Stated | N16: Not Stated | O16: Not Stated | P16: Not Stated | Q16: 1402 | R16: IRR | S16: 92400000000 | T16: =IF(NOT(ISNUMBER(S16)),"(Not stated)",IF(NOT(ISNUMBER(Q16)),"(Cost year not stated / not a Jalali year)",IFERROR(IF(N(IF(R16="EUR",S16,IF(R16="IRR",S16/INDEX('Assumptions & FX Reference'!$C$5:$C$25,MATCH(Q16,'Assumptions & FX Reference'!$A$5:$A$25,0)),IF(R16="USD",S16*INDEX('Assumptions & FX Reference'!$B$5:$B$25,MATCH(Q16,'Assumptions & FX Reference'!$A$5:$A$25,0))/INDEX('Assumptions & FX Reference'!$C$5:$C$25,MATCH(Q16,'Assumptions & FX Reference'!$A$5:$A$25,0)),"(Not stated)"))))>0,IF(R16="EUR",S16,IF(R16="IRR",S16/INDEX('Assumptions & FX Reference'!$C$5:$C$25,MATCH(Q16,'Assumptions & FX Reference'!$A$5:$A$25,0)),IF(R16="USD",S16*INDEX('Assumptions & FX Reference'!$B$5:$B$25,MATCH(Q16,'Assumptions & FX Reference'!$A$5:$A$25,0))/INDEX('Assumptions & FX Reference'!$C$5:$C$25,MATCH(Q16,'Assumptions & FX Reference'!$A$5:$A$25,0)),"(Not stated)"))),"(FX rate not entered for this year)"),"(FX rate not entered for this year)"))) -> 174504.25 | U16: =IF(NOT(ISNUMBER(S16)),"(Not stated)",IF(NOT(ISNUMBER(Q16)),"(Cost year not stated / not a Jalali year)",IFERROR(IF(N(IF(R16="USD",S16,IF(R16="IRR",S16/INDEX('Assumptions & FX Reference'!$B$5:$B$25,MATCH(Q16,'Assumptions & FX Reference'!$A$5:$A$25,0)),IF(R16="EUR",S16*INDEX('Assumptions & FX Reference'!$C$5:$C$25,MATCH(Q16,'Assumptions & FX Reference'!$A$5:$A$25,0))/INDEX('Assumptions & FX Reference'!$B$5:$B$25,MATCH(Q16,'Assumptions & FX Reference'!$A$5:$A$25,0)),"(Not stated)"))))>0,IF(R16="USD",S16,IF(R16="IRR",S16/INDEX('Assumptions & FX Reference'!$B$5:$B$25,MATCH(Q16,'Assumptions & FX Reference'!$A$5:$A$25,0)),IF(R16="EUR",S16*INDEX('Assumptions & FX Reference'!$C$5:$C$25,MATCH(Q16,'Assumptions & FX Reference'!$A$5:$A$25,0))/INDEX('Assumptions & FX Reference'!$B$5:$B$25,MATCH(Q16,'Assumptions & FX Reference'!$A$5:$A$25,0)),"(Not stated)"))),"(FX rate not entered for this year)"),"(FX rate not entered for this year)"))) -> 220000 | V16: =IF(NOT(ISNUMBER(S16)),"(Not stated)",IF(NOT(ISNUMBER(Q16)),"(Cost year not stated / not a Jalali year)",IFERROR(IF(N(IF(R16="IRR",S16,IF(R16="USD",S16*INDEX('Assumptions & FX Reference'!$B$5:$B$25,MATCH(Q16,'Assumptions & FX Reference'!$A$5:$A$25,0)),IF(R16="EUR",S16*INDEX('Assumptions & FX Reference'!$C$5:$C$25,MATCH(Q16,'Assumptions & FX Reference'!$A$5:$A$25,0)),"(Not stated)"))))>0,IF(R16="IRR",S16,IF(R16="USD",S16*INDEX('Assumptions & FX Reference'!$B$5:$B$25,MATCH(Q16,'Assumptions & FX Reference'!$A$5:$A$25,0)),IF(R16="EUR",S16*INDEX('Assumptions & FX Reference'!$C$5:$C$25,MATCH(Q16,'Assumptions & FX Reference'!$A$5:$A$25,0)),"(Not stated)"))),"(FX rate not entered for this year)"),"(FX rate not entered for this year)"))) -> 92400000000 | W16: FOB | X16: Class 3 (Basic) | Y16: Basic Engineering | Z16: PEP-Rev.140205_عزيزيان_Gachsaran_4.xlsx (Sheet P.ME, row 87) | AA16: Unit cost without overhead factor (هزینه واحد بدون ضریب). Source formula = 220,000 USD x USD_Change_IRR (420,000 IRR/USD) = 92,400,000,000 IRR. HVAC group header row 83 carries its own freight allocation of 1,207,442,136.32 IRR (not included); Customs clearance not stated. Equipment list / data sheets are in the E.HVAC document set. | AB16: Y
A17: 13 | B17: HVAC for 33/3.45 Station | C17: Gachsaran 4 Development Plan (Proj No. 591111) | D17: (No Tag - P.ME item 66.5) | E17: HVAC | F17: HVAC-SYS | G17: 1 | H17: SET | I17: HVAC for 33/3.45 Station (P.ME item 66.5 under HVAC group item 66) | J17: Not Stated | K17: Not Stated | L17: Not Stated | M17: Not Stated | N17: Not Stated | O17: Not Stated | P17: Not Stated | Q17: 1402 | R17: IRR | S17: 3700000000 | T17: =IF(NOT(ISNUMBER(S17)),"(Not stated)",IF(NOT(ISNUMBER(Q17)),"(Cost year not stated / not a Jalali year)",IFERROR(IF(N(IF(R17="EUR",S17,IF(R17="IRR",S17/INDEX('Assumptions & FX Reference'!$C$5:$C$25,MATCH(Q17,'Assumptions & FX Reference'!$A$5:$A$25,0)),IF(R17="USD",S17*INDEX('Assumptions & FX Reference'!$B$5:$B$25,MATCH(Q17,'Assumptions & FX Reference'!$A$5:$A$25,0))/INDEX('Assumptions & FX Reference'!$C$5:$C$25,MATCH(Q17,'Assumptions & FX Reference'!$A$5:$A$25,0)),"(Not stated)"))))>0,IF(R17="EUR",S17,IF(R17="IRR",S17/INDEX('Assumptions & FX Reference'!$C$5:$C$25,MATCH(Q17,'Assumptions & FX Reference'!$A$5:$A$25,0)),IF(R17="USD",S17*INDEX('Assumptions & FX Reference'!$B$5:$B$25,MATCH(Q17,'Assumptions & FX Reference'!$A$5:$A$25,0))/INDEX('Assumptions & FX Reference'!$C$5:$C$25,MATCH(Q17,'Assumptions & FX Reference'!$A$5:$A$25,0)),"(Not stated)"))),"(FX rate not entered for this year)"),"(FX rate not entered for this year)"))) -> 6987.7243 | U17: =IF(NOT(ISNUMBER(S17)),"(Not stated)",IF(NOT(ISNUMBER(Q17)),"(Cost year not stated / not a Jalali year)",IFERROR(IF(N(IF(R17="USD",S17,IF(R17="IRR",S17/INDEX('Assumptions & FX Reference'!$B$5:$B$25,MATCH(Q17,'Assumptions & FX Reference'!$A$5:$A$25,0)),IF(R17="EUR",S17*INDEX('Assumptions & FX Reference'!$C$5:$C$25,MATCH(Q17,'Assumptions & FX Reference'!$A$5:$A$25,0))/INDEX('Assumptions & FX Reference'!$B$5:$B$25,MATCH(Q17,'Assumptions & FX Reference'!$A$5:$A$25,0)),"(Not stated)"))))>0,IF(R17="USD",S17,IF(R17="IRR",S17/INDEX('Assumptions & FX Reference'!$B$5:$B$25,MATCH(Q17,'Assumptions & FX Reference'!$A$5:$A$25,0)),IF(R17="EUR",S17*INDEX('Assumptions & FX Reference'!$C$5:$C$25,MATCH(Q17,'Assumptions & FX Reference'!$A$5:$A$25,0))/INDEX('Assumptions & FX Reference'!$B$5:$B$25,MATCH(Q17,'Assumptions & FX Reference'!$A$5:$A$25,0)),"(Not stated)"))),"(FX rate not entered for this year)"),"(FX rate not entered for this year)"))) -> 8809.5238 | V17: =IF(NOT(ISNUMBER(S17)),"(Not stated)",IF(NOT(ISNUMBER(Q17)),"(Cost year not stated / not a Jalali year)",IFERROR(IF(N(IF(R17="IRR",S17,IF(R17="USD",S17*INDEX('Assumptions & FX Reference'!$B$5:$B$25,MATCH(Q17,'Assumptions & FX Reference'!$A$5:$A$25,0)),IF(R17="EUR",S17*INDEX('Assumptions & FX Reference'!$C$5:$C$25,MATCH(Q17,'Assumptions & FX Reference'!$A$5:$A$25,0)),"(Not stated)"))))>0,IF(R17="IRR",S17,IF(R17="USD",S17*INDEX('Assumptions & FX Reference'!$B$5:$B$25,MATCH(Q17,'Assumptions & FX Reference'!$A$5:$A$25,0)),IF(R17="EUR",S17*INDEX('Assumptions & FX Reference'!$C$5:$C$25,MATCH(Q17,'Assumptions & FX Reference'!$A$5:$A$25,0)),"(Not stated)"))),"(FX rate not entered for this year)"),"(FX rate not entered for this year)"))) -> 3700000000 | W17: FOB | X17: Class 3 (Basic) | Y17: Basic Engineering | Z17: PEP-Rev.140205_عزيزيان_Gachsaran_4.xlsx (Sheet P.ME, row 88) | AA17: Unit cost without overhead factor (هزینه واحد بدون ضریب). HVAC group header row 83 carries its own freight allocation of 1,207,442,136.32 IRR (not included); Customs clearance not stated. Equipment list / data sheets are in the E.HVAC document set. | AB17: Y
