Workbook
Name ________________GEN1: [1]D!#REF!
Name ________________GEN1: [1]D!#REF!
Name ________________GEN1: [1]D!#REF!
Name ________________GEN1: [1]D!#REF!
Name ________________GEN1: [1]D!#REF!
Name ________________GEN1: [1]D!#REF!
Name ________________GEN1: [1]D!#REF!
Name ________________GEN1: [1]D!#REF!
Name ________________GEN1: [1]D!#REF!
Name ________________GEN1: [1]D!#REF!
Name ________________GEN1: [1]D!#REF!
Name ________________GEN1: [1]D!#REF!
Name ________________GEN1: [1]D!#REF!
Name ________________GEN1: [1]D!#REF!
Name ________________GEN1: [1]D!#REF!
Name ________________GEN1: [1]D!#REF!
Name ________________GEN1: [1]D!#REF!
Name ________________GEN1: [1]D!#REF!
Name ______GEN1: [1]D!#REF!
Name ______GEN1: [1]D!#REF!
Name _____GEN1: [1]D!#REF!
Name _____GEN1: [1]D!#REF!
Name ____GEN1: [1]D!#REF!
Name ____GEN1: [1]D!#REF!
Name ____GEN1: [1]D!#REF!
Name ____GEN1: [1]D!#REF!
Name ____GEN1: [1]D!#REF!
Name ____GEN1: [1]D!#REF!
Name ____GEN1: [1]D!#REF!
Name ____GEN1: [1]D!#REF!
Name ____GEN1: [1]D!#REF!
Name ____GEN1: [1]D!#REF!
Name ____GEN1: [1]D!#REF!
Name ____GEN1: [1]D!#REF!
Name ____GEN1: [1]D!#REF!
Name ____GEN1: [1]D!#REF!
Name ____GEN1: [1]D!#REF!
Name ____GEN1: [1]D!#REF!
Name ____GEN1: [1]D!#REF!
Name ____GEN1: [1]D!#REF!
Name ____GEN1: [1]D!#REF!
Name ____GEN1: [1]D!#REF!
Name ___GEN1: [1]D!#REF!
Name ___GEN1: [1]D!#REF!
Name _GEN1: [1]D!#REF!
Name _GEN1: [1]D!#REF!
Name _GEN1: [1]D!#REF!
Name _GEN1: [1]D!#REF!
Name _GEN1: [1]D!#REF!
Name _GEN1: [1]D!#REF!
Name _GEN1: [1]D!#REF!
Name _GEN1: [1]D!#REF!
Name _GEN1: [1]D!#REF!
Name _GEN1: [1]D!#REF!
Name _GEN1: [1]D!#REF!
Name _GEN1: [1]D!#REF!
Name _GEN1: [1]D!#REF!
Name _GEN1: [1]D!#REF!
Name _GEN1: [1]D!#REF!
Name _GEN1: [1]D!#REF!

Sheet Cover
A1: Project Title: Revamping of Pazanan II Desalting Plant
A2: Sub-Project Title: Basic Design Studies and Preparation of FEED Package for Revamping of Pazanan II Desalting Plant
A3: Project Budget Ref. 03229 (formerly 53-51-91211)
A4: Doc. Title: BASIC MTO & COST ESTMATION REPORT (MECHANICAL)
A5: Doc. Ref. 91211-PZN-ME-RE-451-R02
A7: DOCUMENT TITLE: MECHANICAL BASIC DESIGN MTO & COST ESTIMATION REPORT
A65: R02 | D65: FEB. 2015 | I65: 91211-TN-ME-0316 | P65: IBB | U65: M.F. | Z65: M.Kh. | AE65: M.M.
A66: R01 | D66: SEP. 2014 | I66: 91211-TN-ME-0304 | P66: IBB | U66: M.F. | Z66: M.Kh. | AE66: M.M.
A67: R00 | D67: JUN. 2014 | I67: 91211-TN-ME-0286 | P67: IFC | U67: M.F. | Z67: M.Kh. | AE67: M.M.
A68: REV. | D68: DATE | I68: TRANS. No. | P68: P.O.I. | U68: PREPARED | Z68: CHECKED | AE68: APPROVED | AJ68: AUTHORIZED

Sheet Record Sheet
A1: Project Title: Revamping of Pazanan II Desalting Plant
A2: Sub-Project Title: Basic Design Studies and Preparation of FEED Package for Revamping of Pazanan II Desalting Plant
A3: Project Budget Ref. 03229 (formerly 53-51-91211)
A4: Doc. Title: BASIC MTO & COST ESTMATION REPORT (MECHANICAL)
A5: Doc. Ref. 91211-PZN-ME-RE-451-R02
P9: CHANGE RECORD SHEET
E11: PAGE | G11: R01 | J11: R02 | M11: R03 | P11: R04 | X11: PAGE | Z11: R01 | AC11: R02 | AF11: R03 | AI11: R04
E12: 1 | G12: X | X12: 51
E13: 2 | G13: X | X13: 52
E14: 3 | G14: X | X14: 53
E15: 4 | G15: X | X15: 54
E16: 5 | G16: X | X16: 55
E17: 6 | G17: X | X17: 56
E18: 7 | G18: X | X18: 57
E19: 8 | G19: X | X19: 58
E20: 9 | G20: X | X20: 59
E21: 10 | G21: X | X21: 60
E22: 11 | G22: X | X22: 61
E23: 12 | G23: X | X23: 62
... E60: 49 | G60: X | X60: 99
E61: 50 | X61: 100

Sheet TITLE
A1: Project Title: Revamping of Pazanan II Desalting Plant
A2: Sub-Project Title: Basic Design Studies and Preparation of FEED Package for Revamping of Pazanan II Desalting Plant
A3: Project Budget Ref. 03229 (formerly 53-51-91211)
A4: Doc. Title: BASIC MTO & COST ESTMATION REPORT (MECHANICAL)
A5: Doc. Ref. 91211-PZN-ME-RE-451-R02
A7: PROCUREMENT MTO & COST ESTIMATION

Sheet DESALTER
A1: Project Title: Revamping of Pazanan II Desalting Plant
A2: Sub-Project Title: Basic Design Studies and Preparation of FEED Package for Revamping of Pazanan II Desalting Plant
A3: Project Budget Ref. 03229 (formerly 53-51-91211)
A4: Doc. Title: BASIC MTO & COST ESTMATION REPORT (MECHANICAL)
A5: Doc. Ref. 91211-PZN-ME-RE-451-R02
A6: DESALTING PACKAGES | I6: استعلام 1 | N6: استعلام 2 | S6: استعلام 3 | X6: استعلام 4 | AC6: استعلام 5 | AU6: استعلام 6 | AZ6: استعلام 7 | BE6: استعلام 8 | BJ6: استعلام 9 | BO6: استعلام 10 | BT6: استعلام 11
A7: Item No. | B7: Description | C7: Qty. (Set) | E7: GOING UNIT PRICE IRR 1404Q1 | F7: GOING UNIT PRICE FOB EUR 1404Q1 | G7: TOTAL PRICE ریال | H7: TOTAL PRICE FOB € | I7: منبع | J7: بهای واحد (ریال) | K7: بهای واحد (یورو) | L7: بهای واحد (دلار) | M7: تاریخ مرجع | N7: منبع | O7: بهای واحد (ریال) | P7: بهای واحد (یورو) | Q7: بهای واحد (دلار) | R7: تاریخ مرجع | S7: منبع | T7: بهای واحد (ریال) | U7: بهای واحد (یورو) | V7: بهای واحد (دلار) | W7: تاریخ مرجع | X7: منبع | Y7: بهای واحد (ریال) | Z7: بهای واحد (یورو) | AA7: بهای واحد (دلار) | AB7: تاریخ مرجع | AC7: منبع | AD7: بهای واحد (ریال) | AE7: بهای واحد (یورو) | AF7: بهای واحد (دلار) | AG7: تاریخ مرجع | AH7: No. of available quotations in IRR | AI7: No. of available quotations in EUR | AJ7: No. of available quotations in USD | AK7: avg. of IRR quotations converted to EUR | AL7: avg. of EUR quotations EUR | AM7: avg. of USD quotations converted to EUR | AN7: aggregate average quoted unit price (all in EUR) | AO7: Ref. Currency | AP7: quoted unit price | AQ7: UNIT PRICE ریال 1393Q3 | AR7: UNIT PRICE FOB € - 1393Q3 | AS7: NEW ITEM unit price IRR | AT7: NEW ITEM unit price EUR | AU7: منبع | AV7: بهای واحد (ریال) | AW7: بهای واحد (یورو) | AX7: بهای واحد (دلار) | AY7: تاریخ مرجع | AZ7: منبع | BA7: بهای واحد (ریال) | BB7: بهای واحد (یورو) | BC7: بهای واحد (دلار) | BD7: تاریخ مرجع | BE7: منبع | BF7: بهای واحد (ریال) | BG7: بهای واحد (یورو) | BH7: بهای واحد (دلار) | BI7: تاریخ مرجع | BJ7: منبع | BK7: بهای واحد (ریال) | BL7: بهای واحد (یورو) | BM7: بهای واحد (دلار) | BN7: تاریخ مرجع | BO7: منبع | BP7: بهای واحد (ریال) | BQ7: بهای واحد (یورو) | BR7: بهای واحد (دلار) | BS7: تاریخ مرجع | BT7: منبع | BU7: بهای واحد (ریال) | BV7: بهای واحد (یورو) | BW7: بهای واحد (دلار) | BX7: تاریخ مرجع
A8: PK-111 | B8: Desalting Package Type: Electrostatic - AC / DC Including 1st Desalter (W/ 3 x 50% Transformer), Recycle Pumps, Related Piping, Instruments, etc. Desalter Vessel Tag No.: DE-111 Vessels Dim. (ID x TL-TL): 3658 x 16764 mm Vessels Design Pressure: 15.5 Barg Vessels Design Temperature: -2.8 / 95 oC Vessels Mat. (Shell/Heads): SA 516 Gr. 70 NACE 'MR-0175' Required: Yes Vessel Design Code & Standard: ASME VIII, DIV.1 & IPS-G-ME-150 Recycle Pumps Tag Nos.: P-112 A/B Pumps Type: Centrifugal (OH2) Pumps Rated Flow (m3/hr): 20.2 Pumps Differential Pressure (Barg): 4.5 Pumps Material Class(Acc. to API 610): D2 NACE 'MR-0175' Required: Yes Pumps Design Code & Standard: API 610 & IPS-G-PM-105 | C8: 1 | E8: =IF(AND(AO8="IRR",SUM(AH8:AJ8)>0),AP8,IF(AND(AO8="IRR",AQ8<>""),AQ8*'[5]Basic INFO'!$E$127,IF(AO8="IRR",AS8,""))) | F8: =IF(AND(AO8="EUR",SUM(AH8:AJ8)>0),AP8,IF(AND(AO8="EUR",AR8<>""),AR8*'[5]Basic INFO'!$C$138,IF(AO8="EUR",AT8,""))) -> 1932650.5 | G8: =IF(AO8="IRR",C8*E8,"") | H8: =IF(AO8="EUR",C8*F8,"") -> 1932650.5 | I8: گازتک ایرانیان | K8: 1815301 | M8: 45686 | N8: مصنوعات فلزی سنگین | P8: 2050000 | R8: 45716 | S8: Thermo Engineering, Italy | W8: declined | X8: خرد صنعت | AB8: no reply | AC8: Petro Technca, Canada | AG8: no reply | AH8: =IF(B8="","",COUNT(J8,O8,T8,Y8,AD8)) -> 0 | AI8: =IF(B8="","",COUNT(K8,P8,U8,Z8,AE8)) -> 2 | AJ8: =IF(B8="","",COUNT(L8,Q8,V8,AA8,AF8)) -> 0 | AK8: =IF(AND(AH8<>"",AH8>0),AVERAGE(J8,O8,T8,Y8,AD8)/('[5]Basic INFO'!$C$101*'[5]Basic INFO'!$C$103),"") | AL8: =IF(AND(AI8<>"",AI8>0),AVERAGE(K8,P8,U8,Z8,AE8),"") -> 1932650.5 | AM8: =IF(AND(AJ8<>"",AJ8>0),AVERAGE(L8,Q8,V8,AA8,AF8)/'[5]Basic INFO'!$C$103,"") | AN8: =IF(SUM(AH8:AJ8)<>0,AVERAGE(AK8:AM8),"") -> 1932650.5 | AO8: EUR | AP8: =IF(B8="","",IF(SUM(AH8:AJ8)=0,"",IF(AO8="IRR",AN8*('[5]Basic INFO'!$C$101*'[5]Basic INFO'!$C$103),IF(AO8="EUR",AN8,AP8)))) -> 1932650.5 | AR8: 2500000 | AU8: Aker Solutions, Norway | AY8: no reply | AZ8: Axens, France | BD8: no reply | BE8: Desalters LLC, USA | BI8: no reply | BJ8: Sulzer, USA | BN8: no reply | BO8: Howe Baker | BS8: no reply | BT8: Process Systems, France | BX8: no reply
B9: برآورد هزینه بدون سربار و مالیات بر ارزش افزوده | G9: =SUM(G8) -> 0 | H9: =SUM(H8) -> 1932650.5
B10: ضریب سربار تأمین کالا | G10: 1.18 | H10: 1.18
B11: مالیات بر ارزش افزوده | G11: 0.1 | H11: 0.1
B12: هزینه تأمین کالا + سربار + مالیات بر ارزش افزوده | G12: =ROUND((G9*G10*(1+G11))/1000000,0)*1000000 -> 0 | H12: =ROUND(H9*H10*(1+H11)/1000,0)*1000 -> 2509000
G13: =ROUND(SUMIF(AP:AP,">0",G:G)*G10*(1+G11)/1000000,0)*1000000 -> 0 | H13: =ROUND(SUMIF(AP:AP,">0",H:H)*H10*(1+H11)/1000,0)*1000 -> 2509000

Sheet HEATERS
A1: Project Title: Revamping of Pazanan II Desalting Plant
A2: Sub-Project Title: Basic Design Studies and Preparation of FEED Package for Revamping of Pazanan II Desalting Plant
A3: Project Budget Ref. 03229 (formerly 53-51-91211)
A4: Doc. Title: BASIC MTO & COST ESTMATION REPORT (MECHANICAL)
A5: Doc. Ref. 91211-PZN-ME-RE-451-R02
A6: INDIRECT FIRED HEATER PACKAGES | I6: استعلام 1 | N6: استعلام 2 | S6: استعلام 3 | X6: استعلام 4 | AC6: استعلام 5 | AU6: استعلام 6 | AZ6: استعلام 7 | BE6: استعلام 8 | BJ6: استعلام 9 | BO6: استعلام 10 | BT6: استعلام 11 | BY6: استعلام 12 | CD6: استعلام 13
A7: Item No. | B7: Description | C7: Qty. (Set) | E7: GOING UNIT PRICE IRR 1404Q1 | F7: GOING UNIT PRICE FOB EUR 1404Q1 | G7: TOTAL PRICE ریال | H7: TOTAL PRICE FOB € | I7: منبع | J7: بهای واحد (ریال) | K7: بهای واحد (یورو) | L7: بهای واحد (دلار) | M7: تاریخ مرجع | N7: منبع | O7: بهای واحد (ریال) | P7: بهای واحد (یورو) | Q7: بهای واحد (دلار) | R7: تاریخ مرجع | S7: منبع | T7: بهای واحد (ریال) | U7: بهای واحد (یورو) | V7: بهای واحد (دلار) | W7: تاریخ مرجع | X7: منبع | Y7: بهای واحد (ریال) | Z7: بهای واحد (یورو) | AA7: بهای واحد (دلار) | AB7: تاریخ مرجع | AC7: منبع | AD7: بهای واحد (ریال) | AE7: بهای واحد (یورو) | AF7: بهای واحد (دلار) | AG7: تاریخ مرجع | AH7: No. of available quotations in IRR | AI7: No. of available quotations in EUR | AJ7: No. of available quotations in USD | AK7: avg. of IRR quotations converted to EUR | AL7: avg. of EUR quotations EUR | AM7: avg. of USD quotations converted to EUR | AN7: aggregate average quoted unit price (all in EUR) | AO7: Ref. Currency | AP7: quoted unit price | AQ7: UNIT PRICE ریال 1393Q3 | AR7: UNIT PRICE FOB € - 1393Q3 | AS7: NEW ITEM unit price IRR | AT7: NEW ITEM unit price EUR | AU7: منبع | AV7: بهای واحد (ریال) | AW7: بهای واحد (یورو) | AX7: بهای واحد (دلار) | AY7: تاریخ مرجع | AZ7: منبع | BA7: بهای واحد (ریال) | BB7: بهای واحد (یورو) | BC7: بهای واحد (دلار) | BD7: تاریخ مرجع | BE7: منبع | BF7: بهای واحد (ریال) | BG7: بهای واحد (یورو) | BH7: بهای واحد (دلار) | BI7: تاریخ مرجع | BJ7: منبع | BK7: بهای واحد (ریال) | BL7: بهای واحد (یورو) | BM7: بهای واحد (دلار) | BN7: تاریخ مرجع | BO7: منبع | BP7: بهای واحد (ریال) | BQ7: بهای واحد (یورو) | BR7: بهای واحد (دلار) | BS7: تاریخ مرجع | BT7: منبع | BU7: بهای واحد (ریال) | BV7: بهای واحد (یورو) | BW7: بهای واحد (دلار) | BX7: تاریخ مرجع | BY7: منبع | BZ7: بهای واحد (ریال) | CA7: بهای واحد (یورو) | CB7: بهای واحد (دلار) | CC7: تاریخ مرجع | CD7: منبع | CE7: بهای واحد (ریال) | CF7: بهای واحد (یورو) | CG7: بهای واحد (دلار) | CH7: تاریخ مرجع
A8: H-111 A/B | B8: Oil Indirect Fired Heater Packages Rated Heat Exchanged (KW): 7725 Shell Dim. (ID x TL-TL): 3900 x 12000 mm Design Press. (Shell/Coils): 0.3/15.5 Barg Design Temperature: -2.8 / 120 oC Material (Shell/Heads): SA 516 Gr. 70 Material (Coils): SA 106 Gr. B NACE 'MR-0175' Required: Yes (for Coils) Design Code & Standard: API Spec.12K , ASME VIII, DIV.1 & IPS-G-ME-200 | C8: 2 | E8: =IF(AND(AO8="IRR",SUM(AH8:AJ8)>0),AP8,IF(AND(AO8="IRR",AQ8<>""),AQ8*'[5]Basic INFO'!$E$127,IF(AO8="IRR",AS8,""))) | F8: =IF(AND(AO8="EUR",SUM(AH8:AJ8)>0),AP8,IF(AND(AO8="EUR",AR8<>""),AR8*'[5]Basic INFO'!$C$138,IF(AO8="EUR",AT8,""))) -> 1164712.8 | G8: =IF(AO8="IRR",C8*E8,"") | H8: =IF(AO8="EUR",C8*F8,"") -> 2329425.7 | I8: گازتک ایرانیان | K8: 1044138.5 | M8: 45686 | N8: انرزی گستر ماد | P8: 1400000 | S8: مصنوعات فلزی سنگین | U8: 1050000 | W8: 45716 | X8: Thermo Engineering, Italy | AB8: declined | AC8: خرد صنعت | AG8: no reply | AH8: =IF(B8="","",COUNT(J8,O8,T8,Y8,AD8)) -> 0 | AI8: =IF(B8="","",COUNT(K8,P8,U8,Z8,AE8)) -> 3 | AJ8: =IF(B8="","",COUNT(L8,Q8,V8,AA8,AF8)) -> 0 | AK8: =IF(AND(AH8<>"",AH8>0),AVERAGE(J8,O8,T8,Y8,AD8)/('[5]Basic INFO'!$C$101*'[5]Basic INFO'!$C$103),"") | AL8: =IF(AND(AI8<>"",AI8>0),AVERAGE(K8,P8,U8,Z8,AE8),"") -> 1164712.8 | AM8: =IF(AND(AJ8<>"",AJ8>0),AVERAGE(L8,Q8,V8,AA8,AF8)/'[5]Basic INFO'!$C$103,"") | AN8: =IF(SUM(AH8:AJ8)<>0,AVERAGE(AK8:AM8),"") -> 1164712.8 | AO8: EUR | AP8: =IF(B8="","",IF(SUM(AH8:AJ8)=0,"",IF(AO8="IRR",AN8*('[5]Basic INFO'!$C$101*'[5]Basic INFO'!$C$103),IF(AO8="EUR",AN8,AP8)))) -> 1164712.8 | AR8: 800000 | AU8: Petro Technca, Canada | AY8: no reply | AZ8: Aker Solutions, Norway | BD8: no reply | BE8: Axens, France | BI8: no reply | BJ8: Desalters LLC, USA | BN8: no reply | BO8: Sulzer, USA | BS8: no reply | BT8: Howe Baker | BX8: no reply | BY8: Process Systems, France | CC8: no reply | CD8: شرکت چمان | CH8: no reply
A9: H-112 | B9: Water Indirect Fired Heater Packages Rated Heat Exchanged (KW): 4174 Dimsion (ID x TL-TL): 2800 x 10400 mm Design Press. (Shell/Coils): 0.3/15.5 Barg Design Temperature: -2.8 / 120 oC Material (Shell/Heads): SA 516 Gr. 70 Material (Coils): SA 106 Gr. B Design Code & Standard: API Spec.12K , ASME VIII, DIV.1 & IPS-G-ME-200 | C9: 1 | E9: =IF(AND(AO9="IRR",SUM(AH9:AJ9)>0),AP9,IF(AND(AO9="IRR",AQ9<>""),AQ9*'[5]Basic INFO'!$E$127,IF(AO9="IRR",AS9,""))) | F9: =IF(AND(AO9="EUR",SUM(AH9:AJ9)>0),AP9,IF(AND(AO9="EUR",AR9<>""),AR9*'[5]Basic INFO'!$C$138,IF(AO9="EUR",AT9,""))) -> 1090791.3 | G9: =IF(AO9="IRR",C9*E9,"") | H9: =IF(AO9="EUR",C9*F9,"") -> 1090791.3 | I9: گازتک ایرانیان | K9: 1452374 | M9: 45686 | N9: انرزی گستر ماد | P9: 1200000 | S9: مصنوعات فلزی سنگین | U9: 620000 | W9: 45716 | X9: Thermo Engineering, Italy | AB9: declined | AC9: خرد صنعت | AG9: no reply | AH9: =IF(B9="","",COUNT(J9,O9,T9,Y9,AD9)) -> 0 | AI9: =IF(B9="","",COUNT(K9,P9,U9,Z9,AE9)) -> 3 | AJ9: =IF(B9="","",COUNT(L9,Q9,V9,AA9,AF9)) -> 0 | AK9: =IF(AND(AH9<>"",AH9>0),AVERAGE(J9,O9,T9,Y9,AD9)/('[5]Basic INFO'!$C$101*'[5]Basic INFO'!$C$103),"") | AL9: =IF(AND(AI9<>"",AI9>0),AVERAGE(K9,P9,U9,Z9,AE9),"") -> 1090791.3 | AM9: =IF(AND(AJ9<>"",AJ9>0),AVERAGE(L9,Q9,V9,AA9,AF9)/'[5]Basic INFO'!$C$103,"") | AN9: =IF(SUM(AH9:AJ9)<>0,AVERAGE(AK9:AM9),"") -> 1090791.3 | AO9: EUR | AP9: =IF(B9="","",IF(SUM(AH9:AJ9)=0,"",IF(AO9="IRR",AN9*('[5]Basic INFO'!$C$101*'[5]Basic INFO'!$C$103),IF(AO9="EUR",AN9,AP9)))) -> 1090791.3 | AR9: 680000 | AU9: Petro Technca, Canada | AY9: no reply | AZ9: Aker Solutions, Norway | BD9: no reply | BE9: Axens, France | BI9: no reply | BJ9: Desalters LLC, USA | BN9: no reply | BO9: Sulzer, USA | BS9: no reply | BT9: Howe Baker | BX9: no reply | BY9: Process Systems, France | CC9: no reply | CD9: شرکت چمان | CH9: no reply
B10: برآورد هزینه بدون سربار و مالیات بر ارزش افزوده | G10: =SUM(G8:G9) -> 0 | H10: =SUM(H8:H9) -> 3420217
B11: ضریب سربار تأمین کالا | G11: 1.18 | H11: 1.18
B12: مالیات بر ارزش افزوده | G12: 0.1 | H12: 0.1
B13: هزینه تأمین کالا + سربار + مالیات بر ارزش افزوده | G13: =ROUND((G10*G11*(1+G12))/1000000,0)*1000000 -> 0 | H13: =ROUND(H10*H11*(1+H12)/1000,0)*1000 -> 4439000
G14: =ROUND(SUMIF(AP:AP,">0",G:G)*G11*(1+G12)/1000000,0)*1000000 -> 0 | H14: =ROUND(SUMIF(AP:AP,">0",H:H)*H11*(1+H12)/1000,0)*1000 -> 4439000

Sheet VESSELS
A1: Project Title: Revamping of Pazanan II Desalting Plant
A2: Sub-Project Title: Basic Design Studies and Preparation of FEED Package for Revamping of Pazanan II Desalting Plant
A3: Project Budget Ref. 03229 (formerly 53-51-91211)
A4: Doc. Title: BASIC MTO & COST ESTMATION REPORT (MECHANICAL)
A5: Doc. Ref. 91211-PZN-ME-RE-451-R02
A6: VESSELS | I6: استعلام 1 | N6: استعلام 2 | S6: استعلام 3 | X6: استعلام 4 | AC6: استعلام 5
A7: Item No. | B7: Description | C7: Qty. (Set) | E7: GOING UNIT PRICE IRR 1404Q1 | F7: GOING UNIT PRICE FOB EUR 1404Q1 | G7: TOTAL PRICE ریال | H7: TOTAL PRICE FOB € | I7: منبع | J7: بهای واحد (ریال) | K7: بهای واحد (یورو) | L7: بهای واحد (دلار) | M7: تاریخ مرجع | N7: منبع | O7: بهای واحد (ریال) | P7: بهای واحد (یورو) | Q7: بهای واحد (دلار) | R7: تاریخ مرجع | S7: منبع | T7: بهای واحد (ریال) | U7: بهای واحد (یورو) | V7: بهای واحد (دلار) | W7: تاریخ مرجع | X7: منبع | Y7: بهای واحد (ریال) | Z7: بهای واحد (یورو) | AA7: بهای واحد (دلار) | AB7: تاریخ مرجع | AC7: منبع | AD7: بهای واحد (ریال) | AE7: بهای واحد (یورو) | AF7: بهای واحد (دلار) | AG7: تاریخ مرجع | AH7: No. of available quotations in IRR | AI7: No. of available quotations in EUR | AJ7: No. of available quotations in USD | AK7: avg. of IRR quotations converted to EUR | AL7: avg. of EUR quotations EUR | AM7: avg. of USD quotations converted to EUR | AN7: aggregate average quoted unit price (all in EUR) | AO7: Ref. Currency | AP7: quoted unit price | AQ7: Unit Price (Rials) | AR7: Unit Price 'FOB' (€) | AS7: NEW ITEM unit price IRR | AT7: NEW ITEM unit price EUR
A8: V-141 | B8: Air Receiver Size (ID x TL-TL): 2300 x 6900 mm Installation Position: Vertical Design Pressure: 13.5 Barg Design Temperature: -2.8 / 85 oC Material (Shell/Heads): SA 516 Gr. 70 Design Code & Standard: ASME VIII, DIV.1 & IPS-G-ME-150 | C8: 1 | E8: =IF(AND(AO8="IRR",SUM(AH8:AJ8)>0),AP8,IF(AND(AO8="IRR",AQ8<>""),AQ8*'[5]Basic INFO'!$E$127,IF(AO8="IRR",AS8,""))) -> 4.5889668e+10 | F8: =IF(AND(AO8="EUR",SUM(AH8:AJ8)>0),AP8,IF(AND(AO8="EUR",AR8<>""),AR8*'[5]Basic INFO'!$C$138,IF(AO8="EUR",AT8,""))) | G8: =IF(AO8="IRR",C8*E8,"") -> 4.5889668e+10 | H8: =IF(AO8="EUR",C8*F8,"") | I8: طرح مکانیک گستر شیراز | M8: no reply | N8: پایساز | R8: no reply | S8: تاشا | W8: no reply | X8: ماشین سازی اراک | Z8: 84000 | AB8: 02/29/2025 | AC8: پولادورزان کیمیا | AE8: =4*12000 -> 48000 | AG8: 45801 | AH8: =IF(B8="","",COUNT(J8,O8,T8,Y8,AD8)) -> 0 | AI8: =IF(B8="","",COUNT(K8,P8,U8,Z8,AE8)) -> 2 | AJ8: =IF(B8="","",COUNT(L8,Q8,V8,AA8,AF8)) -> 0 | AK8: =IF(AND(AH8<>"",AH8>0),AVERAGE(J8,O8,T8,Y8,AD8)/('[5]Basic INFO'!$C$101*'[5]Basic INFO'!$C$103),"") | AL8: =IF(AND(AI8<>"",AI8>0),AVERAGE(K8,P8,U8,Z8,AE8),"") -> 66000 | AM8: =IF(AND(AJ8<>"",AJ8>0),AVERAGE(L8,Q8,V8,AA8,AF8)/'[5]Basic INFO'!$C$103,"") | AN8: =IF(SUM(AH8:AJ8)<>0,AVERAGE(AK8:AM8),"") -> 66000 | AO8: IRR | AP8: =IF(B8="","",IF(SUM(AH8:AJ8)=0,"",IF(AO8="IRR",AN8*('[5]Basic INFO'!$C$101*'[5]Basic INFO'!$C$103),IF(AO8="EUR",AN8,AP8)))) -> 4.5889668e+10 | AQ8: 1700000000
A9: V-151 | B9: Flare K.O. Drum Size (ID x TL-TL): 1300 x 3900 mm Installation Position: Horizontal Design Pressure: 3.5 (F.V.) Barg Design Temperature: -2.8 / 85 oC Material (Shell/Heads): SA 516 Gr. 70 NACE 'MR-0175' Required: Yes Design Code & Standard: ASME VIII, DIV.1 & IPS-G-ME-150 | C9: 1 | E9: =IF(AND(AO9="IRR",SUM(AH9:AJ9)>0),AP9,IF(AND(AO9="IRR",AQ9<>""),AQ9*'[5]Basic INFO'!$E$127,IF(AO9="IRR",AS9,""))) -> 1.1124768e+10 | F9: =IF(AND(AO9="EUR",SUM(AH9:AJ9)>0),AP9,IF(AND(AO9="EUR",AR9<>""),AR9*'[5]Basic INFO'!$C$138,IF(AO9="EUR",AT9,""))) | G9: =IF(AO9="IRR",C9*E9,"") -> 1.1124768e+10 | H9: =IF(AO9="EUR",C9*F9,"") | I9: طرح مکانیک گستر شیراز | M9: no reply | N9: پایساز | R9: no reply | S9: تاشا | W9: no reply | X9: ماشین سازی اراک | Z9: 16000 | AB9: 02/29/2025 | AC9: پولادورزان کیمیا | AE9: =4*4000 -> 16000 | AG9: 45801 | AH9: =IF(B9="","",COUNT(J9,O9,T9,Y9,AD9)) -> 0 | AI9: =IF(B9="","",COUNT(K9,P9,U9,Z9,AE9)) -> 2 | AJ9: =IF(B9="","",COUNT(L9,Q9,V9,AA9,AF9)) -> 0 | AK9: =IF(AND(AH9<>"",AH9>0),AVERAGE(J9,O9,T9,Y9,AD9)/('[5]Basic INFO'!$C$101*'[5]Basic INFO'!$C$103),"") | AL9: =IF(AND(AI9<>"",AI9>0),AVERAGE(K9,P9,U9,Z9,AE9),"") -> 16000 | AM9: =IF(AND(AJ9<>"",AJ9>0),AVERAGE(L9,Q9,V9,AA9,AF9)/'[5]Basic INFO'!$C$103,"") | AN9: =IF(SUM(AH9:AJ9)<>0,AVERAGE(AK9:AM9),"") -> 16000 | AO9: IRR | AP9: =IF(B9="","",IF(SUM(AH9:AJ9)=0,"",IF(AO9="IRR",AN9*('[5]Basic INFO'!$C$101*'[5]Basic INFO'!$C$103),IF(AO9="EUR",AN9,AP9)))) -> 1.1124768e+10 | AQ9: 675000000
A10: V-161 | B10: Closed Drain Drum Size (ID x TL-TL): 2000 x 8000 mm Installation Position: Horizontal Design Pressure: 3.5 (F.V.) Barg Design Temperature: -2.8 / 85 oC Material (Shell/Heads): SA 516 Gr. 70 NACE 'MR-0175' Required: Yes Design Code & Standard: ASME VIII, DIV.1 & IPS-G-ME-150 | C10: 1 | E10: =IF(AND(AO10="IRR",SUM(AH10:AJ10)>0),AP10,IF(AND(AO10="IRR",AQ10<>""),AQ10*'[5]Basic INFO'!$E$127,IF(AO10="IRR",AS10,""))) -> 3.6711734e+10 | F10: =IF(AND(AO10="EUR",SUM(AH10:AJ10)>0),AP10,IF(AND(AO10="EUR",AR10<>""),AR10*'[5]Basic INFO'!$C$138,IF(AO10="EUR",AT10,""))) | G10: =IF(AO10="IRR",C10*E10,"") -> 3.6711734e+10 | H10: =IF(AO10="EUR",C10*F10,"") | I10: طرح مکانیک گستر شیراز | M10: no reply | N10: پایساز | R10: no reply | S10: تاشا | W10: no reply | X10: ماشین سازی اراک | Z10: 65600 | AB10: 2/29/2025 | AC10: پولادورزان کیمیا | AE10: =4*10000 -> 40000 | AG10: 45801 | AH10: =IF(B10="","",COUNT(J10,O10,T10,Y10,AD10)) -> 0 | AI10: =IF(B10="","",COUNT(K10,P10,U10,Z10,AE10)) -> 2 | AJ10: =IF(B10="","",COUNT(L10,Q10,V10,AA10,AF10)) -> 0 | AK10: =IF(AND(AH10<>"",AH10>0),AVERAGE(J10,O10,T10,Y10,AD10)/('[5]Basic INFO'!$C$101*'[5]Basic INFO'!$C$103),"") | AL10: =IF(AND(AI10<>"",AI10>0),AVERAGE(K10,P10,U10,Z10,AE10),"") -> 52800 | AM10: =IF(AND(AJ10<>"",AJ10>0),AVERAGE(L10,Q10,V10,AA10,AF10)/'[5]Basic INFO'!$C$103,"") | AN10: =IF(SUM(AH10:AJ10)<>0,AVERAGE(AK10:AM10),"") -> 52800 | AO10: IRR | AP10: =IF(B10="","",IF(SUM(AH10:AJ10)=0,"",IF(AO10="IRR",AN10*('[5]Basic INFO'!$C$101*'[5]Basic INFO'!$C$103),IF(AO10="EUR",AN10,AP10)))) -> 3.6711734e+10 | AQ10: 1600000000
A11: V-171 | B11: Fuel Oil Storage Drum Size (ID x TL-TL): 1500 x 4500 mm Installation Position: Horizontal Design Pressure: Atm. + Full of Liquid Design Temperature: -2.8 / 85 oC Material (Shell/Heads): SA 285 Gr. C Design Code & Standard: ASME VIII, DIV.1 & IPS-G-ME-150 | C11: 1 | E11: =IF(AND(AO11="IRR",SUM(AH11:AJ11)>0),AP11,IF(AND(AO11="IRR",AQ11<>""),AQ11*'[5]Basic INFO'!$E$127,IF(AO11="IRR",AS11,""))) -> 1.029041e+10 | F11: =IF(AND(AO11="EUR",SUM(AH11:AJ11)>0),AP11,IF(AND(AO11="EUR",AR11<>""),AR11*'[5]Basic INFO'!$C$138,IF(AO11="EUR",AT11,""))) | G11: =IF(AO11="IRR",C11*E11,"") -> 1.029041e+10 | H11: =IF(AO11="EUR",C11*F11,"") | I11: طرح مکانیک گستر شیراز | M11: no reply | N11: پایساز | R11: no reply | S11: تاشا | W11: no reply | X11: ماشین سازی اراک | Z11: 21600 | AB11: 2/29/2025 | AC11: پولادورزان کیمیا | AE11: =4*2000 -> 8000 | AG11: 45801 | AH11: =IF(B11="","",COUNT(J11,O11,T11,Y11,AD11)) -> 0 | AI11: =IF(B11="","",COUNT(K11,P11,U11,Z11,AE11)) -> 2 | AJ11: =IF(B11="","",COUNT(L11,Q11,V11,AA11,AF11)) -> 0 | AK11: =IF(AND(AH11<>"",AH11>0),AVERAGE(J11,O11,T11,Y11,AD11)/('[5]Basic INFO'!$C$101*'[5]Basic INFO'!$C$103),"") | AL11: =IF(AND(AI11<>"",AI11>0),AVERAGE(K11,P11,U11,Z11,AE11),"") -> 14800 | AM11: =IF(AND(AJ11<>"",AJ11>0),AVERAGE(L11,Q11,V11,AA11,AF11)/'[5]Basic INFO'!$C$103,"") | AN11: =IF(SUM(AH11:AJ11)<>0,AVERAGE(AK11:AM11),"") -> 14800 | AO11: IRR | AP11: =IF(B11="","",IF(SUM(AH11:AJ11)=0,"",IF(AO11="IRR",AN11*('[5]Basic INFO'!$C$101*'[5]Basic INFO'!$C$103),IF(AO11="EUR",AN11,AP11)))) -> 1.029041e+10 | AQ11: 370000000
B12: برآورد هزینه بدون سربار و مالیات بر ارزش افزوده | G12: =SUM(G8:G11) -> 1.0401658e+11 | H12: =SUM(H8:H11) -> 0 | AQ12: Total Price (Rials) | AR12: Total Price (Euros)
B13: ضریب سربار تأمین کالا | G13: 1.18 | H13: 1.18
B14: مالیات بر ارزش افزوده | G14: 0.1 | H14: 0.1
B15: هزینه تأمین کالا + سربار + مالیات بر ارزش افزوده | G15: =ROUND((G12*G13*(1+G14))/1000000,0)*1000000 -> 135014000000 | H15: =ROUND(H12*H13*(1+H14)/1000,0)*1000 -> 0
G16: =ROUND(SUMIF(AP:AP,">0",G:G)*G13*(1+G14)/1000000,0)*1000000 -> 135014000000 | H16: =ROUND(SUMIF(AP:AP,">0",H:H)*H13*(1+H14)/1000,0)*1000 -> 0

Sheet TANKS
A1: Project Title: Revamping of Pazanan II Desalting Plant
A2: Sub-Project Title: Basic Design Studies and Preparation of FEED Package for Revamping of Pazanan II Desalting Plant
A3: Project Budget Ref. 03229 (formerly 53-51-91211)
A4: Doc. Title: BASIC MTO & COST ESTMATION REPORT (MECHANICAL)
A5: Doc. Ref. 91211-PZN-ME-RE-451-R02
A6: TANKS | I6: استعلام 1 | N6: استعلام 2 | S6: استعلام 3 | X6: استعلام 4 | AC6: استعلام 5
A7: Item No. | B7: Description | C7: Qty. (Set) | E7: GOING UNIT PRICE IRR 1404Q1 | F7: GOING UNIT PRICE FOB EUR 1404Q1 | G7: TOTAL PRICE ریال | H7: TOTAL PRICE FOB € | I7: منبع | J7: بهای واحد (ریال) | K7: بهای واحد (یورو) | L7: بهای واحد (دلار) | M7: تاریخ مرجع | N7: منبع | O7: بهای واحد (ریال) | P7: بهای واحد (یورو) | Q7: بهای واحد (دلار) | R7: تاریخ مرجع | S7: منبع | T7: بهای واحد (ریال) | U7: بهای واحد (یورو) | V7: بهای واحد (دلار) | W7: تاریخ مرجع | X7: منبع | Y7: بهای واحد (ریال) | Z7: بهای واحد (یورو) | AA7: بهای واحد (دلار) | AB7: تاریخ مرجع | AC7: منبع | AD7: بهای واحد (ریال) | AE7: بهای واحد (یورو) | AF7: بهای واحد (دلار) | AG7: تاریخ مرجع | AH7: No. of available quotations in IRR | AI7: No. of available quotations in EUR | AJ7: No. of available quotations in USD | AK7: avg. of IRR quotations converted to EUR | AL7: avg. of EUR quotations EUR | AM7: avg. of USD quotations converted to EUR | AN7: aggregate average quoted unit price (all in EUR) | AO7: Ref. Currency | AP7: quoted unit price | AQ7: Unit Price (Rials) | AR7: Unit Price 'FOB' (€) | AS7: NEW ITEM unit price IRR | AT7: NEW ITEM unit price EUR
A8: TK-111 | B8: Off Spec. Tank Size (D x H): 20000 x 13000 mm Roof Type: Dome Design Pressure: -0.4 / 25 Kpa(g) Design Temperature: -2.8 / 85 oC Material (Shell/Bottom/Roof): A 283 Gr. C NACE 'MR-0175' Required: Yes Design Code & Standard: API 620 & IPS-G-ME-110 | C8: 1 | E8: =IF(AND(AO8="IRR",SUM(AH8:AJ8)>0),AP8,IF(AND(AO8="IRR",AQ8<>""),AQ8*'[5]Basic INFO'!$E$127,IF(AO8="IRR",AS8,""))) -> 2.8333393e+11 | F8: =IF(AND(AO8="EUR",SUM(AH8:AJ8)>0),AP8,IF(AND(AO8="EUR",AR8<>""),AR8*'[5]Basic INFO'!$C$138,IF(AO8="EUR",AT8,""))) | G8: =IF(AO8="IRR",C8*E8,"") -> 2.8333393e+11 | H8: =IF(AO8="EUR",C8*F8,"") | I8: طرح مکانیک گستر شیراز | M8: no reply | N8: پایساز | R8: no reply | S8: تاشا | W8: no reply | X8: ماشین سازی اراک | Z8: 540000 | AB8: 02/29/2025 | AC8: پولادورزان کیمیا | AE8: =2.5*110000 -> 275000 | AG8: 45801 | AH8: =IF(B8="","",COUNT(J8,O8,T8,Y8,AD8)) -> 0 | AI8: =IF(B8="","",COUNT(K8,P8,U8,Z8,AE8)) -> 2 | AJ8: =IF(B8="","",COUNT(L8,Q8,V8,AA8,AF8)) -> 0 | AK8: =IF(AND(AH8<>"",AH8>0),AVERAGE(J8,O8,T8,Y8,AD8)/('[5]Basic INFO'!$C$101*'[5]Basic INFO'!$C$103),"") | AL8: =IF(AND(AI8<>"",AI8>0),AVERAGE(K8,P8,U8,Z8,AE8),"") -> 407500 | AM8: =IF(AND(AJ8<>"",AJ8>0),AVERAGE(L8,Q8,V8,AA8,AF8)/'[5]Basic INFO'!$C$103,"") | AN8: =IF(SUM(AH8:AJ8)<>0,AVERAGE(AK8:AM8),"") -> 407500 | AO8: IRR | AP8: =IF(B8="","",IF(SUM(AH8:AJ8)=0,"",IF(AO8="IRR",AN8*('[5]Basic INFO'!$C$101*'[5]Basic INFO'!$C$103),IF(AO8="EUR",AN8,AP8)))) -> 2.8333393e+11 | AQ8: 22500000000
A9: TK-191 A/B | B9: Fire Water Tank Size (D x H): 15000 x 10000 mm Roof Type: Cone Design Pressure: Atm. Design Temperature: -2.8 / 85 oC Material (Shell/Bottom/Roof): A 283 Gr. C Design Code & Standard: API 650 & IPS-G-ME-100 | C9: 2 | E9: =IF(AND(AO9="IRR",SUM(AH9:AJ9)>0),AP9,IF(AND(AO9="IRR",AQ9<>""),AQ9*'[5]Basic INFO'!$E$127,IF(AO9="IRR",AS9,""))) -> 1.6252591e+11 | F9: =IF(AND(AO9="EUR",SUM(AH9:AJ9)>0),AP9,IF(AND(AO9="EUR",AR9<>""),AR9*'[5]Basic INFO'!$C$138,IF(AO9="EUR",AT9,""))) | G9: =IF(AO9="IRR",C9*E9,"") -> 3.2505181e+11 | H9: =IF(AO9="EUR",C9*F9,"") | I9: طرح مکانیک گستر شیراز | M9: no reply | N9: پایساز | R9: no reply | S9: تاشا | W9: no reply | X9: ماشین سازی اراک | Z9: 292500 | AB9: 2/29/2025 | AC9: پولادورزان کیمیا | AE9: =2.5*70000 -> 175000 | AG9: 45801 | AH9: =IF(B9="","",COUNT(J9,O9,T9,Y9,AD9)) -> 0 | AI9: =IF(B9="","",COUNT(K9,P9,U9,Z9,AE9)) -> 2 | AJ9: =IF(B9="","",COUNT(L9,Q9,V9,AA9,AF9)) -> 0 | AK9: =IF(AND(AH9<>"",AH9>0),AVERAGE(J9,O9,T9,Y9,AD9)/('[5]Basic INFO'!$C$101*'[5]Basic INFO'!$C$103),"") | AL9: =IF(AND(AI9<>"",AI9>0),AVERAGE(K9,P9,U9,Z9,AE9),"") -> 233750 | AM9: =IF(AND(AJ9<>"",AJ9>0),AVERAGE(L9,Q9,V9,AA9,AF9)/'[5]Basic INFO'!$C$103,"") | AN9: =IF(SUM(AH9:AJ9)<>0,AVERAGE(AK9:AM9),"") -> 233750 | AO9: IRR | AP9: =IF(B9="","",IF(SUM(AH9:AJ9)=0,"",IF(AO9="IRR",AN9*('[5]Basic INFO'!$C$101*'[5]Basic INFO'!$C$103),IF(AO9="EUR",AN9,AP9)))) -> 1.6252591e+11 | AQ9: 13000000000
B10: برآورد هزینه بدون سربار و مالیات بر ارزش افزوده | G10: =SUM(G8:G9) -> 6.0838575e+11 | H10: =SUM(H8:H9) -> 0 | AQ10: Total Price (Rials) | AR10: Total Price (Euros)
B11: ضریب سربار تأمین کالا | G11: 1.18 | H11: 1.18
B12: مالیات بر ارزش افزوده | G12: 0.1 | H12: 0.1
B13: هزینه تأمین کالا + سربار + مالیات بر ارزش افزوده | G13: =ROUND((G10*G11*(1+G12))/1000000,0)*1000000 -> 789685000000 | H13: =ROUND(H10*H11*(1+H12)/1000,0)*1000 -> 0
G14: =ROUND(SUMIF(AP:AP,">0",G:G)*G11*(1+G12)/1000000,0)*1000000 -> 789685000000 | H14: =ROUND(SUMIF(AP:AP,">0",H:H)*H11*(1+H12)/1000,0)*1000 -> 0

Sheet EXCHANG.
A1: Project Title: Revamping of Pazanan II Desalting Plant
A2: Sub-Project Title: Basic Design Studies and Preparation of FEED Package for Revamping of Pazanan II Desalting Plant
A3: Project Budget Ref. 03229 (formerly 53-51-91211)
A4: Doc. Title: BASIC MTO & COST ESTMATION REPORT (MECHANICAL)
A5: Doc. Ref. 91211-PZN-ME-RE-451-R02
A6: PLATE & FRAME HEAT EXCHANGERS | I6: استعلام 1 | N6: استعلام 2 | S6: استعلام 3
A7: Item No. | B7: Description | C7: Qty. (Set) | E7: GOING UNIT PRICE IRR 1404Q1 | F7: GOING UNIT PRICE FOB EUR 1404Q1 | G7: TOTAL PRICE ریال | H7: TOTAL PRICE FOB € | I7: منبع | J7: بهای واحد (ریال) | K7: بهای واحد (یورو) | L7: بهای واحد (دلار) | M7: تاریخ مرجع | N7: منبع | O7: بهای واحد (ریال) | P7: بهای واحد (یورو) | Q7: بهای واحد (دلار) | R7: تاریخ مرجع | S7: منبع | T7: بهای واحد (ریال) | U7: بهای واحد (یورو) | V7: بهای واحد (دلار) | W7: تاریخ مرجع | AH7: No. of available quotations in IRR | AI7: No. of available quotations in EUR | AJ7: No. of available quotations in USD | AK7: avg. of IRR quotations converted to EUR | AL7: avg. of EUR quotations EUR | AM7: avg. of USD quotations converted to EUR | AN7: aggregate average quoted unit price (all in EUR) | AO7: Ref. Currency | AP7: quoted unit price | AQ7: Unit Price (Rials) | AR7: Unit Price 'FOB' (€) | AS7: NEW ITEM unit price IRR | AT7: NEW ITEM unit price EUR
A8: E-111 | B8: Dilution Water / Waste Water H.E. Heat Exchanged (KW): 3155 (Dirty Cond.) Design Pressure: 15.5 Barg Design Temperature: -2.8 / 95 oC Material (Plates/Gaskets): Titanium / HNBR Design Code & Standard: API 662 & ASME VIII, DIV.1 | C8: 1 | E8: =IF(AND(AO8="IRR",SUM(AH8:AJ8)>0),AP8,IF(AND(AO8="IRR",AQ8<>""),AQ8*'[5]Basic INFO'!$E$127,IF(AO8="IRR",AS8,""))) | F8: =IF(AND(AO8="EUR",SUM(AH8:AJ8)>0),AP8,IF(AND(AO8="EUR",AR8<>""),AR8*'[5]Basic INFO'!$C$138,IF(AO8="EUR",AT8,""))) -> 38801.906 | G8: =IF(AO8="IRR",C8*E8,"") | H8: =IF(AO8="EUR",C8*F8,"") -> 38801.906 | I8: گرما گستر | M8: no reply | N8: کول سامر | R8: no reply | S8: پرگاسیران | W8: no reply | AH8: =IF(B8="","",COUNT(J8,O8,T8,Y8,AD8)) -> 0 | AI8: =IF(B8="","",COUNT(K8,P8,U8,Z8,AE8)) -> 0 | AJ8: =IF(B8="","",COUNT(L8,Q8,V8,AA8,AF8)) -> 0 | AK8: =IF(AND(AH8<>"",AH8>0),AVERAGE(J8,O8,T8,Y8,AD8)/('[5]Basic INFO'!$C$101*'[5]Basic INFO'!$C$103),"") | AL8: =IF(AND(AI8<>"",AI8>0),AVERAGE(K8,P8,U8,Z8,AE8),"") | AM8: =IF(AND(AJ8<>"",AJ8>0),AVERAGE(L8,Q8,V8,AA8,AF8)/'[5]Basic INFO'!$C$103,"") | AN8: =IF(SUM(AH8:AJ8)<>0,AVERAGE(AK8:AM8),"") | AO8: EUR | AP8: =IF(B8="","",IF(SUM(AH8:AJ8)=0,"",IF(AO8="IRR",AN8*('[5]Basic INFO'!$C$101*'[5]Basic INFO'!$C$103),IF(AO8="EUR",AN8,AP8)))) | AR8: 25000
B9: برآورد هزینه بدون سربار و مالیات بر ارزش افزوده | G9: =SUM(G8) -> 0 | H9: =SUM(H8) -> 38801.906 | AQ9: Total Price (Rials) | AR9: Total Price (Euros)
B10: ضریب سربار تأمین کالا | G10: 1.18 | H10: 1.18
B11: مالیات بر ارزش افزوده | G11: 0.1 | H11: 0.1
B12: هزینه تأمین کالا + سربار + مالیات بر ارزش افزوده | G12: =ROUND((G9*G10*(1+G11))/1000000,0)*1000000 -> 0 | H12: =ROUND(H9*H10*(1+H11)/1000,0)*1000 -> 50000
G13: =ROUND(SUMIF(AP:AP,">0",G:G)*G10*(1+G11)/1000000,0)*1000000 -> 0 | H13: =ROUND(SUMIF(AP:AP,">0",H:H)*H10*(1+H11)/1000,0)*1000 -> 0

Sheet PUMPS
A1: Project Title: Revamping of Pazanan II Desalting Plant
A2: Sub-Project Title: Basic Design Studies and Preparation of FEED Package for Revamping of Pazanan II Desalting Plant
A3: Project Budget Ref. 03229 (formerly 53-51-91211)
A4: Doc. Title: BASIC MTO & COST ESTMATION REPORT (MECHANICAL)
A5: Doc. Ref. 91211-PZN-ME-RE-451-R02
A6: PUMPS | I6: استعلام 1 | N6: استعلام 2 | S6: استعلام 3 | X6: استعلام 4 | AC6: استعلام 5
A7: Item No. | B7: Description | C7: Qty. (Set) | E7: GOING UNIT PRICE IRR 1404Q1 | F7: GOING UNIT PRICE FOB EUR 1404Q1 | G7: TOTAL PRICE ریال | H7: TOTAL PRICE FOB € | I7: منبع | J7: بهای واحد (ریال) | K7: بهای واحد (یورو) | L7: بهای واحد (دلار) | M7: تاریخ مرجع | N7: منبع | O7: بهای واحد (ریال) | P7: بهای واحد (یورو) | Q7: بهای واحد (دلار) | R7: تاریخ مرجع | S7: منبع | T7: بهای واحد (ریال) | U7: بهای واحد (یورو) | V7: بهای واحد (دلار) | W7: تاریخ مرجع | X7: منبع | Y7: بهای واحد (ریال) | Z7: بهای واحد (یورو) | AA7: بهای واحد (دلار) | AB7: تاریخ مرجع | AC7: منبع | AD7: بهای واحد (ریال) | AE7: بهای واحد (یورو) | AF7: بهای واحد (دلار) | AG7: تاریخ مرجع | AH7: No. of available quotations in IRR | AI7: No. of available quotations in EUR | AJ7: No. of available quotations in USD | AK7: avg. of IRR quotations converted to EUR | AL7: avg. of EUR quotations EUR | AM7: avg. of USD quotations converted to EUR | AN7: aggregate average quoted unit price (all in EUR) | AO7: Ref. Currency | AP7: quoted unit price | AQ7: Unit Price (Rials) | AR7: Unit Price 'FOB' (€) | AS7: NEW ITEM unit price IRR | AT7: NEW ITEM unit price EUR
A8: P-111 A/B | B8: Off Spec. Crude Pumps Type: Centrifugal (VS6) Rated Flow (m3/hr): 45 Differential Head (m): 139.1 Discharge Pressure (Barg): 14.5 Material Class(Acc. to API 610): D1 NACE 'MR-0175' Required: Yes Design Code & Standard: API 610 & IPS-G-PM-105 | C8: 2 | E8: =IF(AND(AO8="IRR",SUM(AH8:AJ8)>0),AP8,IF(AND(AO8="IRR",AQ8<>""),AQ8*'[5]Basic INFO'!$E$127,IF(AO8="IRR",AS8,""))) | F8: =IF(AND(AO8="EUR",SUM(AH8:AJ8)>0),AP8,IF(AND(AO8="EUR",AR8<>""),AR8*'[5]Basic INFO'!$C$138,IF(AO8="EUR",AT8,""))) -> 111500 | G8: =IF(AO8="IRR",C8*E8,"") | H8: =IF(AO8="EUR",C8*F8,"") -> 223000 | I8: آریا سپهر کیهان | K8: 43000 | M8: 45703 | N8: پمپیران | P8: 180000 | R8: 45781 | S8: کالای پمپ | W8: declined | X8: دالاهو پارس کیش (دمکو) | AB8: no reply | AH8: =IF(B8="","",COUNT(J8,O8,T8,Y8,AD8)) -> 0 | AI8: =IF(B8="","",COUNT(K8,P8,U8,Z8,AE8)) -> 2 | AJ8: =IF(B8="","",COUNT(L8,Q8,V8,AA8,AF8)) -> 0 | AK8: =IF(AND(AH8<>"",AH8>0),AVERAGE(J8,O8,T8,Y8,AD8)/('[5]Basic INFO'!$C$101*'[5]Basic INFO'!$C$103),"") | AL8: =IF(AND(AI8<>"",AI8>0),AVERAGE(K8,P8,U8,Z8,AE8),"") -> 111500 | AM8: =IF(AND(AJ8<>"",AJ8>0),AVERAGE(L8,Q8,V8,AA8,AF8)/'[5]Basic INFO'!$C$103,"") | AN8: =IF(SUM(AH8:AJ8)<>0,AVERAGE(AK8:AM8),"") -> 111500 | AO8: EUR | AP8: =IF(B8="","",IF(SUM(AH8:AJ8)=0,"",IF(AO8="IRR",AN8*('[5]Basic INFO'!$C$101*'[5]Basic INFO'!$C$103),IF(AO8="EUR",AN8,AP8)))) -> 111500 | AR8: 75000
A9: P-122 A/B | B9: Deaerated Water Pumps Type: Centrifugal (Horizontal) Rated Flow (m3/hr): 53 Differential Head (m): 35.7 Discharge Pressure (Barg): 2.9 Material Class(Acc. to API 610): I2 Design Code & Standard: ISO 5199 & IPS-M-PM-115 | C9: 2 | E9: =IF(AND(AO9="IRR",SUM(AH9:AJ9)>0),AP9,IF(AND(AO9="IRR",AQ9<>""),AQ9*'[5]Basic INFO'!$E$127,IF(AO9="IRR",AS9,""))) | F9: =IF(AND(AO9="EUR",SUM(AH9:AJ9)>0),AP9,IF(AND(AO9="EUR",AR9<>""),AR9*'[5]Basic INFO'!$C$138,IF(AO9="EUR",AT9,""))) -> 15050 | G9: =IF(AO9="IRR",C9*E9,"") | H9: =IF(AO9="EUR",C9*F9,"") -> 30100 | I9: آریا سپهر کیهان | K9: 14100 | M9: 45703 | N9: پمپیران | P9: 16000 | R9: 45781 | S9: کالای پمپ | W9: declined | X9: دالاهو پارس کیش (دمکو) | AB9: no reply | AH9: =IF(B9="","",COUNT(J9,O9,T9,Y9,AD9)) -> 0 | AI9: =IF(B9="","",COUNT(K9,P9,U9,Z9,AE9)) -> 2 | AJ9: =IF(B9="","",COUNT(L9,Q9,V9,AA9,AF9)) -> 0 | AK9: =IF(AND(AH9<>"",AH9>0),AVERAGE(J9,O9,T9,Y9,AD9)/('[5]Basic INFO'!$C$101*'[5]Basic INFO'!$C$103),"") | AL9: =IF(AND(AI9<>"",AI9>0),AVERAGE(K9,P9,U9,Z9,AE9),"") -> 15050 | AM9: =IF(AND(AJ9<>"",AJ9>0),AVERAGE(L9,Q9,V9,AA9,AF9)/'[5]Basic INFO'!$C$103,"") | AN9: =IF(SUM(AH9:AJ9)<>0,AVERAGE(AK9:AM9),"") -> 15050 | AO9: EUR | AP9: =IF(B9="","",IF(SUM(AH9:AJ9)=0,"",IF(AO9="IRR",AN9*('[5]Basic INFO'!$C$101*'[5]Basic INFO'!$C$103),IF(AO9="EUR",AN9,AP9)))) -> 15050 | AR9: 10000
A10: P-124 | B10: Dilution Water Pump Type: Centrifugal (OH2) Rated Flow (m3/hr): 53 Differential Head (m): 122.3 Discharge Pressure (Barg): 12 Material Class(Acc. to API 610): I2 Design Code & Standard: API 610 & IPS-G-PM-105 | C10: 1 | E10: =IF(AND(AO10="IRR",SUM(AH10:AJ10)>0),AP10,IF(AND(AO10="IRR",AQ10<>""),AQ10*'[5]Basic INFO'!$E$127,IF(AO10="IRR",AS10,""))) | F10: =IF(AND(AO10="EUR",SUM(AH10:AJ10)>0),AP10,IF(AND(AO10="EUR",AR10<>""),AR10*'[5]Basic INFO'!$C$138,IF(AO10="EUR",AT10,""))) -> 22250 | G10: =IF(AO10="IRR",C10*E10,"") | H10: =IF(AO10="EUR",C10*F10,"") -> 22250 | I10: آریا سپهر کیهان | K10: 28500 | M10: 45703 | N10: پمپیران | P10: 16000 | R10: 45781 | S10: کالای پمپ | W10: declined | X10: دالاهو پارس کیش (دمکو) | AB10: no reply | AH10: =IF(B10="","",COUNT(J10,O10,T10,Y10,AD10)) -> 0 | AI10: =IF(B10="","",COUNT(K10,P10,U10,Z10,AE10)) -> 2 | AJ10: =IF(B10="","",COUNT(L10,Q10,V10,AA10,AF10)) -> 0 | AK10: =IF(AND(AH10<>"",AH10>0),AVERAGE(J10,O10,T10,Y10,AD10)/('[5]Basic INFO'!$C$101*'[5]Basic INFO'!$C$103),"") | AL10: =IF(AND(AI10<>"",AI10>0),AVERAGE(K10,P10,U10,Z10,AE10),"") -> 22250 | AM10: =IF(AND(AJ10<>"",AJ10>0),AVERAGE(L10,Q10,V10,AA10,AF10)/'[5]Basic INFO'!$C$103,"") | AN10: =IF(SUM(AH10:AJ10)<>0,AVERAGE(AK10:AM10),"") -> 22250 | AO10: EUR | AP10: =IF(B10="","",IF(SUM(AH10:AJ10)=0,"",IF(AO10="IRR",AN10*('[5]Basic INFO'!$C$101*'[5]Basic INFO'!$C$103),IF(AO10="EUR",AN10,AP10)))) -> 22250 | AR10: 15000
A11: P-125 A/B | B11: Dilution Water Pumps Type: Centrifugal (OH2) Rated Flow (m3/hr): 31 Differential Head (m): 122 Discharge Pressure (Barg): 13 Material Class(Acc. to API 610): I2 Design Code & Standard: API 610 & IPS-G-PM-105 | C11: 2 | E11: =IF(AND(AO11="IRR",SUM(AH11:AJ11)>0),AP11,IF(AND(AO11="IRR",AQ11<>""),AQ11*'[5]Basic INFO'!$E$127,IF(AO11="IRR",AS11,""))) | F11: =IF(AND(AO11="EUR",SUM(AH11:AJ11)>0),AP11,IF(AND(AO11="EUR",AR11<>""),AR11*'[5]Basic INFO'!$C$138,IF(AO11="EUR",AT11,""))) -> 21500 | G11: =IF(AO11="IRR",C11*E11,"") | H11: =IF(AO11="EUR",C11*F11,"") -> 43000 | I11: آریا سپهر کیهان | K11: 27000 | M11: 45703 | N11: پمپیران | P11: 16000 | R11: 45781 | S11: کالای پمپ | W11: declined | X11: دالاهو پارس کیش (دمکو) | AB11: no reply | AH11: =IF(B11="","",COUNT(J11,O11,T11,Y11,AD11)) -> 0 | AI11: =IF(B11="","",COUNT(K11,P11,U11,Z11,AE11)) -> 2 | AJ11: =IF(B11="","",COUNT(L11,Q11,V11,AA11,AF11)) -> 0 | AK11: =IF(AND(AH11<>"",AH11>0),AVERAGE(J11,O11,T11,Y11,AD11)/('[5]Basic INFO'!$C$101*'[5]Basic INFO'!$C$103),"") | AL11: =IF(AND(AI11<>"",AI11>0),AVERAGE(K11,P11,U11,Z11,AE11),"") -> 21500 | AM11: =IF(AND(AJ11<>"",AJ11>0),AVERAGE(L11,Q11,V11,AA11,AF11)/'[5]Basic INFO'!$C$103,"") | AN11: =IF(SUM(AH11:AJ11)<>0,AVERAGE(AK11:AM11),"") -> 21500 | AO11: EUR | AP11: =IF(B11="","",IF(SUM(AH11:AJ11)=0,"",IF(AO11="IRR",AN11*('[5]Basic INFO'!$C$101*'[5]Basic INFO'!$C$103),IF(AO11="EUR",AN11,AP11)))) -> 21500 | AR11: 12000
A12: P-136 A/B | B12: Disposal Water InjectionPumps Type: Centrifugal (BB3) Rated Flow (m3/hr): 91 Differential Head (m): 650 Discharge Pressure (Barg): 72.8 Material Class(Acc. to API 610): D2 NACE 'MR-0175' Required: Yes Design Code & Standard: API 610 & IPS-G-PM-105 | C12: 2 | E12: =IF(AND(AO12="IRR",SUM(AH12:AJ12)>0),AP12,IF(AND(AO12="IRR",AQ12<>""),AQ12*'[5]Basic INFO'!$E$127,IF(AO12="IRR",AS12,""))) | F12: =IF(AND(AO12="EUR",SUM(AH12:AJ12)>0),AP12,IF(AND(AO12="EUR",AR12<>""),AR12*'[5]Basic INFO'!$C$138,IF(AO12="EUR",AT12,""))) -> 317500 | G12: =IF(AO12="IRR",C12*E12,"") | H12: =IF(AO12="EUR",C12*F12,"") -> 635000 | I12: آریا سپهر کیهان | K12: 335000 | M12: 45703 | N12: پمپیران | P12: 300000 | R12: 45781 | S12: کالای پمپ | W12: declined | X12: دالاهو پارس کیش (دمکو) | AB12: no reply | AH12: =IF(B12="","",COUNT(J12,O12,T12,Y12,AD12)) -> 0 | AI12: =IF(B12="","",COUNT(K12,P12,U12,Z12,AE12)) -> 2 | AJ12: =IF(B12="","",COUNT(L12,Q12,V12,AA12,AF12)) -> 0 | AK12: =IF(AND(AH12<>"",AH12>0),AVERAGE(J12,O12,T12,Y12,AD12)/('[5]Basic INFO'!$C$101*'[5]Basic INFO'!$C$103),"") | AL12: =IF(AND(AI12<>"",AI12>0),AVERAGE(K12,P12,U12,Z12,AE12),"") -> 317500 | AM12: =IF(AND(AJ12<>"",AJ12>0),AVERAGE(L12,Q12,V12,AA12,AF12)/'[5]Basic INFO'!$C$103,"") | AN12: =IF(SUM(AH12:AJ12)<>0,AVERAGE(AK12:AM12),"") -> 317500 | AO12: EUR | AP12: =IF(B12="","",IF(SUM(AH12:AJ12)=0,"",IF(AO12="IRR",AN12*('[5]Basic INFO'!$C$101*'[5]Basic INFO'!$C$103),IF(AO12="EUR",AN12,AP12)))) -> 317500 | AR12: 260000
A13: P-137 A/B | B13: Dirty Oil Pumps Type: P.D.-Rotary (Ext. Gear) Rated Flow (m3/hr): 5 Discharge Pressure (Barg): 8 Material Class(Acc. to API 610): D1 NACE 'MR-0175' Required: Yes Design Code & Standard: API 676 & IPS-M-PM-140 | C13: 2 | E13: =IF(AND(AO13="IRR",SUM(AH13:AJ13)>0),AP13,IF(AND(AO13="IRR",AQ13<>""),AQ13*'[5]Basic INFO'!$E$127,IF(AO13="IRR",AS13,""))) | F13: =IF(AND(AO13="EUR",SUM(AH13:AJ13)>0),AP13,IF(AND(AO13="EUR",AR13<>""),AR13*'[5]Basic INFO'!$C$138,IF(AO13="EUR",AT13,""))) -> 30000 | G13: =IF(AO13="IRR",C13*E13,"") | H13: =IF(AO13="EUR",C13*F13,"") -> 60000 | I13: آریا سپهر کیهان | K13: 30000 | M13: 45703 | N13: پمپیران | R13: declined | S13: کالای پمپ | W13: declined | X13: دالاهو پارس کیش (دمکو) | AB13: no reply | AH13: =IF(B13="","",COUNT(J13,O13,T13,Y13,AD13)) -> 0 | AI13: =IF(B13="","",COUNT(K13,P13,U13,Z13,AE13)) -> 1 | AJ13: =IF(B13="","",COUNT(L13,Q13,V13,AA13,AF13)) -> 0 | AK13: =IF(AND(AH13<>"",AH13>0),AVERAGE(J13,O13,T13,Y13,AD13)/('[5]Basic INFO'!$C$101*'[5]Basic INFO'!$C$103),"") | AL13: =IF(AND(AI13<>"",AI13>0),AVERAGE(K13,P13,U13,Z13,AE13),"") -> 30000 | AM13: =IF(AND(AJ13<>"",AJ13>0),AVERAGE(L13,Q13,V13,AA13,AF13)/'[5]Basic INFO'!$C$103,"") | AN13: =IF(SUM(AH13:AJ13)<>0,AVERAGE(AK13:AM13),"") -> 30000 | AO13: EUR | AP13: =IF(B13="","",IF(SUM(AH13:AJ13)=0,"",IF(AO13="IRR",AN13*('[5]Basic INFO'!$C$101*'[5]Basic INFO'!$C$103),IF(AO13="EUR",AN13,AP13)))) -> 30000 | AR13: 10000
A14: P-138 A/B | B14: Evaporation Pond Water Return Pumps Type: Centrifugal (OH2) Rated Flow (m3/hr): 15 Differential Head (m): 27 Discharge Pressure (Barg): 3.2 Material Class(Acc. to API 610): D2 Design Code & Standard: API 610 & IPS-G-PM-105 | C14: 2 | E14: =IF(AND(AO14="IRR",SUM(AH14:AJ14)>0),AP14,IF(AND(AO14="IRR",AQ14<>""),AQ14*'[5]Basic INFO'!$E$127,IF(AO14="IRR",AS14,""))) | F14: =IF(AND(AO14="EUR",SUM(AH14:AJ14)>0),AP14,IF(AND(AO14="EUR",AR14<>""),AR14*'[5]Basic INFO'!$C$138,IF(AO14="EUR",AT14,""))) -> 29000 | G14: =IF(AO14="IRR",C14*E14,"") | H14: =IF(AO14="EUR",C14*F14,"") -> 58000 | I14: آریا سپهر کیهان | K14: 28000 | M14: 45703 | N14: پمپیران | P14: 30000 | R14: 45781 | S14: کالای پمپ | W14: declined | X14: دالاهو پارس کیش (دمکو) | AB14: no reply | AH14: =IF(B14="","",COUNT(J14,O14,T14,Y14,AD14)) -> 0 | AI14: =IF(B14="","",COUNT(K14,P14,U14,Z14,AE14)) -> 2 | AJ14: =IF(B14="","",COUNT(L14,Q14,V14,AA14,AF14)) -> 0 | AK14: =IF(AND(AH14<>"",AH14>0),AVERAGE(J14,O14,T14,Y14,AD14)/('[5]Basic INFO'!$C$101*'[5]Basic INFO'!$C$103),"") | AL14: =IF(AND(AI14<>"",AI14>0),AVERAGE(K14,P14,U14,Z14,AE14),"") -> 29000 | AM14: =IF(AND(AJ14<>"",AJ14>0),AVERAGE(L14,Q14,V14,AA14,AF14)/'[5]Basic INFO'!$C$103,"") | AN14: =IF(SUM(AH14:AJ14)<>0,AVERAGE(AK14:AM14),"") -> 29000 | AO14: EUR | AP14: =IF(B14="","",IF(SUM(AH14:AJ14)=0,"",IF(AO14="IRR",AN14*('[5]Basic INFO'!$C$101*'[5]Basic INFO'!$C$103),IF(AO14="EUR",AN14,AP14)))) -> 29000 | AR14: 35000
A15: P-139 A/B/C | B15: Disposal Water InjectionPumps Type: Centrifugal (BB3) Rated Flow (m3/hr): 44 Differential Head (m): 385 Discharge Pressure (Barg): 48.2 Material Class(Acc. to API 610): D2 NACE 'MR-0175' Required: Yes Design Code & Standard: API 610 & IPS-G-PM-105 | C15: 3 | E15: =IF(AND(AO15="IRR",SUM(AH15:AJ15)>0),AP15,IF(AND(AO15="IRR",AQ15<>""),AQ15*'[5]Basic INFO'!$E$127,IF(AO15="IRR",AS15,""))) | F15: =IF(AND(AO15="EUR",SUM(AH15:AJ15)>0),AP15,IF(AND(AO15="EUR",AR15<>""),AR15*'[5]Basic INFO'!$C$138,IF(AO15="EUR",AT15,""))) -> 247500 | G15: =IF(AO15="IRR",C15*E15,"") | H15: =IF(AO15="EUR",C15*F15,"") -> 742500 | I15: آریا سپهر کیهان | K15: 225000 | M15: 45703 | N15: پمپیران | P15: 270000 | R15: 45781 | S15: کالای پمپ | W15: declined | X15: دالاهو پارس کیش (دمکو) | AB15: no reply | AH15: =IF(B15="","",COUNT(J15,O15,T15,Y15,AD15)) -> 0 | AI15: =IF(B15="","",COUNT(K15,P15,U15,Z15,AE15)) -> 2 | AJ15: =IF(B15="","",COUNT(L15,Q15,V15,AA15,AF15)) -> 0 | AK15: =IF(AND(AH15<>"",AH15>0),AVERAGE(J15,O15,T15,Y15,AD15)/('[5]Basic INFO'!$C$101*'[5]Basic INFO'!$C$103),"") | AL15: =IF(AND(AI15<>"",AI15>0),AVERAGE(K15,P15,U15,Z15,AE15),"") -> 247500 | AM15: =IF(AND(AJ15<>"",AJ15>0),AVERAGE(L15,Q15,V15,AA15,AF15)/'[5]Basic INFO'!$C$103,"") | AN15: =IF(SUM(AH15:AJ15)<>0,AVERAGE(AK15:AM15),"") -> 247500 | AO15: EUR | AP15: =IF(B15="","",IF(SUM(AH15:AJ15)=0,"",IF(AO15="IRR",AN15*('[5]Basic INFO'!$C$101*'[5]Basic INFO'!$C$103),IF(AO15="EUR",AN15,AP15)))) -> 247500 | AR15: 180000
A16: P-151 A/B | B16: Flare K.O. Drum Pumps Type: Centrifugal (OH2) Rated Flow (m3/hr): 10 Differential Head (m): 40 Discharge Pressure (Barg): 6.8 Material Class(Acc. to API 610): S6 Design Code & Standard: API 610 & IPS-G-PM-105 | C16: 2 | E16: =IF(AND(AO16="IRR",SUM(AH16:AJ16)>0),AP16,IF(AND(AO16="IRR",AQ16<>""),AQ16*'[5]Basic INFO'!$E$127,IF(AO16="IRR",AS16,""))) | F16: =IF(AND(AO16="EUR",SUM(AH16:AJ16)>0),AP16,IF(AND(AO16="EUR",AR16<>""),AR16*'[5]Basic INFO'!$C$138,IF(AO16="EUR",AT16,""))) -> 25500 | G16: =IF(AO16="IRR",C16*E16,"") | H16: =IF(AO16="EUR",C16*F16,"") -> 51000 | I16: آریا سپهر کیهان | K16: 21000 | M16: 45703 | N16: پمپیران | P16: 30000 | R16: 45781 | S16: کالای پمپ | W16: declined | X16: دالاهو پارس کیش (دمکو) | AB16: no reply | AH16: =IF(B16="","",COUNT(J16,O16,T16,Y16,AD16)) -> 0 | AI16: =IF(B16="","",COUNT(K16,P16,U16,Z16,AE16)) -> 2 | AJ16: =IF(B16="","",COUNT(L16,Q16,V16,AA16,AF16)) -> 0 | AK16: =IF(AND(AH16<>"",AH16>0),AVERAGE(J16,O16,T16,Y16,AD16)/('[5]Basic INFO'!$C$101*'[5]Basic INFO'!$C$103),"") | AL16: =IF(AND(AI16<>"",AI16>0),AVERAGE(K16,P16,U16,Z16,AE16),"") -> 25500 | AM16: =IF(AND(AJ16<>"",AJ16>0),AVERAGE(L16,Q16,V16,AA16,AF16)/'[5]Basic INFO'!$C$103,"") | AN16: =IF(SUM(AH16:AJ16)<>0,AVERAGE(AK16:AM16),"") -> 25500 | AO16: EUR | AP16: =IF(B16="","",IF(SUM(AH16:AJ16)=0,"",IF(AO16="IRR",AN16*('[5]Basic INFO'!$C$101*'[5]Basic INFO'!$C$103),IF(AO16="EUR",AN16,AP16)))) -> 25500 | AR16: 15000
A17: P-161 A/B | B17: Closed Drain Drum Pumps Type: Centrifugal (OH2) Rated Flow (m3/hr): 25 Differential Head (m): 55 Discharge Pressure (Barg): 5 Material Class(Acc. to API 610): D2 NACE 'MR-0175' Required: Yes Design Code & Standard: API 610 & IPS-G-PM-105 | C17: 2 | E17: =IF(AND(AO17="IRR",SUM(AH17:AJ17)>0),AP17,IF(AND(AO17="IRR",AQ17<>""),AQ17*'[5]Basic INFO'!$E$127,IF(AO17="IRR",AS17,""))) | F17: =IF(AND(AO17="EUR",SUM(AH17:AJ17)>0),AP17,IF(AND(AO17="EUR",AR17<>""),AR17*'[5]Basic INFO'!$C$138,IF(AO17="EUR",AT17,""))) -> 31000 | G17: =IF(AO17="IRR",C17*E17,"") | H17: =IF(AO17="EUR",C17*F17,"") -> 62000 | I17: آریا سپهر کیهان | K17: 32000 | M17: 45703 | N17: پمپیران | P17: 30000 | R17: 45781 | S17: کالای پمپ | W17: declined | X17: دالاهو پارس کیش (دمکو) | AB17: no reply | AH17: =IF(B17="","",COUNT(J17,O17,T17,Y17,AD17)) -> 0 | AI17: =IF(B17="","",COUNT(K17,P17,U17,Z17,AE17)) -> 2 | AJ17: =IF(B17="","",COUNT(L17,Q17,V17,AA17,AF17)) -> 0 | AK17: =IF(AND(AH17<>"",AH17>0),AVERAGE(J17,O17,T17,Y17,AD17)/('[5]Basic INFO'!$C$101*'[5]Basic INFO'!$C$103),"") | AL17: =IF(AND(AI17<>"",AI17>0),AVERAGE(K17,P17,U17,Z17,AE17),"") -> 31000 | AM17: =IF(AND(AJ17<>"",AJ17>0),AVERAGE(L17,Q17,V17,AA17,AF17)/'[5]Basic INFO'!$C$103,"") | AN17: =IF(SUM(AH17:AJ17)<>0,AVERAGE(AK17:AM17),"") -> 31000 | AO17: EUR | AP17: =IF(B17="","",IF(SUM(AH17:AJ17)=0,"",IF(AO17="IRR",AN17*('[5]Basic INFO'!$C$101*'[5]Basic INFO'!$C$103),IF(AO17="EUR",AN17,AP17)))) -> 31000 | AR17: 32000
A18: P-162 | B18: C. D. Drum / Flare K.O. Drum Sump Pump Type: Centrifugal (VS4) Rated Flow (m3/hr): 5 Differential Head (m): 21.4 Discharge Pressure (Barg): 2 Material Class(Acc. to API 610): S6 Design Code & Standard: API 610 & IPS-G-PM-105 | C18: 1 | E18: =IF(AND(AO18="IRR",SUM(AH18:AJ18)>0),AP18,IF(AND(AO18="IRR",AQ18<>""),AQ18*'[5]Basic INFO'!$E$127,IF(AO18="IRR",AS18,""))) | F18: =IF(AND(AO18="EUR",SUM(AH18:AJ18)>0),AP18,IF(AND(AO18="EUR",AR18<>""),AR18*'[5]Basic INFO'!$C$138,IF(AO18="EUR",AT18,""))) -> 34500 | G18: =IF(AO18="IRR",C18*E18,"") | H18: =IF(AO18="EUR",C18*F18,"") -> 34500 | I18: آریا سپهر کیهان | K18: 24000 | M18: 45703 | N18: پمپیران | P18: 45000 | R18: 45781 | S18: کالای پمپ | W18: declined | X18: دالاهو پارس کیش (دمکو) | AB18: no reply | AH18: =IF(B18="","",COUNT(J18,O18,T18,Y18,AD18)) -> 0 | AI18: =IF(B18="","",COUNT(K18,P18,U18,Z18,AE18)) -> 2 | AJ18: =IF(B18="","",COUNT(L18,Q18,V18,AA18,AF18)) -> 0 | AK18: =IF(AND(AH18<>"",AH18>0),AVERAGE(J18,O18,T18,Y18,AD18)/('[5]Basic INFO'!$C$101*'[5]Basic INFO'!$C$103),"") | AL18: =IF(AND(AI18<>"",AI18>0),AVERAGE(K18,P18,U18,Z18,AE18),"") -> 34500 | AM18: =IF(AND(AJ18<>"",AJ18>0),AVERAGE(L18,Q18,V18,AA18,AF18)/'[5]Basic INFO'!$C$103,"") | AN18: =IF(SUM(AH18:AJ18)<>0,AVERAGE(AK18:AM18),"") -> 34500 | AO18: EUR | AP18: =IF(B18="","",IF(SUM(AH18:AJ18)=0,"",IF(AO18="IRR",AN18*('[5]Basic INFO'!$C$101*'[5]Basic INFO'!$C$103),IF(AO18="EUR",AN18,AP18)))) -> 34500 | AR18: 15000
A19: P-163 A/B | B19: O.W.S. Oil Pumps Type: P.D.-Rotary (Progressing Cavity) Rated Flow (m3/hr): 5 Discharge Pressure (Barg): 6.4 Material Class(Acc. to API 610): D1 NACE 'MR-0175' Required: Yes Design Code & Standard: API 676 & IPS-M-PM-140 | C19: 2 | E19: =IF(AND(AO19="IRR",SUM(AH19:AJ19)>0),AP19,IF(AND(AO19="IRR",AQ19<>""),AQ19*'[5]Basic INFO'!$E$127,IF(AO19="IRR",AS19,""))) | F19: =IF(AND(AO19="EUR",SUM(AH19:AJ19)>0),AP19,IF(AND(AO19="EUR",AR19<>""),AR19*'[5]Basic INFO'!$C$138,IF(AO19="EUR",AT19,""))) -> 38801.906 | G19: =IF(AO19="IRR",C19*E19,"") | H19: =IF(AO19="EUR",C19*F19,"") -> 77603.812 | I19: آریا سپهر کیهان | M19: declined | N19: پمپیران | R19: declined | S19: کالای پمپ | W19: declined | X19: دالاهو پارس کیش (دمکو) | AB19: no reply | AH19: =IF(B19="","",COUNT(J19,O19,T19,Y19,AD19)) -> 0 | AI19: =IF(B19="","",COUNT(K19,P19,U19,Z19,AE19)) -> 0 | AJ19: =IF(B19="","",COUNT(L19,Q19,V19,AA19,AF19)) -> 0 | AK19: =IF(AND(AH19<>"",AH19>0),AVERAGE(J19,O19,T19,Y19,AD19)/('[5]Basic INFO'!$C$101*'[5]Basic INFO'!$C$103),"") | AL19: =IF(AND(AI19<>"",AI19>0),AVERAGE(K19,P19,U19,Z19,AE19),"") | AM19: =IF(AND(AJ19<>"",AJ19>0),AVERAGE(L19,Q19,V19,AA19,AF19)/'[5]Basic INFO'!$C$103,"") | AN19: =IF(SUM(AH19:AJ19)<>0,AVERAGE(AK19:AM19),"") | AO19: EUR | AP19: =IF(B19="","",IF(SUM(AH19:AJ19)=0,"",IF(AO19="IRR",AN19*('[5]Basic INFO'!$C$101*'[5]Basic INFO'!$C$103),IF(AO19="EUR",AN19,AP19)))) | AR19: 25000
A20: P-164 A/B | B20: O.W.S. Water Pumps Type: Centrifugal (OH2) Rated Flow (m3/hr): 15 Differential Head (m): 50 Discharge Pressure (Barg): 5.7 Material Class(Acc. to API 610): D2 NACE 'MR-0175' Required: Yes Design Code & Standard: API 610 & IPS-G-PM-105 | C20: 2 | E20: =IF(AND(AO20="IRR",SUM(AH20:AJ20)>0),AP20,IF(AND(AO20="IRR",AQ20<>""),AQ20*'[5]Basic INFO'!$E$127,IF(AO20="IRR",AS20,""))) | F20: =IF(AND(AO20="EUR",SUM(AH20:AJ20)>0),AP20,IF(AND(AO20="EUR",AR20<>""),AR20*'[5]Basic INFO'!$C$138,IF(AO20="EUR",AT20,""))) -> 29600 | G20: =IF(AO20="IRR",C20*E20,"") | H20: =IF(AO20="EUR",C20*F20,"") -> 59200 | I20: آریا سپهر کیهان | K20: 29200 | M20: 45703 | N20: پمپیران | P20: 30000 | R20: 45781 | S20: کالای پمپ | W20: declined | X20: دالاهو پارس کیش (دمکو) | AB20: no reply | AH20: =IF(B20="","",COUNT(J20,O20,T20,Y20,AD20)) -> 0 | AI20: =IF(B20="","",COUNT(K20,P20,U20,Z20,AE20)) -> 2 | AJ20: =IF(B20="","",COUNT(L20,Q20,V20,AA20,AF20)) -> 0 | AK20: =IF(AND(AH20<>"",AH20>0),AVERAGE(J20,O20,T20,Y20,AD20)/('[5]Basic INFO'!$C$101*'[5]Basic INFO'!$C$103),"") | AL20: =IF(AND(AI20<>"",AI20>0),AVERAGE(K20,P20,U20,Z20,AE20),"") -> 29600 | AM20: =IF(AND(AJ20<>"",AJ20>0),AVERAGE(L20,Q20,V20,AA20,AF20)/'[5]Basic INFO'!$C$103,"") | AN20: =IF(SUM(AH20:AJ20)<>0,AVERAGE(AK20:AM20),"") -> 29600 | AO20: EUR | AP20: =IF(B20="","",IF(SUM(AH20:AJ20)=0,"",IF(AO20="IRR",AN20*('[5]Basic INFO'!$C$101*'[5]Basic INFO'!$C$103),IF(AO20="EUR",AN20,AP20)))) -> 29600 | AR20: 15000
A21: P-165 A/B | B21: Oily Water Basin Pumps Type: Centrifugal (OH2) Rated Flow (m3/hr): 15 Differential Head (m): 20 Discharge Pressure (Barg): 2.5 Material Class(Acc. to API 610): S6 Design Code & Standard: API 610 & IPS-G-PM-105 | C21: 2 | E21: =IF(AND(AO21="IRR",SUM(AH21:AJ21)>0),AP21,IF(AND(AO21="IRR",AQ21<>""),AQ21*'[5]Basic INFO'!$E$127,IF(AO21="IRR",AS21,""))) | F21: =IF(AND(AO21="EUR",SUM(AH21:AJ21)>0),AP21,IF(AND(AO21="EUR",AR21<>""),AR21*'[5]Basic INFO'!$C$138,IF(AO21="EUR",AT21,""))) -> 26250 | G21: =IF(AO21="IRR",C21*E21,"") | H21: =IF(AO21="EUR",C21*F21,"") -> 52500 | I21: آریا سپهر کیهان | K21: 22500 | M21: 45703 | N21: پمپیران | P21: 30000 | R21: 45781 | S21: کالای پمپ | W21: declined | X21: دالاهو پارس کیش (دمکو) | AB21: no reply | AH21: =IF(B21="","",COUNT(J21,O21,T21,Y21,AD21)) -> 0 | AI21: =IF(B21="","",COUNT(K21,P21,U21,Z21,AE21)) -> 2 | AJ21: =IF(B21="","",COUNT(L21,Q21,V21,AA21,AF21)) -> 0 | AK21: =IF(AND(AH21<>"",AH21>0),AVERAGE(J21,O21,T21,Y21,AD21)/('[5]Basic INFO'!$C$101*'[5]Basic INFO'!$C$103),"") | AL21: =IF(AND(AI21<>"",AI21>0),AVERAGE(K21,P21,U21,Z21,AE21),"") -> 26250 | AM21: =IF(AND(AJ21<>"",AJ21>0),AVERAGE(L21,Q21,V21,AA21,AF21)/'[5]Basic INFO'!$C$103,"") | AN21: =IF(SUM(AH21:AJ21)<>0,AVERAGE(AK21:AM21),"") -> 26250 | AO21: EUR | AP21: =IF(B21="","",IF(SUM(AH21:AJ21)=0,"",IF(AO21="IRR",AN21*('[5]Basic INFO'!$C$101*'[5]Basic INFO'!$C$103),IF(AO21="EUR",AN21,AP21)))) -> 26250 | AR21: 15000
A22: P-171 | B22: Fuel Oil Pump Type: Centrifugal (Horizontal) Rated Flow (m3/hr): 10 Differential Head (m): 21 Discharge Pressure (Barg): 2 Material Class(Acc. to API 610): S1 Design Code & Standard: ISO 5199 & IPS-M-PM-115 | C22: 1 | E22: =IF(AND(AO22="IRR",SUM(AH22:AJ22)>0),AP22,IF(AND(AO22="IRR",AQ22<>""),AQ22*'[5]Basic INFO'!$E$127,IF(AO22="IRR",AS22,""))) | F22: =IF(AND(AO22="EUR",SUM(AH22:AJ22)>0),AP22,IF(AND(AO22="EUR",AR22<>""),AR22*'[5]Basic INFO'!$C$138,IF(AO22="EUR",AT22,""))) -> 21000 | G22: =IF(AO22="IRR",C22*E22,"") | H22: =IF(AO22="EUR",C22*F22,"") -> 21000 | I22: آریا سپهر کیهان | K22: 12000 | M22: 45703 | N22: پمپیران | P22: 30000 | R22: 45781 | S22: کالای پمپ | W22: declined | X22: دالاهو پارس کیش (دمکو) | AB22: no reply | AH22: =IF(B22="","",COUNT(J22,O22,T22,Y22,AD22)) -> 0 | AI22: =IF(B22="","",COUNT(K22,P22,U22,Z22,AE22)) -> 2 | AJ22: =IF(B22="","",COUNT(L22,Q22,V22,AA22,AF22)) -> 0 | AK22: =IF(AND(AH22<>"",AH22>0),AVERAGE(J22,O22,T22,Y22,AD22)/('[5]Basic INFO'!$C$101*'[5]Basic INFO'!$C$103),"") | AL22: =IF(AND(AI22<>"",AI22>0),AVERAGE(K22,P22,U22,Z22,AE22),"") -> 21000 | AM22: =IF(AND(AJ22<>"",AJ22>0),AVERAGE(L22,Q22,V22,AA22,AF22)/'[5]Basic INFO'!$C$103,"") | AN22: =IF(SUM(AH22:AJ22)<>0,AVERAGE(AK22:AM22),"") -> 21000 | AO22: EUR | AP22: =IF(B22="","",IF(SUM(AH22:AJ22)=0,"",IF(AO22="IRR",AN22*('[5]Basic INFO'!$C$101*'[5]Basic INFO'!$C$103),IF(AO22="EUR",AN22,AP22)))) -> 21000 | AR22: 10000
A23: P-191 | B23: Fire Water Loading Pump Type: Centrifugal (Horizontal) Rated Flow (m3/hr): 33 Differential Head (m): 31 Discharge Pressure (Barg): 2.9 Material Class(Acc. to API 610): I2 Design Code & Standard: ISO 5199 & IPS-M-PM-115 | C23: 1 | E23: =IF(AND(AO23="IRR",SUM(AH23:AJ23)>0),AP23,IF(AND(AO23="IRR",AQ23<>""),AQ23*'[5]Basic INFO'!$E$127,IF(AO23="IRR",AS23,""))) | F23: =IF(AND(AO23="EUR",SUM(AH23:AJ23)>0),AP23,IF(AND(AO23="EUR",AR23<>""),AR23*'[5]Basic INFO'!$C$138,IF(AO23="EUR",AT23,""))) -> 16000 | G23: =IF(AO23="IRR",C23*E23,"") | H23: =IF(AO23="EUR",C23*F23,"") -> 16000 | I23: آریا سپهر کیهان | K23: 19000 | M23: 45703 | N23: پمپیران | P23: 13000 | R23: 45781 | S23: کالای پمپ | W23: declined | X23: دالاهو پارس کیش (دمکو) | AB23: no reply | AH23: =IF(B23="","",COUNT(J23,O23,T23,Y23,AD23)) -> 0 | AI23: =IF(B23="","",COUNT(K23,P23,U23,Z23,AE23)) -> 2 | AJ23: =IF(B23="","",COUNT(L23,Q23,V23,AA23,AF23)) -> 0 | AK23: =IF(AND(AH23<>"",AH23>0),AVERAGE(J23,O23,T23,Y23,AD23)/('[5]Basic INFO'!$C$101*'[5]Basic INFO'!$C$103),"") | AL23: =IF(AND(AI23<>"",AI23>0),AVERAGE(K23,P23,U23,Z23,AE23),"") -> 16000 | AM23: =IF(AND(AJ23<>"",AJ23>0),AVERAGE(L23,Q23,V23,AA23,AF23)/'[5]Basic INFO'!$C$103,"") | AN23: =IF(SUM(AH23:AJ23)<>0,AVERAGE(AK23:AM23),"") -> 16000 | AO23: EUR | AP23: =IF(B23="","",IF(SUM(AH23:AJ23)=0,"",IF(AO23="IRR",AN23*('[5]Basic INFO'!$C$101*'[5]Basic INFO'!$C$103),IF(AO23="EUR",AN23,AP23)))) -> 16000 | AR23: 6500
A24: P-192 | B24: Fire Water Pump-Elect. Motor Driven Type: Centrifugal (Horizontal, Impeller Between Bearings Design) Rated Flow (m3/hr): 825 Differential Head (m): 107 Discharge Pressure (Barg): 11.3 Material Class(Acc. to API 610): I2 Design Code & Standard: NFPA 20 & IPS-M-PM-125 | C24: 1 | E24: =IF(AND(AO24="IRR",SUM(AH24:AJ24)>0),AP24,IF(AND(AO24="IRR",AQ24<>""),AQ24*'[5]Basic INFO'!$E$127,IF(AO24="IRR",AS24,""))) | F24: =IF(AND(AO24="EUR",SUM(AH24:AJ24)>0),AP24,IF(AND(AO24="EUR",AR24<>""),AR24*'[5]Basic INFO'!$C$138,IF(AO24="EUR",AT24,""))) -> 309660.11 | G24: =IF(AO24="IRR",C24*E24,"") | H24: =IF(AO24="EUR",C24*F24,"") -> 309660.11 | I24: آریا سپهر کیهان | K24: 200000 | M24: 45703 | N24: پمپیران | P24: 30000 | R24: 45781 | S24: کالای پمپ | U24: 698980.33 | W24: 45709 | X24: دالاهو پارس کیش (دمکو) | AB24: no reply | AH24: =IF(B24="","",COUNT(J24,O24,T24,Y24,AD24)) -> 0 | AI24: =IF(B24="","",COUNT(K24,P24,U24,Z24,AE24)) -> 3 | AJ24: =IF(B24="","",COUNT(L24,Q24,V24,AA24,AF24)) -> 0 | AK24: =IF(AND(AH24<>"",AH24>0),AVERAGE(J24,O24,T24,Y24,AD24)/('[5]Basic INFO'!$C$101*'[5]Basic INFO'!$C$103),"") | AL24: =IF(AND(AI24<>"",AI24>0),AVERAGE(K24,P24,U24,Z24,AE24),"") -> 309660.11 | AM24: =IF(AND(AJ24<>"",AJ24>0),AVERAGE(L24,Q24,V24,AA24,AF24)/'[5]Basic INFO'!$C$103,"") | AN24: =IF(SUM(AH24:AJ24)<>0,AVERAGE(AK24:AM24),"") -> 309660.11 | AO24: EUR | AP24: =IF(B24="","",IF(SUM(AH24:AJ24)=0,"",IF(AO24="IRR",AN24*('[5]Basic INFO'!$C$101*'[5]Basic INFO'!$C$103),IF(AO24="EUR",AN24,AP24)))) -> 309660.11 | AR24: 80000
A25: P-193 | B25: Fire Water Pump-Diesel Engine Driven Type: Centrifugal (Horizontal, Impeller Between Bearings Design) Rated Flow (m3/hr): 825 Differential Head (m): 107 Discharge Pressure (Barg): 11.3 Material Class(Acc. to API 610): I2 Design Code & Standard: NFPA 20 & IPS-M-PM-125 | C25: 1 | E25: =IF(AND(AO25="IRR",SUM(AH25:AJ25)>0),AP25,IF(AND(AO25="IRR",AQ25<>""),AQ25*'[5]Basic INFO'!$E$127,IF(AO25="IRR",AS25,""))) | F25: =IF(AND(AO25="EUR",SUM(AH25:AJ25)>0),AP25,IF(AND(AO25="EUR",AR25<>""),AR25*'[5]Basic INFO'!$C$138,IF(AO25="EUR",AT25,""))) -> 202973.76 | G25: =IF(AO25="IRR",C25*E25,"") | H25: =IF(AO25="EUR",C25*F25,"") -> 202973.76 | I25: آریا سپهر کیهان | K25: 225000 | M25: 45703 | N25: پمپیران | P25: 120000 | R25: 45781 | S25: کالای پمپ | U25: 263921.27 | W25: 45709 | X25: دالاهو پارس کیش (دمکو) | AB25: no reply | AH25: =IF(B25="","",COUNT(J25,O25,T25,Y25,AD25)) -> 0 | AI25: =IF(B25="","",COUNT(K25,P25,U25,Z25,AE25)) -> 3 | AJ25: =IF(B25="","",COUNT(L25,Q25,V25,AA25,AF25)) -> 0 | AK25: =IF(AND(AH25<>"",AH25>0),AVERAGE(J25,O25,T25,Y25,AD25)/('[5]Basic INFO'!$C$101*'[5]Basic INFO'!$C$103),"") | AL25: =IF(AND(AI25<>"",AI25>0),AVERAGE(K25,P25,U25,Z25,AE25),"") -> 202973.76 | AM25: =IF(AND(AJ25<>"",AJ25>0),AVERAGE(L25,Q25,V25,AA25,AF25)/'[5]Basic INFO'!$C$103,"") | AN25: =IF(SUM(AH25:AJ25)<>0,AVERAGE(AK25:AM25),"") -> 202973.76 | AO25: EUR | AP25: =IF(B25="","",IF(SUM(AH25:AJ25)=0,"",IF(AO25="IRR",AN25*('[5]Basic INFO'!$C$101*'[5]Basic INFO'!$C$103),IF(AO25="EUR",AN25,AP25)))) -> 202973.76 | AR25: 100000
