Workbook
Name Administration_cost: 1.005
Name Contingency_Reserve: 1.15
Name Contractor_profit: 1.1
Name Dollar_Adjustment: 0.1
Name Irr_Adjustment: 0.4
Name IRR_EL_Inflation_Factor: 'basic data'!$L$14
Name IRR_IN_Inflation_Factor: 'basic data'!$K$14
Name IRR_Inflation_Factor: 'basic data'!$B$18
Name IRR_ME_Inflation_Factor: AVERAGE('basic data'!$I$14,'basic data'!$J$14)
Name Lighting_Fixture_Factor: 1.9
Name Material_of_Tank: P.ME!$H$10
Name per_Euro: 'basic data'!$B$1
Name Procurement_All_Insuramce: Procurement!$F$51
Name Procurement_Final_Documentation: Procurement!$F$54
Name Procurement_QC_Inspection: Procurement!$F$53
Name smokeless_factor: 2.5
Name USD_Change_IRR: 'basic data'!$B$2
Name USD_Inflation_Factor: 'basic data'!$C$18

Sheet عملكرد كلي
A1: رديف | B1: شرح | C1: (هزار ريال)
C2: (هزار دلار)
A3: 1 | B3: هزينه هاي در تعهد كارفرما | C3: 67888993
A4: 2 | B4: هزينه انجام شده تاكنون طراحي و مهندسي | C4: 39621943
A5: 3 | B5: جمع هزينه شده | C5: =SUM(C3:C4) -> 107510936
A6: 4 | B6: برآورد اعتبار بخش ريالي زير پروژه 002 | C6: ='EPC Summary'!C15/1000 -> 51783851590
A7: 5 | B7: برآورد اعتبار بخش ارزي زير پروژه 002 | C7: ='EPC Summary'!D12/1000 -> 23392
A8: 6 | B8: پیش بینی تعديل معادل 40 درصد برآورد بخش ريالي زيرپروژه 002 | C8: ='EPC Summary'!G15/1000 -> 20713540636
A9: 7 | B9: پيش بيني اضافه­كاري در سقف 25 درصد برآورد بخش ريالي زير پروژه 002 | C9: ='EPC Summary'!H15/1000 -> 12945962897
A10: 8 | B10: پيش بيني اضافه­كاري در سقف 25 درصد برآورد بخش ارزي زير پروژه 002 | C10: ='EPC Summary'!H16/1000 -> 5848
A11: 9 | B11: جمع كل درخواست بخش ريالي | C11: =C5+C6+C8+C9 -> 85550866059
A12: 10 | B12: جمع كل درخواست بخش ارزي | C12: =C7+C10 -> 29240
A13: 11 | B13: اعتبار مصوب بخش ريالي | C13: 268700000
A14: 12 | B14: اعتبار مصوب بخش ارزي | C14: 18000
A15: 13 | B15: مبلغ افزايش اعتبار بخش ريالي | C15: =C11-C13 -> 85282166059
A16: 14 | B16: مبلغ افزايش اعتبار بخش ارزي | C16: =C12-C14 -> 11240

Sheet EPC Summary
B1: برآورد هزينه هاي مستقيم | G1: برآورد با اعمال بالاسري
A2: بخش | C2: بخش ريالي | D2: بخش ارزي (دلار) | E2: مجموع (ريال) | F2: درصد از كل پروژه | G2: بخش ريالي با اعمال سربار | H2: بخش ارزي(دلار) با اعمال سربار | I2: مجموع (ريال با اعمال سربار) | J2: درصد از كل پروژه
A3: E | B3: مهندسي | C3: =ROUNDUP(PEP!E6,-7) -> 994810000000 | E3: =C3 -> 994810000000 | F3: =E3/E$7 -> 0.020546357 | G3: =ROUNDUP(C3*'basic data'!$B$3,-6) -> 1264727000000 | I3: =ROUNDUP(E3*'basic data'!$B$4,-6) -> 1264727000000 | J3: =I3/I$7 -> 0.020546359
A4: P | B4: كالا | C4: =ROUNDUP(PEP!E21,-7) -> 24007580000000 | D4: =ROUNDUP(PEP!F21,-3) -> 23392000 | E4: =D4*USD_Change_IRR+C4 -> 33832220000000 | F4: =E4/E$7 -> 0.6987554 | G4: =ROUNDUP(C4*'basic data'!$B$3+D4*('basic data'!$B$3-1)*USD_Change_IRR,-6) -> 33187108000000 | H4: =D4 -> 23392000 | I4: =ROUNDUP(E4*'basic data'!$B$4,-6) -> 43011748000000 | J4: =I4/I$7 -> 0.69875539
A5: C | B5: اجرا | C5: =ROUNDUP(PEP!E27,-7) -> 13111410000000 | E5: =D5*USD_Change_IRR+C5 -> 13111410000000 | F5: =E5/E$7 -> 0.27079714 | G5: =ROUNDUP(C5*'basic data'!$B$3,-6) -> 16668864000000 | I5: =ROUNDUP(E5*'basic data'!$B$4,-6) -> 16668864000000 | J5: =I5/I$7 -> 0.27079714
A6: Development | B6: توسعه فناوري | C6: =ROUNDUP(PEP!E28,-7) -> 479390000000 | E6: =C6 -> 479390000000 | F6: =E6/E$7 -> 0.0099011046 | G6: =ROUNDUP(C6*'basic data'!$B$3,-6) -> 609461000000 | I6: =ROUNDUP(E6*'basic data'!$B$4,-6) -> 609461000000 | J6: =I6/I$7 -> 0.0099011125
B7: جمع | C7: =SUM(C3:C6) -> 38593190000000 | D7: =SUM(D3:D6) -> 23392000 | E7: =SUM(E3:E6) -> 48417830000000 | F7: =SUM(F3:F6) -> 1 | G7: =SUM(G3:G6) -> 51730160000000 | H7: =SUM(H3:H6) -> 23392000 | I7: =SUM(I3:I6) -> 61554800000000 | J7: =SUM(J3:J6) -> 1
B10: FR(EPC Initial Capex) | C10: ریال | D10: ارز - دلار | E10: مجموع (ريال + ارز تسعير شده) | G10: Adjustment | H10: Over Work | I10: Elevated Price | J10: 89205005
A11: =C11/$A$15 -> 0.021399949 | B11: مهندسي -E | C11: =I3+J11 -> 1318418590000 | E11: =C11 -> 1318418590000 | G11: =Irr_Adjustment*C11 -> 527367436000 | H11: =ROUNDDOWN(0.25*C11,-3) -> 329604647000 | I11: =H11+G11+C11 -> 2175390673000 | J11: =ROUND(88591123000/1.65,-3) -> 53691590000
A12: =(C12+D12*USD_Change_IRR)/$A$15 -> 0.69814642 | B12: کالا- P | C12: =G4 -> 33187108000000 | D12: =H4 -> 23392000 | E12: =C12+D12*USD_Change_IRR -> 43011748000000 | G12: =Irr_Adjustment*C12 -> 13274843200000 | H12: =0.25*C12 -> 8296777000000 | I12: =H12+G12+C12 -> 54758728200000 | J12: Expenditure
A13: =C13/$A$15 -> 0.27056114 | B13: اجرا- C | C13: =G5 -> 16668864000000 | E13: =C13 -> 16668864000000 | G13: =Irr_Adjustment*C13 -> 6667545600000 | H13: =C13*0.25 -> 4167216000000 | I13: =H13+G13+C13+H14+G14+C14 -> 28509236250000 | J13: 107510936000
A14: =C14/$A$15 -> 0.0098924837 | B14: توسعه - De | C14: =G6 -> 609461000000 | E14: =C14 -> 609461000000 | G14: =Irr_Adjustment*C14 -> 243784400000 | H14: =0.25*C14 -> 152365250000 | J14: Request
A15: =C11+C12+C13+C14+D12*USD_Change_IRR -> 61608491590000 | B15: مجموع | C15: =SUM(C11:C14) -> 51783851590000 | D15: =SUM(D12:D14) -> 23392000 | E15: =SUM(E11:E14) -> 61608491590000 | G15: =SUM(G11:G14) -> 20713540636000 | H15: =SUM(H11:H14) -> 12945962897000 | I15: =H15+G15+C15 -> 85443355123000 | J15: =I16+J13 -> 85550866059000
E16: Bpd_Cost_rate | H16: =D12*0.25 -> 5848000 | I16: =I15 -> 85443355123000 | J16: =D12+H16 -> 29240000
A17: فناوري سخت | B17: =C14-B18-B19 -> 549461000000 | E17: =E15/USD_Change_IRR/110000 -> 1333.5171 | J17: Approved Finance
A18: توسعه مديريت | B18: 30000000000 | J18: 268700000000
A19: سهم داخل | B19: 30000000000 | C19: RFCS | J19: 18000000
C20: =C15 -> 51783851590000 | J20: Finance Increment
C21: =ROUNDUP(D15/1.1,-3) -> 21266000 | J21: =J15-J18 -> 85282166059000
A22: نيروگاه خورشيدي | B22: 100000000000 | J22: =J16-J19 -> 11240000
A23: تصفيه پساب | B23: =B17-B22 -> 449461000000

Sheet PEP
A1: ردیف | B1: شرح | E1: ريال | F1: یورو
A2: 1 | B2: خدمات مهندسی | C2: الف | D2: بازنگری و تائید مهندسی مقدماتی | E2: =Engineering!AJ36 -> 45441000000 | F2: 0
C3: ب | D3: انجام خدمات مهندسی تفصیلی | E3: =ROUNDUP(Engineering!AJ37,-6) -> 748916000000 | F3: 0
C4: ج | D4: مطالعات ارزیابی اثرات زیست محیطی، پيوست سلامت، هزاپ، ژئوتكنيك تكميلي، و نقشه برداري تكميلي | E4: =Engineering!AJ38 -> 34650000000 | F4: 0
C5: د | D5: مديريت مهندسي | E5: =ROUNDUP(Engineering!AJ39,-6) -> 165802000000
D6: جمع خدمات مهندسی | E6: =SUM(E2:E5) -> 994809000000 | F6: 0
A7: 2 | B7: 2-1 تهیه و تامین کالا و تجهیزات خارجی بر مبنای DAP (تحويل در محل پروژه) | C7: الف | D7: هزینه تهیه و تامین کالا و تجهیزات خارجی | E7: 0 | F7: =Procurement!C48 -> 20672777
D8: هزینه تهیه و تامین قطعات یدکی برای دوران راه اندازی و 2 ساله تعمیر و نگهداری | E8: 0 | F8: =Procurement!C49 -> 2719000
C9: ب | D9: هزینه حمل خارجی | E9: 0 | F9: در آيتم الف از 1-2 در نظر گرفته شده است
C10: ج | D10: هزینه بیمه کالا و تجهیزات خارجی | F10: در آيتم الف از 1-2 و ج از 2-2 در نظر گرفته شده است
C11: د | D11: هزینه ترخیص شامل عوارض گمرکی و سود بازرگانی کالا و تجهیزات خارجی | E11: =ROUNDUP(Procurement!D50,-6) -> 1813192000000 | F11: 0
C12: ه‍ | D12: هزینه حمل داخلی کالا و تجهیزات خرید خارج و هزينه حمل كالاي داخلي | E12: =ROUNDUP(Procurement!D52,-6) -> 512751000000 | F12: 0
C13: و | D13: هزینه خدمات فنی سازندگان در دوران نصب و راه اندازی | E13: =ROUNDUP(Procurement!D54,-6) -> 832917000000 | F13: 0
C14: ز | D14: هزینه بازرسی کالا و تجهیزات خارجی | E14: =ROUNDUP(Procurement!D53,-6) -> 300719000000 | F14: 0
B15: 2-2 تهیه و تامین کالا و تجهیزات داخلی برمبنای تحويل در محل پروژه | C15: الف | D15: هزینه تهیه و تامین کالا و تجهیزات داخلی | E15: =ROUNDUP(Procurement!D48,-6) -> 19081325000000 | F15: 0
D16: هزینه تهیه و تامین قطعات یدکی برای دوران راه اندازی و 2 ساله تعمیر و نگهداری | E16: =ROUNDUP(Procurement!D49,-6) -> 1165951000000 | F16: 0
C17: ب | D17: هزینه حمل داخلی | E17: در آيتم ه از 1-2 در نظر گرفته شده است | F17: 0
C18: ج | D18: هزینه بیمه کالا و تجهیزات داخلی و هزينه هاي داخلي بيمه كالا و تجهيزات خريد خارج | E18: =ROUNDUP(Procurement!D51,-6) -> 300719000000 | F18: 0
C19: د | D19: هزینه خدمات فنی سازندگان در دوران نصب و راه اندازی | E19: در آيتم و از 1-2 در نظر گرفته شده است | F19: 0
C20: ه‍ | D20: هزینه بازرسی کالا و تجهیزات داخلی | E20: در آيتم ز از 1-2 در نظر گرفته شده است | F20: 0
D21: جمع خدمات تهیه و تامین کالا و تجهیزات | E21: =SUM(E10:E18) -> 24007574000000 | F21: =SUM(F7:F9) -> 23391777
A22: 3 | B22: عملیات ساختمانی و اجرا | C22: الف | D22: تجهیز و برچیدن | E22: =ROUNDUP(Construction!F3,-6) -> 287281000000 | F22: 0
C23: ب | D23: ساخت و نصب و راه اندازی | E23: =ROUNDUP(Construction!F4,-6) -> 11352175000000 | F23: 0
C24: ج | D24: تسهیلات مورد نیاز کارفرما | E24: =ROUNDUP(Construction!F5,-6) -> 1284816000000 | F24: 0
C25: د | D25: الزامات HSE (مقررات ایمنی، بهداشت و محیط زیست شرکت ملی نفت ایران) | E25: =ROUNDUP(Construction!F6,-6) -> 115133000000 | F25: 0
C26: ه‍ | D26: =Construction!K7 -> ه: هزینه دفتر فنی کارگاه | E26: =Construction!F7 -> 72000000000
D27: جمع خدمات ساختمانی | E27: =SUM(E22:E26) -> 13111405000000 | F27: 0
A28: 4 | B28: توسعه فناوريهاي سخت، توسعه قابليتهاي مديريتي و توسعه سهم داخل | C28: الف | D28: يك درصد از كل برآورد | E28: =ROUNDUP((F21*USD_Change_IRR+E27+E21+E6)*1/100,-6) -> 479384000000
D29: جمع کل پروژه ( ردیف های 5 ، 4 ، 3 ، 2 ، 1) | E29: =E6+E21+E27+E28 -> 38593172000000 | F29: =F6+F21+F27 -> 23391777

Sheet basic data
A1: per Euro | B1: =447996/412907 -> 1.0849804 | D1: Year | E1: ME0 | F1: ME | G1: IN | H1: EL | I1: ME0 | J1: ME | K1: IN | L1: EL | M1: درصد تغيير شاخص قيمت توليد كننده در بخش صنعت - طبق آمار منتشر شده در بهمن ماه 1401 در مركز آمار ايران | N1: Year | O1: Ind. PPI | P1: Ind. PPI Variation | Q1: 1395=100
A2: per $ | B2: 420000 | C2: ريال | D2: 94 | E2: -12.6 | F2: -0.62 | G2: -2.3 | H2: -1.6 | I2: =1+E2/100 -> 0.874 | J2: =1+F2/100 -> 0.9938 | K2: =1+G2/100 -> 0.977 | L2: =1+H2/100 -> 0.984 | M2: ME0: ساخت فلزات پايه | N2: 1395 | P2: 4.7
A3: overhead factor (E,G,D) | B3: =Contractor_profit*Contingency_Reserve*Administration_cost -> 1.271325 | D3: 95 | E3: 1.9 | F3: 3.4 | G3: 2.7 | H3: 2 | I3: =1+E3/100 -> 1.019 | J3: =1+F3/100 -> 1.034 | K3: =1+G3/100 -> 1.027 | L3: =1+H3/100 -> 1.02 | M3: ME: ساخت محصولات فلزي ساخته شده به جز ماشين آلات و تجهيزات | N3: 1396 | P3: 13.3
A4: overhead factor (P) | B4: =Contractor_profit*Contingency_Reserve*Administration_cost -> 1.271325 | D4: 96 | E4: 31.8 | F4: 6.7 | G4: 0.8 | H4: 11.5 | I4: =1+E4/100 -> 1.318 | J4: =1+F4/100 -> 1.067 | K4: =1+G4/100 -> 1.008 | L4: =1+H4/100 -> 1.115 | M4: IN: ساخت محصولات رايانه اي، الكترونيكي و نوري | N4: 1397 | P4: 58.6
A5: overhead factor (C) | B5: =Contractor_profit*Contingency_Reserve*Administration_cost -> 1.271325 | D5: 97 | E5: 67.9 | F5: 66.7 | G5: 58.8 | H5: 68.1 | I5: =1+E5/100 -> 1.679 | J5: =1+F5/100 -> 1.667 | K5: =1+G5/100 -> 1.588 | L5: =1+H5/100 -> 1.681 | M5: EL: ساخت تجهيزات برقي | N5: 1398 | O5: 246.2 | P5: 37.1
A6: سال مبنا | B6: تورم ريالي | C6: تورم ارزي | D6: 98 | E6: 32.7 | F6: 49.2 | G6: 43.1 | H6: 43 | I6: =1+E6/100 -> 1.327 | J6: =1+F6/100 -> 1.492 | K6: =1+G6/100 -> 1.431 | L6: =1+H6/100 -> 1.43 | N6: 1399 | O6: 386.1 | P6: 56.8
A7: 1392 | B7: 0.373 | C7: 0.02 | D7: 99 | E7: 105.6 | F7: 62.9 | G7: 37.3 | H7: 71 | I7: =1+E7/100 -> 2.056 | J7: =1+F7/100 -> 1.629 | K7: =1+G7/100 -> 1.373 | L7: =1+H7/100 -> 1.71 | N7: 1400 | O7: 605 | P7: 56.7
A8: 1393 | B8: 0.156 | C8: 0.02 | D8: 1400 | E8: 54.9 | F8: 53.4 | G8: 37.6 | H8: 46.9 | I8: =1+E8/100 -> 1.549 | J8: =1+F8/100 -> 1.534 | K8: =1+G8/100 -> 1.376 | L8: =1+H8/100 -> 1.469 | N8: 99.2 | O8: 355.6 | P8: 23.9
A9: 1394 | B9: 0.119 | C9: 0.02 | D9: 1400.2 | E9: 98.2 | F9: 71.5 | G9: 53.3 | H9: 79.3 | I9: 1 | J9: 1 | K9: 1 | L9: 1 | N9: 99.3 | O9: 433.1 | P9: 37.4
A10: 1395 | B10: 0.09 | C10: 0.02 | D10: 1400.3 | E10: 72.3 | F10: 61.9 | G10: 45 | H10: 60.9 | I10: 1 | J10: 1 | K10: 1 | L10: 1 | N10: 99.4 | O10: 485.8 | P10: 56.8
A11: 1396 | B11: 0.096 | C11: 0.02 | D11: 1400.4 | E11: 54.9 | F11: 53.4 | G11: 37.6 | H11: 46.9 | I11: 1 | J11: 1 | K11: 1 | L11: 1 | N11: 1400.1 | O11: 525.6 | P11: 78.5
A12: 1397 | B12: 0.312 | C12: 0.02 | D12: 1401.1 | E12: 36.5 | F12: 46 | G12: 27.3 | H12: 38.2 | I12: =1+E12/100 -> 1.365 | J12: =1+F12/100 -> 1.46 | K12: =1+G12/100 -> 1.273 | L12: =1+H12/100 -> 1.382 | N12: 1400.2 | O12: 577 | P12: 80.4
A13: 1398 | B13: 0.412 | C13: 0.02 | D13: 1401.2 | E13: 21.6 | F13: 41.6 | G13: 21.2 | H13: 35.4 | I13: 1 | J13: 1 | K13: 1 | L13: 1 | N13: 1400.3 | O13: 633.9 | P13: 69.7
A14: 1399 | B14: 0.471 | C14: 0.012 | I14: =PRODUCT(I2:I13) -> 11.369198 | J14: =PRODUCT(J2:J13) -> 9.9491888 | K14: =PRODUCT(K2:K13) -> 5.5275547 | L14: =PRODUCT(L2:L13) -> 9.3389884 | M14: ضريب تغيير قيمت نسبت به سال مبنا (1395) | N14: 1400.4 | O14: 683.6 | P14: 56.7
A15: 1400 | B15: 0.462 | C15: 0.047 | N15: 1401.1 | O15: 768.9 | P15: 48
A16: 1401 | B16: 0.465 | C16: 0.08 | N16: 1401.2 | O16: 750.9 | P16: 40.4
A17: 1402 | B17: 0.5 | C17: 0.04
B18: =PRODUCT(B7+1,B8+1,B9+1,B10+1,B11+1,B12+1,B13+1,B14+1,B15+1,B16+1,B17+1) -> 18.576033 | C18: =PRODUCT(C7+1,C8+1,C9+1,C10+1,C11+1,C12+1,C13+1,C14+1,C15+1,C16+1,C17+1) -> 1.3670534

Sheet Engineering
B1: لیست مدارک مهندسی تفصیلی پروژه احداث واحد نمکردایی گچساران-4 به روش EPC | AE1: بهاي كل (ریال) | AF1: حق الزحمه (ریال به ازای یک نفرساعت) | AI1: نفرساعت نيروي انساني | AL1: شرح
AF2: مهندس ارشد | AG2: مهندس طراح | AH2: نقشه کش | AI2: مهندس ارشد | AJ2: مهندس طراح | AK2: نقشه کش
AE3: =(AK3*AH3+AJ3*AG3+AI3*AF3) -> 45441000000 | AF3: 9180000 | AI3: =SUM(W9,U9,S9,Q9,O9,M9,K9,I9,G9,E9,C9) -> 4950 | AL3: بازنگری و صحه گذاری اسناد پایه
A4: جدول نفر ساعت مهندسی مورد نیاز انجام مهندسی تفصیلی
AI5: نفرساعت نيروي انساني | AL5: شرح | AN5: شرح | AO5: نفر ساعت مهندسی | AS5: حق الزحمه (ریال) نفر ساعت | AV5: بهای کل
AI6: مهندس ارشد | AJ6: مهندس طراح | AK6: نقشه کش | AO6: سال | AP6: نقشه کش | AQ6: مهندس طراح | AR6: مهندس ارشد | AS6: نقشه کش | AT6: مهندس طراح | AU6: مهندس ارشد | AV6: (ریال)
B7: PR | D7: ME | F7: HV | H7: SF | J7: PI | L7: IN | N7: EL | P7: CV | R7: AR | T7: ST | V7: TC | X7: PC | Z7: DRAFT MAN | AI7: =C23-C9 -> 1269 | AJ7: =B23 -> 5210.65 | AK7: =Z10 -> 624.75 | AL7: بخش فرآيند | AN7: بخش فرآيند | AO7: سال 1402 | AP7: =ROUND(AK$7*0.4,0) -> 250 | AQ7: =ROUND(AJ$7*0.4,0) -> 2084 | AR7: =ROUND(AI$7*0.4,0) -> 508 | AS7: 5120000 | AT7: 6400000 | AU7: 8000000 | AV7: =SUMPRODUCT(AS7:AU7,AP7:AR7) -> 18681600000
B8: Jr | C8: Sr | D8: Jr | E8: Sr | F8: Jr | G8: Sr | H8: Jr | I8: Sr | J8: Jr | K8: Sr | L8: Jr | M8: Sr | N8: Jr | O8: Sr | P8: Jr | Q8: Sr | R8: Jr | S8: Sr | T8: Jr | U8: Sr | V8: Jr | W8: Sr | X8: Jr | Y8: Sr | AI8: =E23-E9 -> 1171.6 | AJ8: =D23 -> 4957.5 | AK8: =Z11 -> 224.25 | AL8: بخش كارهاي مكانيكال | AO8: سال 1403 | AP8: =ROUND(AK$7*0.4,0) -> 250 | AQ8: =ROUND(AJ$7*0.4,0) -> 2084 | AR8: =ROUND($AI$7*0.4,0) -> 508 | AS8: 7168000 | AT8: 8960000 | AU8: 11200000 | AV8: =SUMPRODUCT(AS8:AU8,AP8:AR8) -> 26154240000
A9: Endorsement | B9: 0 | C9: =E.Endorsement!E5 -> 600 | D9: 0 | E9: =E.Endorsement!E10 -> 600 | F9: 0 | G9: =E.Endorsement!E11 -> 400 | H9: 0 | I9: =E.Endorsement!E6 -> 500 | J9: 0 | K9: =E.Endorsement!E12 -> 400 | L9: 0 | M9: =E.Endorsement!E15 -> 400 | N9: 0 | O9: =E.Endorsement!E13 -> 500 | P9: 0 | Q9: =E.Endorsement!E7 -> 400 | R9: 0 | S9: =E.Endorsement!E9 -> 400 | T9: 0 | U9: =E.Endorsement!E8 -> 400 | V9: 0 | W9: =E.Endorsement!E14 -> 350 | X9: 0 | Y9: 0 | Z9: 0 | AI9: =G23-G9 -> 292.4 | AJ9: =F23 -> 1555.55 | AK9: =Z12 -> 1380 | AL9: بخش كارهاي HVAC | AO9: سال 1404 | AP9: =ROUND(AK$7*0.2,0) -> 125 | AQ9: =ROUND(AJ$7*0.2,0) -> 1042 | AR9: =ROUND($AI$7*0.2,0) -> 254 | AS9: 10035200 | AT9: 12544000 | AU9: 15680000 | AV9: =SUMPRODUCT(AS9:AU9,AP9:AR9) -> 18307968000
A10: Process | B10: =E.Process!C146 -> 4045.65 | C10: =E.Process!D146 -> 1109 | D10: =E.Process!E146 -> 161 | E10: =E.Process!F146 -> 23 | F10: =E.Process!G146 -> 0 | G10: =E.Process!H146 -> 1 | H10: =E.Process!I146 -> 5 | I10: =E.Process!J146 -> 2 | ... Z10: =E.Process!AA146 -> 624.75 | AI10: =I23-I9 -> 677.4 | AJ10: =H23 -> 1665.55 | AK10: =Z13 -> 368 | AL10: بخش ایمنی | AN10: بخش كارهاي مكانيكال | AO10: سال 1402 | AP10: =ROUND(AK$8*0.4,0) -> 90 | AQ10: =ROUND(AJ$8*0.4,0) -> 1983 | AR10: =ROUND($AI$8*0.4,0) -> 469 | AS10: 5120000 | AT10: 6400000 | AU10: 8000000 | AV10: =SUMPRODUCT(AS10:AU10,AP10:AR10) -> 16904000000
A11: Mechanic | B11: =E.Mechanic!C145 -> 604 | C11: =E.Mechanic!D145 -> 77 | D11: =E.Mechanic!E145 -> 4649 | E11: =E.Mechanic!F145 -> 1070.6 | F11: =E.Mechanic!G145 -> 0 | G11: =E.Mechanic!H145 -> 0 | H11: =E.Mechanic!I145 -> 6 | I11: =E.Mechanic!J145 -> 1 | ... Z11: =E.Mechanic!AA145 -> 224.25 | AI11: =K23-K9 -> 2404.6 | AJ11: =J23 -> 7970 | AK11: =Z14 -> 4887.5 | AL11: بخش كارهاي لوله كشي و خطوط لوله | AO11: سال 1403 | AP11: =ROUND(AK$8*0.4,0) -> 90 | AQ11: =ROUND(AJ$8*0.4,0) -> 1983 | AR11: =ROUND($AI$8*0.4,0) -> 469 | AS11: 7168000 | AT11: 8960000 | AU11: 11200000 | AV11: =SUMPRODUCT(AS11:AU11,AP11:AR11) -> 23665600000
A12: HVAC | B12: =E.HVAC!C51 -> 0 | C12: =E.HVAC!D51 -> 0 | D12: =E.HVAC!E51 -> 0 | E12: =E.HVAC!F51 -> 0 | F12: =E.HVAC!G51 -> 1543.55 | G12: =E.HVAC!H51 -> 287.4 | H12: =E.HVAC!I51 -> 0 | I12: =E.HVAC!J51 -> 0 | ... Z12: =E.HVAC!AA51 -> 1380 | AI12: =M23-M9 -> 5246.7 | AJ12: =L23 -> 7618.9 | AK12: =Z15 -> 1075.25 | AL12: بخش كارهاي ابزار دقيق | AO12: سال 1404 | AP12: =ROUND(AK$8*0.2,0) -> 45 | AQ12: =ROUND(AJ$8*0.2,0) -> 992 | AR12: =ROUND($AI$8*0.2,0) -> 234 | AS12: 10035200 | AT12: 12544000 | AU12: 15680000 | AV12: =SUMPRODUCT(AS12:AU12,AP12:AR12) -> 16564352000
A13: HSE | B13: =E.HSE!C77 -> 7 | C13: =E.HSE!D77 -> 1 | D13: =E.HSE!E77 -> 20 | E13: =E.HSE!F77 -> 0 | F13: =E.HSE!G77 -> 0 | G13: =E.HSE!H77 -> 0 | H13: =E.HSE!I77 -> 1624.55 | I13: =E.HSE!J77 -> 628.4 | ... Z13: =E.HSE!AA77 -> 368 | AI13: =O23-O9 -> 2437.8 | AJ13: =N23 -> 7549.56 | AK13: =Z16 -> 3772 | AL13: بخش كارهاي برقي | AN13: بخش كارهاي HVAC | AO13: سال 1402 | AP13: =ROUND(AK$9*0.4,0) -> 552 | AQ13: =ROUND(AJ$9*0.4,0) -> 622 | AR13: =ROUND($AI$9*0.4,0) -> 117 | AS13: 5120000 | AT13: 6400000 | AU13: 8000000 | AV13: =SUMPRODUCT(AS13:AU13,AP13:AR13) -> 7743040000
A14: Piping&Pipeline | B14: ='E.Piping&Pipeline'!C151 -> 65 | C14: ='E.Piping&Pipeline'!D151 -> 49 | D14: ='E.Piping&Pipeline'!E151 -> 0 | E14: ='E.Piping&Pipeline'!F151 -> 45 | F14: ='E.Piping&Pipeline'!G151 -> 0 | G14: ='E.Piping&Pipeline'!H151 -> 0 | H14: ='E.Piping&Pipeline'!I151 -> 0 | I14: ='E.Piping&Pipeline'!J151 -> 17 | ... Z14: ='E.Piping&Pipeline'!AA151 -> 4887.5 | AI14: =Q23-Q9 -> 696.4 | AJ14: =P23 -> 3485.8 | AK14: =Z17 -> 598 | AL14: بخش كارهاي مخابرات | AO14: سال 1403 | AP14: =ROUND(AK$9*0.4,0) -> 552 | AQ14: =ROUND(AJ$9*0.4,0) -> 622 | AR14: =ROUND($AI$9*0.4,0) -> 117 | AS14: 7168000 | AT14: 8960000 | AU14: 11200000 | AV14: =SUMPRODUCT(AS14:AU14,AP14:AR14) -> 10840256000
A15: Instrument | B15: =E.Instrument!C192 -> 476 | C15: =E.Instrument!D192 -> 29 | D15: =E.Instrument!E192 -> 0 | E15: =E.Instrument!F192 -> 8 | F15: =E.Instrument!G192 -> 0 | G15: =E.Instrument!H192 -> 0 | H15: =E.Instrument!I192 -> 13 | I15: =E.Instrument!J192 -> 10 | ... Z15: =E.Instrument!AA192 -> 1075.25 | AI15: =S23-S9 -> 296.2 | AJ15: =R23 -> 1763.35 | AK15: =Z18 -> 1919.35 | AL15: بخش كارهاي سيويل | AO15: سال 1404 | AP15: =ROUND(AK$9*0.2,0) -> 276 | AQ15: =ROUND(AJ$9*0.2,0) -> 311 | AR15: =ROUND($AI$9*0.2,0) -> 58 | AS15: 10035200 | AT15: 12544000 | AU15: 15680000 | AV15: =SUMPRODUCT(AS15:AU15,AP15:AR15) -> 7580339200
A16: Electrical | B16: =E.Electrical!C235 -> 5 | C16: =E.Electrical!D235 -> 0 | D16: =E.Electrical!E235 -> 79 | E16: =E.Electrical!F235 -> 8 | F16: =E.Electrical!G235 -> 0 | G16: =E.Electrical!H235 -> 0 | H16: =E.Electrical!I235 -> 0 | I16: =E.Electrical!J235 -> 0 | ... Z16: =E.Electrical!AA235 -> 3772 | AI16: =U23-U9 -> 1008.5 | AJ16: =T23 -> 4983.95 | AK16: =Z19 -> 3254.5 | AL16: بخش كارهاي معماری | AN16: بخش ایمنی | AO16: سال 1402 | AP16: =ROUND(AK$10*0.4,0) -> 147 | AQ16: =ROUND(AJ$10*0.4,0) -> 666 | AR16: =ROUND($AI$10*0.4,0) -> 271 | AS16: 5120000 | AT16: 6400000 | AU16: 8000000 | AV16: =SUMPRODUCT(AS16:AU16,AP16:AR16) -> 7183040000
A17: Telecom | B17: =E.TELECOM!C53 -> 0 | C17: =E.TELECOM!D53 -> 0 | D17: =E.TELECOM!E53 -> 0 | E17: =E.TELECOM!F53 -> 0 | F17: =E.TELECOM!G53 -> 0 | G17: =E.TELECOM!H53 -> 0 | H17: =E.TELECOM!I53 -> 0 | I17: =E.TELECOM!J53 -> 0 | ... Z17: =E.TELECOM!AA53 -> 598 | AI17: =W23-W9 -> 306.8 | AJ17: =V23 -> 1266.5 | AK17: =Z21 -> 3914.6 | AL17: بخش كارهاي سازه | AO17: سال 1403 | AP17: =ROUND(AK$10*0.4,0) -> 147 | AQ17: =ROUND(AJ$10*0.4,0) -> 666 | AR17: =ROUND($AI$10*0.4,0) -> 271 | AS17: 7168000 | AT17: 8960000 | AU17: 11200000 | AV17: =SUMPRODUCT(AS17:AU17,AP17:AR17) -> 10056256000
A18: Civil | B18: =E.Civil!C152 -> 6 | C18: =E.Civil!D152 -> 3 | D18: =E.Civil!E152 -> 8 | E18: =E.Civil!F152 -> 4 | F18: =E.Civil!G152 -> 0 | G18: =E.Civil!H152 -> 0 | H18: =E.Civil!I152 -> 4 | I18: =E.Civil!J152 -> 2 | ... Z18: =E.Civil!AA152 -> 1919.35 | AI18: =Y23-Y9 -> 230 | AJ18: =X23 -> 860 | AK18: =Z22 -> 0 | AL18: کنترل پروژه | AO18: سال 1404 | AP18: =ROUND(AK$10*0.2,0) -> 74 | AQ18: =ROUND(AJ$10*0.2,0) -> 333 | AR18: =ROUND($AI$10*0.2,0) -> 135 | AS18: 10035200 | AT18: 12544000 | AU18: 15680000 | AV18: =SUMPRODUCT(AS18:AU18,AP18:AR18) -> 7036556800
A19: Architectural | B19: =E.Arichitectural!C83 -> 2 | C19: =E.Arichitectural!D83 -> 1 | D19: =E.Arichitectural!E83 -> 14 | E19: =E.Arichitectural!F83 -> 1 | F19: =E.Arichitectural!G83 -> 12 | G19: =E.Arichitectural!H83 -> 4 | H19: =E.Arichitectural!I83 -> 5 | I19: =E.Arichitectural!J83 -> 13 | ... Z19: =E.Arichitectural!AA83 -> 3254.5 | AI19: =SUM(AI7:AI18) -> 16037.4 | AJ19: =SUM(AJ3:AJ18) -> 48887.31 | AK19: =SUM(AK3:AK18) -> 22018.2 | AL19: مجموع | AN19: بخش كارهاي لوله كشي و خطوط لوله | AO19: سال 1402 | AP19: =ROUND(AK$11*0.4,0) -> 1955 | AQ19: =ROUND(AJ$11*0.4,0) -> 3188 | AR19: =ROUND($AI$11*0.4,0) -> 962 | AS19: 5120000 | AT19: 6400000 | AU19: 8000000 | AV19: =SUMPRODUCT(AS19:AU19,AP19:AR19) -> 38108800000
AO20: سال 1403 | AP20: =ROUND(AK$11*0.4,0) -> 1955 | AQ20: =ROUND(AJ$11*0.4,0) -> 3188 | AR20: =ROUND($AI$11*0.4,0) -> 962 | AS20: 7168000 | AT20: 8960000 | AU20: 11200000 | AV20: =SUMPRODUCT(AS20:AU20,AP20:AR20) -> 53352320000
A21: Structural | B21: =E.Structure!C328 -> 0 | C21: =E.Structure!D328 -> 0 | D21: =E.Structure!E328 -> 26.5 | E21: =E.Structure!F328 -> 12 | F21: =E.Structure!G328 -> 0 | G21: =E.Structure!H328 -> 0 | H21: =E.Structure!I328 -> 8 | I21: =E.Structure!J328 -> 4 | ... Z21: =E.Structure!AA328 -> 3914.6 | AJ21: مطالعات زیست محیطی و غیره | AO21: سال 1404 | AP21: =ROUND(AK$11*0.2,0) -> 978 | AQ21: =ROUND(AJ$12*0.2,0) -> 1524 | AR21: =ROUND($AI$11*0.2,0) -> 481 | AS21: 10035200 | AT21: 12544000 | AU21: 15680000 | AV21: =SUMPRODUCT(AS21:AU21,AP21:AR21) -> 36473561600
A22: Project Control | B22: ='E.Project Control'!C13 -> 0 | C22: ='E.Project Control'!D13 -> 0 | D22: ='E.Project Control'!E13 -> 0 | E22: ='E.Project Control'!F13 -> 0 | F22: ='E.Project Control'!G13 -> 0 | G22: ='E.Project Control'!H13 -> 0 | H22: ='E.Project Control'!I13 -> 0 | I22: ='E.Project Control'!J13 -> 0 | ... Z22: ='E.Project Control'!AA13 -> 0 | AJ22: حق الزحمه | AK22: شرح | AN22: بخش كارهاي ابزار دقيق | AO22: سال 1402 | AP22: =ROUND(AK$12*0.4,0) -> 430 | AQ22: =ROUND(AJ$12*0.4,0) -> 3048 | AR22: =ROUND($AI$12*0.4,0) -> 2099 | AS22: 5120000 | AT22: 6400000 | AU22: 8000000 | AV22: =SUMPRODUCT(AS22:AU22,AP22:AR22) -> 38500800000
A23: Total | B23: =SUM(B9:B22) -> 5210.65 | C23: =SUM(C9:C22) -> 1869 | D23: =SUM(D9:D22) -> 4957.5 | E23: =SUM(E9:E22) -> 1771.6 | F23: =SUM(F9:F22) -> 1555.55 | G23: =SUM(G9:G22) -> 692.4 | H23: =SUM(H9:H22) -> 1665.55 | I23: =SUM(I9:I22) -> 1177.4 | ... Z23: =SUM(Z9:Z22) -> 22018.2 | AJ23: 4000000000 | AK23: مطالعات FMEA, HAZID, HAZOP (فاز طرح و ساخت) | AO23: سال 1403 | AP23: =ROUND(AK$12*0.4,0) -> 430 | AQ23: =ROUND(AJ$12*0.4,0) -> 3048 | AR23: =ROUND($AI$12*0.4,0) -> 2099 | AS23: 7168000 | AT23: 8960000 | AU23: 11200000 | AV23: =SUMPRODUCT(AS23:AU23,AP23:AR23) -> 53901120000
AJ24: 1500000000 | AK24: مطالعات پیوست سلامت | AO24: سال 1404 | AP24: =ROUND(AK$12*0.2,0) -> 215 | AQ24: =ROUND(AJ$11*0.2,0) -> 1594 | AR24: =ROUND($AI$12*0.2,0) -> 1049 | AS24: 10035200 | AT24: 12544000 | AU24: 15680000 | AV24: =SUMPRODUCT(AS24:AU24,AP24:AR24) -> 38601024000
AJ25: 3500000000 | AK25: مطالعات ارزیابی اثرات زیست محیطی (فاز طرح و ساخت) | AN25: بخش كارهاي برقي | AO25: سال 1402 | AP25: =ROUND(AK$13*0.4,0) -> 1509 | AQ25: =ROUND(AJ$13*0.4,0) -> 3020 | AR25: =ROUND($AI$13*0.4,0) -> 975 | AS25: 5120000 | AT25: 6400000 | AU25: 8000000 | AV25: =SUMPRODUCT(AS25:AU25,AP25:AR25) -> 34854080000
AJ26: 9000000000 | AK26: مطالعات ژئوتکنیک تکمیلی مورد نیاز برای تهیه مدارک مهندسی | AO26: سال 1403 | AP26: =ROUND(AK$13*0.4,0) -> 1509 | AQ26: =ROUND(AJ$13*0.4,0) -> 3020 | AR26: =ROUND($AI$13*0.4,0) -> 975 | AS26: 7168000 | AT26: 8960000 | AU26: 11200000 | AV26: =SUMPRODUCT(AS26:AU26,AP26:AR26) -> 48795712000
AJ27: 3500000000 | AK27: مطالعات پدافند غیر عامل | AO27: سال 1404 | AP27: =ROUND(AK$13*0.2,0) -> 754 | AQ27: =ROUND(AJ$13*0.2,0) -> 1510 | AR27: =ROUND($AI$13*0.2,0) -> 488 | AS27: 10035200 | AT27: 12544000 | AU27: 15680000 | AV27: =SUMPRODUCT(AS27:AU27,AP27:AR27) -> 34159820800
AJ28: 4000000000 | AK28: عملیات نقشه برداری مورد نیاز برای تهیه مدارک مهندسی | AN28: بخش كارهاي مخابرات | AO28: سال 1402 | AP28: =ROUND(AK$14*0.4,0) -> 239 | AQ28: =ROUND(AJ$14*0.4,0) -> 1394 | AR28: =ROUND($AI$14*0.4,0) -> 279 | AS28: 5120000 | AT28: 6400000 | AU28: 8000000 | AV28: =SUMPRODUCT(AS28:AU28,AP28:AR28) -> 12377280000
AJ29: 4000000000 | AK29: عملیات مستند سازی و استقرار سیستم ارسال مدارک | AO29: سال 1403 | AP29: =ROUND(AK$14*0.4,0) -> 239 | AQ29: =ROUND(AJ$14*0.4,0) -> 1394 | AR29: =ROUND($AI$14*0.4,0) -> 279 | AS29: 7168000 | AT29: 8960000 | AU29: 11200000 | AV29: =SUMPRODUCT(AS29:AU29,AP29:AR29) -> 17328192000
AJ30: 3500000000 | AK30: مهندسی ارزش | AO30: سال 1404 | AP30: =ROUND(AK$14*0.2,0) -> 120 | AQ30: =ROUND(AJ$14*0.2,0) -> 697 | AR30: =ROUND($AI$14*0.2,0) -> 139 | AS30: 10035200 | AT30: 12544000 | AU30: 15680000 | AV30: =SUMPRODUCT(AS30:AU30,AP30:AR30) -> 12126912000
AJ31: =SUM(AJ23:AJ30)*0.05 -> 1650000000 | AK31: ماليات قرارداد شركتهاي ثالث بر عهده پيمانكار به ميزان 5 درصد | AN31: بخش كارهاي سيويل | AO31: سال 1402 | AP31: =ROUND(AK$15*0.4,0) -> 768 | AQ31: =ROUND(AJ$15*0.4,0) -> 705 | AR31: =ROUND($AI$15*0.4,0) -> 118 | AS31: 5120000 | AT31: 6400000 | AU31: 8000000 | AV31: =SUMPRODUCT(AS31:AU31,AP31:AR31) -> 9388160000
AJ32: =SUM(AJ23:AJ31) -> 34650000000 | AK32: مجموع | AO32: سال 1403 | AP32: =ROUND(AK$15*0.4,0) -> 768 | AQ32: =ROUND(AJ$15*0.4,0) -> 705 | AR32: =ROUND($AI$15*0.4,0) -> 118 | AS32: 7168000 | AT32: 8960000 | AU32: 11200000 | AV32: =SUMPRODUCT(AS32:AU32,AP32:AR32) -> 13143424000
AO33: سال 1404 | AP33: =ROUND(AK$15*0.2,0) -> 384 | AQ33: =ROUND(AJ$15*0.2,0) -> 353 | AR33: =ROUND($AI$15*0.2,0) -> 59 | AS33: 10035200 | AT33: 12544000 | AU33: 15680000 | AV33: =SUMPRODUCT(AS33:AU33,AP33:AR33) -> 9206668800
AN34: بخش كارهاي معماری | AO34: سال 1402 | AP34: =ROUND(AK$16*0.4,0) -> 1302 | AQ34: =ROUND(AJ$16*0.4,0) -> 1994 | AR34: =ROUND($AI$16*0.4,0) -> 403 | AS34: 5120000 | AT34: 6400000 | AU34: 8000000 | AV34: =SUMPRODUCT(AS34:AU34,AP34:AR34) -> 22651840000
AJ35: مبلغ (ريال) | AK35: شرح | AO35: سال 1403 | AP35: =ROUND(AK$16*0.4,0) -> 1302 | AQ35: =ROUND(AJ$16*0.4,0) -> 1994 | AR35: =ROUND($AI$16*0.4,0) -> 403 | AS35: 7168000 | AT35: 8960000 | AU35: 11200000 | AV35: =SUMPRODUCT(AS35:AU35,AP35:AR35) -> 31712576000
AJ36: =AE3 -> 45441000000 | AK36: بازنگری و صحه گذاری اسناد پایه | AO36: سال 1404 | AP36: =ROUND(AK$16*0.2,0) -> 651 | AQ36: =ROUND(AJ$16*0.2,0) -> 997 | AR36: =ROUND($AI$16*0.2,0) -> 202 | AS36: 10035200 | AT36: 12544000 | AU36: 15680000 | AV36: =SUMPRODUCT(AS36:AU36,AP36:AR36) -> 22206643200
AJ37: =AV43 -> 748915072000 | AK37: مهندسی تفصیلی | AN37: بخش كارهاي سازه | AO37: سال 1402 | AP37: =ROUND(AK$17*0.4,0) -> 1566 | AQ37: =ROUND(AJ$17*0.4,0) -> 507 | AR37: =ROUND($AI$17*0.4,0) -> 123 | AS37: 5120000 | AT37: 6400000 | AU37: 8000000 | AV37: =SUMPRODUCT(AS37:AU37,AP37:AR37) -> 12246720000
AJ38: =AJ32 -> 34650000000 | AK38: مطالعات زیست محیطی و غیره | AO38: سال 1403 | AP38: =ROUND(AK$17*0.4,0) -> 1566 | AQ38: =ROUND(AJ$17*0.4,0) -> 507 | AR38: =ROUND($AI$17*0.4,0) -> 123 | AS38: 7168000 | AT38: 8960000 | AU38: 11200000 | AV38: =SUMPRODUCT(AS38:AU38,AP38:AR38) -> 17145408000
AJ39: =SUM(AJ36:AJ38)*0.2 -> 165801214400 | AK39: مديريت مهندسي | AO39: سال 1404 | AP39: =ROUND(AK$17*0.2,0) -> 783 | AQ39: =ROUND(AJ$17*0.2,0) -> 253 | AR39: =ROUND($AI$17*0.2,0) -> 61 | AS39: 10035200 | AT39: 12544000 | AU39: 15680000 | AV39: =SUMPRODUCT(AS39:AU39,AP39:AR39) -> 11987673600
AJ40: =SUM(AJ36:AJ39) -> 994807286400 | AK40: مجموع | AN40: کنترل پروژه | AO40: سال 1402 | AP40: =ROUND(AK$18*0.4,0) -> 0 | AQ40: =ROUND(AJ$18*0.4,0) -> 344 | AR40: =ROUND($AI$18*0.4,0) -> 92 | AS40: 5120000 | AT40: 6400000 | AU40: 8000000 | AV40: =SUMPRODUCT(AS40:AU40,AP40:AR40) -> 2937600000
...

Sheet Procurement
A1: جدول 2.1 -جدول خلاصه مالی تفكيكي تهيه و خريد كالاي مکانیک و لوله و اتصالات مورد نياز پروژه بر اساس پیوست 1،2 و3 | F1: ارز مرجع | G1: =USD_Change_IRR -> 420000
A2: رديف | B2: شرح فعاليت ها | C2: دلار | D2: ريال | F2: ضريب تورم عمومي ريالي | G2: =IRR_Inflation_Factor -> 18.576033
A3: 1 | B3: الكترواستاتيك ها و ادوات مربوطه | C3: =P.ME!I126 -> 7594862.8 | D3: =P.ME!K126 -> 0 | F3: ضريب تورم ارزي دلار | G3: =USD_Inflation_Factor -> 1.3670534
A4: 2 | B4: كوره ها و ادوات مربوطه | C4: =P.ME!I127 -> 6487000 | D4: =P.ME!K127 -> 0
A5: 3 | B5: مبدل نفت / نفت و مبدل آب / آب | C5: =P.ME!I128 -> 0 | D5: =P.ME!K128 -> 625209000000
A6: 4 | B6: تلمبه ها | C6: =P.ME!I129 -> 0 | D6: =P.ME!K129 -> 2082268000000
A7: 5 | B7: شيرآلات و اتصالات ، رنگها و لوله های داخل سایت | C7: =P.ME!I130 -> 0 | D7: =P.ME!K130 -> 2452617000000
A8: 6 | B8: خرید لوله های بیرون سایت | C8: =P.ME!I131 -> 0 | D8: =P.ME!K131 -> 2982846000000
A9: 7 | B9: مخزن های اتمسفریک و تحت فشار | C9: =P.ME!I132 -> 0 | D9: =P.ME!K132 -> 797604000000
A10: 8 | B10: سیستم پساب | C10: =P.ME!I133 -> 4773913.7 | D10: =P.ME!K133 -> 0
A11: 9 | B11: air compressor Packages | C11: =P.ME!I134 -> 0 | D11: =P.ME!K134 -> 418938000000
A12: 10 | B12: Flare & Ignitor | C12: =P.ME!I135 -> 0 | D12: =P.ME!K135 -> 372764000000
B13: بسته های تزریق مواد شیمیایی | C13: =P.ME!I136 -> 0 | D13: =P.ME!K136 -> 337896000000
A14: 12 | B14: Vacuum Deaerator Package | C14: =P.ME!I137 -> 0 | D14: =P.ME!K137 -> 1.3442907e+11
A15: 13 | B15: سیستم HVAC | C15: =P.ME!I138 -> 0 | D15: =P.ME!K138 -> 370840000000
A16: 14 | B16: جرثقیلهای سقفی | C16: =P.ME!I139 -> 0 | D16: =P.ME!K139 -> 401940000000
A17: 15 | B17: خرید اقلام ایمنی و آتش نشانی | C17: =P.ME!I140 -> 0 | D17: =P.ME!K140 -> 163763000000
A18: 16 | B18: گیرنده و فرستنده توپک | C18: =P.ME!I141 -> 0 | D18: =P.ME!K141 -> 94500000000
A19: 17 | B19: مواد شیمیایی مصرفی | C19: =P.ME!I142 -> 0 | D19: =P.ME!K142 -> 592670000000
B20: جمع كل | C20: =P.ME!I143 -> 18855777 | D20: =SUM(D3:D19) -> 1.1828284e+13
A22: جدول 2.4 -جدول خلاصه مالی تفكيكي تهيه و خريد كالاي برق و مخابرات مورد نياز پروژه بر اساس پیوست 4
A23: رديف | B23: شرح فعاليت ها | C23: دلار | D23: ريال
A24: 1 | B24: تابلوها | C24: =P.EL!G173 -> 0 | D24: =ROUNDUP(P.EL!H173,-6) -> 806342000000
A25: 2 | B25: اتصالات برق (شامل گلندها، شرودها، جعبه هاي اتصال، مفصلها و ...) | C25: =P.EL!G174 -> 0 | D25: =ROUNDUP(P.EL!H174,-6) -> 305001000000
A26: 3 | B26: كابلهاي قدرت | C26: =P.EL!G175 -> 0 | D26: =ROUNDUP(P.EL!H175,-6) -> 627631000000
A27: 4 | B27: ترانس ها و UPS دیزل ژنراتور | C27: =ROUNDUP(P.EL!G176,-3) -> 1414000 | D27: =ROUNDUP(P.EL!H176,-6) -> 575848000000
A28: 5 | B28: وسايل و تجهيزات مخابرات، و پیجینگ | C28: =ROUNDUP(P.EL!G177,-3) -> 197000 | D28: =ROUNDUP(P.EL!H177,-6) -> 7581000000
A29: 6 | B29: پایه ها و برجهاي روشنائي و سایر ملحقات و ادوات روشنایی | C29: =P.EL!G178 -> 0 | D29: =ROUNDUP(P.EL!H178,-6) -> 169114000000
A30: 7 | B30: خط انتقال برق شامل کابل ، پایه ها و یراق آلات | C30: =P.EL!G179 -> 0 | D30: =ROUNDUP(P.EL!H179,-6) -> 532980000000
B31: جمع كل | C31: =SUM(C24:C30) -> 1611000 | D31: =SUM(D24:D30) -> 3024497000000
A33: جدول 2.5 -جدول خلاصه مالی تفكيكي تهيه و خريدادوات و تجهیزات ابزاردقیق و تجهیزات آزمایشگاه مورد نياز پروژه بر اساس پیوست 5و6
A34: رديف | B34: شرح فعاليت ها | C34: دلار | D34: ريال
A35: 1 | B35: ادوات ابزار دقیق شامل : ترانسمیترها ، سوئیچ ها ، گیج ها و ... | C35: =ROUNDUP(P.IN!E133+P.IN!E134,-3) -> 206000 | D35: =ROUNDUP(P.IN!G133+P.IN!G134,-6) -> 761483000000
A36: 2 | B36: شیرآلات ابزار شامل : شیر ON/OFF ، شیرهای کنترلی ، PSV ، PCV | C36: =ROUNDUP(P.IN!E135,-3) -> 0 | D36: =ROUNDUP(P.IN!G135,-6) -> 1232422000000
A37: 3 | B37: سيستم كنترل ( DCS,FGS )، ESD | C37: =ROUNDUP(P.IN!E136,-3) -> 0 | D37: =P.IN!G136 -> 701447326000
A38: 4 | B38: ادوات F&G و CO2 Total Flooding و ابزار خاص | C38: =P.IN!E137 -> 0 | D38: =ROUNDUP(P.IN!G137,-6) -> 604298000000
A39: 5 | B39: اقلام بالک ابزار دقیق | C39: =P.IN!E138 -> 0 | D39: =ROUNDUP(P.IN!G138,-6) -> 78020000000
A40: 6 | B40: کابلهای ابزار دقیق و ملحقات شامل : گلند سینی و ... | C40: =P.IN!E139 -> 0 | D40: =ROUNDUP(P.IN!G139+P.IN!G140,-6) -> 229255000000
A41: 7 | B41: تجهیزات آزمایشگاه | C41: =ROUNDUP(P.IN!E141,-3) -> 0 | D41: =ROUNDUP(P.IN!G141,-6) -> 436842000000
A42: 8 | B42: CCTV | C42: =P.IN!E142 -> 0 | D42: =ROUNDUP(P.IN!G142,-6) -> 184776000000
...

Sheet Construction
F2: :خلاصه براورد ساخت و اجرا مطابق تفکیک نرخ پیمان- پیوست یک قرارداد
F3: =E27 -> 2.8728056e+11 | K3: الف:تجهیز و برچیدن مطابق جدول ب-1 | Q3: الف
F4: =H27+0.15*H27 -> 1.1352174e+13 | K4: ب:ساخت و نصب و راه اندازی مطابق جدول ب-1 | Q4: ب
F5: =M33 -> 1.2848158e+12 | K5: ج:تسهیلات مورد نیاز کارفرما مطابق جدول ب-2 | Q5: ج
F6: =B36 -> 1.1513294e+11 | K6: د: الزامات HSEمطابق جدول ب-3 | Q6: د
F7: =M38 -> 72000000000 | K7: ه: هزینه دفتر فنی کارگاه | Q7: ه
F8: =SUM(F3:J7) -> 1.3111403e+13 | K8: مجموع
B10: شرح ردیف های الف و ب - برآورد هزینه ساخت و نصب و راه اندازی و تجهیز کارگاه - مطابق جداول
B11: جمع کل | E11: هزینه تجهیز کارگاه | H11: هزینه اجرا پس از اعمال ضریب بروزرسانی | I11: ضریب بروزرسانی به سه ماهه اول 1402 | J11: هزینه اجرا پس از اعمال ضرایب فهرست بهای مربوطه | M11: هزینه اجرامطابق فهرست بهای مربوطه | P11: عنوان
B12: =E12+H12 -> 4.6492494e+11 | E12: ='C.RETAINING WAL'!E25 -> 1.745129e+11 | H12: =ROUND(J12*I12,0) -> 290412038226 | I12: 1.06 | J12: ='C.foundation-2'!A31 -> 2.7397362e+11 | M12: ='C.foundation-2'!B31 -> 175163935524 | P12: اجرای فونداسیون تجهیزات
B13: =H13 -> 637828274396 | E13: یک قلم در ردیف اول محاسبه گردید | H13: =ROUND(J13*I13,0) -> 637828274396 | I13: 1.06 | J13: ='C.ROAD-2'!A27 -> 6.0172479e+11 | M13: ='C.ROAD-2'!B27 -> 380893730036 | P13: اجرای جاده های داخلی و خارجی
B14: =H14 -> 719145156294 | E14: یک قلم در ردیف اول محاسبه گردید | H14: =ROUND(J14*I14,0) -> 719145156294 | I14: 1.06 | J14: ='C.Shelters-2'!A46 -> 6.7843883e+11 | M14: ='C.Shelters-2'!B46 -> 438710828644 | P14: اجرای سایبانها
B15: =H15 -> 1709692715148 | E15: یک قلم در ردیف اول محاسبه گردید | H15: =ROUND(J15*I15,0) -> 1709692715148 | I15: 1.06 | J15: ='C.Buildings'!G20 -> 1612917655800 | M15: =J15/'C.Note'!$G$55 -> 1.0494617e+12 | P15: اجرای ساختمانها
B16: =H16 -> 2158472497849 | E16: یک قلم در ردیف اول محاسبه گردید | H16: =ROUND(J16*I16,0) -> 2158472497849 | I16: 1.06 | J16: ='C.OTHERS-2'!A33 -> 2.0362948e+12 | M16: ='C.OTHERS-2'!B33 -> 1239981269679 | P16: اجرای ابنیه و اقلام متفرقه
B17: =H17 -> 1103852062935 | E17: یک قلم در ردیف اول محاسبه گردید | H17: =ROUND(J17*I17,0) -> 1103852062935 | I17: 1.06 | J17: ='C.SITE-2'!A22 -> 1041369870693 | M17: ='C.SITE-2'!B22 -> 461314673320 | P17: محوطه سازی واحدها
B18: =H18 -> 171750408507 | E18: یک قلم در ردیف اول محاسبه گردید | H18: =ROUND(J18*I18,0) -> 171750408507 | I18: 1.062 | J18: ='C.RETAINING WAL'!A7 -> 161723548500 | M18: ='C.RETAINING WAL'!B7 -> 102421500000 | P18: اجرای دیوار حایل و شیروانی دورواحد
B19: =H19 -> 200075296057 | E19: یک قلم در ردیف اول محاسبه گردید | H19: =ROUND(J19*I19,0) -> 200075296057 | I19: 1.06 | J19: ='C.UG CIVIL-2'!A30 -> 1.8875028e+11 | M19: ='C.UG CIVIL-2'!B30 -> 113706706200 | P19: دفن کابل و لوله های دفنی
B20: =H20 -> 992055090120 | E20: یک قلم در ردیف اول محاسبه گردید | H20: =ROUND(J20*I20,0) -> 992055090120 | I20: 1.06 | J20: ='C.STEEL STRUCTURE (2)'!A29 -> 9.3590103e+11 | M20: ='C.STEEL STRUCTURE (2)'!B29 -> 607865879900 | P20: نصب و اجرای سازه های فلزی متفرقه
B21: =H21 -> 8711234972 | E21: یک قلم در ردیف اول محاسبه گردید | H21: =ROUND(J21*I21,0) -> 8711234972 | I21: 1.06 | J21: ='C.SITE-3'!B17 -> 8218146200 | M21: - | P21: احداث فضای سبز
B22: =SUM(E22:H22) -> 3.4726254e+11 | E22: ='C.Note'!$I$23*Construction!H22 -> 1.965637e+10 | H22: =ROUND(J22*I22,0) -> 327606170624 | I22: 1.061 | J22: ='C.mECHANICAL'!A239 -> 3.0877113e+11 | M22: ='C.mECHANICAL'!B239 -> 150633619879 | P22: اجرا و نصب تجهیزات مکانیک
B23: =SUM(E23:H23) -> 2.9669944e+11 | E23: ='C.Note'!$I$23*Construction!H23 -> 1.6794308e+10 | H23: =ROUND(J23*I23,0) -> 279905133293 | I23: 1.061 | J23: ='C.PIPELINE'!A51 -> 263812566723 | M23: ='C.PIPELINE'!B51 -> 109329700258 | P23: اجرای خطوط لوله
B24: =SUM(E24:H24) -> 9.2517346e+11 | E24: ='C.Note'!$I$23*Construction!H24 -> 5.2368309e+10 | H24: =ROUND(J24*I24,0) -> 872805147240 | I24: 1.06 | J24: ='C.PIPING'!A87 -> 8.2340108e+11 | M24: ='C.PIPING'!B87 -> 328965674112 | P24: اجرای پایپینگ درون واحدها
B25: =SUM(E25:H25) -> 2.1370356e+11 | E25: ='C.Note'!$I$23*Construction!H25 -> 1.2096428e+10 | H25: =ROUND(J25*I25,0) -> 201607130784 | I25: 1.058 | J25: ='C.ELECTRICAL'!A167 -> 190554944030 | M25: ='C.ELECTRICAL'!B167 -> 162341006850 | P25: اجرای برق
B26: =SUM(E26:H26) -> 2.093897e+11 | E26: ='C.Note'!$I$23*Construction!H26 -> 1.1852247e+10 | H26: =ROUND(J26*I26,0) -> 197537455978 | I26: 1.058 | J26: ='C.INSTRUMENT'!A97 -> 186708370490 | M26: ='C.INSTRUMENT'!B97 -> 75559842024 | P26: اجرای ابزاردقیق
B27: =SUM(B12:D26) -> 1.0158736e+13 | E27: =SUM(E12:G26) -> 2.8728056e+11 | H27: =SUM(H12:H26) -> 9871455812423 | J27: =SUM(J12:L26) -> 9.3125607e+12 | M27: =SUM(M12:O26) -> 5.39635e+12 | P27: مجموع
B29: شرح ردیف د - برآورد هزینه ایمنی کارگاه (HSE) | M29: شرح ردیف ج - برآورد تسهیلات کارفرما
B30: ='C.HSE(1)'!B27 -> 8.0139507e+10 | E30: لوازم حفاظت فردی و تجهیزات | M30: ='C.tashilat (2)'!B24 -> 1.1747869e+12 | P30: تسهيلات رفاهي گروه نظارت
B31: ='C.HSE(2)'!B17 -> 2.8588515e+09 | E31: سدجش و اندازه گیری 1 | M31: =SUM('C.tashilat'!C9,'C.tashilat'!C24,'C.tashilat'!C36) -> 1.1002883e+11 | P31: تسهیلات ماموریت داخل و خارج و آموزش
B32: ='C.HSE(2)'!B21 -> 81900000 | E32: سدجش و اندازه گیری 2
B33: ='C.HSE(2)'!B37 -> 5.0526809e+09 | E33: آموزش | M33: =SUM(M30:O32) -> 1.2848158e+12 | P33: مجموع
B34: ='C.HSE(1)'!C34 -> 27000000000 | E34: نیروی انسانی
M35: شرح ردیف ه: هزینه دفتر فنی کارگاه
B36: =SUM(B30:D35) -> 1.1513294e+11 | E36: مجموع | M36: 4 نفر طی بیست و چهار ماه هزینه نفر ماه : 750،000،000 ریال | P36: پرسنل دفتر فنی کارگاه (طبق توضیح بند 6 صفحه قبل (صفحه 4)
M38: =4*24*750000000 -> 72000000000 | P38: مجموع

Sheet C.CONTENT
P2: فهرست
Q3: الف) مبانی محاسبات براورد
Q4: ب) خلاصه برآورد مالی بخش اجرا
Q5: پیوست یک - برآورد هزینه اجرای پروژه بر اساس فهارس بها
B6: جدول 1 - برآورد اجرا بر اساس فهرست بهای ابنیه 1402 - احداث فونداسیون تجهیزات وادوات (بر اساس ریز متره مندرج در جدول الف پیوست 2) | Q6: -
B7: جدول 2 - برآورد اجرا بر اساس فهرست بهای ابنیه 1402 - احداث سایبان تجهیزات(بر اساس ریز متره مندرج در جدول ب پیوست 2) | Q7: -
B8: جدول 3 - برآورد اجرا بر اساس فهرست بهای ابنیه 140 - احداث جاده های دسترسی، جاده های داخل واحدها و پاترول(بر اساس ریز متره مندرج در جدول ج پیوست 2) | Q8: -
B9: جدول 4 - برآورد اجرا بر اساس فهرست بهای ابنیه 1402 - احداث ابنیه متفرقه (بر اساس ریز متره مندرج در جدول د پیوست 2) | Q9: -
B10: جدول 5 - برآورد اجرا بر اساس فهرست بهای ابنیه 1402 -محوطه سازی واحدها (بر اساس ریز متره مندرج در جدول ه پیوست 2) | Q10: -
B11: جدول 6 - برآورد اجرا فضای سبز - خارج از فهرست بها | Q11: -
B12: جدول7 - برآورد اجرا بر اساس فهرست بهای ابنیه 1402 - دفن لوله ها (داخل و خارج واحد) و کابل های زیر زمینی (بر اساس ریز متره مندرج در جدول و پیوست 2) | Q12: -
B13: جدول 8 - برآورد اجرا بر اساس فهرست بهای ابنیه 1402 - سازه های فلزی متفرقه (بر اساس ریز متره مندرج در جدول ط پیوست 2) | Q13: -
B14: جدول10 - برآورد اجرا بر اساس فهرست بهای باند و راه 1402 -ساخت دیوار حایل مجاور تپه و سطوح کوهبری شده و شیروانی دورتادور کارخانه | Q14: -
B15: جدول 11 - برآورد اجرا بر اساس فهرست بهای ابنیه 1402 -تجهیز و برچیدن کارگاه | Q15: -
B16: جدول 12 - برآورد اجرای لوله کشی وپایپینگ بر اساس فهرست بهای اختصاصی تاسیسات نفت و گاز، رشته نصب واحدهای بهره برداری نفت و گاز -1401 | Q16: -
B17: جدول 13 - برآورد اجراو نصب تجهیزات مکانیک بر اساس فهرست بهای اختصاصی تاسیسات نفت و گاز، رشته نصب واحدهای بهره برداری نفت و گاز -1401 | Q17: -
... B29: جدول 18-5: براورد هزینه ایمنی کارگاه : آموزش | Q29: -
C30: پیوست دو - ریز متره و برآورد احجام بخش سیویل وسازه
B31: جدول الف : ریز برآورد متره فونداسیون تجهیزات | Q31: -
B32: جدول ب-1 : ریز برآورد متره سایبانها - فونداسیون و کف سازی | Q32: -
B33: جدول ب-2 : ریز برآورد متره سایبانها - لسکلت فلزی | Q33: -
B34: جدول ج : ریز برآورد متره جاده ها | Q34: -
B35: جدول د : ریز برآورد متره ابنیه متفرقه | Q35: -
B36: جدول ه : ریز برآورد متره محوطه سازی | Q36: -
B37: جدول و : ریز برآورد کانال های لوله ها و کابل های دفنی | Q37: -
B38: جدول ط : ریز برآورد متره سازه های فلزی متفرقه | Q38: -

Sheet C.Note
R4: مبانی محاسبات براورد : | S4: الف)
R6: جهت براورد هزینه اجرای بخش سیویل و سازه از "فهرست بهای واحد پایه رشته ابنیه" سال 1402 استفاده شده است. | S6: -1
B8: با توجه به آنکه این پروژه در حد مهندسی مقدماتی و پایه بوده و نقشه معماری فاز یک آن اماده گردیده لیکن نقشه های فاز 2 معماری، نقشه های اجرایی فونداسیون، سازه بتی و فولادی و نیز نقشه های تاسیسات آن تهیه نگردیده و میبایست در مرحله مهندسی تفصیلی انجام شود، لذا امکان تهیه ریز برآورد اقلام و استفاده از فهرست احاد بهای ابنیه در این مرحله از پروژه میسر نمیباشد. لذا برای برآورد هزینه ساخت و اجرای ساختمانها از ابلاغیه شماره 47855/ش م مورخ 1401/12/16شورای مرکزی سازمان نظام مهندسی ساختمان که بر مبنای متراژ ساخت بنا میباشد، استفاده گردیده است | S8: -2
B13: جهت برآورد هزینه اجرای سایر بخشها از "فهرست بهای اختصاصی تاسیسات نفت و گاز - رشته نصب واحدهای بهره برداری نفت و گاز ایستگاه تراکم گاز" و "فهرست بهای اختصاصی تاسیسات نفت و گاز - رشته خطوط لوله روزمینی جریانی نفت و گاز" سال 1401 استفاده شده است. | S13: -3
R16: ضریب بالاسری بخش اجرا بر اساس فهرست بهای اختصاصی نصب واحدهای بهره برداری که در محاسبه هزینه پروژه منظور شده است معادل است با : | S16: -4
O17: گروه لوله کشی | R17: 1-4-
R18: هزینه بالاسری برای کارهایی که از طریق مناقصات انجام میشود : 48%
R19: ضریب هزینه تفاوت بیمه های تامین اجتماعی به میزان 1
R20: ضریب منطقه ای : 1.12
R21: ضریب بروزرسانی به سه ماهه چهارم 1401 : 1.51
G22: =1.48*1.12*1.51 -> 2.502976 | R22: ضریب اجرا که به صورت خطی در مبالغ محاسبه شده فهرست بها ضرب میگردد : =1.12*1.51 * 1.48 = | S22: -
I23: 0.06 | R23: ضریب هزینه تجهیز و برچیدن کارگاه که مبلغ آن با مبلغ اجرا جمع میگردد = | S23: -
O25: گروه نصب تجهیزات | R25: 2-4-
R26: هزینه بالاسری برای کارهایی که از طریق مناقصات انجام میشود : 48%
R27: ضریب هزینه تفاوت بیمه های تامین اجتماعی به میزان 1
R28: ضریب منطقه ای : 1.12
R29: ضریب بروزرسانی به سه ماهه چهارم 1401 : 1.515
G30: =1.48*1.12*1.515 -> 2.511264 | R30: ضریب اجرا که به صورت خطی در مبالغ محاسبه شده فهرست بها ضرب میگردد : =1.12*1.515 * 1.48 = | S30: -
I31: 0.06 | R31: ضریب هزینه تجهیز و برچیدن کارگاه که مبلغ آن با مبلغ اجرا جمع میگردد = | S31: -
M33: گروه نصب کارهای برقی و ابزار دقیق | R33: 3-4-
R34: هزینه بالاسری برای کارهایی که از طریق مناقصات انجام میشود : 48%
R35: ضریب هزینه تفاوت بیمه های تامین اجتماعی به میزان 1
R36: ضریب منطقه ای : 1.12
R37: ضریب بروزرسانی به سه ماهه چهارم 1401 : 1.491
G38: =1.48*1.12*1.491 -> 2.4714816 | R38: ضریب اجرا که به صورت خطی در مبالغ محاسبه شده فهرست بها ضرب میگردد : =1.12*1.491 * 1.48 = | S38: -
I39: 0.06 | R39: ضریب هزینه تجهیز و برچیدن کارگاه که مبلغ آن با مبلغ اجرا جمع میگردد = | S39: -
R41: ضریب بالاسری بخش اجرا بر اساس فهرست بهای اختصاصی خطوط لوله روزمینی که در محاسبه هزینه پروژه منظور شده است معادل است با : | S41: -5
R43: هزینه بالاسری برای کارهایی که از طریق مناقصات انجام میشود : 48%
R44: ضریب هزینه تفاوت بیمه های تامین اجتماعی به میزان 1
R45: ضریب منطقه ای : 1.11
R46: ضریب بروزرسانی به سه ماهه چهارم 1401 : 1.469
G47: =1.48*1.11*1.469 -> 2.4132732 | R47: ضریب اجرا که به صورت خطی در مبالغ محاسبه شده فهرست بها ضرب میگردد : =1.11*1.469 * 1.48 = | S47: -
I48: 0.06 | R48: ضریب هزینه تجهیز و برچیدن کارگاه که مبلغ آن با مبلغ اجرا جمع میگردد = | S48: -
R51: ضریب بالاسری بخش اجرا بر اساس فهرست رشته ابنیه که در محاسبه هزینه پروژه منظور شده است معادل است با | S51: -5
K52: 1.41 | R52: ضریب بالاسری برای کارهایی که از طریق مناقصات انجام میشود :
R53: ضریب منطقه ای : 1.09 | S53: -
R54: ضریب هزینه تجهیز و برچیدن کارگاه که مبلغ آن با مبلغ اجرا جمع میگردد = 4% | S54: -
G55: =1.41*1*1.09 -> 1.5369 | R55: ضریب اجرا که به صورت خطی در مبالغ محاسبه شده فهرست بها ضرب میگردد : 1.09 * 1.41 = | S55: -
R57: برای دفتر فنی کارگاه 4 نفر به شرح زیر برای مدت 20 ماه در نظر گرفته شده است: | S57: -6
R58: سرپرست دفتر فنی ، کنترل پروژه، دو نفر کارشناس فنی بر حسب نیاز
...

Sheet C.foundation-2
A1: جدول 1 - برآورد اجرا بر اساس فهرست بهای ابنیه 1402 - احداث فونداسیون تجهیزات وادوات (بر اساس ریز متره مندرج در جدول الف پیوست 2)
A2: ارزش کار | B2: مبلغ بدون اعمال ضرایب | C2: مقـدار | D2: واحد بــها با اعمال ضریب | E2: واحد بــهامطابق فهرست ابنیه 1402 | F2: واحـد | G2: شــــــــرح | I2: ردیف
F3: * | G3: خاکبرداری و پی کنی با ماشین | I3: * | K3: =ROUND(L4*L5*L6*L7,3) -> 1.537
A4: =C4*D4 -> 26335376064 | B4: =ROUND(C4*E4,0) -> 17134272000 | C4: ='C.Foundation-1'!I36 -> 9664 | D4: =E4*$K$3 -> 2725101 | E4: 1773000 | F4: m3 | G4: کندن زمین در صورت لزوم استفاده از چکش هیدرولیکی در زمین های سنگی و حمل و تخلیه مواد کنده شده تا فاصله ٢٠ متر از مرکز ثقل برداشت | I4: 30504 | K4: منطقه ای گچساران. | L4: 1.09
B5: =ROUND(C5*E5,0) -> 0 | F5: * | G5: قالب بندی فلزی | I5: * | K5: بالاسری | L5: 1.41
A6: =C6*D6 -> 10024235613 | B6: =ROUND(C6*E6,0) -> 6521949000 | C6: ='C.Foundation-1'!K36 -> 4501 | D6: =E6*$K$3 -> 2227113 | E6: 1449000 | F6: m2 | G6: تهیه مصالح و قالب بندی فلزی در پی ها | I6: 60101 | K6: تجهیزکارگاه | L6: 1
B7: =ROUND(C7*E7,0) -> 0 | F7: * | G7: تهیه مصالح و اجرای پی | I7: * | K7: بروزرسانی | L7: 1
A8: =C8*D8 -> 145592263520 | B8: =ROUND(C8*E8,0) -> 94724960000 | C8: ='C.Foundation-1'!N36 -> 376640 | D8: =E8*$K$3 -> 386555.5 | E8: 251500 | F8: Kg | G8: تهیه، بریدن، خم کردن و کار گذاشتن میلگرد آج دار به قطر ١٢ تا ١٨ میلی متر، برای بتن مسلح با سیم پیچی لازم. | I8: 70202
A9: =C9*D9 -> 63865785195 | B9: =ROUND(C9*E9,0) -> 41552235000 | C9: ='C.Foundation-1'!M36 -> 4149 | D9: =E9*$K$3 -> 15393055 | E9: 10015000 | F9: m3 | G9: تهیه و اجرای بتن با شن و ماسه طبیعی با عیار 350 کیلو سیمان | I9: 80106
A10: =C10*D10 -> 5.1271185e+08 | B10: =ROUND(C10*E10,0) -> 333579600 | C10: =C9 -> 4149 | D10: =E10*$K$3 -> 123574.8 | E10: 80400 | F10: m3 | G10: اضافه بهایه ردیفهای بتنه ریزی در بتن مسلح | I10: 80310
A11: =C11*D11 -> 2.5667055e+08 | B11: =ROUND(C11*E11,0) -> 166994500 | C11: 500 | D11: =E11*$K$3 -> 513341.09 | E11: =ROUND(31400*L31,0) -> 333989 | F11: kg | G11: نهیه و نصب انکربولت، میل مهار با مهره مربوطه | I11: 70606
B12: =ROUND(C12*E12,0) -> 0 | F12: * | G12: تهیه خاک مناسب از فاصله 15 کیلومتری | I12: *
A13: =C13*D13 -> 1.323293e+09 | B13: =ROUND(C13*E13,0) -> 860958384 | C13: ='C.Foundation-1'!J36 -> 4472 | D13: =E13*$K$3 -> 295906.31 | E13: =ROUND(18100*L31,0) -> 192522 | F13: m3 | G13: تهیه خاک مناسب از داخل یا خارج از کارگاه شامل کندن و حمل تا 500 متری | I13: 31002
A14: =C14*D14 -> 1670251752 | B14: =ROUND(C14*E14,0) -> 108669600 | C14: =C13 -> 4472 | D14: =E14*$K$3*10 -> 373491 | E14: 24300 | F14: m3-Km | G14: حمل مواد حاصل از عمليات خاكي، فاصله حمل بيش از500 متر تا10 كيلومتر ، براي هر كيلومتر مازاد بر500 متر اول | I14: 30703
A15: =C15*D15 -> 680472936 | B15: =ROUND(C15*E15,0) -> 88545600 | C15: =C13 -> 4472 | D15: =E15*$K$3*5 -> 152163 | E15: 19800 | F15: m3-Km | G15: حمل مواد حاصل از عمليات خاكي،فاصله حمل بيش از10 كيلومتر تا30 كيلومتر باشد، براي هر كيلومتر مازاد بر10 كيلومتر | I15: 30704
B16: =ROUND(C16*E16,0) -> 0 | F16: * | G16: خاکریزی و آبپاشی و کوبیدن با ماشین | I16: *
A17: =C17*D17 -> 961823860 | B17: =ROUND(C17*E17,0) -> 625780000 | C17: ='C.Foundation-1'!O36 -> 2680 | D17: =E17*$K$3 -> 358889.5 | E17: 233500 | F17: m3 | G17: پخش و کوبیدن خاکریزیها با 100% تراکم | I17: 30904
B18: =ROUND(C18*E18,0) -> 0 | F18: * | G18: آبپاشی و کوبیدن سطوح با دست | I18: *
A19: =C19*D19 -> 129452288 | B19: =ROUND(C19*E19,0) -> 84224000 | C19: ='C.Foundation-1'!J36-'C.Foundation-1'!O36 -> 1792 | D19: =E19*$K$3 -> 72239 | E19: 47000 | F19: m2 | G19: آبپاشی و کوبیدن سطوح با تراکم 95 درصد | I19: 20601
B20: =ROUND(C20*E20,0) -> 0 | F20: * | G20: تهیه مصالح و اجرای بتن با عیار 150 کیلو سیمان | I20: *
A21: =C21*D21 -> 1.0945921e+10 | B21: =ROUND(C21*E21,0) -> 7121614200 | C21: ='C.Foundation-1'!L36 -> 795.8 | D21: =E21*$K$3 -> 13754613 | E21: 8949000 | F21: m3 | G21: تهیه و اجرای بتن با شن و ماسه طبیعی با 150 کیلو سیمان | I21: 80102
A22: =C22*D22 -> 2.0732301e+08 | B22: =ROUND(C22*E22,0) -> 134888100 | C22: =C21 -> 795.8 | D22: =E22*$K$3 -> 260521.5 | E22: 169500 | F22: m3 | G22: اضافه بها برای بتن به ضخامت 15 سانتیمتر و کمتر | I22: 80304
B23: =ROUND(C23*E23,0) -> 0 | F23: * | G23: حمل خاک تا km10 با ماشین | I23: *
A24: =C24*D24 -> 1826988864 | B24: =ROUND(C24*E24,0) -> 1188672000 | C24: ='C.Foundation-1'!I36 -> 9664 | D24: =E24*$K$3 -> 189051 | E24: 123000 | F24: m3 | G24: بارگیری موادحاصل عملیات خاکی و حمل تا فاصله 100 متری | I24: 30701
A25: =C26*D25 -> 352772240 | B25: =ROUND(C25*E25,0) -> 45904000 | C25: =C24 -> 9664 | D25: =E25*$K$3*5 -> 36503.75 | E25: 4750 | F25: m3-Km | G25: حمل مواد حاصل از عمليات خاكي برای فاصله حمل بیش از 100متر تا 500متر، به ازایه ر 100 متر مازاد | I25: 30702
A26: =C26*D26 -> 3609417024 | B26: =ROUND(C26*E26,0) -> 234835200 | C26: =C25 -> 9664 | D26: =E26*$K$3*10 -> 373491 | E26: 24300 | F26: m3-Km | G26: حمل مواد حاصل از عمليات خاكي، فاصله حمل بيش از500 متر تا10 كيلومتر ، براي هر كيلومتر مازاد بر500 متر اول | I26: 30703
A27: =C27*D27 -> 9.0591607e+08 | B27: =ROUND(C27*E27,0) -> 589405380 | C27: ='C.Foundation-1'!P36 -> 1410 | D27: =E27*$K$3 -> 642493.67 | E27: =ROUND(39300*L31,0) -> 418018 | F27: مترمربع | G27: تهیه و اجرای بتن آسفالتی با سنگ شکسته از مصالح رودخانه ای برای قشر رویه ( توپکا ) ، هر گاه دانه بندی مصالح صفر تا 12/5 میلی متر باشد ، به ازای هر سانتی متر ضخامت آسفالت | I27: 270306
B28: =ROUND(C28*E28,0) -> 0 | G28: اجرای لایه نفوذ ناپذیر زیر فونداسیون مخازن | I28: *
A29: =C29*D29 -> 3224257120 | B29: =ROUND(C29*E29,0) -> 2097760000 | C29: ='C.Foundation-1'!Q36 -> 2240 | D29: =E29*$K$3 -> 1439400.5 | E29: 936500 | F29: m2 | G29: تهیه و اجرای ژئوممبرین (زمین غشا) از جنس پلی اتیلن سنگین (High Density Poly Ethylene) به ضخامت یک میلی متر | I29: 231206 | K29: چهارم 91 | L29: 481.9
A30: =C30*D30 -> 1548688960 | B30: =ROUND(C30*D30,0) -> 1548688960 | C30: ='C.Foundation-1'!Q36 -> 2240 | D30: =ROUND(65000*L31,0) -> 691379 | E30: - | F30: m2 | G30: تهیه مصالح و اجرای ژئو تکستایل بافته | I30: 231207* | K30: چهارم 1401 | L30: 5125.778
A31: =SUM(A3:A30) -> 2.7397362e+11 | B31: =SUM(B3:B30) -> 175163935524 | G31: مجموع | K31: ضریب بروزرسانی اعمال شده براساس فهرست ابنیه | L31: =L30/L29 -> 10.636601

Sheet C.Shelters-2
A1: جدول 2 - برآورد اجرا بر اساس فهرست بهای ابنیه 1402 - احداث سایبان تجهیزات(بر اساس ریز متره مندرج در جدول ب پیوست 2)
A2: ارزش کار | B2: مبلغ بدون اعمال ضرایب | C2: مقـدار | D2: واحد بــها با اعمال ضریب | E2: واحد بــهامطابق فهرست ابنیه 1402 | F2: واحـد | G2: شــــــــرح | I2: ردیف
F3: * | G3: خاکبرداری و پی کنی با ماشین | I3: * | K3: =ROUND(L4*L5*L6*L7,3) -> 1.537
A4: =C4*D4 -> 1.6926965e+10 | B4: =ROUND(C4*E4,0) -> 11012989500 | C4: ='C.Shelters-1'!F26 -> 6211.5 | D4: =E4*$K$3 -> 2725101 | E4: 1773000 | F4: m3 | G4: کندن زمین در صورت لزوم استفاده از چکش هیدرولیکی در زمین های سنگی و حمل و تخلیه مواد کنده شده تا فاصله ٢٠ متر از مرکز ثقل برداشت | I4: 30504 | K4: منطقه ای گچساران. | L4: 1.09
A5: =C6*D5 -> 2.2674304e+08 | B5: =ROUND(C5*E5,0) -> 29504625 | C5: =C4 -> 6211.5 | D5: =E5*$K$3*5 -> 36503.75 | E5: 4750 | F5: m3-Km | G5: حمل مواد حاصل از عمليات خاكي برای فاصله حمل بیش از 100متر تا 500متر، به ازایهر 100 متر مازاد | I5: 30702 | K5: بالاسری | L5: 1.41
A6: =C6*D6 -> 2.3199393e+09 | B6: =ROUND(C6*E6,0) -> 150939450 | C6: =C5 -> 6211.5 | D6: =E6*$K$3*10 -> 373491 | E6: 24300 | F6: m3-Km | G6: حمل مواد حاصل از عمليات خاكي، فاصله حمل بيش از500 متر تا10 كيلومتر ، براي هر كيلومتر مازاد بر500 متر اول | I6: 30703 | K6: تجهیزکارگاه | L6: 1
B7: =ROUND(C7*E7,0) -> 0 | F7: * | G7: قالب بندی فلزی | I7: * | K7: بروزرسانی | L7: 1
A8: =C8*D8 -> 3287218788 | B8: =ROUND(C8*E8,0) -> 2138724000 | C8: ='C.Shelters-1'!H26 -> 1476 | D8: =E8*$K$3 -> 2227113 | E8: 1449000 | F8: m2 | G8: تهیه مصالح و قالب بندی فلزی در پی ها | I8: 60101
A9: =C9*D9 -> 1.5108956e+08 | B9: =ROUND(C9*E9,0) -> 98301600 | C9: ='C.Shelters-1'!R26 -> 4428 | D9: =E9*$K$3 -> 34121.4 | E9: 22200 | F9: dm3 | G9: تعبیه انواع درز در مقطع عرضی قطعات بتنی بدون پر کرد آن بر حسب حجم درز. | I9: 60912
B10: =ROUND(C10*E10,0) -> 0 | F10: * | G10: تهیه مصالح و اجرای پی | I10: *
A11: =C11*D11 -> 8617682340 | B11: =ROUND(C11*E11,0) -> 5606820000 | C11: ='C.Shelters-1'!Q26 -> 17305 | D11: =E11*$K$3 -> 497988 | E11: 324000 | F11: Kg | G11: تهيه، بريدن، خم كردن و كار گذاشتن ميل گرد ساده به قطر تا 10 ميلي‌متر، براي بتن مسلح | I11: 70101
A12: =C12*D12 -> 1.5452556e+10 | B12: =ROUND(C12*E12,0) -> 10053712500 | C12: ='C.Shelters-1'!K26 -> 39975 | D12: =E12*$K$3 -> 386555.5 | E12: 251500 | F12: Kg | G12: تهیه، بریدن، خم کردن و کار گذاشتن میلگرد آج دار به قطر ١٢ تا ١٨ میلی متر، برای بتن مسلح با سیم پیچی لازم. | I12: 70202
A13: =C13*D13 -> 2.1244725e+10 | B13: =ROUND(C13*E13,0) -> 13822202250 | C13: ='C.Shelters-1'!J26+'C.Shelters-1'!P26 -> 1380.15 | D13: =E13*$K$3 -> 15393055 | E13: 10015000 | F13: m3 | G13: تهیه و اجرای بتن با شن و ماسه طبیعی با عیار 350 کیلو سیمان | I13: 80106
A14: =C14*D14 -> 1.7055176e+08 | B14: =ROUND(C14*E14,0) -> 110964060 | C14: =C13 -> 1380.15 | D14: =E14*$K$3 -> 123574.8 | E14: 80400 | F14: m3 | G14: اضافه بهایه ردیفهای بتنه ریزی در بتن مسلح | I14: 80310
A15: =C15*D15 -> 19011565 | B15: =ROUND(C15*E15,0) -> 12369268 | C15: ='C.Shelters-1'!P26 -> 519.15 | D15: =E15*$K$3 -> 36620.562 | E15: =ROUND(2240*L23,0) -> 23826 | F15: m4 | G15: اضافه بها براي بتن كف‌سازي‌ها با هر وسيله و به هر ضخامت | I15: 80306
A16: =C16*D16 -> 7.8926193e+08 | B16: =ROUND(C16*E16,0) -> 513508088 | C16: ='C.Shelters-1'!M26 -> 1537.5 | D16: =E16*$K$3 -> 513341.09 | E16: =ROUND(31400*L23,0) -> 333989 | F16: kg | G16: نهیه و نصب انکربولت، میل مهار با مهره مربوطه | I16: 70606
B17: =ROUND(C17*E17,0) -> 0 | F17: * | G17: تهیه خاک مناسب از فاصله 15 کیلومتری | I17: *
A18: =C18*D18 -> 1.0918943e+09 | B18: =ROUND(C18*E18,0) -> 710406180 | C18: ='C.Shelters-1'!G26 -> 3690 | D18: =E18*$K$3 -> 295906.31 | E18: =ROUND(18100*L23,0) -> 192522 | F18: m3 | G18: تهیه خاک مناسب از داخل یا خارج از کارگاه شامل کندن و حمل تا 500 متری | I18: 31002
A19: =C19*D19 -> 1378181790 | B19: =ROUND(C19*E19,0) -> 89667000 | C19: =C18 -> 3690 | D19: =E19*$K$3*10 -> 373491 | E19: 24300 | F19: m3-Km | G19: حمل مواد حاصل از عمليات خاكي، فاصله حمل بيش از500 متر تا10 كيلومتر ، براي هر كيلومتر مازاد بر500 متر اول | I19: 30703
A20: =C20*D20 -> 561481470 | B20: =ROUND(C20*E20,0) -> 73062000 | C20: =C18 -> 3690 | D20: =E20*$K$3*5 -> 152163 | E20: 19800 | F20: m3-Km | G20: حمل مواد حاصل از عمليات خاكي،فاصله حمل بيش از10 كيلومتر تا30 كيلومتر باشد، براي هر كيلومتر مازاد بر10 كيلومتر | I20: 30704
B21: =ROUND(C21*E21,0) -> 0 | F21: * | G21: خاکریزی و آبپاشی و کوبیدن با ماشین | I21: * | K21: چهارم 91 | L21: 481.9
A22: =C22*D22 -> 6.6215113e+08 | B22: =ROUND(C22*E22,0) -> 430807500 | C22: ='C.Shelters-1'!L26 -> 1845 | D22: =E22*$K$3 -> 358889.5 | E22: 233500 | F22: m3 | G22: پخش و کوبیدن خاکریزیها با 100% تراکم | I22: 30904 | K22: چهارم 1401 | L22: 5125.778
B23: =ROUND(C23*E23,0) -> 0 | F23: * | G23: آبپاشی و کوبیدن سطوح با دست | I23: * | K23: ضریب بروزرسانی اعمال شده براساس فهرست ابنیه | L23: =L22/L21 -> 10.636601
A24: =C24*D24 -> 133280955 | B24: =ROUND(C24*E24,0) -> 86715000 | C24: ='C.Shelters-1'!G26-'C.Shelters-1'!L26 -> 1845 | D24: =E24*$K$3 -> 72239 | E24: 47000 | F24: m2 | G24: آبپاشی و کوبیدن سطوح با تراکم 95 درصد | I24: 20601
B25: =ROUND(C25*E25,0) -> 0 | F25: * | G25: تهیه مصالح و اجرای بتن با عیار 150 کیلو سیمان | I25: *
A26: =C26*D26 -> 9.9934141e+09 | B26: =ROUND(C26*E26,0) -> 6501895950 | C26: ='C.Shelters-1'!I26+'C.Shelters-1'!O26 -> 726.55 | D26: =E26*$K$3 -> 13754613 | E26: 8949000 | F26: m3 | G26: تهیه و اجرای بتن با شن و ماسه طبیعی با 150 کیلو سیمان | I26: 80102
A27: =C27*D27 -> 1.892819e+08 | B27: =ROUND(C27*E27,0) -> 123150225 | C27: =C26 -> 726.55 | D27: =E27*$K$3 -> 260521.5 | E27: 169500 | F27: m3 | G27: اضافه بها برای بتن به ضخامت 15 سانتیمتر و کمتر | I27: 80304
B28: =ROUND(C28*E28,0) -> 0 | F28: * | G28: حمل خاک تا km10 با ماشین | I28: *
A29: =C29*D29 -> 1.1742903e+09 | B29: =ROUND(C29*E29,0) -> 764014500 | C29: ='C.Shelters-1'!F26 -> 6211.5 | D29: =E29*$K$3 -> 189051 | E29: 123000 | F29: m3 | G29: بارگیری موادحاصل عملیات خاکی و حمل تا فاصله 100 متری | I29: 30701
A30: =C31*D30 -> 2.2674304e+08 | B30: =ROUND(C30*E30,0) -> 29504625 | C30: =C29 -> 6211.5 | D30: =E30*$K$3*5 -> 36503.75 | E30: 4750 | F30: m3-Km | G30: حمل مواد حاصل از عمليات خاكي برای فاصله حمل بیش از 100متر تا 500متر، به ازایه ر 100 متر مازاد | I30: 30702
A31: =C31*D31 -> 2.3199393e+08 | B31: =ROUND(C31*E31,0) -> 150939450 | C31: =C29 -> 6211.5 | D31: =E31*$K$3 -> 37349.1 | E31: 24300 | F31: m3 | G31: حمل از 500 متر تا 10 کیلومتر | I31: 30703
B32: =ROUND(C32*E32,0) -> 0 | G32: عملیات بنایی | I32: *
A33: =C33*D33 -> 8.7022633e+09 | B33: =ROUND(C33*E33,0) -> 5661849900 | C33: ='C.Shelters-1'!N26 -> 1038.3 | D33: =E33*$K$3 -> 8381261 | E33: 5453000 | F33: m3 | G33: سنگ چيني دركف ساختمان (بلوكاژ) با سنگ لاشه. | I33: 40102
B34: =ROUND(C34*E34,0) -> 0 | G34: ساخت سازه فلزی | I34: *
A35: =C35*D35 -> 6.0924142e+10 | B35: =ROUND(C35*E35,0) -> 39638348460 | C35: ='C.Shelters-1 (2)'!F26 -> 118677.69 | D35: =E35*$K$3 -> 513358 | E35: 334000 | F35: Kg | G35: تهیه ، ساخت و نصب ستون از یک تیرآهن | I35: 90101
A36: =C36*D36 -> 5.5913668e+10 | B36: =ROUND(C36*E36,0) -> 36378443739 | C36: ='C.Shelters-1 (2)'!G26 -> 136259.57 | D36: =E36*$K$3 -> 410346.72 | E36: =ROUND(25100*L23,0) -> 266979 | F36: Kg | G36: تهیه و نصب تیرحمال با جوشکاریهای لازم در محل اتصال | I36: 90210
A37: =C37*D37 -> 7.4841167e+10 | B37: =ROUND(C37*E37,0) -> 48693016660 | C37: =SUM(C35:C36) -> 254937.26 | D37: =E37*$K$3 -> 293567 | E37: 191000 | F37: Kg | G37: اضافه بها در صورت مصرف تیراهن پهن | I37: 90605
A38: =C38*D38 -> 1.9660703e+10 | B38: =ROUND(C38*E38,0) -> 12791608885 | C38: ='C.Shelters-1 (2)'!J26 -> 52745.64 | D38: =E38*$K$3 -> 372745.55 | E38: =ROUND(22800*L23,0) -> 242515 | F38: Kg | G38: تهیه و نصب پرلین روی سطح شیبدار اسکلت فلزی از پروفیلZ | I38: 90203
A39: =C39*D39 -> 2.1990251e+10 | B39: =ROUND(C39*E39,0) -> 14307254850 | C39: ='C.Shelters-1 (2)'!I26 -> 43954.7 | D39: =E39*$K$3 -> 500293.5 | E39: 325500 | F39: Kg | G39: تهیه ونصب بادبندبا تمام قطعات اتصال | I39: 90402
A40: =C40*D40 -> 3.2767838e+10 | B40: =ROUND(C40*E40,0) -> 21319348141 | C40: ='C.Shelters-1 (2)'!H26 -> 87909.4 | D40: =E40*$K$3 -> 372745.55 | E40: =ROUND(22800*L23,0) -> 242515 | F40: Kg | G40: تهیه و نصب پرلین روی سطح شیبدار اسکلت فلزی با قطعات اتصال | I40: 90204
...

Sheet C.ROAD-2
A1: جدول 3 - برآورد اجرا بر اساس فهرست بهای ابنیه 1402 - احداث جاده های دسترسی، جاده های داخل واحدها و پاترول(بر اساس ریز متره مندرج در جدول ج پیوست2)
A2: ارزش کار | B2: مبلغ بدون اعمال ضرایب | C2: مقـدار | D2: واحد بــها با اعمال ضریب | E2: واحد بــهامطابق فهرست ابنیه 1402 | F2: واحـد | G2: شــــــــرح | I2: ردیف
A3: =C3*D3 -> 3.6577852e+10 | B3: =ROUND(C3*E3,0) -> 23798212400 | C3: ='C.ROAD-1'!H20 -> 8260.4 | D3: =E3*$K$3 -> 4428097 | E3: 2881000 | F3: m3 | G3: تهیه مصالح زیر اساس از مصالح رودخانه ای با دانه بندی صفر تا 50 میلی متر | I3: 260101 | K3: =ROUND(L4*L5*L6*L7,3) -> 1.537
A4: =C4*D4 -> 4.5338254e+10 | B4: =ROUND(C4*E4,0) -> 29497888400 | C4: ='C.ROAD-1'!I20 -> 8260.4 | D4: =E4*$K$3 -> 5488627 | E4: 3571000 | F4: m3 | G4: تهیه مصالح اساس از مصالح رودخانه ای با دانه بندی صفر تا 38 میلی متر ، وقتی که حداقل 50 درصد مصالح مانده روی الک نمره 4 در یک وجه شکسته باشد | I4: 260302 | K4: منطقه ای گچساران. | L4: 1.09
