Workbook

Sheet Guide
A1: راهنمای بانک قیمت پمپ – نسخه ۸
A2: بر اساس شرح نیاز و اصلاحات سازمانی مهر ۱۴۰۵
A4: ترتیب ستون‌ها | B4: شناسایی ← مشخصات کلیدی (نوع و متریال API 610، دبی، هد، توان، استانداردها، آب‌بند) ← مشخصات تکمیلی ← قیمت ← دامنه کار ← منبع ← محاسبات ← کنترل. ستون‌های فرعی گروه‌بندی شده‌اند و با «+» بالای ستون باز می‌شوند.
A5: رنگ‌ها | B5: سرستون زرد = ورودی Dropdown؛ آبی روشن = ورودی آزاد؛ خاکستری = فرمول. سلول زرد پررنگ = مقدار استنباطی (شاهد در Note). سلول آبی در ستون IRR = تبدیل با نرخ بانک؛ نرخ و قیمت پروژه در Note.
A6: Standards | B6: ستون Standards خودکار از ستون‌های جمع‌شده Pump Standard، IPS، NACE و NFPA 20 ساخته می‌شود. ورودی‌ها را در همان ستون‌های جمع‌شده تغییر دهید.
A7: نرمال‌سازی | B7: Normalized EUR = قیمت یورویی سال منبع ÷ (MAT × SEAL × DRIVE × SCOPE) = قیمت معادل پیکربندی پایه. ضرایب در Factors_ROT و هنوز کالیبره نشده‌اند.
A8: تعدیل | B8: یورو × PPI(هدف)/PPI(پایه)، با کف ۲۵٬۰۰۰ یورو (۱۴۰۴) برای API 610 گریز از مرکز کلاس S/D؛ دلار و ریال با نرخ‌های سال هدف. شاخص PPI از Eurostat C28.13 (EA20)؛ عدد ۱۴۰۵ پیش‌بینی است. CPI استفاده نمی‌شود.
A9: Price Basis چیست؟ | B9: ستون Price Basis می‌گوید عدد قیمت «چه نوع قیمتی» است و از کدام سند آمده: پیشنهاد فروشنده (Inquiry)، برآورد مشاور در MTO مرحله FEED یا Basic، یا قیمت خرید. برچسب کلاس برآورد که در خود سند منبع نوشته شده، عیناً داخل همین متن آمده است.
A10: Incoterm چیست؟ | B10: ستون Incoterm شرط تحویل قیمت است (EXW، FOB و ...). Note هر سلول صریحاً می‌گوید این قیمت «شامل» چه هزینه‌هایی هست و «شامل» چه هزینه‌هایی نیست (حمل، بیمه، ترخیص، بازرسی، یدکی، سربار، مالیات، نصب) و هر کدام در کدام سلول سند منبع جداگانه آمده است. جدول معرفی حالت‌ها در Executive Dashboard است.
A11: یعنی چه قیمتی می‌بینیم؟ | B11: Unit Price (Reference) و معادل‌های یورو/دلار/ریال سال منبع = قیمت تجهیز در سطح فروشنده، بدون سربار پروژه، مالیات و نصب (جز آنچه Note همان ردیف خلاف آن را بگوید). قیمت‌های Escalated همان قیمت است که فقط از نظر زمان به سال هدف آورده شده؛ هیچ هزینه دیگری به آن اضافه نشده است.
A12: Estimator | B12: پارامترها در سمت چپ با ضریب متناظر در ستون C؛ محاسبات و نتیجه در پنل سمت راست.
A13: Search | B13: فیلترها در سه بلوک بالا؛ خلاصه نتایج و لیست رکوردها زیر آن.
A14: Vendor_Quotes | B14: سند پیوست استعلام‌ها؛ در محاسبات Master استفاده نمی‌شود.
A15: رکورد جدید | B15: آخرین ردیف Master را کپی و زیر آن Paste کنید تا فرمول‌ها منتقل شوند (Dropdownها تا ردیف ۶۰۰).

Sheet Executive Dashboard
A1: EXECUTIVE DASHBOARD – بانک قیمت پمپ
A2: فقط رکوردهای Include = Y شمارش می‌شوند. روی سرستون‌ها و سلول‌ها Note توضیحی یا ترجمه فارسی هست.
A4: Target year | B4: ='Assumptions & FX Reference'!$I$5 -> 1404 | C4: EUR→IRR | D4: ='Assumptions & FX Reference'!$I$8 -> 695268 | E4: USD→IRR | F4: ='Assumptions & FX Reference'!$I$11 -> 658533 | G4: PPI target | H4: ='Assumptions & FX Reference'!$I$12 -> 123.416
A6: 1) Pump sub-categories
A7: Sub-Category | B7: Full Name | C7: شرح | D7: Records | E7: With escalated price | F7: % Material stated | G7: % Seal stated | H7: % Size driver
A8: ROT-CRU | B8: Crude Oil & Main Transfer Pumps | C8: پمپ‌های نفت خام: انتقال نفت شور و نمک‌زدایی‌شده، Booster، Off-spec و انتقال اصلی | D8: =COUNTIFS('Master Database'!$BG$5:$BG$600,"Y",'Master Database'!$E$5:$E$600,A8) -> 15 | E8: =COUNTIFS('Master Database'!$BG$5:$BG$600,"Y",'Master Database'!$E$5:$E$600,A8,'Master Database'!$AG$5:$AG$600,">0") -> 10 | F8: =IF(D8=0,"",COUNTIFS('Master Database'!$BG$5:$BG$600,"Y",'Master Database'!$E$5:$E$600,A8,'Master Database'!$G$5:$G$600,"<>Not stated")/D8) -> 0.46666667 | G8: =IF(D8=0,"",COUNTIFS('Master Database'!$BG$5:$BG$600,"Y",'Master Database'!$E$5:$E$600,A8,'Master Database'!$P$5:$P$600,"<>Not stated")/D8) -> 0 | H8: =IF(D8=0,"",COUNTIFS('Master Database'!$BG$5:$BG$600,"Y",'Master Database'!$E$5:$E$600,A8,'Master Database'!$K$5:$K$600,">0")/D8) -> 0.93333333
A9: ROT-WAT | B9: Desalting & Process Water Pumps | C9: آب فرآیندی واحد: آب رقیق‌سازی، Recycle دیسالتر، آب هوازدایی‌شده، آب شیرین و آب خنک‌کن | D9: =COUNTIFS('Master Database'!$BG$5:$BG$600,"Y",'Master Database'!$E$5:$E$600,A9) -> 36 | E9: =COUNTIFS('Master Database'!$BG$5:$BG$600,"Y",'Master Database'!$E$5:$E$600,A9,'Master Database'!$AG$5:$AG$600,">0") -> 28 | F9: =IF(D9=0,"",COUNTIFS('Master Database'!$BG$5:$BG$600,"Y",'Master Database'!$E$5:$E$600,A9,'Master Database'!$G$5:$G$600,"<>Not stated")/D9) -> 0.66666667 | G9: =IF(D9=0,"",COUNTIFS('Master Database'!$BG$5:$BG$600,"Y",'Master Database'!$E$5:$E$600,A9,'Master Database'!$P$5:$P$600,"<>Not stated")/D9) -> 0 | H9: =IF(D9=0,"",COUNTIFS('Master Database'!$BG$5:$BG$600,"Y",'Master Database'!$E$5:$E$600,A9,'Master Database'!$K$5:$K$600,">0")/D9) -> 0.91666667
A10: ROT-INJ | B10: Produced Water & Disposal Injection Pumps | C10: آب تولیدی و پساب: Booster و پمپ‌های پرفشار تزریق به چاه دفعی | D10: =COUNTIFS('Master Database'!$BG$5:$BG$600,"Y",'Master Database'!$E$5:$E$600,A10) -> 21 | E10: =COUNTIFS('Master Database'!$BG$5:$BG$600,"Y",'Master Database'!$E$5:$E$600,A10,'Master Database'!$AG$5:$AG$600,">0") -> 15 | F10: =IF(D10=0,"",COUNTIFS('Master Database'!$BG$5:$BG$600,"Y",'Master Database'!$E$5:$E$600,A10,'Master Database'!$G$5:$G$600,"<>Not stated")/D10) -> 0.80952381 | G10: =IF(D10=0,"",COUNTIFS('Master Database'!$BG$5:$BG$600,"Y",'Master Database'!$E$5:$E$600,A10,'Master Database'!$P$5:$P$600,"<>Not stated")/D10) -> 0 | H10: =IF(D10=0,"",COUNTIFS('Master Database'!$BG$5:$BG$600,"Y",'Master Database'!$E$5:$E$600,A10,'Master Database'!$K$5:$K$600,">0")/D10) -> 0.76190476
A11: ROT-DRN | B11: Drainage, Flare & OWS Pumps | C11: درین بسته و باز، Flare KO Drum، جداکننده آب و نفت (OWS)، نفت بازیافتی و لجن | D11: =COUNTIFS('Master Database'!$BG$5:$BG$600,"Y",'Master Database'!$E$5:$E$600,A11) -> 33 | E11: =COUNTIFS('Master Database'!$BG$5:$BG$600,"Y",'Master Database'!$E$5:$E$600,A11,'Master Database'!$AG$5:$AG$600,">0") -> 27 | F11: =IF(D11=0,"",COUNTIFS('Master Database'!$BG$5:$BG$600,"Y",'Master Database'!$E$5:$E$600,A11,'Master Database'!$G$5:$G$600,"<>Not stated")/D11) -> 0.75757576 | G11: =IF(D11=0,"",COUNTIFS('Master Database'!$BG$5:$BG$600,"Y",'Master Database'!$E$5:$E$600,A11,'Master Database'!$P$5:$P$600,"<>Not stated")/D11) -> 0 | H11: =IF(D11=0,"",COUNTIFS('Master Database'!$BG$5:$BG$600,"Y",'Master Database'!$E$5:$E$600,A11,'Master Database'!$K$5:$K$600,">0")/D11) -> 0.63636364
A12: ROT-AUX | B12: Chemical, Fuel & Auxiliary Pumps | C12: پمپ‌های جانبی: مواد شیمیایی، گلایکول، گازوئیل و سوخت | D12: =COUNTIFS('Master Database'!$BG$5:$BG$600,"Y",'Master Database'!$E$5:$E$600,A12) -> 11 | E12: =COUNTIFS('Master Database'!$BG$5:$BG$600,"Y",'Master Database'!$E$5:$E$600,A12,'Master Database'!$AG$5:$AG$600,">0") -> 9 | F12: =IF(D12=0,"",COUNTIFS('Master Database'!$BG$5:$BG$600,"Y",'Master Database'!$E$5:$E$600,A12,'Master Database'!$G$5:$G$600,"<>Not stated")/D12) -> 0.63636364 | G12: =IF(D12=0,"",COUNTIFS('Master Database'!$BG$5:$BG$600,"Y",'Master Database'!$E$5:$E$600,A12,'Master Database'!$P$5:$P$600,"<>Not stated")/D12) -> 0 | H12: =IF(D12=0,"",COUNTIFS('Master Database'!$BG$5:$BG$600,"Y",'Master Database'!$E$5:$E$600,A12,'Master Database'!$K$5:$K$600,">0")/D12) -> 0.54545455
A13: ROT-FIR | B13: Firewater & Safety Pumps | C13: آتش‌نشانی: پمپ اصلی برقی و دیزلی، Jockey و بارگیری آب آتش‌نشانی | D13: =COUNTIFS('Master Database'!$BG$5:$BG$600,"Y",'Master Database'!$E$5:$E$600,A13) -> 16 | E13: =COUNTIFS('Master Database'!$BG$5:$BG$600,"Y",'Master Database'!$E$5:$E$600,A13,'Master Database'!$AG$5:$AG$600,">0") -> 16 | F13: =IF(D13=0,"",COUNTIFS('Master Database'!$BG$5:$BG$600,"Y",'Master Database'!$E$5:$E$600,A13,'Master Database'!$G$5:$G$600,"<>Not stated")/D13) -> 0.75 | G13: =IF(D13=0,"",COUNTIFS('Master Database'!$BG$5:$BG$600,"Y",'Master Database'!$E$5:$E$600,A13,'Master Database'!$P$5:$P$600,"<>Not stated")/D13) -> 0 | H13: =IF(D13=0,"",COUNTIFS('Master Database'!$BG$5:$BG$600,"Y",'Master Database'!$E$5:$E$600,A13,'Master Database'!$K$5:$K$600,">0")/D13) -> 1
A14: TOTAL | D14: =COUNTIFS('Master Database'!$BG$5:$BG$600,"Y") -> 132 | E14: =COUNTIFS('Master Database'!$BG$5:$BG$600,"Y",'Master Database'!$AG$5:$AG$600,">0") -> 105 | F14: =IF(D14=0,"",COUNTIFS('Master Database'!$BG$5:$BG$600,"Y",'Master Database'!$G$5:$G$600,"<>Not stated")/D14) -> 0.6969697 | G14: =IF(D14=0,"",COUNTIFS('Master Database'!$BG$5:$BG$600,"Y",'Master Database'!$P$5:$P$600,"<>Not stated")/D14) -> 0 | H14: =IF(D14=0,"",COUNTIFS('Master Database'!$BG$5:$BG$600,"Y",'Master Database'!$K$5:$K$600,">0")/D14) -> 0.8030303
A16: 2) API 610 material classes (Table H.1)
A17: Class | B17: Casing | C17: Impeller | D17: Wear rings / Shaft | E17: Typical service
A18: I-1 | B18: Cast iron | C18: Cast iron | D18: Cast-iron rings; carbon-steel shaft | E18: Water and non-corrosive services, low temperature
A19: I-2 | B19: Cast iron | C19: Bronze | D19: Bronze rings; carbon-steel shaft | E19: Water, fire water, fresh water
A20: S-1 | B20: Carbon steel | C20: Cast iron | D20: Cast-iron rings; carbon-steel shaft | E20: Non-corrosive hydrocarbons
A21: S-3 | B21: Carbon steel | C21: Ni-resist | D21: Ni-resist rings; AISI 4140 shaft | E21: Mildly abrasive or corrosive services
A22: S-4 | B22: Carbon steel | C22: Carbon steel | D22: Cast-iron rings; carbon-steel shaft | E22: General hydrocarbons
A23: S-5 | B23: Carbon steel | C23: Carbon steel | D23: Hardened 12% Cr rings; AISI 4140 shaft | E23: General and hot hydrocarbons
A24: S-6 | B24: Carbon steel | C24: 12% Cr | D24: Hardened 12% Cr rings; 12% Cr shaft | E24: Hot hydrocarbons, sour water, mild corrosion
A25: S-8 | B25: Carbon steel | C25: 316 stainless steel | D25: Hard-faced 316 rings; 316 shaft | E25: More corrosive services
A26: S-9 | B26: Carbon steel | C26: Ni-Cu alloy | D26: Ni-Cu rings; Ni-Cu shaft | E26: Special corrosive services
A27: C-6 | B27: 12% Cr | C27: 12% Cr | D27: Hardened 12% Cr rings; 12% Cr shaft | E27: Boiler feed water, hot hydrocarbons
A28: A-7 | B28: Austenitic stainless steel | C28: Austenitic stainless steel | D28: Hard-faced rings; austenitic shaft | E28: High corrosion, low temperature
... A33: Not stated | B33: — | C33: — | D33: — | E33: Not stated in source
A36: 3) Pump types per API 610
A37: Type | B37: Name | C37: Description
A38: OH1 | B38: Overhung, foot-mounted | C38: Single-stage overhung, foot-mounted; moderate temperature and pressure
A39: OH2 | B39: Overhung, centreline-mounted | C39: Single-stage overhung, centreline-mounted; the most common refinery process pump, suitable for high temperature
A40: OH3 | B40: Vertical in-line, separate bearing bracket | C40: Vertical in-line pump with separate bearing bracket
A41: OH4 | B41: Vertical in-line, rigidly coupled | C41: Vertical in-line pump, rigidly coupled
A42: OH5 | B42: Vertical in-line, close-coupled | C42: Vertical in-line pump, close-coupled (impeller on the motor shaft)
A43: OH6 | B43: High-speed integral gear | C43: High-speed integral-gear pump; low flow, high head
A44: BB1 | B44: Between bearings, 1–2 stage, axially split | C44: Between bearings, 1–2 stage, axially split casing
A45: BB2 | B45: Between bearings, 1–2 stage, radially split | C45: Between bearings, 1–2 stage, radially split; high temperature and pressure
A46: BB3 | B46: Between bearings, multistage, axially split | C46: Multistage, axially split casing; water injection and high-pressure transfer
A47: BB4 | B47: Between bearings, multistage, single casing radially split | C47: Multistage single-casing ring-section pump
A48: BB5 | B48: Between bearings, multistage, double casing (barrel) | C48: Multistage double-casing (barrel) pump; the most severe high-pressure services
... A60: Not stated | B60: — | C60: Pump type not stated in source
...

Sheet Master Database
A1: MASTER PUMP PRICE DATABASE – v8
A2: ستون‌های گروه‌بندی‌شده با دکمه «+» بالای ستون‌ها باز می‌شوند. سرستون زرد = ورودی Dropdown، خاکستری = فرمول. سلول زرد پررنگ = مقدار استنباطی (شاهد در Note)؛ سلول آبی = تبدیل ارز با نرخ بانک (نرخ پروژه در Note). روی هر سرستون Note توضیحی هست.
A3: شناسایی | F3: مشخصات کلیدی | V3: مشخصات تکمیلی | Y3: قیمت | AJ3: منبع و سازنده | AL3: دامنه کار (Scope) | AS3: کنترل و ردیابی | AT3: محاسبات نرمال‌سازی و تعدیل (فرمول) | BE3: کنترل و ردیابی
A4: Row | B4: Equipment Name | C4: Project Name | D4: Tag No. | E4: Sub-Category | F4: API 610 Type | G4: API 610 Material Class | H4: Capacity (m³/h) | I4: Diff. Head (m) | J4: Power (kW) | K4: Size Driver kW (est.) | L4: Standards | M4: Pump Standard | N4: IPS Standard | O4: NACE MR0175 (Y/N) | P4: Seal Type / Arrangement | Q4: API 682 Category | R4: API 682 Seal Plan | S4: Driver Type | T4: Service Fluid | U4: Quantity | V4: Pump Family | W4: Discharge Pressure (barg) | X4: Power Basis | Y4: Cost Year (Jalali) | Z4: Reference Currency | AA4: Unit Price (Reference) | AB4: Unit Price EUR (source yr) | AC4: Unit Price USD (source yr) | AD4: Unit Price IRR (source yr) | AE4: Price Basis (as stated in source) | AF4: Incoterm | AG4: Escalated Unit Price EUR (target yr) | AH4: Escalated Unit Price USD (target yr) | AI4: Escalated Unit Price IRR (target yr) | AJ4: Manufacturer / Supplier (as in source) | AK4: Project Phase | AL4: Scope: Driver incl. | AM4: Scope: Baseplate & Coupling | AN4: Scope: Seal Support System | AO4: Scope: Comm. Spares | AP4: Scope: 2-yr Spares | AQ4: Scope: TPI | AR4: Scope: Witnessed FAT | AS4: QA Flag | AT4: MAT_F | AU4: SEAL_F | AV4: DRIVE_F | AW4: SCOPE_F | AX4: ALL_F | AY4: Normalized EUR (base config, source yr) | AZ4: PPI Base | BA4: PPI Target | BB4: Floor Applies | BC4: Normalized Escalated EUR | BD4: Cost Coefficient (NormEsc EUR / kW^n) | BE4: Source Document | BF4: Remarks & Notes | BG4: Include in Totals (Y/N)
A5: 1 | B5: 2nd Stage Separators Oil Pumps | C5: (نام پروژه در فایل قید نشده است) – CSV 18061405 | D5: (Not stated in source document) | E5: ROT-CRU | F5: Not stated | G5: Not stated | I5: 95.8 | J5: 54.3 | K5: =IF(ISNUMBER(J5),J5,IF(AND(ISNUMBER(H5),ISNUMBER(I5)),H5*I5/(367*'Assumptions & FX Reference'!$I$17),"")) -> 54.3 | L5: =IF(IF(OR(M5="Not stated",M5=""),""," + "&M5)&IF(OR(N5="None",N5=""),""," + "&N5)&IF(O5="Y"," + NACE MR0175","")="","Not stated",MID(IF(OR(M5="Not stated",M5=""),""," + "&M5)&IF(OR(N5="None",N5=""),""," + "&N5)&IF(O5="Y"," + NACE MR0175",""),4,300)) -> Not stated | M5: Not stated | N5: None | O5: Not stated | P5: Not stated | Q5: Not stated | R5: Not stated | S5: Electric Motor | T5: Crude Oil | U5: 1 | V5: Centrifugal | X5: Not stated | Y5: (Not stated) | Z5: USD | AA5: 240000 | AB5: =IF(NOT(ISNUMBER(AA5)),"(Not stated)",IF(NOT(ISNUMBER(Y5)),"(Cost year not stated)",IFERROR(IF(Z5="EUR",AA5,IF(Z5="IRR",AA5/INDEX('Assumptions & FX Reference'!$C$5:$C$25,MATCH(Y5,'Assumptions & FX Reference'!$A$5:$A$25,0)),IF(Z5="USD",AA5*INDEX('Assumptions & FX Reference'!$B$5:$B$25,MATCH(Y5,'Assumptions & FX Reference'!$A$5:$A$25,0))/INDEX('Assumptions & FX Reference'!$C$5:$C$25,MATCH(Y5,'Assumptions & FX Reference'!$A$5:$A$25,0)),"(Currency?)"))),"(FX rate missing)"))) -> (Cost year not stated) | AC5: =IF(NOT(ISNUMBER(AA5)),"(Not stated)",IF(NOT(ISNUMBER(Y5)),"(Cost year not stated)",IFERROR(IF(Z5="USD",AA5,IF(Z5="IRR",AA5/INDEX('Assumptions & FX Reference'!$B$5:$B$25,MATCH(Y5,'Assumptions & FX Reference'!$A$5:$A$25,0)),IF(Z5="EUR",AA5*INDEX('Assumptions & FX Reference'!$C$5:$C$25,MATCH(Y5,'Assumptions & FX Reference'!$A$5:$A$25,0))/INDEX('Assumptions & FX Reference'!$B$5:$B$25,MATCH(Y5,'Assumptions & FX Reference'!$A$5:$A$25,0)),"(Currency?)"))),"(FX rate missing)"))) -> (Cost year not stated) | AD5: =IF(NOT(ISNUMBER(AA5)),"(Not stated)",IF(NOT(ISNUMBER(Y5)),"(Cost year not stated)",IFERROR(IF(Z5="IRR",AA5,IF(Z5="USD",AA5*INDEX('Assumptions & FX Reference'!$B$5:$B$25,MATCH(Y5,'Assumptions & FX Reference'!$A$5:$A$25,0)),IF(Z5="EUR",AA5*INDEX('Assumptions & FX Reference'!$C$5:$C$25,MATCH(Y5,'Assumptions & FX Reference'!$A$5:$A$25,0)),"(Currency?)"))),"(FX rate missing)"))) -> (Cost year not stated) | AE5: Purchase price (USD) – 18061405 pump CSV; project and year not stated | AF5: Not stated | AG5: =IF(AND(Z5="EUR",N(AA5)>5000000),"(Check currency – excluded)",IF(AND(ISNUMBER(AB5),ISNUMBER(AZ5),ISNUMBER(BA5)),IF(AND(BB5="Y",ISNUMBER('Assumptions & FX Reference'!$I$15)),MAX(AB5*BA5/AZ5,'Assumptions & FX Reference'!$I$13*BA5/'Assumptions & FX Reference'!$I$15),AB5*BA5/AZ5),"(PPI/FX missing)")) -> (PPI/FX missing) | AH5: =IF(AND(ISNUMBER(AG5),ISNUMBER('Assumptions & FX Reference'!$I$8),ISNUMBER('Assumptions & FX Reference'!$I$11)),AG5*'Assumptions & FX Reference'!$I$8/'Assumptions & FX Reference'!$I$11,"") | AI5: =IF(AND(ISNUMBER(AG5),ISNUMBER('Assumptions & FX Reference'!$I$8)),AG5*'Assumptions & FX Reference'!$I$8,"") | AJ5: (Not stated in source document) | AK5: Not stated | AL5: Not stated | AM5: Not stated | AN5: Not stated | AO5: Not stated | AP5: Not stated | AQ5: Not stated | AR5: Not stated | AS5: =IF(AND(Z5="EUR",N(AA5)>5000000),"Check currency (EUR>5M); ","")&IF(NOT(ISNUMBER(AA5)),"No price; ","")&IF(G5="Not stated","Material missing; ","")&IF(P5="Not stated","Seal missing; ","")&IF(K5="","Size driver missing; ","")&IF(NOT(ISNUMBER(AZ5)),"Base-year PPI missing; ","") -> Material missing; Seal missing; Base-year PPI missing; | AT5: =IFERROR(INDEX(Factors_ROT!$F$5:$F$200,MATCH("MAT|"&G5,Factors_ROT!$A$5:$A$200,0)),1) -> 1 | AU5: =IFERROR(INDEX(Factors_ROT!$F$5:$F$200,MATCH("SEAL_ARR|"&P5,Factors_ROT!$A$5:$A$200,0)),1)*IFERROR(INDEX(Factors_ROT!$F$5:$F$200,MATCH("SEAL_CAT|"&Q5,Factors_ROT!$A$5:$A$200,0)),1)*IFERROR(INDEX(Factors_ROT!$F$5:$F$200,MATCH("SEAL_PLAN|"&R5,Factors_ROT!$A$5:$A$200,0)),1) -> 1 | AV5: =IFERROR(INDEX(Factors_ROT!$F$5:$F$200,MATCH("DRV|"&S5,Factors_ROT!$A$5:$A$200,0)),1)*IFERROR(INDEX(Factors_ROT!$F$5:$F$200,MATCH("NACE|"&O5,Factors_ROT!$A$5:$A$200,0)),1) -> 1 | AW5: =IFERROR(INDEX(Factors_ROT!$F$5:$F$200,MATCH("SC_DRV|"&AL5,Factors_ROT!$A$5:$A$200,0)),1)*IFERROR(INDEX(Factors_ROT!$F$5:$F$200,MATCH("SC_BSP|"&AM5,Factors_ROT!$A$5:$A$200,0)),1)*IFERROR(INDEX(Factors_ROT!$F$5:$F$200,MATCH("SC_SEAL|"&AN5,Factors_ROT!$A$5:$A$200,0)),1)*IFERROR(INDEX(Factors_ROT!$F$5:$F$200,MATCH("SC_COMM|"&AO5,Factors_ROT!$A$5:$A$200,0)),1)*IFERROR(INDEX(Factors_ROT!$F$5:$F$200,MATCH("SC_2Y|"&AP5,Factors_ROT!$A$5:$A$200,0)),1)*IFERROR(INDEX(Factors_ROT!$F$5:$F$200,MATCH("SC_TPI|"&AQ5,Factors_ROT!$A$5:$A$200,0)),1)*IFERROR(INDEX(Factors_ROT!$F$5:$F$200,MATCH("SC_FAT|"&AR5,Factors_ROT!$A$5:$A$200,0)),1) -> 1 | AX5: =AT5*AU5*AV5*AW5 -> 1 | AY5: =IF(ISNUMBER(AB5),AB5/AX5,"") | AZ5: =IFERROR(IF(N(INDEX(Escalation_Index!$B$5:$B$25,MATCH(Y5,Escalation_Index!$A$5:$A$25,0)))>0,INDEX(Escalation_Index!$B$5:$B$25,MATCH(Y5,Escalation_Index!$A$5:$A$25,0)),""),"") | BA5: =IF(ISNUMBER('Assumptions & FX Reference'!$I$12),'Assumptions & FX Reference'!$I$12,"") -> 123.416 | BB5: =IF(AND(M5="API 610",LEFT(V5,11)="Centrifugal",OR(LEFT(G5,2)="S-",LEFT(G5,2)="D-")),"Y","N") -> N | BC5: =IF(ISNUMBER(AG5),AG5/AX5,"") | BD5: =IF(AND(ISNUMBER(BC5),ISNUMBER(K5)),IF(K5>0,BC5/K5^'Assumptions & FX Reference'!$I$16,""),"") | BE5: 18061405_Pump_only_CSV.csv – section Pumps (row 1) | BF5: Type: Centrifugal | Driver: موتور الکتریکی (E) | Power: 54.3 kW | Head: 95.8 m | گمرک و حمل: $14400 | Duplicate of the xlsx-sourced record for the same pump (see PUMPS.csv row); kept for reference, excluded from totals. | Original type text: Centrifugal | BG5: N
A6: 2 | B6: 3rd Stage Separators Oil Pumps | C6: (نام پروژه در فایل قید نشده است) – CSV 18061405 | D6: (Not stated in source document) | E6: ROT-CRU | F6: Not stated | G6: Not stated | I6: 59.9 | J6: 33.1 | K6: =IF(ISNUMBER(J6),J6,IF(AND(ISNUMBER(H6),ISNUMBER(I6)),H6*I6/(367*'Assumptions & FX Reference'!$I$17),"")) -> 33.1 | L6: =IF(IF(OR(M6="Not stated",M6=""),""," + "&M6)&IF(OR(N6="None",N6=""),""," + "&N6)&IF(O6="Y"," + NACE MR0175","")="","Not stated",MID(IF(OR(M6="Not stated",M6=""),""," + "&M6)&IF(OR(N6="None",N6=""),""," + "&N6)&IF(O6="Y"," + NACE MR0175",""),4,300)) -> Not stated | M6: Not stated | N6: None | O6: Not stated | P6: Not stated | Q6: Not stated | R6: Not stated | S6: Electric Motor | T6: Crude Oil | U6: 1 | V6: Centrifugal | X6: Not stated | Y6: (Not stated) | Z6: USD | AA6: 280000 | AB6: =IF(NOT(ISNUMBER(AA6)),"(Not stated)",IF(NOT(ISNUMBER(Y6)),"(Cost year not stated)",IFERROR(IF(Z6="EUR",AA6,IF(Z6="IRR",AA6/INDEX('Assumptions & FX Reference'!$C$5:$C$25,MATCH(Y6,'Assumptions & FX Reference'!$A$5:$A$25,0)),IF(Z6="USD",AA6*INDEX('Assumptions & FX Reference'!$B$5:$B$25,MATCH(Y6,'Assumptions & FX Reference'!$A$5:$A$25,0))/INDEX('Assumptions & FX Reference'!$C$5:$C$25,MATCH(Y6,'Assumptions & FX Reference'!$A$5:$A$25,0)),"(Currency?)"))),"(FX rate missing)"))) -> (Cost year not stated) | AC6: =IF(NOT(ISNUMBER(AA6)),"(Not stated)",IF(NOT(ISNUMBER(Y6)),"(Cost year not stated)",IFERROR(IF(Z6="USD",AA6,IF(Z6="IRR",AA6/INDEX('Assumptions & FX Reference'!$B$5:$B$25,MATCH(Y6,'Assumptions & FX Reference'!$A$5:$A$25,0)),IF(Z6="EUR",AA6*INDEX('Assumptions & FX Reference'!$C$5:$C$25,MATCH(Y6,'Assumptions & FX Reference'!$A$5:$A$25,0))/INDEX('Assumptions & FX Reference'!$B$5:$B$25,MATCH(Y6,'Assumptions & FX Reference'!$A$5:$A$25,0)),"(Currency?)"))),"(FX rate missing)"))) -> (Cost year not stated) | AD6: =IF(NOT(ISNUMBER(AA6)),"(Not stated)",IF(NOT(ISNUMBER(Y6)),"(Cost year not stated)",IFERROR(IF(Z6="IRR",AA6,IF(Z6="USD",AA6*INDEX('Assumptions & FX Reference'!$B$5:$B$25,MATCH(Y6,'Assumptions & FX Reference'!$A$5:$A$25,0)),IF(Z6="EUR",AA6*INDEX('Assumptions & FX Reference'!$C$5:$C$25,MATCH(Y6,'Assumptions & FX Reference'!$A$5:$A$25,0)),"(Currency?)"))),"(FX rate missing)"))) -> (Cost year not stated) | AE6: Purchase price (USD) – 18061405 pump CSV; project and year not stated | AF6: Not stated | AG6: =IF(AND(Z6="EUR",N(AA6)>5000000),"(Check currency – excluded)",IF(AND(ISNUMBER(AB6),ISNUMBER(AZ6),ISNUMBER(BA6)),IF(AND(BB6="Y",ISNUMBER('Assumptions & FX Reference'!$I$15)),MAX(AB6*BA6/AZ6,'Assumptions & FX Reference'!$I$13*BA6/'Assumptions & FX Reference'!$I$15),AB6*BA6/AZ6),"(PPI/FX missing)")) -> (PPI/FX missing) | AH6: =IF(AND(ISNUMBER(AG6),ISNUMBER('Assumptions & FX Reference'!$I$8),ISNUMBER('Assumptions & FX Reference'!$I$11)),AG6*'Assumptions & FX Reference'!$I$8/'Assumptions & FX Reference'!$I$11,"") | AI6: =IF(AND(ISNUMBER(AG6),ISNUMBER('Assumptions & FX Reference'!$I$8)),AG6*'Assumptions & FX Reference'!$I$8,"") | AJ6: (Not stated in source document) | AK6: Not stated | AL6: Not stated | AM6: Not stated | AN6: Not stated | AO6: Not stated | AP6: Not stated | AQ6: Not stated | AR6: Not stated | AS6: =IF(AND(Z6="EUR",N(AA6)>5000000),"Check currency (EUR>5M); ","")&IF(NOT(ISNUMBER(AA6)),"No price; ","")&IF(G6="Not stated","Material missing; ","")&IF(P6="Not stated","Seal missing; ","")&IF(K6="","Size driver missing; ","")&IF(NOT(ISNUMBER(AZ6)),"Base-year PPI missing; ","") -> Material missing; Seal missing; Base-year PPI missing; | AT6: =IFERROR(INDEX(Factors_ROT!$F$5:$F$200,MATCH("MAT|"&G6,Factors_ROT!$A$5:$A$200,0)),1) -> 1 | AU6: =IFERROR(INDEX(Factors_ROT!$F$5:$F$200,MATCH("SEAL_ARR|"&P6,Factors_ROT!$A$5:$A$200,0)),1)*IFERROR(INDEX(Factors_ROT!$F$5:$F$200,MATCH("SEAL_CAT|"&Q6,Factors_ROT!$A$5:$A$200,0)),1)*IFERROR(INDEX(Factors_ROT!$F$5:$F$200,MATCH("SEAL_PLAN|"&R6,Factors_ROT!$A$5:$A$200,0)),1) -> 1 | AV6: =IFERROR(INDEX(Factors_ROT!$F$5:$F$200,MATCH("DRV|"&S6,Factors_ROT!$A$5:$A$200,0)),1)*IFERROR(INDEX(Factors_ROT!$F$5:$F$200,MATCH("NACE|"&O6,Factors_ROT!$A$5:$A$200,0)),1) -> 1 | AW6: =IFERROR(INDEX(Factors_ROT!$F$5:$F$200,MATCH("SC_DRV|"&AL6,Factors_ROT!$A$5:$A$200,0)),1)*IFERROR(INDEX(Factors_ROT!$F$5:$F$200,MATCH("SC_BSP|"&AM6,Factors_ROT!$A$5:$A$200,0)),1)*IFERROR(INDEX(Factors_ROT!$F$5:$F$200,MATCH("SC_SEAL|"&AN6,Factors_ROT!$A$5:$A$200,0)),1)*IFERROR(INDEX(Factors_ROT!$F$5:$F$200,MATCH("SC_COMM|"&AO6,Factors_ROT!$A$5:$A$200,0)),1)*IFERROR(INDEX(Factors_ROT!$F$5:$F$200,MATCH("SC_2Y|"&AP6,Factors_ROT!$A$5:$A$200,0)),1)*IFERROR(INDEX(Factors_ROT!$F$5:$F$200,MATCH("SC_TPI|"&AQ6,Factors_ROT!$A$5:$A$200,0)),1)*IFERROR(INDEX(Factors_ROT!$F$5:$F$200,MATCH("SC_FAT|"&AR6,Factors_ROT!$A$5:$A$200,0)),1) -> 1 | AX6: =AT6*AU6*AV6*AW6 -> 1 | AY6: =IF(ISNUMBER(AB6),AB6/AX6,"") | AZ6: =IFERROR(IF(N(INDEX(Escalation_Index!$B$5:$B$25,MATCH(Y6,Escalation_Index!$A$5:$A$25,0)))>0,INDEX(Escalation_Index!$B$5:$B$25,MATCH(Y6,Escalation_Index!$A$5:$A$25,0)),""),"") | BA6: =IF(ISNUMBER('Assumptions & FX Reference'!$I$12),'Assumptions & FX Reference'!$I$12,"") -> 123.416 | BB6: =IF(AND(M6="API 610",LEFT(V6,11)="Centrifugal",OR(LEFT(G6,2)="S-",LEFT(G6,2)="D-")),"Y","N") -> N | BC6: =IF(ISNUMBER(AG6),AG6/AX6,"") | BD6: =IF(AND(ISNUMBER(BC6),ISNUMBER(K6)),IF(K6>0,BC6/K6^'Assumptions & FX Reference'!$I$16,""),"") | BE6: 18061405_Pump_only_CSV.csv – section Pumps (row 2) | BF6: Type: Centrifugal | Driver: موتور الکتریکی (E) | Power: 33.1 kW | Head: 59.9 m | گمرک و حمل: $16800 | Duplicate of the xlsx-sourced record for the same pump (see PUMPS.csv row); kept for reference, excluded from totals. | Original type text: Centrifugal | BG6: N
A7: 3 | B7: Stabilized Oil Pump | C7: (نام پروژه در فایل قید نشده است) – CSV 18061405 | D7: (Not stated in source document) | E7: ROT-CRU | F7: Not stated | G7: Not stated | I7: 34.8 | J7: 57.4 | K7: =IF(ISNUMBER(J7),J7,IF(AND(ISNUMBER(H7),ISNUMBER(I7)),H7*I7/(367*'Assumptions & FX Reference'!$I$17),"")) -> 57.4 | L7: =IF(IF(OR(M7="Not stated",M7=""),""," + "&M7)&IF(OR(N7="None",N7=""),""," + "&N7)&IF(O7="Y"," + NACE MR0175","")="","Not stated",MID(IF(OR(M7="Not stated",M7=""),""," + "&M7)&IF(OR(N7="None",N7=""),""," + "&N7)&IF(O7="Y"," + NACE MR0175",""),4,300)) -> Not stated | M7: Not stated | N7: None | O7: Not stated | P7: Not stated | Q7: Not stated | R7: Not stated | S7: Electric Motor | T7: Crude Oil | U7: 1 | V7: Centrifugal | X7: Not stated | Y7: (Not stated) | Z7: USD | AA7: 250000 | AB7: =IF(NOT(ISNUMBER(AA7)),"(Not stated)",IF(NOT(ISNUMBER(Y7)),"(Cost year not stated)",IFERROR(IF(Z7="EUR",AA7,IF(Z7="IRR",AA7/INDEX('Assumptions & FX Reference'!$C$5:$C$25,MATCH(Y7,'Assumptions & FX Reference'!$A$5:$A$25,0)),IF(Z7="USD",AA7*INDEX('Assumptions & FX Reference'!$B$5:$B$25,MATCH(Y7,'Assumptions & FX Reference'!$A$5:$A$25,0))/INDEX('Assumptions & FX Reference'!$C$5:$C$25,MATCH(Y7,'Assumptions & FX Reference'!$A$5:$A$25,0)),"(Currency?)"))),"(FX rate missing)"))) -> (Cost year not stated) | AC7: =IF(NOT(ISNUMBER(AA7)),"(Not stated)",IF(NOT(ISNUMBER(Y7)),"(Cost year not stated)",IFERROR(IF(Z7="USD",AA7,IF(Z7="IRR",AA7/INDEX('Assumptions & FX Reference'!$B$5:$B$25,MATCH(Y7,'Assumptions & FX Reference'!$A$5:$A$25,0)),IF(Z7="EUR",AA7*INDEX('Assumptions & FX Reference'!$C$5:$C$25,MATCH(Y7,'Assumptions & FX Reference'!$A$5:$A$25,0))/INDEX('Assumptions & FX Reference'!$B$5:$B$25,MATCH(Y7,'Assumptions & FX Reference'!$A$5:$A$25,0)),"(Currency?)"))),"(FX rate missing)"))) -> (Cost year not stated) | AD7: =IF(NOT(ISNUMBER(AA7)),"(Not stated)",IF(NOT(ISNUMBER(Y7)),"(Cost year not stated)",IFERROR(IF(Z7="IRR",AA7,IF(Z7="USD",AA7*INDEX('Assumptions & FX Reference'!$B$5:$B$25,MATCH(Y7,'Assumptions & FX Reference'!$A$5:$A$25,0)),IF(Z7="EUR",AA7*INDEX('Assumptions & FX Reference'!$C$5:$C$25,MATCH(Y7,'Assumptions & FX Reference'!$A$5:$A$25,0)),"(Currency?)"))),"(FX rate missing)"))) -> (Cost year not stated) | AE7: Purchase price (USD) – 18061405 pump CSV; project and year not stated | AF7: Not stated | AG7: =IF(AND(Z7="EUR",N(AA7)>5000000),"(Check currency – excluded)",IF(AND(ISNUMBER(AB7),ISNUMBER(AZ7),ISNUMBER(BA7)),IF(AND(BB7="Y",ISNUMBER('Assumptions & FX Reference'!$I$15)),MAX(AB7*BA7/AZ7,'Assumptions & FX Reference'!$I$13*BA7/'Assumptions & FX Reference'!$I$15),AB7*BA7/AZ7),"(PPI/FX missing)")) -> (PPI/FX missing) | AH7: =IF(AND(ISNUMBER(AG7),ISNUMBER('Assumptions & FX Reference'!$I$8),ISNUMBER('Assumptions & FX Reference'!$I$11)),AG7*'Assumptions & FX Reference'!$I$8/'Assumptions & FX Reference'!$I$11,"") | AI7: =IF(AND(ISNUMBER(AG7),ISNUMBER('Assumptions & FX Reference'!$I$8)),AG7*'Assumptions & FX Reference'!$I$8,"") | AJ7: (Not stated in source document) | AK7: Not stated | AL7: Not stated | AM7: Not stated | AN7: Not stated | AO7: Not stated | AP7: Not stated | AQ7: Not stated | AR7: Not stated | AS7: =IF(AND(Z7="EUR",N(AA7)>5000000),"Check currency (EUR>5M); ","")&IF(NOT(ISNUMBER(AA7)),"No price; ","")&IF(G7="Not stated","Material missing; ","")&IF(P7="Not stated","Seal missing; ","")&IF(K7="","Size driver missing; ","")&IF(NOT(ISNUMBER(AZ7)),"Base-year PPI missing; ","") -> Material missing; Seal missing; Base-year PPI missing; | AT7: =IFERROR(INDEX(Factors_ROT!$F$5:$F$200,MATCH("MAT|"&G7,Factors_ROT!$A$5:$A$200,0)),1) -> 1 | AU7: =IFERROR(INDEX(Factors_ROT!$F$5:$F$200,MATCH("SEAL_ARR|"&P7,Factors_ROT!$A$5:$A$200,0)),1)*IFERROR(INDEX(Factors_ROT!$F$5:$F$200,MATCH("SEAL_CAT|"&Q7,Factors_ROT!$A$5:$A$200,0)),1)*IFERROR(INDEX(Factors_ROT!$F$5:$F$200,MATCH("SEAL_PLAN|"&R7,Factors_ROT!$A$5:$A$200,0)),1) -> 1 | AV7: =IFERROR(INDEX(Factors_ROT!$F$5:$F$200,MATCH("DRV|"&S7,Factors_ROT!$A$5:$A$200,0)),1)*IFERROR(INDEX(Factors_ROT!$F$5:$F$200,MATCH("NACE|"&O7,Factors_ROT!$A$5:$A$200,0)),1) -> 1 | AW7: =IFERROR(INDEX(Factors_ROT!$F$5:$F$200,MATCH("SC_DRV|"&AL7,Factors_ROT!$A$5:$A$200,0)),1)*IFERROR(INDEX(Factors_ROT!$F$5:$F$200,MATCH("SC_BSP|"&AM7,Factors_ROT!$A$5:$A$200,0)),1)*IFERROR(INDEX(Factors_ROT!$F$5:$F$200,MATCH("SC_SEAL|"&AN7,Factors_ROT!$A$5:$A$200,0)),1)*IFERROR(INDEX(Factors_ROT!$F$5:$F$200,MATCH("SC_COMM|"&AO7,Factors_ROT!$A$5:$A$200,0)),1)*IFERROR(INDEX(Factors_ROT!$F$5:$F$200,MATCH("SC_2Y|"&AP7,Factors_ROT!$A$5:$A$200,0)),1)*IFERROR(INDEX(Factors_ROT!$F$5:$F$200,MATCH("SC_TPI|"&AQ7,Factors_ROT!$A$5:$A$200,0)),1)*IFERROR(INDEX(Factors_ROT!$F$5:$F$200,MATCH("SC_FAT|"&AR7,Factors_ROT!$A$5:$A$200,0)),1) -> 1 | AX7: =AT7*AU7*AV7*AW7 -> 1 | AY7: =IF(ISNUMBER(AB7),AB7/AX7,"") | AZ7: =IFERROR(IF(N(INDEX(Escalation_Index!$B$5:$B$25,MATCH(Y7,Escalation_Index!$A$5:$A$25,0)))>0,INDEX(Escalation_Index!$B$5:$B$25,MATCH(Y7,Escalation_Index!$A$5:$A$25,0)),""),"") | BA7: =IF(ISNUMBER('Assumptions & FX Reference'!$I$12),'Assumptions & FX Reference'!$I$12,"") -> 123.416 | BB7: =IF(AND(M7="API 610",LEFT(V7,11)="Centrifugal",OR(LEFT(G7,2)="S-",LEFT(G7,2)="D-")),"Y","N") -> N | BC7: =IF(ISNUMBER(AG7),AG7/AX7,"") | BD7: =IF(AND(ISNUMBER(BC7),ISNUMBER(K7)),IF(K7>0,BC7/K7^'Assumptions & FX Reference'!$I$16,""),"") | BE7: 18061405_Pump_only_CSV.csv – section Pumps (row 3) | BF7: Type: Centrifugal | Driver: موتور الکتریکی (E) | Power: 57.4 kW | Head: 34.8 m | گمرک و حمل: $15000 | Duplicate of the xlsx-sourced record for the same pump (see PUMPS.csv row); kept for reference, excluded from totals. | Original type text: Centrifugal | BG7: N
A8: 4 | B8: Product Oil Pump | C8: (نام پروژه در فایل قید نشده است) – CSV 18061405 | D8: (Not stated in source document) | E8: ROT-CRU | F8: Not stated | G8: Not stated | I8: 329 | J8: 379 | K8: =IF(ISNUMBER(J8),J8,IF(AND(ISNUMBER(H8),ISNUMBER(I8)),H8*I8/(367*'Assumptions & FX Reference'!$I$17),"")) -> 379 | L8: =IF(IF(OR(M8="Not stated",M8=""),""," + "&M8)&IF(OR(N8="None",N8=""),""," + "&N8)&IF(O8="Y"," + NACE MR0175","")="","Not stated",MID(IF(OR(M8="Not stated",M8=""),""," + "&M8)&IF(OR(N8="None",N8=""),""," + "&N8)&IF(O8="Y"," + NACE MR0175",""),4,300)) -> Not stated | M8: Not stated | N8: None | O8: Not stated | P8: Not stated | Q8: Not stated | R8: Not stated | S8: Electric Motor | T8: Crude Oil | U8: 1 | V8: Centrifugal | X8: Not stated | Y8: (Not stated) | Z8: USD | AA8: 420000 | AB8: =IF(NOT(ISNUMBER(AA8)),"(Not stated)",IF(NOT(ISNUMBER(Y8)),"(Cost year not stated)",IFERROR(IF(Z8="EUR",AA8,IF(Z8="IRR",AA8/INDEX('Assumptions & FX Reference'!$C$5:$C$25,MATCH(Y8,'Assumptions & FX Reference'!$A$5:$A$25,0)),IF(Z8="USD",AA8*INDEX('Assumptions & FX Reference'!$B$5:$B$25,MATCH(Y8,'Assumptions & FX Reference'!$A$5:$A$25,0))/INDEX('Assumptions & FX Reference'!$C$5:$C$25,MATCH(Y8,'Assumptions & FX Reference'!$A$5:$A$25,0)),"(Currency?)"))),"(FX rate missing)"))) -> (Cost year not stated) | AC8: =IF(NOT(ISNUMBER(AA8)),"(Not stated)",IF(NOT(ISNUMBER(Y8)),"(Cost year not stated)",IFERROR(IF(Z8="USD",AA8,IF(Z8="IRR",AA8/INDEX('Assumptions & FX Reference'!$B$5:$B$25,MATCH(Y8,'Assumptions & FX Reference'!$A$5:$A$25,0)),IF(Z8="EUR",AA8*INDEX('Assumptions & FX Reference'!$C$5:$C$25,MATCH(Y8,'Assumptions & FX Reference'!$A$5:$A$25,0))/INDEX('Assumptions & FX Reference'!$B$5:$B$25,MATCH(Y8,'Assumptions & FX Reference'!$A$5:$A$25,0)),"(Currency?)"))),"(FX rate missing)"))) -> (Cost year not stated) | AD8: =IF(NOT(ISNUMBER(AA8)),"(Not stated)",IF(NOT(ISNUMBER(Y8)),"(Cost year not stated)",IFERROR(IF(Z8="IRR",AA8,IF(Z8="USD",AA8*INDEX('Assumptions & FX Reference'!$B$5:$B$25,MATCH(Y8,'Assumptions & FX Reference'!$A$5:$A$25,0)),IF(Z8="EUR",AA8*INDEX('Assumptions & FX Reference'!$C$5:$C$25,MATCH(Y8,'Assumptions & FX Reference'!$A$5:$A$25,0)),"(Currency?)"))),"(FX rate missing)"))) -> (Cost year not stated) | AE8: Purchase price (USD) – 18061405 pump CSV; project and year not stated | AF8: Not stated | AG8: =IF(AND(Z8="EUR",N(AA8)>5000000),"(Check currency – excluded)",IF(AND(ISNUMBER(AB8),ISNUMBER(AZ8),ISNUMBER(BA8)),IF(AND(BB8="Y",ISNUMBER('Assumptions & FX Reference'!$I$15)),MAX(AB8*BA8/AZ8,'Assumptions & FX Reference'!$I$13*BA8/'Assumptions & FX Reference'!$I$15),AB8*BA8/AZ8),"(PPI/FX missing)")) -> (PPI/FX missing) | AH8: =IF(AND(ISNUMBER(AG8),ISNUMBER('Assumptions & FX Reference'!$I$8),ISNUMBER('Assumptions & FX Reference'!$I$11)),AG8*'Assumptions & FX Reference'!$I$8/'Assumptions & FX Reference'!$I$11,"") | AI8: =IF(AND(ISNUMBER(AG8),ISNUMBER('Assumptions & FX Reference'!$I$8)),AG8*'Assumptions & FX Reference'!$I$8,"") | AJ8: (Not stated in source document) | AK8: Not stated | AL8: Not stated | AM8: Not stated | AN8: Not stated | AO8: Not stated | AP8: Not stated | AQ8: Not stated | AR8: Not stated | AS8: =IF(AND(Z8="EUR",N(AA8)>5000000),"Check currency (EUR>5M); ","")&IF(NOT(ISNUMBER(AA8)),"No price; ","")&IF(G8="Not stated","Material missing; ","")&IF(P8="Not stated","Seal missing; ","")&IF(K8="","Size driver missing; ","")&IF(NOT(ISNUMBER(AZ8)),"Base-year PPI missing; ","") -> Material missing; Seal missing; Base-year PPI missing; | AT8: =IFERROR(INDEX(Factors_ROT!$F$5:$F$200,MATCH("MAT|"&G8,Factors_ROT!$A$5:$A$200,0)),1) -> 1 | AU8: =IFERROR(INDEX(Factors_ROT!$F$5:$F$200,MATCH("SEAL_ARR|"&P8,Factors_ROT!$A$5:$A$200,0)),1)*IFERROR(INDEX(Factors_ROT!$F$5:$F$200,MATCH("SEAL_CAT|"&Q8,Factors_ROT!$A$5:$A$200,0)),1)*IFERROR(INDEX(Factors_ROT!$F$5:$F$200,MATCH("SEAL_PLAN|"&R8,Factors_ROT!$A$5:$A$200,0)),1) -> 1 | AV8: =IFERROR(INDEX(Factors_ROT!$F$5:$F$200,MATCH("DRV|"&S8,Factors_ROT!$A$5:$A$200,0)),1)*IFERROR(INDEX(Factors_ROT!$F$5:$F$200,MATCH("NACE|"&O8,Factors_ROT!$A$5:$A$200,0)),1) -> 1 | AW8: =IFERROR(INDEX(Factors_ROT!$F$5:$F$200,MATCH("SC_DRV|"&AL8,Factors_ROT!$A$5:$A$200,0)),1)*IFERROR(INDEX(Factors_ROT!$F$5:$F$200,MATCH("SC_BSP|"&AM8,Factors_ROT!$A$5:$A$200,0)),1)*IFERROR(INDEX(Factors_ROT!$F$5:$F$200,MATCH("SC_SEAL|"&AN8,Factors_ROT!$A$5:$A$200,0)),1)*IFERROR(INDEX(Factors_ROT!$F$5:$F$200,MATCH("SC_COMM|"&AO8,Factors_ROT!$A$5:$A$200,0)),1)*IFERROR(INDEX(Factors_ROT!$F$5:$F$200,MATCH("SC_2Y|"&AP8,Factors_ROT!$A$5:$A$200,0)),1)*IFERROR(INDEX(Factors_ROT!$F$5:$F$200,MATCH("SC_TPI|"&AQ8,Factors_ROT!$A$5:$A$200,0)),1)*IFERROR(INDEX(Factors_ROT!$F$5:$F$200,MATCH("SC_FAT|"&AR8,Factors_ROT!$A$5:$A$200,0)),1) -> 1 | AX8: =AT8*AU8*AV8*AW8 -> 1 | AY8: =IF(ISNUMBER(AB8),AB8/AX8,"") | AZ8: =IFERROR(IF(N(INDEX(Escalation_Index!$B$5:$B$25,MATCH(Y8,Escalation_Index!$A$5:$A$25,0)))>0,INDEX(Escalation_Index!$B$5:$B$25,MATCH(Y8,Escalation_Index!$A$5:$A$25,0)),""),"") | BA8: =IF(ISNUMBER('Assumptions & FX Reference'!$I$12),'Assumptions & FX Reference'!$I$12,"") -> 123.416 | BB8: =IF(AND(M8="API 610",LEFT(V8,11)="Centrifugal",OR(LEFT(G8,2)="S-",LEFT(G8,2)="D-")),"Y","N") -> N | BC8: =IF(ISNUMBER(AG8),AG8/AX8,"") | BD8: =IF(AND(ISNUMBER(BC8),ISNUMBER(K8)),IF(K8>0,BC8/K8^'Assumptions & FX Reference'!$I$16,""),"") | BE8: 18061405_Pump_only_CSV.csv – section Pumps (row 4) | BF8: Type: Centrifugal | Driver: موتور الکتریکی (E) | Power: 379 kW | Head: 329 m | گمرک و حمل: $25200 | Duplicate of the xlsx-sourced record for the same pump (see PUMPS.csv row); kept for reference, excluded from totals. | Original type text: Centrifugal | BG8: N
A9: 5 | B9: Off Spec Crude Pump | C9: (نام پروژه در فایل قید نشده است) – CSV 18061405 | D9: (Not stated in source document) | E9: ROT-CRU | F9: Not stated | G9: Not stated | I9: 311.3 | J9: 48 | K9: =IF(ISNUMBER(J9),J9,IF(AND(ISNUMBER(H9),ISNUMBER(I9)),H9*I9/(367*'Assumptions & FX Reference'!$I$17),"")) -> 48 | L9: =IF(IF(OR(M9="Not stated",M9=""),""," + "&M9)&IF(OR(N9="None",N9=""),""," + "&N9)&IF(O9="Y"," + NACE MR0175","")="","Not stated",MID(IF(OR(M9="Not stated",M9=""),""," + "&M9)&IF(OR(N9="None",N9=""),""," + "&N9)&IF(O9="Y"," + NACE MR0175",""),4,300)) -> Not stated | M9: Not stated | N9: None | O9: Not stated | P9: Not stated | Q9: Not stated | R9: Not stated | S9: Electric Motor | T9: Crude Oil | U9: 1 | V9: Centrifugal | X9: Not stated | Y9: (Not stated) | Z9: USD | AA9: 75000 | AB9: =IF(NOT(ISNUMBER(AA9)),"(Not stated)",IF(NOT(ISNUMBER(Y9)),"(Cost year not stated)",IFERROR(IF(Z9="EUR",AA9,IF(Z9="IRR",AA9/INDEX('Assumptions & FX Reference'!$C$5:$C$25,MATCH(Y9,'Assumptions & FX Reference'!$A$5:$A$25,0)),IF(Z9="USD",AA9*INDEX('Assumptions & FX Reference'!$B$5:$B$25,MATCH(Y9,'Assumptions & FX Reference'!$A$5:$A$25,0))/INDEX('Assumptions & FX Reference'!$C$5:$C$25,MATCH(Y9,'Assumptions & FX Reference'!$A$5:$A$25,0)),"(Currency?)"))),"(FX rate missing)"))) -> (Cost year not stated) | AC9: =IF(NOT(ISNUMBER(AA9)),"(Not stated)",IF(NOT(ISNUMBER(Y9)),"(Cost year not stated)",IFERROR(IF(Z9="USD",AA9,IF(Z9="IRR",AA9/INDEX('Assumptions & FX Reference'!$B$5:$B$25,MATCH(Y9,'Assumptions & FX Reference'!$A$5:$A$25,0)),IF(Z9="EUR",AA9*INDEX('Assumptions & FX Reference'!$C$5:$C$25,MATCH(Y9,'Assumptions & FX Reference'!$A$5:$A$25,0))/INDEX('Assumptions & FX Reference'!$B$5:$B$25,MATCH(Y9,'Assumptions & FX Reference'!$A$5:$A$25,0)),"(Currency?)"))),"(FX rate missing)"))) -> (Cost year not stated) | AD9: =IF(NOT(ISNUMBER(AA9)),"(Not stated)",IF(NOT(ISNUMBER(Y9)),"(Cost year not stated)",IFERROR(IF(Z9="IRR",AA9,IF(Z9="USD",AA9*INDEX('Assumptions & FX Reference'!$B$5:$B$25,MATCH(Y9,'Assumptions & FX Reference'!$A$5:$A$25,0)),IF(Z9="EUR",AA9*INDEX('Assumptions & FX Reference'!$C$5:$C$25,MATCH(Y9,'Assumptions & FX Reference'!$A$5:$A$25,0)),"(Currency?)"))),"(FX rate missing)"))) -> (Cost year not stated) | AE9: Purchase price (USD) – 18061405 pump CSV; project and year not stated | AF9: Not stated | AG9: =IF(AND(Z9="EUR",N(AA9)>5000000),"(Check currency – excluded)",IF(AND(ISNUMBER(AB9),ISNUMBER(AZ9),ISNUMBER(BA9)),IF(AND(BB9="Y",ISNUMBER('Assumptions & FX Reference'!$I$15)),MAX(AB9*BA9/AZ9,'Assumptions & FX Reference'!$I$13*BA9/'Assumptions & FX Reference'!$I$15),AB9*BA9/AZ9),"(PPI/FX missing)")) -> (PPI/FX missing) | AH9: =IF(AND(ISNUMBER(AG9),ISNUMBER('Assumptions & FX Reference'!$I$8),ISNUMBER('Assumptions & FX Reference'!$I$11)),AG9*'Assumptions & FX Reference'!$I$8/'Assumptions & FX Reference'!$I$11,"") | AI9: =IF(AND(ISNUMBER(AG9),ISNUMBER('Assumptions & FX Reference'!$I$8)),AG9*'Assumptions & FX Reference'!$I$8,"") | AJ9: (Not stated in source document) | AK9: Not stated | AL9: Not stated | AM9: Not stated | AN9: Not stated | AO9: Not stated | AP9: Not stated | AQ9: Not stated | AR9: Not stated | AS9: =IF(AND(Z9="EUR",N(AA9)>5000000),"Check currency (EUR>5M); ","")&IF(NOT(ISNUMBER(AA9)),"No price; ","")&IF(G9="Not stated","Material missing; ","")&IF(P9="Not stated","Seal missing; ","")&IF(K9="","Size driver missing; ","")&IF(NOT(ISNUMBER(AZ9)),"Base-year PPI missing; ","") -> Material missing; Seal missing; Base-year PPI missing; | AT9: =IFERROR(INDEX(Factors_ROT!$F$5:$F$200,MATCH("MAT|"&G9,Factors_ROT!$A$5:$A$200,0)),1) -> 1 | AU9: =IFERROR(INDEX(Factors_ROT!$F$5:$F$200,MATCH("SEAL_ARR|"&P9,Factors_ROT!$A$5:$A$200,0)),1)*IFERROR(INDEX(Factors_ROT!$F$5:$F$200,MATCH("SEAL_CAT|"&Q9,Factors_ROT!$A$5:$A$200,0)),1)*IFERROR(INDEX(Factors_ROT!$F$5:$F$200,MATCH("SEAL_PLAN|"&R9,Factors_ROT!$A$5:$A$200,0)),1) -> 1 | AV9: =IFERROR(INDEX(Factors_ROT!$F$5:$F$200,MATCH("DRV|"&S9,Factors_ROT!$A$5:$A$200,0)),1)*IFERROR(INDEX(Factors_ROT!$F$5:$F$200,MATCH("NACE|"&O9,Factors_ROT!$A$5:$A$200,0)),1) -> 1 | AW9: =IFERROR(INDEX(Factors_ROT!$F$5:$F$200,MATCH("SC_DRV|"&AL9,Factors_ROT!$A$5:$A$200,0)),1)*IFERROR(INDEX(Factors_ROT!$F$5:$F$200,MATCH("SC_BSP|"&AM9,Factors_ROT!$A$5:$A$200,0)),1)*IFERROR(INDEX(Factors_ROT!$F$5:$F$200,MATCH("SC_SEAL|"&AN9,Factors_ROT!$A$5:$A$200,0)),1)*IFERROR(INDEX(Factors_ROT!$F$5:$F$200,MATCH("SC_COMM|"&AO9,Factors_ROT!$A$5:$A$200,0)),1)*IFERROR(INDEX(Factors_ROT!$F$5:$F$200,MATCH("SC_2Y|"&AP9,Factors_ROT!$A$5:$A$200,0)),1)*IFERROR(INDEX(Factors_ROT!$F$5:$F$200,MATCH("SC_TPI|"&AQ9,Factors_ROT!$A$5:$A$200,0)),1)*IFERROR(INDEX(Factors_ROT!$F$5:$F$200,MATCH("SC_FAT|"&AR9,Factors_ROT!$A$5:$A$200,0)),1) -> 1 | AX9: =AT9*AU9*AV9*AW9 -> 1 | AY9: =IF(ISNUMBER(AB9),AB9/AX9,"") | AZ9: =IFERROR(IF(N(INDEX(Escalation_Index!$B$5:$B$25,MATCH(Y9,Escalation_Index!$A$5:$A$25,0)))>0,INDEX(Escalation_Index!$B$5:$B$25,MATCH(Y9,Escalation_Index!$A$5:$A$25,0)),""),"") | BA9: =IF(ISNUMBER('Assumptions & FX Reference'!$I$12),'Assumptions & FX Reference'!$I$12,"") -> 123.416 | BB9: =IF(AND(M9="API 610",LEFT(V9,11)="Centrifugal",OR(LEFT(G9,2)="S-",LEFT(G9,2)="D-")),"Y","N") -> N | BC9: =IF(ISNUMBER(AG9),AG9/AX9,"") | BD9: =IF(AND(ISNUMBER(BC9),ISNUMBER(K9)),IF(K9>0,BC9/K9^'Assumptions & FX Reference'!$I$16,""),"") | BE9: 18061405_Pump_only_CSV.csv – section Pumps (row 5) | BF9: Type: Centrifugal | Driver: موتور الکتریکی (E) | Power: 48 kW | Head: 311.3 m | گمرک و حمل: $4500 | Duplicate of the xlsx-sourced record for the same pump (see PUMPS.csv row); kept for reference, excluded from totals. | Original type text: Centrifugal | BG9: N
A10: 6 | B10: Second Stage Desalter Water Criculated Pump | C10: (نام پروژه در فایل قید نشده است) – CSV 18061405 | D10: (Not stated in source document) | E10: ROT-WAT | F10: Not stated | G10: Not stated | I10: 32 | J10: 2.2 | K10: =IF(ISNUMBER(J10),J10,IF(AND(ISNUMBER(H10),ISNUMBER(I10)),H10*I10/(367*'Assumptions & FX Reference'!$I$17),"")) -> 2.2 | L10: =IF(IF(OR(M10="Not stated",M10=""),""," + "&M10)&IF(OR(N10="None",N10=""),""," + "&N10)&IF(O10="Y"," + NACE MR0175","")="","Not stated",MID(IF(OR(M10="Not stated",M10=""),""," + "&M10)&IF(OR(N10="None",N10=""),""," + "&N10)&IF(O10="Y"," + NACE MR0175",""),4,300)) -> Not stated | M10: Not stated | N10: None | O10: Not stated | P10: Not stated | Q10: Not stated | R10: Not stated | S10: Electric Motor | T10: Process / Dilution Water | U10: 1 | V10: Centrifugal | X10: Not stated | Y10: (Not stated) | Z10: USD | AA10: 60000 | AB10: =IF(NOT(ISNUMBER(AA10)),"(Not stated)",IF(NOT(ISNUMBER(Y10)),"(Cost year not stated)",IFERROR(IF(Z10="EUR",AA10,IF(Z10="IRR",AA10/INDEX('Assumptions & FX Reference'!$C$5:$C$25,MATCH(Y10,'Assumptions & FX Reference'!$A$5:$A$25,0)),IF(Z10="USD",AA10*INDEX('Assumptions & FX Reference'!$B$5:$B$25,MATCH(Y10,'Assumptions & FX Reference'!$A$5:$A$25,0))/INDEX('Assumptions & FX Reference'!$C$5:$C$25,MATCH(Y10,'Assumptions & FX Reference'!$A$5:$A$25,0)),"(Currency?)"))),"(FX rate missing)"))) -> (Cost year not stated) | AC10: =IF(NOT(ISNUMBER(AA10)),"(Not stated)",IF(NOT(ISNUMBER(Y10)),"(Cost year not stated)",IFERROR(IF(Z10="USD",AA10,IF(Z10="IRR",AA10/INDEX('Assumptions & FX Reference'!$B$5:$B$25,MATCH(Y10,'Assumptions & FX Reference'!$A$5:$A$25,0)),IF(Z10="EUR",AA10*INDEX('Assumptions & FX Reference'!$C$5:$C$25,MATCH(Y10,'Assumptions & FX Reference'!$A$5:$A$25,0))/INDEX('Assumptions & FX Reference'!$B$5:$B$25,MATCH(Y10,'Assumptions & FX Reference'!$A$5:$A$25,0)),"(Currency?)"))),"(FX rate missing)"))) -> (Cost year not stated) | AD10: =IF(NOT(ISNUMBER(AA10)),"(Not stated)",IF(NOT(ISNUMBER(Y10)),"(Cost year not stated)",IFERROR(IF(Z10="IRR",AA10,IF(Z10="USD",AA10*INDEX('Assumptions & FX Reference'!$B$5:$B$25,MATCH(Y10,'Assumptions & FX Reference'!$A$5:$A$25,0)),IF(Z10="EUR",AA10*INDEX('Assumptions & FX Reference'!$C$5:$C$25,MATCH(Y10,'Assumptions & FX Reference'!$A$5:$A$25,0)),"(Currency?)"))),"(FX rate missing)"))) -> (Cost year not stated) | AE10: Purchase price (USD) – 18061405 pump CSV; project and year not stated | AF10: Not stated | AG10: =IF(AND(Z10="EUR",N(AA10)>5000000),"(Check currency – excluded)",IF(AND(ISNUMBER(AB10),ISNUMBER(AZ10),ISNUMBER(BA10)),IF(AND(BB10="Y",ISNUMBER('Assumptions & FX Reference'!$I$15)),MAX(AB10*BA10/AZ10,'Assumptions & FX Reference'!$I$13*BA10/'Assumptions & FX Reference'!$I$15),AB10*BA10/AZ10),"(PPI/FX missing)")) -> (PPI/FX missing) | AH10: =IF(AND(ISNUMBER(AG10),ISNUMBER('Assumptions & FX Reference'!$I$8),ISNUMBER('Assumptions & FX Reference'!$I$11)),AG10*'Assumptions & FX Reference'!$I$8/'Assumptions & FX Reference'!$I$11,"") | AI10: =IF(AND(ISNUMBER(AG10),ISNUMBER('Assumptions & FX Reference'!$I$8)),AG10*'Assumptions & FX Reference'!$I$8,"") | AJ10: (Not stated in source document) | AK10: Not stated | AL10: Not stated | AM10: Not stated | AN10: Not stated | AO10: Not stated | AP10: Not stated | AQ10: Not stated | AR10: Not stated | AS10: =IF(AND(Z10="EUR",N(AA10)>5000000),"Check currency (EUR>5M); ","")&IF(NOT(ISNUMBER(AA10)),"No price; ","")&IF(G10="Not stated","Material missing; ","")&IF(P10="Not stated","Seal missing; ","")&IF(K10="","Size driver missing; ","")&IF(NOT(ISNUMBER(AZ10)),"Base-year PPI missing; ","") -> Material missing; Seal missing; Base-year PPI missing; | AT10: =IFERROR(INDEX(Factors_ROT!$F$5:$F$200,MATCH("MAT|"&G10,Factors_ROT!$A$5:$A$200,0)),1) -> 1 | AU10: =IFERROR(INDEX(Factors_ROT!$F$5:$F$200,MATCH("SEAL_ARR|"&P10,Factors_ROT!$A$5:$A$200,0)),1)*IFERROR(INDEX(Factors_ROT!$F$5:$F$200,MATCH("SEAL_CAT|"&Q10,Factors_ROT!$A$5:$A$200,0)),1)*IFERROR(INDEX(Factors_ROT!$F$5:$F$200,MATCH("SEAL_PLAN|"&R10,Factors_ROT!$A$5:$A$200,0)),1) -> 1 | AV10: =IFERROR(INDEX(Factors_ROT!$F$5:$F$200,MATCH("DRV|"&S10,Factors_ROT!$A$5:$A$200,0)),1)*IFERROR(INDEX(Factors_ROT!$F$5:$F$200,MATCH("NACE|"&O10,Factors_ROT!$A$5:$A$200,0)),1) -> 1 | AW10: =IFERROR(INDEX(Factors_ROT!$F$5:$F$200,MATCH("SC_DRV|"&AL10,Factors_ROT!$A$5:$A$200,0)),1)*IFERROR(INDEX(Factors_ROT!$F$5:$F$200,MATCH("SC_BSP|"&AM10,Factors_ROT!$A$5:$A$200,0)),1)*IFERROR(INDEX(Factors_ROT!$F$5:$F$200,MATCH("SC_SEAL|"&AN10,Factors_ROT!$A$5:$A$200,0)),1)*IFERROR(INDEX(Factors_ROT!$F$5:$F$200,MATCH("SC_COMM|"&AO10,Factors_ROT!$A$5:$A$200,0)),1)*IFERROR(INDEX(Factors_ROT!$F$5:$F$200,MATCH("SC_2Y|"&AP10,Factors_ROT!$A$5:$A$200,0)),1)*IFERROR(INDEX(Factors_ROT!$F$5:$F$200,MATCH("SC_TPI|"&AQ10,Factors_ROT!$A$5:$A$200,0)),1)*IFERROR(INDEX(Factors_ROT!$F$5:$F$200,MATCH("SC_FAT|"&AR10,Factors_ROT!$A$5:$A$200,0)),1) -> 1 | AX10: =AT10*AU10*AV10*AW10 -> 1 | AY10: =IF(ISNUMBER(AB10),AB10/AX10,"") | AZ10: =IFERROR(IF(N(INDEX(Escalation_Index!$B$5:$B$25,MATCH(Y10,Escalation_Index!$A$5:$A$25,0)))>0,INDEX(Escalation_Index!$B$5:$B$25,MATCH(Y10,Escalation_Index!$A$5:$A$25,0)),""),"") | BA10: =IF(ISNUMBER('Assumptions & FX Reference'!$I$12),'Assumptions & FX Reference'!$I$12,"") -> 123.416 | BB10: =IF(AND(M10="API 610",LEFT(V10,11)="Centrifugal",OR(LEFT(G10,2)="S-",LEFT(G10,2)="D-")),"Y","N") -> N | BC10: =IF(ISNUMBER(AG10),AG10/AX10,"") | BD10: =IF(AND(ISNUMBER(BC10),ISNUMBER(K10)),IF(K10>0,BC10/K10^'Assumptions & FX Reference'!$I$16,""),"") | BE10: 18061405_Pump_only_CSV.csv – section Pumps (row 6) | BF10: Type: Centrifugal | Driver: موتور الکتریکی (E) | Power: 2.2 kW | Head: 32 m | گمرک و حمل: $3600 | Duplicate of the xlsx-sourced record for the same pump (see PUMPS.csv row); kept for reference, excluded from totals. | Original type text: Centrifugal | BG10: N
A11: 7 | B11: Degassing Water Pump | C11: (نام پروژه در فایل قید نشده است) – CSV 18061405 | D11: (Not stated in source document) | E11: ROT-WAT | F11: Not stated | G11: Not stated | I11: 36.2 | J11: 13.1 | K11: =IF(ISNUMBER(J11),J11,IF(AND(ISNUMBER(H11),ISNUMBER(I11)),H11*I11/(367*'Assumptions & FX Reference'!$I$17),"")) -> 13.1 | L11: =IF(IF(OR(M11="Not stated",M11=""),""," + "&M11)&IF(OR(N11="None",N11=""),""," + "&N11)&IF(O11="Y"," + NACE MR0175","")="","Not stated",MID(IF(OR(M11="Not stated",M11=""),""," + "&M11)&IF(OR(N11="None",N11=""),""," + "&N11)&IF(O11="Y"," + NACE MR0175",""),4,300)) -> Not stated | M11: Not stated | N11: None | O11: Not stated | P11: Not stated | Q11: Not stated | R11: Not stated | S11: Electric Motor | T11: Process / Dilution Water | U11: 1 | V11: Centrifugal | X11: Not stated | Y11: (Not stated) | Z11: USD | AA11: 60000 | AB11: =IF(NOT(ISNUMBER(AA11)),"(Not stated)",IF(NOT(ISNUMBER(Y11)),"(Cost year not stated)",IFERROR(IF(Z11="EUR",AA11,IF(Z11="IRR",AA11/INDEX('Assumptions & FX Reference'!$C$5:$C$25,MATCH(Y11,'Assumptions & FX Reference'!$A$5:$A$25,0)),IF(Z11="USD",AA11*INDEX('Assumptions & FX Reference'!$B$5:$B$25,MATCH(Y11,'Assumptions & FX Reference'!$A$5:$A$25,0))/INDEX('Assumptions & FX Reference'!$C$5:$C$25,MATCH(Y11,'Assumptions & FX Reference'!$A$5:$A$25,0)),"(Currency?)"))),"(FX rate missing)"))) -> (Cost year not stated) | AC11: =IF(NOT(ISNUMBER(AA11)),"(Not stated)",IF(NOT(ISNUMBER(Y11)),"(Cost year not stated)",IFERROR(IF(Z11="USD",AA11,IF(Z11="IRR",AA11/INDEX('Assumptions & FX Reference'!$B$5:$B$25,MATCH(Y11,'Assumptions & FX Reference'!$A$5:$A$25,0)),IF(Z11="EUR",AA11*INDEX('Assumptions & FX Reference'!$C$5:$C$25,MATCH(Y11,'Assumptions & FX Reference'!$A$5:$A$25,0))/INDEX('Assumptions & FX Reference'!$B$5:$B$25,MATCH(Y11,'Assumptions & FX Reference'!$A$5:$A$25,0)),"(Currency?)"))),"(FX rate missing)"))) -> (Cost year not stated) | AD11: =IF(NOT(ISNUMBER(AA11)),"(Not stated)",IF(NOT(ISNUMBER(Y11)),"(Cost year not stated)",IFERROR(IF(Z11="IRR",AA11,IF(Z11="USD",AA11*INDEX('Assumptions & FX Reference'!$B$5:$B$25,MATCH(Y11,'Assumptions & FX Reference'!$A$5:$A$25,0)),IF(Z11="EUR",AA11*INDEX('Assumptions & FX Reference'!$C$5:$C$25,MATCH(Y11,'Assumptions & FX Reference'!$A$5:$A$25,0)),"(Currency?)"))),"(FX rate missing)"))) -> (Cost year not stated) | AE11: Purchase price (USD) – 18061405 pump CSV; project and year not stated | AF11: Not stated | AG11: =IF(AND(Z11="EUR",N(AA11)>5000000),"(Check currency – excluded)",IF(AND(ISNUMBER(AB11),ISNUMBER(AZ11),ISNUMBER(BA11)),IF(AND(BB11="Y",ISNUMBER('Assumptions & FX Reference'!$I$15)),MAX(AB11*BA11/AZ11,'Assumptions & FX Reference'!$I$13*BA11/'Assumptions & FX Reference'!$I$15),AB11*BA11/AZ11),"(PPI/FX missing)")) -> (PPI/FX missing) | AH11: =IF(AND(ISNUMBER(AG11),ISNUMBER('Assumptions & FX Reference'!$I$8),ISNUMBER('Assumptions & FX Reference'!$I$11)),AG11*'Assumptions & FX Reference'!$I$8/'Assumptions & FX Reference'!$I$11,"") | AI11: =IF(AND(ISNUMBER(AG11),ISNUMBER('Assumptions & FX Reference'!$I$8)),AG11*'Assumptions & FX Reference'!$I$8,"") | AJ11: (Not stated in source document) | AK11: Not stated | AL11: Not stated | AM11: Not stated | AN11: Not stated | AO11: Not stated | AP11: Not stated | AQ11: Not stated | AR11: Not stated | AS11: =IF(AND(Z11="EUR",N(AA11)>5000000),"Check currency (EUR>5M); ","")&IF(NOT(ISNUMBER(AA11)),"No price; ","")&IF(G11="Not stated","Material missing; ","")&IF(P11="Not stated","Seal missing; ","")&IF(K11="","Size driver missing; ","")&IF(NOT(ISNUMBER(AZ11)),"Base-year PPI missing; ","") -> Material missing; Seal missing; Base-year PPI missing; | AT11: =IFERROR(INDEX(Factors_ROT!$F$5:$F$200,MATCH("MAT|"&G11,Factors_ROT!$A$5:$A$200,0)),1) -> 1 | AU11: =IFERROR(INDEX(Factors_ROT!$F$5:$F$200,MATCH("SEAL_ARR|"&P11,Factors_ROT!$A$5:$A$200,0)),1)*IFERROR(INDEX(Factors_ROT!$F$5:$F$200,MATCH("SEAL_CAT|"&Q11,Factors_ROT!$A$5:$A$200,0)),1)*IFERROR(INDEX(Factors_ROT!$F$5:$F$200,MATCH("SEAL_PLAN|"&R11,Factors_ROT!$A$5:$A$200,0)),1) -> 1 | AV11: =IFERROR(INDEX(Factors_ROT!$F$5:$F$200,MATCH("DRV|"&S11,Factors_ROT!$A$5:$A$200,0)),1)*IFERROR(INDEX(Factors_ROT!$F$5:$F$200,MATCH("NACE|"&O11,Factors_ROT!$A$5:$A$200,0)),1) -> 1 | AW11: =IFERROR(INDEX(Factors_ROT!$F$5:$F$200,MATCH("SC_DRV|"&AL11,Factors_ROT!$A$5:$A$200,0)),1)*IFERROR(INDEX(Factors_ROT!$F$5:$F$200,MATCH("SC_BSP|"&AM11,Factors_ROT!$A$5:$A$200,0)),1)*IFERROR(INDEX(Factors_ROT!$F$5:$F$200,MATCH("SC_SEAL|"&AN11,Factors_ROT!$A$5:$A$200,0)),1)*IFERROR(INDEX(Factors_ROT!$F$5:$F$200,MATCH("SC_COMM|"&AO11,Factors_ROT!$A$5:$A$200,0)),1)*IFERROR(INDEX(Factors_ROT!$F$5:$F$200,MATCH("SC_2Y|"&AP11,Factors_ROT!$A$5:$A$200,0)),1)*IFERROR(INDEX(Factors_ROT!$F$5:$F$200,MATCH("SC_TPI|"&AQ11,Factors_ROT!$A$5:$A$200,0)),1)*IFERROR(INDEX(Factors_ROT!$F$5:$F$200,MATCH("SC_FAT|"&AR11,Factors_ROT!$A$5:$A$200,0)),1) -> 1 | AX11: =AT11*AU11*AV11*AW11 -> 1 | AY11: =IF(ISNUMBER(AB11),AB11/AX11,"") | AZ11: =IFERROR(IF(N(INDEX(Escalation_Index!$B$5:$B$25,MATCH(Y11,Escalation_Index!$A$5:$A$25,0)))>0,INDEX(Escalation_Index!$B$5:$B$25,MATCH(Y11,Escalation_Index!$A$5:$A$25,0)),""),"") | BA11: =IF(ISNUMBER('Assumptions & FX Reference'!$I$12),'Assumptions & FX Reference'!$I$12,"") -> 123.416 | BB11: =IF(AND(M11="API 610",LEFT(V11,11)="Centrifugal",OR(LEFT(G11,2)="S-",LEFT(G11,2)="D-")),"Y","N") -> N | BC11: =IF(ISNUMBER(AG11),AG11/AX11,"") | BD11: =IF(AND(ISNUMBER(BC11),ISNUMBER(K11)),IF(K11>0,BC11/K11^'Assumptions & FX Reference'!$I$16,""),"") | BE11: 18061405_Pump_only_CSV.csv – section Pumps (row 7) | BF11: Type: Centrifugal | Driver: موتور الکتریکی (E) | Power: 13.1 kW | Head: 36.2 m | گمرک و حمل: $3600 | Duplicate of the xlsx-sourced record for the same pump (see PUMPS.csv row); kept for reference, excluded from totals. | Original type text: Centrifugal | BG11: N
A12: 8 | B12: Disposal Water Pump | C12: (نام پروژه در فایل قید نشده است) – CSV 18061405 | D12: (Not stated in source document) | E12: ROT-INJ | F12: Not stated | G12: Not stated | I12: 1383 | J12: 423 | K12: =IF(ISNUMBER(J12),J12,IF(AND(ISNUMBER(H12),ISNUMBER(I12)),H12*I12/(367*'Assumptions & FX Reference'!$I$17),"")) -> 423 | L12: =IF(IF(OR(M12="Not stated",M12=""),""," + "&M12)&IF(OR(N12="None",N12=""),""," + "&N12)&IF(O12="Y"," + NACE MR0175","")="","Not stated",MID(IF(OR(M12="Not stated",M12=""),""," + "&M12)&IF(OR(N12="None",N12=""),""," + "&N12)&IF(O12="Y"," + NACE MR0175",""),4,300)) -> Not stated | M12: Not stated | N12: None | O12: Not stated | P12: Not stated | Q12: Not stated | R12: Not stated | S12: Electric Motor | T12: Produced / Disposal Water | U12: 1 | V12: Centrifugal | X12: Not stated | Y12: (Not stated) | Z12: USD | AA12: 410000 | AB12: =IF(NOT(ISNUMBER(AA12)),"(Not stated)",IF(NOT(ISNUMBER(Y12)),"(Cost year not stated)",IFERROR(IF(Z12="EUR",AA12,IF(Z12="IRR",AA12/INDEX('Assumptions & FX Reference'!$C$5:$C$25,MATCH(Y12,'Assumptions & FX Reference'!$A$5:$A$25,0)),IF(Z12="USD",AA12*INDEX('Assumptions & FX Reference'!$B$5:$B$25,MATCH(Y12,'Assumptions & FX Reference'!$A$5:$A$25,0))/INDEX('Assumptions & FX Reference'!$C$5:$C$25,MATCH(Y12,'Assumptions & FX Reference'!$A$5:$A$25,0)),"(Currency?)"))),"(FX rate missing)"))) -> (Cost year not stated) | AC12: =IF(NOT(ISNUMBER(AA12)),"(Not stated)",IF(NOT(ISNUMBER(Y12)),"(Cost year not stated)",IFERROR(IF(Z12="USD",AA12,IF(Z12="IRR",AA12/INDEX('Assumptions & FX Reference'!$B$5:$B$25,MATCH(Y12,'Assumptions & FX Reference'!$A$5:$A$25,0)),IF(Z12="EUR",AA12*INDEX('Assumptions & FX Reference'!$C$5:$C$25,MATCH(Y12,'Assumptions & FX Reference'!$A$5:$A$25,0))/INDEX('Assumptions & FX Reference'!$B$5:$B$25,MATCH(Y12,'Assumptions & FX Reference'!$A$5:$A$25,0)),"(Currency?)"))),"(FX rate missing)"))) -> (Cost year not stated) | AD12: =IF(NOT(ISNUMBER(AA12)),"(Not stated)",IF(NOT(ISNUMBER(Y12)),"(Cost year not stated)",IFERROR(IF(Z12="IRR",AA12,IF(Z12="USD",AA12*INDEX('Assumptions & FX Reference'!$B$5:$B$25,MATCH(Y12,'Assumptions & FX Reference'!$A$5:$A$25,0)),IF(Z12="EUR",AA12*INDEX('Assumptions & FX Reference'!$C$5:$C$25,MATCH(Y12,'Assumptions & FX Reference'!$A$5:$A$25,0)),"(Currency?)"))),"(FX rate missing)"))) -> (Cost year not stated) | AE12: Purchase price (USD) – 18061405 pump CSV; project and year not stated | AF12: Not stated | AG12: =IF(AND(Z12="EUR",N(AA12)>5000000),"(Check currency – excluded)",IF(AND(ISNUMBER(AB12),ISNUMBER(AZ12),ISNUMBER(BA12)),IF(AND(BB12="Y",ISNUMBER('Assumptions & FX Reference'!$I$15)),MAX(AB12*BA12/AZ12,'Assumptions & FX Reference'!$I$13*BA12/'Assumptions & FX Reference'!$I$15),AB12*BA12/AZ12),"(PPI/FX missing)")) -> (PPI/FX missing) | AH12: =IF(AND(ISNUMBER(AG12),ISNUMBER('Assumptions & FX Reference'!$I$8),ISNUMBER('Assumptions & FX Reference'!$I$11)),AG12*'Assumptions & FX Reference'!$I$8/'Assumptions & FX Reference'!$I$11,"") | AI12: =IF(AND(ISNUMBER(AG12),ISNUMBER('Assumptions & FX Reference'!$I$8)),AG12*'Assumptions & FX Reference'!$I$8,"") | AJ12: (Not stated in source document) | AK12: Not stated | AL12: Not stated | AM12: Not stated | AN12: Not stated | AO12: Not stated | AP12: Not stated | AQ12: Not stated | AR12: Not stated | AS12: =IF(AND(Z12="EUR",N(AA12)>5000000),"Check currency (EUR>5M); ","")&IF(NOT(ISNUMBER(AA12)),"No price; ","")&IF(G12="Not stated","Material missing; ","")&IF(P12="Not stated","Seal missing; ","")&IF(K12="","Size driver missing; ","")&IF(NOT(ISNUMBER(AZ12)),"Base-year PPI missing; ","") -> Material missing; Seal missing; Base-year PPI missing; | AT12: =IFERROR(INDEX(Factors_ROT!$F$5:$F$200,MATCH("MAT|"&G12,Factors_ROT!$A$5:$A$200,0)),1) -> 1 | AU12: =IFERROR(INDEX(Factors_ROT!$F$5:$F$200,MATCH("SEAL_ARR|"&P12,Factors_ROT!$A$5:$A$200,0)),1)*IFERROR(INDEX(Factors_ROT!$F$5:$F$200,MATCH("SEAL_CAT|"&Q12,Factors_ROT!$A$5:$A$200,0)),1)*IFERROR(INDEX(Factors_ROT!$F$5:$F$200,MATCH("SEAL_PLAN|"&R12,Factors_ROT!$A$5:$A$200,0)),1) -> 1 | AV12: =IFERROR(INDEX(Factors_ROT!$F$5:$F$200,MATCH("DRV|"&S12,Factors_ROT!$A$5:$A$200,0)),1)*IFERROR(INDEX(Factors_ROT!$F$5:$F$200,MATCH("NACE|"&O12,Factors_ROT!$A$5:$A$200,0)),1) -> 1 | AW12: =IFERROR(INDEX(Factors_ROT!$F$5:$F$200,MATCH("SC_DRV|"&AL12,Factors_ROT!$A$5:$A$200,0)),1)*IFERROR(INDEX(Factors_ROT!$F$5:$F$200,MATCH("SC_BSP|"&AM12,Factors_ROT!$A$5:$A$200,0)),1)*IFERROR(INDEX(Factors_ROT!$F$5:$F$200,MATCH("SC_SEAL|"&AN12,Factors_ROT!$A$5:$A$200,0)),1)*IFERROR(INDEX(Factors_ROT!$F$5:$F$200,MATCH("SC_COMM|"&AO12,Factors_ROT!$A$5:$A$200,0)),1)*IFERROR(INDEX(Factors_ROT!$F$5:$F$200,MATCH("SC_2Y|"&AP12,Factors_ROT!$A$5:$A$200,0)),1)*IFERROR(INDEX(Factors_ROT!$F$5:$F$200,MATCH("SC_TPI|"&AQ12,Factors_ROT!$A$5:$A$200,0)),1)*IFERROR(INDEX(Factors_ROT!$F$5:$F$200,MATCH("SC_FAT|"&AR12,Factors_ROT!$A$5:$A$200,0)),1) -> 1 | AX12: =AT12*AU12*AV12*AW12 -> 1 | AY12: =IF(ISNUMBER(AB12),AB12/AX12,"") | AZ12: =IFERROR(IF(N(INDEX(Escalation_Index!$B$5:$B$25,MATCH(Y12,Escalation_Index!$A$5:$A$25,0)))>0,INDEX(Escalation_Index!$B$5:$B$25,MATCH(Y12,Escalation_Index!$A$5:$A$25,0)),""),"") | BA12: =IF(ISNUMBER('Assumptions & FX Reference'!$I$12),'Assumptions & FX Reference'!$I$12,"") -> 123.416 | BB12: =IF(AND(M12="API 610",LEFT(V12,11)="Centrifugal",OR(LEFT(G12,2)="S-",LEFT(G12,2)="D-")),"Y","N") -> N | BC12: =IF(ISNUMBER(AG12),AG12/AX12,"") | BD12: =IF(AND(ISNUMBER(BC12),ISNUMBER(K12)),IF(K12>0,BC12/K12^'Assumptions & FX Reference'!$I$16,""),"") | BE12: 18061405_Pump_only_CSV.csv – section Pumps (row 8) | BF12: Type: Centrifugal | Driver: موتور الکتریکی (E) | Power: 423 kW | Head: 1383 m | گمرک و حمل: $24600 | Duplicate of the xlsx-sourced record for the same pump (see PUMPS.csv row); kept for reference, excluded from totals. | Original type text: Centrifugal | BG12: N
