Workbook
Name aa: [1]Doc.List!$C$11:$AX$1835
Name Ahvaz_Transport: 1000000
Name Ali: [2]Cover!$E$67:$G$616
Name asdsf: IF(c.cefty.1392!ulkuykuk*c.cefty.1392!jljuul*c.cefty.1392!liuluill*c.cefty.1392!ukuyluyl>0,1,0)
Name asdsf: IF('EPC 1402 (2)'!ulkuykuk*'EPC 1402 (2)'!jljuul*'EPC 1402 (2)'!liuluill*'EPC 1402 (2)'!ukuyluyl>0,1,0)
Name asdsf: IF(Extra.1405!ulkuykuk*Extra.1405!jljuul*Extra.1405!liuluill*Extra.1405!ukuyluyl>0,1,0)
Name asdsf: IF('FR1405'!ulkuykuk*'FR1405'!jljuul*'FR1405'!liuluill*'FR1405'!ukuyluyl>0,1,0)
Name asdsf: IF(Inflation!ulkuykuk*Inflation!jljuul*Inflation!liuluill*Inflation!ukuyluyl>0,1,0)
Name asdsf: IF(p.lab.1392!ulkuykuk*p.lab.1392!jljuul*p.lab.1392!liuluill*p.lab.1392!ukuyluyl>0,1,0)
Name asdsf: IF('Summary_M3 1405'!ulkuykuk*'Summary_M3 1405'!jljuul*'Summary_M3 1405'!liuluill*'Summary_M3 1405'!ukuyluyl>0,1,0)
Name asdsf: IF([0]!ulkuykuk*[0]!jljuul*[0]!liuluill*[0]!ukuyluyl>0,1,0)
Name c_az: '[3]200'!#REF!
Name c_az: '[3]200'!#REF!
Name c_az: '[3]200'!#REF!
Name c_az: '[3]200'!#REF!
Name c_az: '[3]200'!#REF!
Name c_az: '[3]200'!#REF!
Name c_az: '[3]200'!#REF!
Name c_az: '[3]200'!#REF!
Name c_az1: '[3]200'!#REF!
Name c_az1: '[3]200'!#REF!
Name c_az1: '[3]200'!#REF!
Name c_az1: '[3]200'!#REF!
Name c_az1: '[3]200'!#REF!
Name c_az1: '[3]200'!#REF!
Name c_az1: '[3]200'!#REF!
Name c_az1: '[3]200'!#REF!
Name Categories: #REF!
Name Categories: #REF!
Name Categories: #REF!
Name Categories: #REF!
Name Categories: #REF!
Name Categories: #REF!
Name Categories: #REF!
Name Categories: #REF!
Name Catering_Ahvaz: 4500000
Name Catering_Gachsaran: 5500000
Name Chapters: #REF!
Name Chapters: #REF!
Name Chapters: #REF!
Name Chapters: #REF!
Name Chapters: #REF!
Name Chapters: #REF!
Name Chapters: #REF!
Name Chapters: #REF!
Name chart: '[4]PLAN QTY'!$AI$25
Name CoefDetails: #REF!
Name CoefDetails: #REF!
Name CoefDetails: #REF!
Name CoefDetails: #REF!
Name CoefDetails: #REF!
Name CoefDetails: #REF!
Name CoefDetails: #REF!
Name CoefDetails: #REF!
Name Coefs: #REF!
Name Coefs: #REF!
Name Coefs: #REF!
Name Coefs: #REF!
Name Coefs: #REF!
Name Coefs: #REF!

Sheet EPC 1402 (2)
B2: خلاصه مالی کل پروژه 1402
B4: رديف | C4: بخش | D4: گچساران 3 | E4: بی بی حکیمه 1 | F4: درصد گچساران 4 | G4: درصد مارون 3
B5: 1 | C5: مجموع بخش E | D5: 0.028 | E5: 0.022 | F5: 0.02 | G5: 0.018
B6: 2 | C6: مجموع بخش P | D6: 0.646 | E6: 0.634 | F6: 0.69 | G6: 0.618
B7: 3 | C7: مجموع بخش C | D7: 0.316 | E7: 0.334 | F7: 0.28 | G7: 0.354
B8: 4 | C8: فناوری | D8: 0.01 | E8: 0.01 | F8: 0.01 | G8: 0.01
B9: 5 | C9: جمع | D9: =SUM(D5:D8) -> 1 | E9: =SUM(E5:E8) -> 1 | F9: 1 | G9: 1

Sheet E.1392
B2: جدول تفكيكي خدمات مهندسي (E)
B4: ردیف | C4: شرح | G4: feed | J4: 1392 | M4: دليل افزايش /ريال
G5: نيروي انساني نفر ساعت | H5: بهاي واحد ريال | I5: بهاي كل | J5: نيروي انساني نفر ساعت | K5: بهاي واحد ريال | L5: بهاي كل
B6: 1 | C6: بازنگري مطالعات مهندسي پايه | G6: 3112 | H6: 280000 | I6: =H6*G6 -> 871360000 | J6: 3112 | K6: 550000 | L6: =K6*J6 -> 1711600000 | M6: تورم ساليانه
B7: 2 | C7: بخش فرآيند و ايمني | G7: 11461 | H7: 250000 | I7: =H7*G7 -> 2865250000 | J7: 11461 | K7: 550000 | L7: =K7*J7 -> 6303550000 | M7: تورم ساليانه
B8: 3 | C8: بخش كارهاي سيويل و سازه | G8: 6126 | H8: 250000 | I8: =H8*G8 -> 1531500000 | J8: 6312 | K8: 550000 | L8: =K8*J8 -> 3471600000 | M8: افزايش اقلام جديد 10درصد تورم ساليانه 90درصد
B9: 4 | C9: بخش كارهاي مكانيكال و HVAC | G9: 5704 | H9: 250000 | I9: =H9*G9 -> 1426000000 | J9: 5704 | K9: 550000 | L9: =K9*J9 -> 3137200000 | M9: تورم ساليانه
B10: 5 | C10: بخش كارهاي لوله كشي و خطوط لوله | G10: 5176 | H10: 250000 | I10: =H10*G10 -> 1294000000 | J10: 5176 | K10: 550000 | L10: =K10*J10 -> 2846800000 | M10: تورم ساليانه
B11: 6 | C11: بخش كارهاي برقي و مخابرات | G11: 6760 | H11: 250000 | I11: =H11*G11 -> 1690000000 | J11: 6760 | K11: 550000 | L11: =K11*J11 -> 3718000000 | M11: تورم ساليانه
B12: 7 | C12: بخش كارهاي ابزار دقيق | G12: 7183 | H12: 250000 | I12: =H12*G12 -> 1795750000 | J12: 7183 | K12: 550000 | L12: =K12*J12 -> 3950650000 | M12: تورم ساليانه
B13: 8 | C13: ساير هزينه هاي مهندسي | I13: 880283525 | L13: 1300000000 | M13: تورم ساليانه
C17: جمع کل : | G17: =SUM(G6:G16) -> 45522 | I17: =SUM(I6:I16) -> 12354143525 | J17: =SUM(J6:J15) -> 45708 | K17: =SUM(K6:K15) -> 3850000 | L17: =SUM(L6:L15) -> 26439400000

Sheet p.lab.1392
G1: نرخ ازاد یورو | H1: اتاق ارز
G2: 42000 | H2: 32600
E4: هزینه واحد بدون ضریب | G4: هزینه کل بدون ضریب
E5: خرید | G5: خرید
B6: DESCRIPTION | C6: size | D6: Qty. | E6: Rls | F6: Euro | G6: Rls | H6: Euro
A7: 1 | B7: Laboratory | H7: =F7*D7 -> 0
A8: 2 | B8: Microwave Digestion System | D8: 1 | F8: 30000 | H8: =F8*D8 -> 30000
A9: 3 | B9: Ion Meter | D9: 1 | F9: 13750 | H9: =F9*D9 -> 13750
A10: 4 | B10: Oxygen Meter | D10: 2 | F10: 1260 | H10: =F10*D10 -> 2520
A11: 5 | B11: Barometer | D11: 2 | F11: 2860 | H11: =F11*D11 -> 5720
A12: 6 | B12: Oil Test Centrifuge | D12: 2 | F12: 25500 | H12: =F12*D12 -> 51000
A13: 7 | B13: Dual Extraction Apparatus | D13: 5 | F13: 20500 | H13: =F13*D13 -> 102500
A14: 8 | B14: Evaporator Mantless (500 cc) | D14: 2 | F14: 1200 | H14: =F14*D14 -> 2400 | J14: =F14/1.31 -> 916.03053
A15: 9 | B15: Water Still For Douuble Distillation | D15: 4 | F15: 6700 | H15: =F15*D15 -> 26800
A16: 10 | B16: Ph Meter | D16: 2 | F16: 2500 | H16: =F16*D16 -> 5000
A17: 11 | B17: Balance | D17: 2 | F17: 6500 | H17: =F17*D17 -> 13000
A18: 12 | B18: R.V.P Automatic | D18: 2 | F18: 55800 | H18: =F18*D18 -> 111600 | J18: =F18/1.31 -> 42595.42
A19: 13 | B19: Thermostatic Water Baths | D19: 2 | F19: 5400 | H19: =F19*D19 -> 10800 | J19: =F19/1.31 -> 4122.1374
A20: 14 | B20: Density/Visco Meter | D20: 2 | F20: 63300 | H20: =F20*D20 -> 126600
A21: 15 | B21: Oxygen Meter | D21: 2 | F21: 1260 | H21: =F21*D21 -> 2520 | J21: =F21/1.31 -> 961.83206
A22: 16 | B22: Baro Meter | D22: 2 | F22: 2900 | H22: =F22*D22 -> 5800 | J22: =F22/1.31 -> 2213.7405
A23: 17 | B23: Salt In Crude Analyzer | D23: 2 | F23: 31000 | H23: =F23*D23 -> 62000 | J23: =F23/1.31 -> 23664.122
A24: 18 | B24: H2S Analyzer For The Determination Of H2S in Fuel Oil | D24: 2 | F24: 49000 | H24: =F24*D24 -> 98000
A25: 19 | B25: Industrial Hood (complete set with valves , sinks , exhoust , etc) | D25: 4 | E25: 1050000000 | G25: =E25 -> 1050000000 | J25: =F25/1.31 -> 0
A26: 20 | B26: Sink (Chemically resistant with attachments) | D26: 10 | E26: (item19)
A27: 21 | B27: Industrial cupboards(floor & wall mounted) | D27: 1 | E27: (item19)
A28: 22 | B28: Safty shower & eyewash | D28: 4 | E28: (item19)
A29: 23 | B29: Exhaust Fan(Wall mounted) | D29: 4 | E29: (item19)
A30: 24 | B30: Ice Maker | D30: 4 | E30: (item19)
G32: =SUM(G7:G31) -> 1050000000 | H32: =SUM(H7:H31) -> 670010
G33: Rls | H33: Euro
G34: خرید
G35: هزینه کل بدون ضریب

Sheet EL.p.1392
B2: جدول تفكيكي تهيه و خريد كالاي مورد نياز پروژه (يورو - ريال )-P - اقلام برقي و مخابراتي
B4: ردیف | C4: شرح | G4: feed | I4: 1392 | K4: 1402 | M4: برآورد نهایی سال 1402 | O4: كل قرارداد قديم با نرخ تسعير زمان پيمان به ريال | P4: كل قرارداد جديد با نرخ تسعير پيمان جديد به ريال | Q4: مابه التفاوت قرارداد جديد و قديم به ريال | R4: مقدار افزايش يا كاهش ارزی | S4: مقدار افزايش يا كاهش ریالی | T4: افزايش اقلام جديد/یورو | U4: نرخ تسعير ارز/یورو | V4: تورم ساليانه/ريال | W4: تغيير احجام/ یورو | X4: تغيير احجام/ريال | Y4: ضعف در برآورد اوليه/یورو | Z4: ضعف در برآورد اوليه/ريال | AA4: افزايش اقلام جديد/ریال
G5: یورو | H5: ریال | I5: یورو | J5: ریال | K5: یورو | L5: ریال | M5: یورو | N5: ریال
B6: 1 | C6: تابلو ها(نمکزدایی و بهره برداری) | G6: 0 | H6: 7365900474 | I6: 150000 | J6: 11000000000 | K6: =I6*Inflation!Euro_Inflation_Factor -> 226395.58 | L6: =J6*Inflation!IRR_Inflation_Factor -> 5.4768344e+11 | N6: 628485722475 | O6: =(G6*13700)+H6 -> 7365900474 | P6: =(I6*32160)+J6 -> 15824000000 | Q6: =P6-O6 -> 8458099526 | R6: =I6-G6 -> 150000 | S6: =J6-H6 -> 3634099526 | V6: =S6 -> 3634099526 | Y6: =R6 -> 150000
B7: 2 | C7: اتصالات برق( شامل : گلندها‏، شرود ها ،جعبه هاي اتصال ، مفصلها و ...) و تجهیزات Earthing & Lightning | G7: 0 | H7: 2208218421 | J7: 6000000000 | K7: =I7*Inflation!Euro_Inflation_Factor -> 0 | L7: =J7*Inflation!IRR_Inflation_Factor -> 2.9873642e+11 | N7: 244000184294 | O7: =(G7*13700)+H7 -> 2208218421 | P7: =(I7*32160)+J7 -> 6000000000 | Q7: =P7-O7 -> 3791781579 | R7: =I7-G7 -> 0 | S7: =J7-H7 -> 3791781579 | V7: =0.7*S7 -> 2.6542471e+09 | Z7: =0.3*S7 -> 1.1375345e+09
B8: 3 | C8: كابلهاي قدرت | G8: 0 | H8: 10026505263 | J8: 32000000000 | K8: =I8*Inflation!Euro_Inflation_Factor -> 0 | L8: =J8*Inflation!IRR_Inflation_Factor -> 1.5932609e+12 | N8: 592730999306 | O8: =(G8*13700)+H8 -> 10026505263 | P8: =(I8*32160)+J8 -> 32000000000 | Q8: =P8-O8 -> 21973494737 | R8: =I8-G8 -> 0 | S8: =J8-H8 -> 21973494737 | V8: =S8 -> 21973494737
B9: 4 | C9: ترانس های واحد نمکزدایی و بهر برداری،دیزل ژنراتور و دستگاه های شارژر صنعتی،UPS و دیزل ژنراتور | G9: 0 | H9: 2208218421 | I9: =15000+222000 -> 237000 | J9: 11600000000 | K9: =I9*Inflation!Euro_Inflation_Factor -> 357705.01 | L9: =J9*Inflation!IRR_Inflation_Factor -> 5.7755709e+11 | M9: =(450527692324*0.554466129702747)/550000 -> 454186.08 | N9: =450527692324*0.445533870297253 -> 2.0072535e+11 | O9: =(G9*13700)+H9 -> 2208218421 | P9: =(I9*32160)+J9 -> 19221920000 | Q9: =P9-O9 -> 17013701579 | R9: =I9-G9 -> 237000 | S9: =J9-H9 -> 9391781579 | V9: =0.6*S9 -> 5.6350689e+09 | Y9: =R9 -> 237000 | Z9: =0.4*S9 -> 3.7567126e+09
B10: 5 | C10: وسايل و تجهيزات مخابرات و پيجينگ | G10: 0 | H10: 2744457408 | J10: 4000000000 | K10: =I10*Inflation!Euro_Inflation_Factor -> 0 | L10: =J10*Inflation!IRR_Inflation_Factor -> 1.9915762e+11 | M10: =(74091374913*0.929198602787513)/550000 -> 125173.82 | N10: =74091374913*0.0708013972124875 -> 5.2457729e+09 | O10: =(G10*13700)+H10 -> 2744457408 | P10: =(I10*32160)+J10 -> 4000000000 | Q10: =P10-O10 -> 1255542592 | R10: =I10-G10 -> 0 | S10: =J10-H10 -> 1255542592 | V10: =S10 -> 1255542592
B11: 6 | C11: برجهاي روشنايي و پست هاي برق و خط انتقال | G11: 0 | H11: 3879302632 | I11: 60000 | J11: 18700000000 | K11: 0 | L11: 754000000000 | N11: 754000000000 | O11: =(G11*13700)+H11 -> 3879302632 | P11: =(I11*32160)+J11 -> 20629600000 | Q11: =P11-O11 -> 16750297368 | R11: =I11-G11 -> 60000 | S11: =J11-H11 -> 14820697368 | V11: =0.6*S11 -> 8.8924184e+09 | W11: =R11 -> 60000 | X11: =0.4*S11 -> 5.9282789e+09
B12: 7 | C12: دیزل ژنراتور و سیستم های DC&UPS | I12: 222000 | K12: =I12*Inflation!Euro_Inflation_Factor -> 335065.46 | L12: =J12*Inflation!IRR_Inflation_Factor -> 0 | O12: =(G12*13700)+H12 -> 0 | P12: =(I12*32160)+J12 -> 7139520000 | Q12: =P12-O12 -> 7139520000 | R12: =I12-G12 -> 222000 | S12: =J12-H12 -> 0 | T12: =R12 -> 222000
B13: 8 | C13: ترا نس های واحد بهره برداری | J13: 3000000000 | K13: =I13*Inflation!Euro_Inflation_Factor -> 0 | L13: =J13*Inflation!IRR_Inflation_Factor -> 1.4936821e+11 | O13: =(G13*13700)+H13 -> 0 | P13: =(I13*32160)+J13 -> 3000000000 | Q13: =P13-O13 -> 3000000000 | R13: =I13-G13 -> 0 | S13: =J13-H13 -> 3000000000 | AA13: =S13 -> 3000000000
B14: 9 | C14: تابلوهای واحد بهره برداری | I14: 270000 | J14: 5700000000 | K14: =I14*Inflation!Euro_Inflation_Factor -> 407512.04 | L14: =J14*Inflation!IRR_Inflation_Factor -> 2.837996e+11 | O14: =(G14*13700)+H14 -> 0 | P14: =(I14*32160)+J14 -> 14383200000 | Q14: =P14-O14 -> 14383200000 | R14: =I14-G14 -> 270000 | S14: =J14-H14 -> 5700000000 | T14: =I14 -> 270000 | AA14: =S14 -> 5700000000
C15: جمع کل : | G15: =SUM(G6:G14) -> 0 | H15: =SUM(H6:H14) -> 28432602619 | I15: =SUM(I6:I14) -> 939000 | J15: =SUM(J6:J14) -> 92000000000 | K15: =SUM(K6:K14) -> 1326678.1 | L15: =SUM(L6:L14) -> 4.4035633e+12 | M15: =SUM(M6:M11) -> 579359.91 | N15: =SUM(N6:N11) -> 2.425188e+12 | O15: =(G15*13700)+H15 -> 28432602619 | P15: =SUM(P6:P14) -> 122198240000 | Q15: =P15-O15 -> 93765637381 | R15: =I15-G15 -> 939000 | S15: =J15-H15 -> 63567397381 | T15: =SUM(T6:T14) -> 492000 | U15: =SUM(U6:U14) -> 0 | V15: =SUM(V6:V14) -> 4.4044871e+10 | W15: =SUM(W6:W14) -> 60000 | X15: =SUM(X6:X14) -> 5.9282789e+09 | Y15: =SUM(Y6:Y14) -> 387000 | Z15: =SUM(Z6:Z14) -> 4.8942471e+09 | AA15: =SUM(AA6:AA14) -> 8700000000
P24: جدول خلاصه مالی تفكيكي تهيه و خريد كالاي برق و مخابرات مورد نياز پروژه گچساران4
G25: percentage added | H25: ratio maron/gach4 | I25: گچساران4 | J25: مارون3 | K25: CORRECTION | L25: ratio maron/gach4 | P25: رديف | Q25: شرح فعاليت ها | R25: دلار | S25: ريال | T25: يورو
D26: =F26-J26 -> -1.4542247e+12 | E26: =F26/I26 -> 0.8 | F26: =G26*J26+J26 -> 645073600000 | G26: =((0.8*I26-J26)/J26) -> -0.69271942 | H26: =$J26/$I26 -> 2.6034837 | I26: =S26 -> 806342000000 | J26: =(L14+L6+((K14+K6)*Inflation!G3)) -> 2.0992983e+12 | K26: =L26*1.0265 -> 2.6724761 | L26: =(L14+L6+((K14+K6)*Inflation!G3))/S26 -> 2.6034837 | P26: 1 | Q26: تابلوها | R26: 0 | S26: 806342000000 | T26: 0
D27: =F27-J27 -> -5.4736239e+10 | E27: =F27/I27 -> 0.8 | F27: =G27*J27+J27 -> 2.4400018e+11 | G27: =((0.8*I27-J27)/J27) -> -0.18322586 | H27: =$J27/$I27 -> 0.97946294 | I27: =S27 -> 3.0500023e+11 | J27: =L7 -> 2.9873642e+11 | K27: =L27*2.2 -> 2.1548185 | L27: =L7/S27 -> 0.97946294 | P27: 2 | Q27: اتصالات برق (شامل گلندها، شرودها، جعبه هاي اتصال، مفصلها و ...) | R27: 0 | S27: 3.0500023e+11 | T27: 0
H28: =$J28/$I28 -> 2.5385321 | I28: =S28 -> 627630805000 | J28: =L8 -> 1.5932609e+12 | L28: =L8/S28 -> 2.5385321 | P28: 3 | Q28: كابلهاي قدرت | R28: 0 | S28: 627630805000
D29: =F29-J29 -> 4.3298842e+11 | E29: =F29/I29 -> 0.8 | F29: =G29*J29+J29 -> 2.5454547e+12 | G29: =((0.8*I29-J29)/J29) -> 0.20496821 | H29: =$J29/$I29 -> 0.66391793 | I29: =(S29+T29*Inflation!G3) -> 3.1818183e+12 | J29: =(L9+(K9*Inflation!G3)+L13+(K12*Inflation!G3)) -> 2.1124662e+12 | K29: =L29*2.3 -> 1.5270112 | L29: =(L9+(K9*Inflation!G3)+L13+(K12*Inflation!G3))/(S29+T29*Inflation!G3) -> 0.66391793 | P29: 4 | Q29: ترانسفورماتورها، دستگاههاي شارژر صنعتي، UPS صنعتي و دیزل ژنراتور | R29: 0 | S29: 575848000000 | T29: 1302985.2
D30: =F30-J30 -> 9.6333034e+10 | E30: =F30/I30 -> 0.8 | F30: =G30*J30+J30 -> 2.9549065e+11 | G30: =((0.8*I30-J30)/J30) -> 0.48370249 | H30: =$J30/$I30 -> 0.53919166 | I30: =(S30+(T30*Inflation!G3)) -> 3.6936331e+11 | J30: =L10 -> 1.9915762e+11 | K30: =L30*1.16 -> 0.62546232 | L30: =L10/(S30+(T30*Inflation!G3)) -> 0.53919166 | P30: 5 | Q30: وسايل و تجهيزات مخابرات، و پیجینگ | R30: 0 | S30: 7.5807744e+09 | T30: 180891.27
D31: =F31-J31 -> -1.9232516e+11 | E31: =F31/I31 -> 0.8 | F31: =G31*J31+J31 -> 5.6167484e+11 | G31: =((0.8*I31-J31)/J31) -> -0.25507316 | H31: =$J31/$I31 -> 1.073931 | I31: =(S31+S32) -> 7.0209355e+11 | J31: =(L11+K11*Inflation!G3) -> 754000000000 | K31: =L31*1.44 -> 1.5464606 | L31: =(L11+K11*Inflation!G3)/(S31+S32) -> 1.073931 | P31: 6 | Q31: پایه ها و برجهاي روشنائي و سایر ملحقات و ادوات روشنایی | R31: 0 | S31: 1.6911356e+11
P32: 7 | Q32: خط انتقال برق شامل کابل ، پایه ها و یراق آلات | R32: 0 | S32: 5.3297999e+11
Q33: جمع كل بدون حمل و يدكي | R33: 0 | S33: 3.0244954e+12 | T33: 1483876.4 | U33: گچساران4
S34: =L15 -> 4.4035633e+12 | T34: =K15 -> 1326678.1 | U34: مارون 3
S36: =T36/T37 -> 1.1776748 | T36: =S34+T34*Inflation!G3 -> 7.0569195e+12 | U36: 77میلیارد -افزایش طول خط انتقال
T37: =S33+T33*Inflation!G3 -> 5.9922482e+12

Sheet IN.p&C.1392
C1: FEED مارون 3 | E1: 1392 | G1: تغییرات(%) | H1: توضیحات
A2: رديف | B2: شرح | C2: یورو | D2: ريال | E2: یورو | F2: ريال
A3: 1 | B3: ادوات ابزار دقیق شامل : ترانسمیترها ، سوئیچ ها ، گیج ها و ... | C3: 295416 | E3: 498000 | G3: =((E3-C3)/C3)*100 -> 68.575839 | H3: - تبدیل نرخ قیمت پایه از ریال به یورو بر اساس هر یورو 14120ریال. - واقعی نبودن برآورد اولیه واقعی مشخص نبودن قیمت پایه و روش محاسبه در نظر گرفته شده جهت تجهیزات ابزاردقیق در مهندسی پایه
A4: 2 | B4: شیرآلات ابزار شامل : شیر ON/OFF ، شیرهای کنترلی ، PSV ، PCV | C4: 444484 | E4: 489000 | G4: =((E4-C4)/C4)*100 -> 10.015209 | H4: - تبدیل نرخ قیمت پایه از ریال به یورو بر اساس هر یورو 14120ریال. - واقعی نبودن برآورد اولیه واقعی مشخص نبودن قیمت پایه و روش محاسبه در نظر گرفته شده جهت تجهیزات ابزاردقیق در مهندسی پایه
A5: 3 | B5: سيستم كنترل ( DCS )، ESD | C5: =D5/14120 -> 568822.09 | D5: 8031767850 | E5: 1079990 | G5: =((E5-C5)/C5)*100 -> 89.864287 | H5: - تبدیل نرخ قیمت پایه از ریال به یورو بر اساس هر یورو 14120ریال. - واقعی نبودن برآورد اولیه واقعی عدم در نظر گرفتن سیستم کنترل واحد بهره برداری در محاسبات - افزایش هزینه های تامین سیستم FCS ناشی از تحریمها - محدود شدن سازندگان سیستم FCS از سوی اداره اسانداردها
A6: 4 | B6: سیستم F&G | C6: =D6/14120 -> 187603.89 | D6: 2648966882 | E6: 200000 | G6: =((E6-C6)/C6)*100 -> 6.6075993 | H6: - تبدیل نرخ قیمت پایه از ریال به یورو بر اساس هر یورو 14120ریال. - واقعی نبودن برآورد اولیه واقعی مشخص نبودن قیمت پایه و روش محاسبه در نظر گرفته شده جهت تجهیزات ابزاردقیق در مهندسی پایه
A7: 5 | B7: سیستم CCTV و حفاظت پیرامونی | E7: 250000 | H7: در محاسبات جدید هزینه های سیستم حفاظت پیرامونی ومشخصات مورد نیاز اداره حراست در نظر گرفته شده است
A8: 6 | B8: اقلام بالک ابزار دقیق | D8: 1790447368 | F8: 9050000000 | G8: =((F8-D8)/D8)*100 -> 405.46026 | H8: تغییر نرخ ارز مشخص نبودن قیمت پایه و روش محاسبه در نظر گرفته شده جهت تجهیزات ابزاردقیق در مهندسی پایه
A9: 6 | B9: کابلهای ابزار دقیق و ملحقات شامل : گلند سینی و ... | D9: 5072934211 | F9: 15750000000 | G9: =((F9-D9)/D9)*100 -> 210.47121 | H9: تغییر نرخ ارز مشخص نبودن قیمت پایه و روش محاسبه در نظر گرفته شده جهت تجهیزات ابزاردقیق در مهندسی پایه
A10: 7 | B10: نصب دستگاههاي ابزاردقيق داخل واحد | D10: 1759824479 | F10: =((E3+E4)*32000*0.05)+(F9*0.05) -> 2366700000 | G10: =((F10-D10)/D10)*100 -> 34.485003 | H10: تغییر نرخ ارز تغییر روش محاسبه کارهای اجرایی %5 قیمت کل تجهیزات
A11: 8 | B11: نصب سيستم كنترل و دستگاههاي ابزاردقيق داخل اتاق كنترل | D11: 2150896585 | F11: =(E5+E6+E7)*32000*0.05 -> 2447984000 | G11: =((F11-D11)/D11)*100 -> 13.812259 | H11: تغییر نرخ ارز تغییر روش محاسبه کارهای اجرایی %5 قیمت کل تجهیزات
A12: 10 | B12: جمع كل | C12: =SUM(C3:C9) -> 1496326 | D12: =SUM(D3:D11) -> 21454837375 | E12: =SUM(E3:E9) -> 2516990 | F12: =SUM(F3:F11)*18.52 -> 548463947680
E13: =E12*Inflation!Euro_Inflation_Factor -> 3798902.7 | F13: =(F8+F9)*Inflation!IRR_Inflation_Factor -> 1.2347772e+12
E14: =(6157862*0.8)-E13-G14 -> -870389.86 | F14: =F13-(170000000000*0.8) -> 1.0987772e+12 | G14: =F14/550000 -> 1997776.8
E15: =E13+E14 -> 2928512.8 | F15: =F10+F11 -> 4814684000 | G15: اجرا
D16: =(F10+F11)*Inflation!IRR_Inflation_Factor -> 2.3972025e+11 | F16: =F9+F8 -> 24800000000 | G16: کالای ریالی
D17: =1.058*186000000000*0.8 -> 157430400000
D18: =D17-D16 -> -8.2289847e+10

Sheet ME.p.1392
B2: جدول تفكيكي تهيه و خريد كالاي مورد نياز پروژه (يورو - ريال )-P- اقلام مکانیکی
B4: ردیف | C4: شرح | G4: feed | I4: 1392 | K4: كل قرارداد قديم با نرخ تسعير زمان پيمان به ريال | L4: كل قرارداد جديد با نرخ تسعير پيمان جديد به ريال | M4: مابه التفاوت قرارداد جديد و قديم به ريال | N4: مقدار افزايش يا كاهش ارزی | O4: مقدار افزايش يا كاهش ریالی | P4: نرخ تسعير ارز/یورو | Q4: تغيير احجام/ یورو | R4: ضعف در برآورد اوليه/یورو | S4: تورم ساليانه /ريال | T4: ضعف در برآورد اوليه/ریال
G5: یورو | H5: ریال | I5: یورو | J5: ریال
B6: 1 | C6: الكترواستاتيك و ادوات مربوطه | G6: 1942474 | H6: 19336831579 | I6: 1942474 | J6: 28038405790 | K6: =(G6*13700)+H6 -> 45948725379 | L6: =(I6*32160)+J6 -> 90508369630 | M6: =L6-K6 -> 44559644251 | N6: =I6-G6 -> 0 | O6: =J6-H6 -> 8701574211 | P6: =((M6-O6)/32160) -> 1114989.7 | S6: =O6 -> 8701574211
B7: 2 | C7: كوره ها و ادوات مربوطه | G7: 1028368 | H7: 8355421053 | I7: 1028368 | J7: 12115360530 | K7: =(G7*13700)+H7 -> 22444062653 | L7: =(I7*32160)+J7 -> 45187675410 | M7: =L7-K7 -> 22743612757 | N7: =I7-G7 -> 0 | O7: =J7-H7 -> 3759939477 | P7: =(M7-O7)/32160 -> 590288.35 | S7: =O7 -> 3759939477
B8: 3 | C8: مبدل نفت/نفت و مبدل آب/آب | G8: 257092 | H8: 0 | I8: 257092 | K8: =(G8*13700)+H8 -> 3522160400 | L8: =(I8*32160)+J8 -> 8268078720 | M8: =L8-K8 -> 4745918320 | N8: =I8-G8 -> 0 | O8: =J8-H8 -> 0 | P8: =(M8-O8)/32160 -> 147572.09
B9: 4 | C9: تلمبه ها | G9: 2436548 | H9: 0 | I9: 2436548 | J9: =I9*1.38 -> 3362436.2 | K9: =(G9*13700)+H9 -> 33380707600 | L9: =(I9*32160)+J9 -> 7.8362746e+10 | M9: =L9-K9 -> 4.4982039e+10 | N9: =I9-G9 -> 0 | O9: =J9-H9 -> 3362436.2 | P9: =(M9-O9)/32160 -> 1398590.7
B10: 5 | C10: شيرآلات و اتصالات، رنگ ها و لوله هاي داخل سايت و مواد شيميايي | G10: 0 | H10: 16232939240 | I10: 2943642 | K10: =(G10*13700)+H10 -> 16232939240 | L10: =(I10*32160)+J10 -> 94667526720 | M10: =L10-K10 -> 78434587480 | N10: =I10-G10 -> 2943642 | O10: =J10-H10 -> -16232939240 | P10: 0 | R10: =N10 -> 2943642 | T10: =O10 -> -16232939240
B11: 6 | C11: خريد لوله هاي بيرون سايت | G11: 1294373 | H11: 21856642749 | I11: 1294373 | J11: 25000000000 | K11: =(G11*13700)+H11 -> 39589552849 | L11: =(I11*32160)+J11 -> 66627035680 | M11: =L11-K11 -> 27037482831 | N11: =I11-G11 -> 0 | O11: =J11-H11 -> 3143357251 | P11: =(M11-O11)/32160 -> 742976.54 | S11: =O11 -> 3143357251
B12: 7 | C12: مخزن هاي اتمسفريك و تحت فشار | G12: 0 | H12: 8214572526 | I12: 509664 | J12: 1848278818 | K12: =(G12*13700)+H12 -> 8214572526 | L12: =(I12*32160)+J12 -> 18239073058 | M12: =L12-K12 -> 10024500532 | N12: =I12-G12 -> 509664 | O12: =J12-H12 -> -6366293708 | P12: 0 | R12: =N12 -> 509664 | T12: =O12 -> -6366293708
B13: 8 | C13: سيستم پساب | G13: 1629393 | H13: 0 | I13: 1908368 | K13: =(G13*13700)+H13 -> 22322684100 | L13: =(I13*32160)+J13 -> 61373114880 | M13: =L13-K13 -> 39050430780 | N13: =I13-G13 -> 278975 | O13: =J13-H13 -> 0 | P13: =(((M13-O13)/32160))-(N13) -> 935279.69 | Q13: =N13 -> 278975
B14: 9 | C14: chemical injection and air compressor package | G14: 0 | H14: 8485526895 | I14: 433567 | J14: 3818487103 | K14: =(G14*13700)+H14 -> 8485526895 | L14: =(I14*32160)+J14 -> 17762001823 | M14: =L14-K14 -> 9276474928 | N14: =I14-G14 -> 433567 | O14: =J14-H14 -> -4667039792 | P14: 0 | R14: =N14 -> 433567 | T14: =O14 -> -4667039792
B15: 10 | C15: Flares | G15: 31422 | H15: 895223684 | I15: 190593 | K15: =(G15*13700)+H15 -> 1325705084 | L15: =(I15*32160)+J15 -> 6129470880 | M15: =L15-K15 -> 4803765796 | N15: =I15-G15 -> 159171 | O15: =J15-H15 -> -895223684 | P15: =(((M15-O15)/32160))-(N15) -> 18036.384 | R15: =N15 -> 159171 | T15: =O15 -> -895223684
B16: 11 | C16: Ignitors | G16: 150256 | H16: 0 | I16: 150256 | K16: =(G16*13700)+H16 -> 2058507200 | L16: =(I16*32160)+J16 -> 4832232960 | M16: =L16-K16 -> 2773725760 | N16: =I16-G16 -> 0 | O16: =J16-H16 -> 0 | P16: =(M16-O16)/32160 -> 86247.692
B17: 12 | C17: Vacum Dearator Package | G17: 259377 | H17: 0 | I17: 259377 | K17: =(G17*13700)+H17 -> 3553464900 | L17: =(I17*32160)+J17 -> 8341564320 | M17: =L17-K17 -> 4788099420 | N17: =I17-G17 -> 0 | O17: =J17-H17 -> 0 | P17: =(M17-O17)/32160 -> 148883.69
B18: 13 | C18: سيستم HVAC | G18: 0 | H18: 2625392658 | J18: 8425000000 | K18: =(G18*13700)+H18 -> 2625392658 | L18: =(I18*32160)+J18 -> 8425000000 | M18: =L18-K18 -> 5799607342 | N18: =I18-G18 -> 0 | O18: =J18-H18 -> 5799607342 | P18: =((M18-O18)/32160) -> 0 | S18: =O18 -> 5799607342
B19: 14 | C19: جرثقيل هاي سقفي | G19: 0 | H19: 692306316 | J19: 6500000000 | K19: =(G19*13700)+H19 -> 692306316 | L19: =(I19*32160)+J19 -> 6500000000 | M19: =L19-K19 -> 5807693684 | N19: =I19-G19 -> 0 | O19: =J19-H19 -> 5807693684 | P19: =((M19-O19)/32160) -> 0 | S19: =O19 -> 5807693684
C20: جمع کل : | G20: =SUM(G6:G19) -> 9029303 | H20: =SUM(H6:H19) -> 86694856700 | I20: =SUM(I6:I17) -> 13354322 | J20: =SUM(J6:J19) -> 8.5748895e+10 | K20: =(G20*13700)+H20 -> 210396307800 | L20: =(I20*32160)+J20 -> 5.1522389e+11 | M20: =L20-K20 -> 3.0482758e+11 | N20: =SUM(N6:N16) -> 4325019 | O20: =J20-H20 -> -9.4596202e+08 | P20: =SUM(P6:P19) -> 5182864.8 | Q20: =SUM(Q6:Q16) -> 278975 | R20: =SUM(R6:R16) -> 4046044 | S20: =SUM(S6:S19) -> 27212171965 | T20: =SUM(T6:T16) -> -28161496424
J23: =J20*Inflation!IRR_Inflation_Factor -> 4.2693864e+12

Sheet SEFTY.p.1392
G1: نرخ ازاد یورو | H1: اتاق ارز
G2: 42000 | H2: 32600
E4: هزینه واحد بدون ضریب | G4: هزینه کل بدون ضریب
E5: خرید | G5: خرید
B6: DESCRIPTION | C6: size | D6: Qty. | E6: Rls | F6: Euro | G6: Rls | H6: Euro
B7: Safety
A8: 1 | B8: WATER HYDRANT | C8: 6" | D8: 13 | E8: =J8*$G$2 -> 29400000 | G8: =E8*D8 -> 382200000 | H8: =F8*D8 -> 0 | J8: 700
A9: 2 | B9: WATER HYDRANT WITH MONITOR | C9: 6" | D9: 15 | E9: =J9*$G$2 -> 44100000 | G9: =E9*D9 -> 661500000 | H9: =F9*D9 -> 0 | J9: 1050
A10: 3 | B10: OS&Y GATE VALVE-ISOLATING VALVE | C10: 12" | D10: 2 | G10: =E10*D10 -> 0 | H10: =F10*D10 -> 0
A11: 4 | B11: OS&Y GATE VALVE-ISOLATING VALVE | C11: 6" | D11: 19 | G11: 0 | H11: =F11*D11 -> 0
A12: 5 | B12: DELUGE VALVE | C12: 4" | D12: 2 | G12: =E12*D12 -> 0 | H12: =F12*D12 -> 0
A13: 6 | B13: DRY POWDER PORTABLE FIRE EXTINGUISHER | C13: 12 KG | D13: 20 | E13: =J13*$G$2 -> 2520000 | G13: =E13*D13 -> 50400000 | H13: =F13*D13 -> 0 | J13: 60
A14: 7 | B14: DRY POWDER WHELEED FIRE EXTINGUISHER | C14: 75 KG | D14: 8 | E14: =J14*$G$2 -> 31500000 | G14: =E14*D14 -> 252000000 | H14: =F14*D14 -> 0 | J14: 750
A15: 8 | B15: CO2 PORTABLE FIRE EXTINGUISHER | C15: 5 KG | D15: 20 | E15: =J15*$G$2 -> 1890000 | G15: =E15*D15 -> 37800000 | H15: =F15*D15 -> 0 | J15: 45
A16: 9 | B16: CO2 WHEELD FIRE EXTINGUISHER | C16: 30 KG | D16: 12 | E16: =J16*$G$2 -> 18900000 | G16: =E16*D16 -> 226800000 | H16: =F16*D16 -> 0 | J16: 450
A17: 10 | B17: SAFETY SHOWER & EYE WASH | C17: - | D17: 5 | E17: =J17*$G$2 -> 31500000 | G17: =E17*D17 -> 157500000 | H17: =F17*D17 -> 0 | J17: 750
A18: 11 | B18: WIND SOCK | C18: - | D18: 2 | G18: =E18*D18 -> 0 | H18: =F18*D18 -> 0
A19: 12 | B19: HOSE REEL | C19: - | D19: 13 | G19: =E19*D19 -> 0 | H19: =F19*D19 -> 0
A20: 13 | B20: FIRST AID KIT | C20: - | D20: 3 | E20: =J20*$G$2 -> 3150000 | G20: =E20*D20 -> 9450000 | H20: =F20*D20 -> 0 | J20: 75
A21: 14 | B21: EMERGENCY EQUIPMENT BOX | C21: - | D21: 2 | G21: =E21*D21 -> 0 | H21: =F21*D21 -> 0
A22: 15 | B22: EMERGENCY BREATING APPARATUS WITH MASK | C22: - | D22: 1 | G22: =E22*D22 -> 0 | H22: =F22*D22 -> 0
A23: 16 | B23: FIRE MAN CABINET | C23: - | D23: 1 | G23: =E23*D23 -> 0 | H23: =F23*D23 -> 0
A24: 17 | B24: STRETCHER | C24: - | D24: 2 | G24: =E24*D24 -> 0 | H24: =F24*D24 -> 0
A25: 18 | B25: CO2 TOTAL FLOODING SYSTEM | C25: - | D25: 3 | E25: =J25*$G$2 -> 840000000 | G25: 0 | H25: =F25*D25 -> 0 | J25: 20000
A26: 19 | B26: FIRE SHED EQUIPMENT INCLUDING : 100 lit foam drums, 3% FP (5 NOS.), Fire Hose, 25 m (10 NOS.) Foam Nozzle 10X (2 NOS.) Water Nozzle, 450 lpm (Fog/Jet/Stop) (5 NOS.)) 12 kg portable powder fire extinguisher (6 NOS.) 75 kg Wheeled powder fire extinguisher (2 NOS.) 5 kg portable CO2 fire extinguisher (2 NOS.) In Line Inductor, 450 lpm with pick up tube (2 NOS.) Drum Wrench (1 NO.) Hose Bridge (1 NO.) | C26: - | D26: 7 | E26: =J26*$G$2 -> 168000000 | G26: =E26*D26 -> 1176000000 | H26: =F26*D26 -> 0 | J26: 4000
A27: 20 | B27: FIRE DOSE SYSTEM | C27: - | D27: 3 | G27: =E27*D27 -> 0 | H27: =F27*D27 -> 0
A28: 21 | B28: 9 LIT WATER EXTINGUISHER | C28: - | D28: 8 | E28: =J28*$G$2 -> 1890000 | G28: =E28*D28 -> 15120000 | H28: =F28*D28 -> 0 | J28: 45
A29: 22 | B29: WATER SPRAY SYSTEM | C29: - | D29: 1 | G29: =E29*D29 -> 0 | H29: =F29*D29 -> 0
A30: 23 | B30: SAFETY SIGN | C30: - | D30: 179 | G30: =E30*D30 -> 0 | H30: =F30*D30 -> 0
A31: 24 | B31: AXE | C31: - | D31: 3 | G31: 0 | H31: =F31*D31 -> 0
A32: 25 | B32: RECHARGEABLE FLASHLIGHT (EXPLOSION PROOF) | C32: - | D32: 1 | G32: =E32*D32 -> 0 | H32: =F32*D32 -> 0
A33: 26 | B33: EMERGENCY BREATHING APPARATUS WITH AIR MASTER | C33: - | D33: 5 | G33: =E33*D33 -> 0 | H33: =F33*D33 -> 0
A34: 27 | B34: BREATHING RECOVERY DEVICE | C34: - | D34: 2 | G34: =E34*D34 -> 0 | H34: =F34*D34 -> 0
A35: 52 | G35: =E35*D35 -> 0 | H35: =F35*D35 -> 0
G37: =SUM(G8:G36) -> 2968770000 | H37: =SUM(H8:H36) -> 0
G38: Rls | H38: Euro
G39: خرید
G40: هزینه کل بدون ضریب

Sheet p.summary1392
B2: برآورد کلی بخش تهیه و خرید کالای مورد نیاز کل پروژه (یورو - ریال)
B4: رديف | C4: بخش | F4: feed / یورو | G4: 1392 /یورو | H4: feed/ ریال | I4: 1392 /ریال | J4: جمع کل برآورد قدیم / ریال | K4: جمع کل برآورد جدید / ریال | M4: در صد رشدکل برآورد جدید نسبت به قدیم در بخش کالا
B5: 1 | C5: مکانیک | F5: 9029303 | G5: 13354322 | H5: 86694856700 | I5: ='ME.p.1392'!J20 -> 8.5748895e+10 | J5: =(F5*13700)+H5 -> 210396307800 | K5: =(G5*32160)+I5 -> 5.1522389e+11 | M5: =K5/J5*100-100 -> 144.88257
B6: 2 | C6: برق ومخابرات | F6: 0 | G6: 717000 | H6: 28432602619 | I6: ='EL.p.1392'!J15 -> 92000000000 | J6: =(F6*13700)+H6 -> 28432602619 | K6: =(G6*32160)+I6 -> 115058720000 | M6: =K6/J6*100-100 -> 304.67178
B7: 3 | C7: ابزاردقیق | F7: ='IN.p&C.1392'!C12 -> 1496326 | G7: ='IN.p&C.1392'!E12 -> 2516990 | H7: =SUM('IN.p&C.1392'!D5:D9) -> 17544116311 | I7: ='IN.p&C.1392'!F16 -> 24800000000 | J7: =(F7*13700)+H7 -> 3.8043782e+10 | K7: =(G7*32160)+I7 -> 105746398400 | M7: =K7/J7*100-100 -> 177.95974
B8: 4 | C8: ایمنی | F8: 0 | G8: 0 | H8: 1969492105 | I8: ='SEFTY.p.1392'!G37 -> 2968770000 | J8: =(F8*13700)+H8 -> 1969492105 | K8: =(G8*32160)+I8 -> 2968770000 | M8: =K8/J8*100-100 -> 50.737847
B9: 5 | C9: لوازم یدکی و ترخیص | F9: 488460 | G9: 825366 | H9: 28035386975 | I9: 185089085859 | J9: =(F9*13700)+H9 -> 34727288975 | K9: =(G9*32160)+I9 -> 211632856419 | M9: =K9/J9*100-100 -> 509.4137
B10: 6 | C10: جمع | F10: =SUM(F5:F9) -> 11014089 | G10: =SUM(G5:G9) -> 17413678 | H10: =SUM(H5:H9) -> 162676454710 | I10: =SUM(I5:I9) -> 3.9060675e+11 | J10: =(F10*13700)+H10 -> 3.1356947e+11 | K10: =(G10*32160)+I10 -> 9.5063064e+11 | M10: =K10/J10*100-100 -> 203.16428
B11: توضیحات :

Sheet CV1392
B3: رديف | C3: شرح | G3: Feed | H3: 1392 | I3: در صد نسبت به برآورد كل | J3: در صد رشد ناشي از افزايش قيمت ها
B4: 1 | C4: تغييرات ناشي از افزايش ابعاد ساختمان ها ، افزايش مسير خط انتقال برق و بخشي از عمليات خاكي به علت جابجايي زمين پروژه | G4: 0 | H4: 53937235487 | I4: =H4/H7*100 -> 17.580402
B5: 2 | C5: تغييرات جديد ناشي از جابجايي زمين پروژه شامل جمع آوري دو عدد حوضچه تبخير موجود در زمين پروژه ، احداث دو عدد حوضچه تبخير جديد مازاد بر حوضچه تبخير اصلي پروژه جديد ،احداث ساختمان work shop ، احداث سايبان پمپ هاي آب آتش نشاني و خريد و نصب سيستم بسته تصفيه فاضلاب | G5: 0 | H5: 81226100000 | I5: =H5/H7*100 -> 26.474985
B6: 3 | C6: برآورد كارهاي موجود در كتابچه قديم طبق فهرست بهاء سال 92 رشته ابنيه | G6: 73807829439 | H6: 171639864513 | I6: =H6/H7*100 -> 55.944614
B7: 4 | C7: كل برآورد بخش سيويل | G7: =G4+G5+G6 -> 73807829439 | H7: =SUM(H4:H6) -> 306803200000 | I7: 100

Sheet c.cefty.1392
A1: برآورد هزينه ايمني كارگاه پروژه مارون 3 بنگستان
A2: رديف | B2: عنوان | C2: بهاي كل
A3: 1 | B3: لوازم حفاظت فردي و تجهيزات | C3: =H84 -> 5912000000
A4: 2 | B4: سنجش و اندازه گيري(1) | C4: =F48 -> 240000000
A5: 3 | B5: سنجش و اندازه گيري(2) | C5: =G35 -> 144000000
A6: 4 | B6: اموزش | C6: =H25 -> 434000000
A7: 5 | B7: نيروي انساني | C7: =F31 -> 2520000000
A8: کل هزینه کارگاهی مارون 3 بنگستان | C8: =SUM(C3:C7) -> 9250000000
A9: .
A10: برآورد هزينه ايمني در كارگاه پروژه مارون3 بنگستان
A11: آموزش
A12: ردیف | B12: سر فصل دوره ها | C12: تعداد دوره در سال | D12: مدت زمان پروژه (سال) | E12: تعداد دوره در كل زمان پروژه | F12: زمان دوره (روز) | G12: بهاي دوره (ريال) | H12: بهاي كل
A13: 1 | B13: MSDS و کار با مواد شیمیایی | C13: 2 | D13: 4 | E13: 8 | F13: 1 | G13: 5000000 | H13: 40000000
A14: 2 | B14: ایمنی داربست ها ،کار در ارتفاع،بالابرها،جرثقیل و لیفتراک ها | C14: 2 | D14: 4 | E14: 8 | F14: 1 | G14: 5000000 | H14: 40000000
A15: 3 | B15: ایمنی برق و برق صنعتی،صاعقه و رعد و برق و سیستم های ارتینگ | C15: 2 | D15: 4 | E15: 8 | F15: 1 | G15: 5000000 | H15: 40000000
A16: 4 | B16: آتش نشانی و اطفا حریق | C16: 3 | D16: 4 | E16: 12 | F16: 1 | G16: 3500000 | H16: 42000000
A17: 5 | B17: آشنایی با استانداردهای ISO9001وTS29001 | C17: 1 | D17: 4 | E17: 4 | F17: 1 | G17: 5000000 | H17: 20000000
A18: 6 | B18: آشنایی با استانداردهای ISO14001 | C18: 1 | D18: 4 | E18: 4 | F18: 1 | G18: 5000000 | H18: 20000000
A19: 7 | B19: آشنایی با OHSAS18001 | C19: 2 | D19: 4 | E19: 8 | F19: 1 | G19: 5000000 | H19: 40000000
A20: 8 | B20: کنترل عملیات HSE،IMSوپرمیت ها | C20: 2 | D20: 4 | E20: 8 | F20: 1 | G20: 5000000 | H20: 40000000
A21: 9 | B21: ایمنی کار با پرتوها و اشعه ها | C21: 1 | D21: 4 | E21: 4 | F21: 1 | G21: 5000000 | H21: 20000000
A22: 10 | B22: اورژانس،کمک های اولیه و ارگونومی و مدیریت بحران | C22: 3 | D22: 4 | E22: 12 | F22: 1 | G22: 5000000 | H22: 60000000
A23: 11 | B23: ایمنی جوشکاری،برشکاری و عملیات سندبلاست | C23: 2 | D23: 4 | E23: 8 | F23: 1 | G23: 5000000 | H23: 40000000
A24: 12 | B24: انبارداری و رعایت اصول مربوطه | C24: 2 | D24: 4 | E24: 8 | F24: 1 | G24: 4000000 | H24: 32000000
A25: مجموع | H25: =SUM(H13:H24) -> 434000000
A26: برآورد هزينه ايمني در كارگاه پروژه مارون3 بنگستان
A27: نیروی انسانی
A28: رديف | B28: عنوان | C28: واحد/ نفر | D28: مقدار حقوق ماهانه (ریال) | E28: زمان كل پروژه (ماه) | F28: جمع (ريال)
A29: 1 | B29: کارشناس HSE جهت سایت ویزیت و نظارت بر انجام ایمن کارها | C29: 2 | D29: 20000000 | E29: 42 | F29: 1680000000
A30: 2 | B30: کارشناس IMS جهت مستندسازی فرآیندهای مربوطه و کارهای داکیومنتی | C30: 1 | D30: 20000000 | E30: 42 | F30: 840000000
A31: مجموع | F31: =SUM(F29:F30) -> 2520000000
A32: برآورد هزينه ايمني در كارگاه پروژه مارون3 بنگستان
A33: سنجش و اندازه گیری(2)
A34: رديف | B34: عنوان | C34: تعداد نفرات | D34: بهای انجام آزمايشات براي هر نفر(ريال) | E34: كل زمان پروژه (ماه) | F34: دفعات انجام آزمايشات در كل زمان پروژه | G34: بهاي كل (ريال)
A35: 1 | B35: انجام آزمایشات دوره ای طب صنعتی برای پرسنل آبدارخانه و آشپزخانه | C35: 15 | D35: 1200000 | E35: 42 | F35: 8 | G35: 144000000
A46: سنجش و اندازه گیری(1)
A47: رديف | B47: عنوان | C47: بهای اندازه گیری درهر دوره(ريال) | D47: كل زمان پروژه (سال) | E47: تعداد دفعات اندازه‌گيري در كل زمان پروژه | F47: بهاي كل(ريال)
A48: 1 | B48: اندازه‌گیری آلاینده‌های فیزیکی، شیمیایی وارگونومیکی در محیط کار شامل: | C48: 60000000 | D48: 4 | E48: 4 | F48: 240000000
B49: 1- نور 2- صدا3- هوا 4- ارتعاش5 - استرس گرمایی6 - اشعه X-UV-IR
B50: 7-گردو غبار 8- فیوم جوشکاری9- گازهای خروجی ماشین آلات10- آب آشامیدنی
...

Sheet c.summary1392
B2: جدول تفكيك قيمت بخش اجرايي (C)
B4: ردیف | C4: شرح | G4: Feed | H4: 1392 | I4: 1402 | J4: مابه التفاوت قرارداد جديد و قديم به ريال | K4: افزايش اقلام جديد/ریال | L4: تورم ساليانه /ريال | M4: تغيير احجام/ ریال | N4: ضعف در برآورد اوليه/ریال
G5: ریال | H5: ریال
B6: 1 | C6: تجهيز كارگاه | G6: 5424752834 | H6: 0 | J6: =H6-G6 -> -5424752834 | L6: =0.5*J6 -> -2712376417 | N6: =0.5*J6 -> -2712376417
B7: 2 | C7: برچيدن كارگاه | G7: 957309324 | H7: 0 | J7: =H7-G7 -> -957309324 | L7: =J7 -> -957309324
B8: 3 | C8: تسهيلات رفاهي گروه نظارت ، بازديدهاي داخلي و خارجي ، آموزش پرسنل در داخل | G8: 3021143119 | H8: 0 | J8: =H8-G8 -> -3021143119 | L8: =0.55*J8 -> -1.6616287e+09 | N8: =0.45*J8 -> -1.3595144e+09
B9: 4 | C9: انجام كارهاي اجرايي سيويل | G9: 73807829439 | H9: 306803200000 | J9: =H9-G9 -> 232995370561 | K9: =0.34*J9 -> 7.9218426e+10 | L9: =0.33*J9 -> 7.6888472e+10 | M9: =0.23*J9 -> 5.3588935e+10 | N9: =0.1*J9 -> 2.3299537e+10
B10: 5 | C10: هزينه ايمني در كارگاه | G10: 5555428022 | H10: ='c.cefty.1392'!C8 -> 9250000000 | J10: =H10-G10 -> 3694571978 | L10: =J10 -> 3694571978
B11: 6 | C11: انجام كارهاي اجرايي نصب دستگاه ها | G11: 18894843991 | H11: =G11*2.38 -> 4.4969729e+10 | J11: =H11-G11 -> 2.6074885e+10 | L11: =J11 -> 2.6074885e+10
B12: 7 | C12: انجام كارهاي اجرايي لوله كشي | G12: 18147619049 | H12: =G12*2.38 -> 4.3191333e+10 | J12: =H12-G12 -> 2.5043714e+10 | L12: =J12 -> 2.5043714e+10
B13: 8 | C13: نصب دستگا ههاي ابزار دقيق داخل واحد | G13: 1759824479 | H13: 2365100000 | J13: =H13-G13 -> 605275521 | K13: =0.3*J13 -> 1.8158266e+08 | N13: =0.7*J13 -> 4.2369286e+08
B14: 9 | C14: نصب سيستم كنترل و دستگاه هاي ابزار دقيق داخل اتاق كنترل | G14: 2150896585 | H14: 2320000000 | J14: =H14-G14 -> 169103415 | N14: =J14 -> 169103415
B15: 10 | C15: انجام كارهاي اجرايي برق و مخابرات | G15: 4571016275 | H15: 15873760000 | I15: =H15*Inflation!IRR_Inflation_Factor -> 7.9034505e+11 | J15: =H15-G15 -> 11302743725 | L15: =0.7*J15 -> 7.9119206e+09 | M15: =0.15*J15 -> 1.6954116e+09 | N15: =0.15*J15 -> 1.6954116e+09
B16: 11 | C16: انجام آزمايشات كليه كارهاي اجرايي (مكانيك،برق ،ابزار دقيق ) | G16: 1684354128 | H16: =0.04*(H15+H14+H13+H12+H11) -> 4.3487969e+09 | J16: =H16-G16 -> 2.6644428e+09 | K16: =0.15*J16 -> 3.9966641e+08 | L16: =0.7*J16 -> 1.8651099e+09 | M16: =0.15*J16 -> 3.9966641e+08
B17: 12 | C17: راه اندازي و كاركرد 72 ساعته | G17: 2653941537 | H17: =0.06*(H16+H15+H14+H13+H12+H11) -> 6.7841231e+09 | J17: =H17-G17 -> 4.1301816e+09 | L17: =J17 -> 4.1301816e+09
J18: =H18-G18 -> 0
J19: =H19-G19 -> 0
C20: جمع کل : | G20: =SUM(G6:G19) -> 138628958782 | H20: =SUM(H6:H19) -> 4.3590604e+11 | J20: =H20-G20 -> 2.9727708e+11 | K20: =SUM(K6:K19) -> 7.9799675e+10 | L20: =SUM(L6:L19) -> 1.4027754e+11 | M20: =SUM(M6:M19) -> 5.5684013e+10 | N20: =SUM(N6:N19) -> 2.1515854e+10

Sheet E.p.c summary 1392
B2: خلاصه مالی کل کل پروژه
B4: رديف | C4: بخش | F4: FEED/ یورو | G4: یورو 1392 | H4: FEED / ریال | I4: ریال 1392 | J4: در صد رشد ارزی/یورو | K4: درصد رشد ریالی | M4: برآورد کل اولیه به ریال | N4: برآورد کل جدید به ریال | O4: در صد رشد کل (ارزی + ریالی)
B5: 1 | C5: مجموع بخش E | H5: 12354143525 | I5: =E.1392!L17 -> 26439400000 | J5: 0 | K5: =I5/H5*100-100 -> 114.01241 | M5: =(F5*13700)+H5 -> 12354143525 | N5: =(G5*32160)+I5 -> 26439400000 | O5: =N5/M5*100-100 -> 114.01241
B6: 2 | C6: مجموع بخش P | F6: 10257663 | G6: 17340188 | H6: 162676454707 | I6: =p.summary1392!I10 -> 3.9060675e+11 | J6: =G6/F6*100 -> 169.04619 | K6: =I6/H6*100 -> 240.11265 | M6: =(F6*13700)+H6 -> 303206437807 | N6: =(G6*32160)+I6 -> 9.482672e+11 | O6: =N6/M6*100-100 -> 212.74639
B7: 3 | C7: مجموع بخش C | H7: 138628958782 | I7: ='c.summary1392'!H20 -> 4.3590604e+11 | J7: 0 | K7: =I7/H7*100-100 -> 214.44083 | M7: =(F7*13700)+H7 -> 138628958782 | N7: =(G7*32160)+I7 -> 4.3590604e+11 | O7: =N7/M7*100-100 -> 214.44083
B8: 6 | C8: جمع | F8: =SUM(F5:F7) -> 10257663 | G8: =SUM(G5:G7) -> 17340188 | H8: =SUM(H5:H7) -> 313659557014 | I8: =SUM(I5:I7) -> 8.5295219e+11 | J8: =SUM(J5:J7) -> 169.04619 | K8: =I8/H8*100-100 -> 171.93566 | M8: =(F8*13700)+H8 -> 454189540114 | N8: =(G8*32160)+I8 -> 1.4106126e+12 | O8: =N8/M8*100-100 -> 210.57797
B9: توضیحات :

Sheet Inflation
B2: سال مبنا | C2: تورم ريالي | D2: تورم ارزي
B3: 1392 | C3: 0.37 | D3: 0.02 | F3: یورو به ریال | G3: 2000000
B4: 1393 | C4: 0.156 | D4: 0.02 | F4: یورو به دلار | G4: 1.1
B5: 1394 | C5: 0.119 | D5: 0.02 | F5: درصد هزینه ترخیص | G5: 0.2
B6: 1395 | C6: 0.09 | D6: 0.02 | F6: كتابچه های نهایی و مدارك كالا | G6: 0.03
B7: 1396 | C7: 0.096 | D7: 0.02 | F7: نرخ تسعیر ارز سال 93 | G7: 40530.8
B8: 1397 | C8: 0.312 | D8: 0.02
B9: 1398 | C9: 0.412 | D9: 0.02 | F9: ضریب بالاسری | G9: =G12*G11*G10 -> 1.271325
B10: 1399 | C10: 0.47 | D10: 0.05 | F10: درصد سود پیمانکار EPC | G10: 1.1
B11: 1400 | C11: 0.462 | D11: 0.05 | F11: هزينه هاي عمومي و مديريت پروژه | G11: 1.005
B12: 1401 | C12: 0.465 | D12: 0.049 | F12: ذخیره احتیاطی | G12: 1.15
B13: 1402 | C13: 0.5 | D13: 0.04
B14: 1403 | C14: 0.4 | D14: 0.04
B15: 1404 | C15: 0.6 | D15: 0.04
B16: 1405 | C16: 0.2 | D16: 0.01
C17: =PRODUCT(C3+1,C4+1,C5+1,C6+1,C7+1,C8+1,C9+1,C10+1,C11+1,C12+1,C13+1,C14+1,C15+1,C16+1) -> 49.789404 | D17: =PRODUCT(D3+1,D4+1,D5+1,D6+1,D7+1,D8+1,D9+1,D10+1,D11+1,D12+1,D13+1,D14+1,D15+1,D16+1) -> 1.5093039

Sheet E.1405
B4: جدول تفكيكي خدمات مهندسي (E)
B6: ردیف | C6: شرح | G6: feed | J6: 1392 | M6: 1405
G7: نيروي انساني نفر ساعت | H7: بهاي واحد ريال | I7: بهاي كل | J7: نيروي انساني نفر ساعت | K7: بهاي واحد ريال | L7: بهاي كل | M7: بهای کل
B8: 1 | C8: بازنگري مطالعات مهندسي پايه | G8: 3112 | H8: 280000 | I8: =H8*G8 -> 871360000 | J8: 3112 | K8: 550000 | L8: =K8*J8 -> 1711600000 | M8: =L8*Inflation!IRR_Inflation_Factor -> 8.5219544e+10
B9: 2 | C9: بخش فرآيند و ايمني | G9: 11461 | H9: 250000 | I9: =H9*G9 -> 2865250000 | J9: 11461 | K9: 550000 | L9: =K9*J9 -> 6303550000 | M9: =L9*Inflation!IRR_Inflation_Factor -> 3.1385e+11
B10: 3 | C10: بخش كارهاي سيويل و سازه | G10: 6126 | H10: 250000 | I10: =H10*G10 -> 1531500000 | J10: 6312 | K10: 550000 | L10: =K10*J10 -> 3471600000 | M10: =L10*Inflation!IRR_Inflation_Factor -> 1.7284889e+11
B11: 4 | C11: بخش كارهاي مكانيكال و HVAC | G11: 5704 | H11: 250000 | I11: =H11*G11 -> 1426000000 | J11: 5704 | K11: 550000 | L11: =K11*J11 -> 3137200000 | M11: =L11*Inflation!IRR_Inflation_Factor -> 1.5619932e+11
B12: 5 | C12: بخش كارهاي لوله كشي و خطوط لوله | G12: 5176 | H12: 250000 | I12: =H12*G12 -> 1294000000 | J12: 5176 | K12: 550000 | L12: =K12*J12 -> 2846800000 | M12: =L12*Inflation!IRR_Inflation_Factor -> 1.4174048e+11
B13: 6 | C13: بخش كارهاي برقي و مخابرات | G13: 6760 | H13: 250000 | I13: =H13*G13 -> 1690000000 | J13: 6760 | K13: 550000 | L13: =K13*J13 -> 3718000000 | M13: =L13*Inflation!IRR_Inflation_Factor -> 1.85117e+11
B14: 7 | C14: بخش كارهاي ابزار دقيق | G14: 7183 | H14: 250000 | I14: =H14*G14 -> 1795750000 | J14: 7183 | K14: 550000 | L14: =K14*J14 -> 3950650000 | M14: =L14*Inflation!IRR_Inflation_Factor -> 1.9670051e+11
B15: 8 | C15: ساير هزينه هاي مهندسي | I15: 880283525 | L15: 1300000000 | M15: =L15*Inflation!IRR_Inflation_Factor -> 6.4726225e+10
C16: جمع کل : | G16: =SUM(G8:G15) -> 45522 | I16: =SUM(I8:I15) -> 12354143525 | J16: =SUM(J8:J15) -> 45708 | K16: =SUM(K8:K15) -> 3850000 | L16: =SUM(L8:L15) -> 26439400000 | M16: =M15+M14+M13+M12+M11+M10+M9+M8 -> 1.316402e+12
L18: =L16*Inflation!IRR_Inflation_Factor -> 1.316402e+12

Sheet IN.P&C 1405
B3: برآورد ابزار دقیق بر اساس 1405
B4: رديف | C4: شرح | D4: یورو | E4: ريال
B5: 1 | C5: ادوات ابزار دقیق شامل : ترانسمیترها ، سوئیچ ها ، گیج ها و ... | D5: ='IN.p&C.1392'!E3*Inflation!Euro_Inflation_Factor -> 751633.32 | E5: 0
B6: 2 | C6: شیرآلات ابزار شامل : شیر ON/OFF ، شیرهای کنترلی ، PSV ، PCV | D6: ='IN.p&C.1392'!E4*Inflation!Euro_Inflation_Factor -> 738049.58 | E6: 0
B7: 3 | C7: سيستم كنترل ( DCS )، ESD | D7: ='IN.p&C.1392'!E5*Inflation!Euro_Inflation_Factor -> 1630033.1 | E7: 0
B8: 4 | C8: سیستم F&G | D8: ='IN.p&C.1392'!E6*Inflation!Euro_Inflation_Factor -> 301860.77 | E8: 0
B9: 5 | C9: سیستم CCTV و حفاظت پیرامونی | D9: ='IN.p&C.1392'!E7*Inflation!Euro_Inflation_Factor -> 377325.96 | E9: 0
B10: 6 | C10: اقلام بالک ابزار دقیق | E10: ='IN.p&C.1392'!F8*Inflation!IRR_Inflation_Factor -> 4.5059411e+11
B11: 6 | C11: کابلهای ابزار دقیق و ملحقات شامل : گلند سینی و ... | E11: ='IN.p&C.1392'!F9*Inflation!IRR_Inflation_Factor -> 7.8418311e+11
B12: 7 | C12: نصب دستگاههاي ابزاردقيق داخل واحد | E12: ='IN.p&C.1392'!F10*Inflation!IRR_Inflation_Factor -> 1.1783658e+11
B13: 8 | C13: نصب سيستم كنترل و دستگاههاي ابزاردقيق داخل اتاق كنترل | E13: ='IN.p&C.1392'!F11*Inflation!IRR_Inflation_Factor -> 1.2188366e+11
B14: 10 | C14: جمع كل | D14: =D9+D8+D7+D6+D5 -> 3798902.7 | E14: =E13+E12+E11+E10 -> 1.4744975e+12
E17: اجرای ابزار دقیق ریال | F17: =E13+E12 -> 2.3972025e+11
E18: کالای ریالی | F18: =E11+E10 -> 1.2347772e+12
F19: =F18+F17 -> 1.4744975e+12

Sheet ME.P.1405
B3: جدول تفكيكي تهيه و خريد كالاي مورد نياز پروژه (يورو - ريال )-P- اقلام مکانیکی
B5: ردیف | C5: شرح | G5: 1405
G6: یورو | H6: ریال
B7: 1 | C7: الكترواستاتيك و ادوات مربوطه | G7: ='ME.p.1392'!I6*Inflation!Euro_Inflation_Factor -> 2931783.5 | H7: ='ME.p.1392'!J6*Inflation!IRR_Inflation_Factor -> 1.3960155e+12
B8: 2 | C8: كوره ها و ادوات مربوطه ( نفت و آب) | G8: ='ME.p.1392'!I7*Inflation!Euro_Inflation_Factor -> 1552119.8 | H8: ='ME.p.1392'!J7*Inflation!IRR_Inflation_Factor -> 6.0321658e+11
B9: 3 | C9: مبدل نفت/نفت و مبدل آب/آب | G9: 0 | H9: ='ME.p.1392'!I8*Inflation!Euro_Inflation_Factor*Inflation!G3 -> 7.7605989e+11
B10: 4 | C10: تلمبه ها | G10: ='ME.p.1392'!I9*Inflation!Euro_Inflation_Factor*0.45 -> 1654871.1 | H10: ='ME.p.1392'!J9*Inflation!Euro_Inflation_Factor*Inflation!G3*0.55 -> 5.5824318e+12
B11: 5 | C11: شيرآلات و اتصالات، رنگ ها و لوله هاي داخل سايت و مواد شيميايي | G11: 0 | H11: ='ME.p.1392'!I10*Inflation!Euro_Inflation_Factor*Inflation!G3 -> 8.8857004e+12
B12: 6 | C12: خريد لوله هاي بيرون سايت | G12: 0 | H12: =('ME.p.1392'!J11)+('ME.p.1392'!I11*Inflation!Euro_Inflation_Factor*Inflation!G3) -> 3.9322043e+12
B13: 7 | C13: مخزن هاي اتمسفريك و تحت فشار | G13: 0 | H13: =('ME.p.1392'!J12*Inflation!IRR_Inflation_Factor)+('ME.p.1392'!I12*Inflation!Euro_Inflation_Factor*Inflation!G3) -> 1.6305004e+12
B14: 8 | C14: سیستم پساب ( فیلتر) | G14: 0 | H14: =('ME.p.1392'!I13*Inflation!Euro_Inflation_Factor*Inflation!G3)*0.4 -> 2.3042457e+12
B15: 9 | C15: سیستم پساب ( IGF ) | G15: ='ME.p.1392'!I13*Inflation!Euro_Inflation_Factor*0.6 -> 1728184.3 | H15: 0
B16: 10 | C16: chemical injection and air compressor package | G16: 0 | H16: =('ME.p.1392'!J14*Inflation!IRR_Inflation_Factor)+('ME.p.1392'!I14*Inflation!Euro_Inflation_Factor*Inflation!G3) -> 1.4988889e+12
B17: 11 | C17: Flares | G17: 0 | H17: ='ME.p.1392'!I15*Inflation!Euro_Inflation_Factor*Inflation!G3 -> 5.753255e+11
B18: 12 | C18: Ignitors | G18: 0 | H18: ='ME.p.1392'!I16*Inflation!Euro_Inflation_Factor*Inflation!G3 -> 4.5356392e+11
B19: 13 | C19: Vacum Dearator Package | G19: 0 | H19: ='ME.p.1392'!I17*Inflation!Euro_Inflation_Factor*Inflation!G3 -> 7.8295741e+11
B20: 14 | C20: سيستم HVAC | G20: 0 | H20: ='ME.p.1392'!J18*Inflation!IRR_Inflation_Factor -> 4.1947573e+11
B21: 15 | C21: جرثقيل هاي سقفي | G21: 0 | H21: ='ME.p.1392'!J19*Inflation!IRR_Inflation_Factor -> 3.2363113e+11
B22: 16 | C22: اقلام آزمایشگاه | G22: 0 | H22: =Extra.1405!C7 -> 2.0747762e+12
C23: جمع کل : | G23: =SUM(G7:G22) -> 7866958.7 | H23: =SUM(H7:H22) -> 3.1238993e+13

Sheet EL.P.1405
D4: جدول تفكيكي تهيه و خريد كالاي مورد نياز پروژه (يورو - ريال ) - اقلام برق و مخابرات
D5: ردیف | E5: شرح | I5: برآورد نهایی سال 1405
I6: یورو | J6: ریال
D7: 1 | E7: تابلو ها(نمکزدایی و بهره برداری) | J7: 628485722475
D8: 2 | E8: اتصالات برق( شامل : گلندها‏، شرود ها ،جعبه هاي اتصال ، مفصلها و ...) و تجهیزات Earthing & Lightning | J8: 244000184294
D9: 3 | E9: كابلهاي قدرت | J9: 592730999306
D10: 4 | E10: ترانس های واحد نمکزدایی و بهر برداری،دیزل ژنراتور و دستگاه های شارژر صنعتی،UPS و دیزل ژنراتور | I10: =(450527692324*0.554466129702747)/550000 -> 454186.08 | J10: =450527692324*0.445533870297253 -> 2.0072535e+11
D11: 5 | E11: وسايل و تجهيزات مخابرات و پيجينگ | I11: =(74091374913*0.929198602787513)/550000 -> 125173.82 | J11: =74091374913*0.0708013972124875 -> 5.2457729e+09
D12: 6 | E12: برجهاي روشنايي و پست هاي برق و خط انتقال | J12: 754000000000
D13: 7 | E13: دیزل ژنراتور و سیستم های DC&UPS
D14: 8 | E14: ترا نس های واحد بهره برداری
D15: 9 | E15: تابلوهای واحد بهره برداری
E16: جمع کل : | I16: =SUM(I7:I12) -> 579359.91 | J16: =SUM(J7:J12) -> 2.425188e+12

Sheet CV1405
A1: برگ خلاصه برآورد بخش سيويل
A2: رديف | B2: شـرح | D2: توضیحات | E2: مساحت | F2: مبلغ بدون ضریب(ریال) | G2: ضریب بالاسری | H2: قیمت نهایی(ریال) | I2: قیمت نهایی(ریال) 1405 | K2: قيمت هاي اضافه شده
A3: 1 | B3: CONTROL ROOM BUILDING | D3: 22m*31m | E3: 680 | F3: 7600000000 | G3: 1.3 | H3: =F3*G3 -> 9880000000 | I3: =E3*N33 -> 2.0605034e+11
A4: 2 | B4: WORKSHOP BUILDING | D4: دو طبقه (11m*20m) | E4: 231 | F4: 4756000000 | G4: 1.3 | H4: =F4*G4 -> 6182800000 | I4: =E4*N33 -> 6.9996512e+10 | J4: جديد | K4: 6182800000
A5: 3 | B5: MV-LV SWITCH ROOM | D5: 22m*30m | E5: 660 | F5: 4523000000 | G5: 1.3 | H5: =F5*G5 -> 5879900000 | I5: =E5*N33 -> 1.9999003e+11
A6: 4 | B6: GUARD HOUSE | D6: 14m*7m | E6: 100 | F6: 1251000000 | G6: 1.3 | H6: =F6*G6 -> 1626300000 | I6: =E6*N33 -> 3.030152e+10
A7: 5 | B7: DEAERATED WATER PUMP SHELTER | E7: 279متر مربع | F7: 2100000000 | G7: 1.3 | H7: =F7*G7 -> 2730000000 | I7: =F7*Inflation!IRR_Inflation_Factor*$N$42 -> 1.7033649e+11 | J7: جديد | K7: 2730000000
A8: 6 | B8: CHEMICAL STORAGE | E8: 336متر مربع | F8: 2500000000 | G8: 1.3 | H8: =F8*G8 -> 3250000000 | I8: =F8*Inflation!IRR_Inflation_Factor*$N$42 -> 2.0278154e+11 | J8: 136متر مربع اضافه شده | K8: 1.3154762e+09
A9: 7 | B9: PUMPS SHELTER | E9: 647متر مربع | F9: 4900000000 | G9: 1.3 | H9: =F9*G9 -> 6370000000 | I9: =F9*Inflation!IRR_Inflation_Factor*$N$42 -> 3.9745181e+11 | J9: 487مترمربع اضافه شده | K9: 4.7947295e+09
A10: 8 | B10: CHEMICAL INJECTION PACKAGE | E10: 223متر مربع | F10: 1700000000 | G10: 1.3 | H10: =F10*G10 -> 2210000000 | I10: =F10*Inflation!IRR_Inflation_Factor*$N$42 -> 1.3789145e+11 | J10: 63متر مربع اضافه شده | K10: 6.2434978e+08
A11: 9 | B11: EMERGENCY GENERATOR & AIR COMPRESSOR ROOM | E11: 208متر مربع | F11: 1500000000 | G11: 1.3 | H11: =F11*G11 -> 1950000000 | I11: =F11*Inflation!IRR_Inflation_Factor*$N$42 -> 1.2166892e+11 | J11: 48مترمربع اضافه شده | K11: 450000000
A12: 10 | B12: FIRE EXTINGUISHER SHELTER | E12: 16متر مربع | F12: 170000000 | G12: 1.3 | H12: =F12*G12 -> 221000000 | I12: =F12*Inflation!IRR_Inflation_Factor*$N$42 -> 1.3789145e+10
A13: 11 | B13: FIRE WATER PUMPS SHELTER | E13: 344متر مربع | F13: 1900000000 | G13: 1.3 | H13: =F13*G13 -> 2470000000 | I13: =F13*Inflation!IRR_Inflation_Factor*$N$42 -> 1.5411397e+11 | J13: جديد | K13: 2470000000
A14: 12 | B14: PARKING SHELTER | E14: 214متر مربع | F14: 1000000000 | G14: 1.3 | H14: =F14*G14 -> 1300000000 | I14: =F14*Inflation!IRR_Inflation_Factor*$N$42 -> 8.1112615e+10
A15: 13 | B15: جمع آوري و بسترسازي حوضچه هاي موجود | D15: 300m*150m | E15: 45000متر مربع | F15: 37524000000 | G15: 1.3 | H15: =F15*G15 -> 48781200000 | I15: =F15*Inflation!IRR_Inflation_Factor*$N$42 -> 3.0436698e+12 | J15: جديد | K15: 48781200000
A16: 14 | B16: EVAPORATION POUND | D16: 125m*175m | E16: 22000متر مربع | F16: 16788000000 | G16: 1.3 | H16: =F16*G16 -> 21824400000 | I16: =F16*Inflation!IRR_Inflation_Factor*$N$42 -> 1.3617186e+12
A17: 15 | B17: EVAPORATION POUND | D17: 90m*90m & 80m*70m | E17: 14000متر مربع | F17: 14817000000 | G17: 1.3 | H17: =F17*G17 -> 19262100000 | I17: =F17*Inflation!IRR_Inflation_Factor*$N$42 -> 1.2018456e+12 | J17: جديد | K17: 19262100000
A18: 16 | B18: FENCE | D18: حدود سه کیلومتر | F18: 6354000000 | G18: 1.3 | H18: =F18*G18 -> 8260200000 | I18: =F18*Inflation!IRR_Inflation_Factor*$N$42 -> 5.1538956e+11
A19: 17 | B19: عملیات خاکی سایت | D19: 280m*220m | E19: 62000متر مربع | F19: 42631000000 | G19: 1.3 | H19: =F19*G19 -> 55420300000 | I19: =F19*Inflation!IRR_Inflation_Factor*$N$42 -> 3.4579119e+12 | J19: 60%اضافه شده | K19: 33252180000
A20: 18 | B20: احداث جاده با بلوار وسط یک متری | D20: 2500متر | F20: 13870000000 | G20: 1.3 | H20: =F20*G20 -> 18031000000 | I20: =F20*Inflation!IRR_Inflation_Factor*$N$42 -> 1.125032e+12 | J20: 50%اضافه شده | K20: 9015500000
A21: 19 | B21: فونداسیون دکل برق | D21: 25عدد | E21: 5كيلومتر | F21: =230000000*25 -> 5750000000 | G21: 1.3 | H21: =F21*G21 -> 7475000000 | I21: =F21*Inflation!IRR_Inflation_Factor*$N$42 -> 4.6639754e+11 | J21: 60%اضافه شده | K21: 4485000000
A22: 20 | B22: خريد و نصب سيستم بسته تصفيه فاضلاب | D22: 15مترمكعب در روز | E22: مقطوع | F22: 1800000000 | G22: 1 | H22: =F22*G22 -> 1800000000 | I22: =F22*Inflation!IRR_Inflation_Factor*$N$42 -> 1.4600271e+11 | J22: جديد | K22: 1800000000
A23: 21 | B23: عملیات خاکی Hot,cold Flare ,burn pit | D23: 60m*60m | E23: 3عدد | F23: 8543000000 | G23: 1.3 | H23: =F23*G23 -> 11105900000 | I23: =F23*Inflation!IRR_Inflation_Factor*$N$42 -> 6.9294507e+11 | J23: مجموع | K23: =SUM(K3:K22) -> 1.3516334e+11
A24: 22 | B24: HC CLOSE DRAIN | D24: 15m*15m | E24: 225متر مربع | F24: 2582000000 | G24: 1.3 | H24: =F24*G24 -> 3356600000 | I24: =F24*Inflation!IRR_Inflation_Factor*$N$42 -> 2.0943277e+11 | M24: جدول ضرائب برای ساختمان ها
A25: 23 | B25: کالورتها | D25: ده عدد | F25: 720000000 | G25: 1.3 | H25: =F25*G25 -> 936000000 | I25: =F25*Inflation!IRR_Inflation_Factor*$N$42 -> 5.8401083e+10 | M25: تعدیل | N25: 1.06
A26: 24 | B26: پل باکس بتنی | D26: هشت عدد با دهانه 7متری | F26: 1400000000 | G26: 1.3 | H26: =F26*G26 -> 1820000000 | I26: =F26*Inflation!IRR_Inflation_Factor*$N$42 -> 1.1355766e+11 | M26: منطقه ای مارون | N26: 1.09
A27: 25 | B27: آسفالت دور تا دور سایت | D27: 1800متر | F27: 7000000000 | G27: 1.3 | H27: =F27*G27 -> 9100000000 | I27: =F27*Inflation!IRR_Inflation_Factor*$N$42 -> 5.6778831e+11 | M27: بالاسری | N27: 1.41
A28: 26 | B28: ترنچ با درپوش بتنی | D28: دویست متر | F28: 1250000000 | G28: 1.3 | H28: =F28*G28 -> 1625000000 | I28: =F28*Inflation!IRR_Inflation_Factor*$N$42 -> 1.0139077e+11 | M28: تجهیز کارگاه | N28: 1
A29: 27 | B29: کانال آبهای سطحی | D29: دویست متر | F29: 1000000000 | G29: 1.3 | H29: =F29*G29 -> 1300000000 | I29: =F29*Inflation!IRR_Inflation_Factor*$N$42 -> 8.1112615e+10 | M29: بروز رسانی | N29: 1
A30: 28 | B30: OILY WTER SEPARATOR | D30: 12m*6m | E30: 75متر مربع | F30: 500000000 | G30: 1.3 | H30: =F30*G30 -> 650000000 | I30: =F30*Inflation!IRR_Inflation_Factor*$N$42 -> 4.0556308e+10 | M30: ضريب تطبيق | N30: 2
A31: 29 | B31: MANHOLE | D31: بیست عدد | F31: =20*50000000 -> 1000000000 | G31: 1.3 | H31: =F31*G31 -> 1300000000 | I31: =F31*Inflation!IRR_Inflation_Factor*$N$42 -> 8.1112615e+10 | M31: کل ضرائب | N31: =N25*N26*N27*N28*N29*N30 -> 3.258228
A32: 30 | B32: PIPE TRACK | D32: 450m | F32: 1335000000 | G32: 1.3 | H32: =F32*G32 -> 1735500000 | I32: =F32*Inflation!IRR_Inflation_Factor*$N$42 -> 1.0828534e+11 | M32: قیمت واحد 1402 نظام مهندسی | N32: 93000000
A33: 31 | B33: جدول کاری | D33: هزار متر دو ردیف | F33: 1400000000 | G33: 1.3 | H33: =F33*G33 -> 1820000000 | I33: =F33*Inflation!IRR_Inflation_Factor*$N$42 -> 1.1355766e+11 | M33: قیمت واحد جدید | N33: =N32*N31 -> 3.030152e+08
A34: 32 | B34: ساپورت اچ خط لوله 6 اینچ آب | D34: 3500متر | F34: 450000000 | G34: 1.3 | H34: =F34*G34 -> 585000000 | I34: =F34*Inflation!IRR_Inflation_Factor*$N$42 -> 3.6500677e+10
A35: 33 | B35: فونداسیون مخزن | E35: 5عدد | F35: 2400000000 | G35: 1.3 | H35: =F35*G35 -> 3120000000 | I35: =F35*Inflation!IRR_Inflation_Factor*$N$42 -> 1.9467028e+11 | M35: جدول ضرائب برای کارهای غیر ساختمانی
A36: 34 | B36: شن ریزی سایت به ضخامت 10 سانتیمتر | D36: 280m*220m | E36: 660متر مربع | F36: 550000000 | G36: 1.3 | H36: =F36*G36 -> 715000000 | I36: =F36*Inflation!IRR_Inflation_Factor*$N$42 -> 4.4611938e+10 | M36: تعدیل | N36: 1.06
A37: 35 | B37: مسیر خط لوله RTP | D37: 8 km | F37: 1800000000 | G37: 1.3 | H37: =F37*G37 -> 2340000000 | I37: =F37*Inflation!IRR_Inflation_Factor*$N$42 -> 1.4600271e+11 | M37: منطقه ای مارون | N37: 1.09
A38: 36 | B38: فونداسیون روشنایی جاده | D38: 50عدد | F38: 1000000000 | G38: 1.3 | H38: =F38*G38 -> 1300000000 | I38: =F38*Inflation!IRR_Inflation_Factor*$N$42 -> 8.1112615e+10 | M38: بالاسری | N38: 1.41
A39: 37 | B39: عملیات اجرایی در واحد بهره برداری | F39: 13900000000 | G39: 1.3 | H39: =F39*G39 -> 18070000000 | I39: =F39*Inflation!IRR_Inflation_Factor*$N$42 -> 1.1274653e+12 | M39: تجهیز کارگاه | N39: 1
A40: 38 | B40: خريد و نصب پكيج تصفيه آب آشاميدني | D40: ظرفيت 5ليتر در دقيقه | E40: مقطوع | F40: 200000000 | G40: 1 | H40: =F40*G40 -> 200000000 | I40: =F40*Inflation!IRR_Inflation_Factor*$N$42 -> 1.6222523e+10 | M40: بروز رسانی | N40: 1
...

Sheet Sheet1

Sheet Extra.1405
B1: کلیه نرخ ها در این بخش 1405 میباشند .
B2: موارد جدید | C2: تخمین ریالی | D2: ارزی | F2: خدمات فنی سازندگان در دوران نصب و راه اندازی | O2: «خلاصه مالی دفترچه ها» | U2: برآورد هزينه | V2: منشا هزينه | W2: رديف
B3: ساخت گودال محل جمع آوری و حوضچه های تبخیر | C3: =Extra.1405!R8 -> 78142886019 | D3: 0 | F3: پکیج | G3: نفر روز | H3: نرخ نفر روز | K3: شماره پیمان: | O3: نام دستگاه اجرایی: | S3: کد مدرک: | U3: 79052570000 | V3: A1 خدمات كارشناسي مشاور | W3: 1
B4: استحکام سازی زمین به جهت ناپایداری به طریق شمع کوبی | C4: 500000000000 | D4: 0 | K4: پروژه: پروژه گودال نمک مارون3 | O4: نام مهندس مشاور: | S4: تاریخ: 1402/05/16 | U4: 11737000000 | V4: A2 خدمات جنبي مطالعات(نقشه برداري، توپوگرافي و اقلام تحويل شدني) | W4: 2
B5: ساخت ، تجهیز و نگهداری کمپ استراحتگاه کارفرما | C5: 644374000000 | D5: 0 | E5: دربرآورد نهایی لحاظ شده. | F5: دیسالتر | G5: 5 | H5: 300 | I5: =G5*H5 -> 1500 | K5: وضعیت: مبالغ دفترچه ها | O5: تجهیز به روش: درصدی از مبلغ باضرایب | S5: نوع ضریب: خالص | U5: 5489770000 | V5: D هزينه هاي مستثني از ارزيابي مالي مشاور(بليت، اياب و ذهاب، اقامت، پذيرايي، پذیرایی كارفرما) | W5: 3
B6: کمبود برآورد راه اندازی و تست 72 ساعته | C6: =('c.summary1405'!L5+'c.summary1405'!L6+'c.summary1405'!L7+'c.summary1405'!L8+'c.summary1405'!L9)*0.025 -> 8.1825677e+11 | U6: =SUM(U3:U5) -> 96279340000
B7: خرید اقلام آزمایشگاه | C7: =('p.lab.1392'!G32*Inflation!IRR_Inflation_Factor)+('p.lab.1392'!H32*Inflation!Euro_Inflation_Factor*Inflation!G3) -> 2.0747762e+12 | D7: 0 | F7: پکیج تزریق | G7: 3 | H7: 300 | I7: =G7*H7 -> 900 | K7: ردیف | L7: عنوان دفترچه | M7: فهرست بها | N7: ستاره دار | O7: جمع برآوردی | P7: درصدی | Q7: تجهیزباضرایب | R7: جمع برآوردی کل | S7: اقلام فاکتوری
B8: اجرای بخش ابزاردقیق (کمبودهای برآورد اولیه) | C8: =91599188310*0.8*1.058 -> 7.7529553e+10 | D8: 0 | E8: در بخش C لحاظ شده. | K8: 1 | L8: ابنیه | M8: 73617195320 | N8: 0 | O8: 73617195320 | P8: 0.04 | Q8: 4.5256907e+09 | R8: 78142886019 | S8: 0
B9: کالای بخش ابزاردقیق (کمبودهای برآورد اولیه) | C9: 0 | D9: 972724 | E9: در بخش P لحاظ شده.
B10: کالای بخش مكانيك (کمبودهای برآورد اولیه) | C10: =('ME.p.1392'!J20*Inflation!IRR_Inflation_Factor*0.3)+('ME.p.1392'!I20*Inflation!Euro_Inflation_Factor*Inflation!G3*0.1) -> 5.3119618e+12 | D10: 0
B11: اجرای بخش مكانيك (کمبودهای برآورد اولیه) | C11: =('c.summary1392'!H12+'c.summary1392'!H11)*0.1*Inflation!IRR_Inflation_Factor -> 4.3894867e+11
B12: هزینه رفع کمبودهای مهندسی پایه | C12: =U6 -> 96279340000 | D12: 0
B13: مجموع | C13: =SUM(C3:C12) -> 1.0040269e+13 | D13: =SUM(D3:D12) -> 972724 | F13: کمپرسور | G13: 3 | H13: 300 | I13: =G13*H13 -> 900
C14: 0 | D14: 0 | E14: در بخش C لحاظ شده. | F14: تابلو برق | G14: 10 | H14: 300 | I14: =G14*H14 -> 3000
C15: 0 | D15: 0 | E15: در بخشEلحاظ شده. | F15: ترانش و دیزل و یوپی اس | G15: 5 | H15: 300 | I15: =G15*H15 -> 1500
C16: 0 | D16: 0 | E16: در بخش P لحاظ شده. | F16: تابلو کنترل | G16: 15 | H16: 300 | I16: =G16*H16 -> 4500
B17: جمع کل | C17: =C16+C15+C14 -> 0 | D17: 0 | F17: شیر ابزرا دقیق | G17: 3 | H17: 300 | I17: =G17*H17 -> 900
B18: خدمات فنی سازندگان | C18: =I18*Inflation!G3 -> 26400000000 | E18: در برآورد نهای لحاظ شده. | F18: مجموع | G18: =SUM(G5:G17) -> 44 | H18: 300 | I18: =SUM(I5:I17) -> 13200

Sheet c.summary1405
B2: شرح | F2: 1405
F3: ریال
B4: تجهيز كارگاه و برچیدن کارگاه | F4: =(F7+F8+F9+F10+F11+F12+F13+F14+F15)*0.05 -> 1.2325193e+12 | H4: اجرای پروژه مارون 3 بنگستان 1405
B5: تسهيلات رفاهي کارفرما | F5: 571426000000 | H5: 1 | I5: سویل و معماری | L5: =(F7+Extra.1405!C3+Extra.1405!C4)*Inflation!G9 -> 2.3893438e+13
B6: ساخت و تجهیز و نگهداری کمپ کارفرما | F6: =Extra.1405!C5 -> 644374000000 | H6: 1 | I6: مکانیک | L6: =(F8+F9+F10+Extra.1405!C11)*Inflation!G9 -> 6.7240219e+12
B7: انجام كارهاي اجرايي سيويل | F7: ='CV1405'!I45 -> 18215980092146 | H7: 2 | I7: برق ومخابرات | L7: =F13*Inflation!G9 -> 1.0047854e+12
B8: هزينه ايمني در كارگاه | F8: ='c.summary1392'!H10*Inflation!IRR_Inflation_Factor -> 4.6055199e+11 | H8: 3 | I8: ابزاردقیق | L8: =(F11+F12+Extra.1405!C8)*Inflation!G9 -> 4.033276e+11
B9: انجام كارهاي اجرايي نصب دستگاه ها | F9: ='c.summary1392'!H11*Inflation!IRR_Inflation_Factor -> 2.239016e+12 | H9: 4 | I9: تست و راه اندازی | L9: =(F14+F15)*Inflation!G9 -> 7.0469729e+11
B10: انجام كارهاي اجرايي لوله كشي | F10: ='c.summary1392'!H12*Inflation!IRR_Inflation_Factor -> 2.1504707e+12 | H10: 5 | I10: تسهیلات رفاهی کارفرما | L10: =F5*Inflation!G9 -> 7.2646816e+11
B11: نصب دستگا ههاي ابزار دقيق داخل واحد | F11: ='IN.P&C 1405'!E12 -> 1.1783658e+11 | H11: 6 | I11: ساخت و نگهداری کمپ کارفرما | L11: =F6*Inflation!G9 -> 8.1920878e+11
B12: نصب سيستم كنترل و دستگاه هاي ابزار دقيق داخل اتاق كنترل | F12: ='IN.P&C 1405'!E13 -> 1.2188366e+11 | H12: 7 | I12: تجهیز کارگاه پیمانکار | L12: =(L9+L8+L7+L6+L5)*0.05 -> 1.6365135e+12
B13: انجام كارهاي اجرايي برق و مخابرات | F13: ='c.summary1392'!H15*Inflation!IRR_Inflation_Factor -> 7.9034505e+11 | H13: 8 | I13: برچیدن کارگاه پیمانکار | L13: =(L9+L8+L7+L6+L5)*0.025 -> 8.1825677e+11
B14: انجام آزمايشات كليه كارهاي اجرايي (مكانيك،برق ،ابزار دقيق ) | F14: ='c.summary1392'!H16*Inflation!IRR_Inflation_Factor -> 2.16524e+11 | H14: 9 | I14: جمع | L14: =L13+L12+L11+L10+L9+L8+L7+L6+L5 -> 3.6730718e+13
B15: راه اندازي و كاركرد 72 ساعته | F15: ='c.summary1392'!H17*Inflation!IRR_Inflation_Factor -> 3.3777745e+11
B16: جمع کل : | F16: =F15+F14+F13+F12+F11+F10+F9+F8+F7+F6+F5+F4 -> 2.7098705e+13 | O16: =L13+L12+L9+L8+L7+L6+L5+L11+L10 -> 3.6730718e+13

Sheet p.summary1405
B2: کالای پروژه مارون 3 بنگستان 1405
B3: رديف | C3: بخش | F3: ریال | H3: یورو
B4: 1 | C4: مکانیک | F4: ='ME.P.1405'!H23+Extra.1405!C10 -> 3.6550955e+13 | H4: ='ME.P.1405'!G23*Inflation!G9 -> 10001461
B5: 2 | C5: برق ومخابرات | F5: ='EL.P.1405'!J16 -> 2.425188e+12 | H5: ='EL.P.1405'!I16*Inflation!G9 -> 736554.73
