Workbook

Sheet ماشین_حساب
B1: ماشین‌حساب قیمت پمپ — انتقال قیمت قدیم به سال هدف
B2: فقط خانه‌های زرد را پر کنید. بقیه خودکار محاسبه می‌شود. روش: تبدیل به یورو ← تعدیل با شاخص قیمت پمپ (PPI) ← کف قیمت پمپ API ← تبدیل با نرخ یوروی سال هدف.
B4: الف) ورودی‌ها
B5: ورودی | D5: مقدار | F5: راهنما
B6: نوع پمپ | D6: گریز از مرکز API 610 | F6: از لیست انتخاب کنید. کف قیمت فقط به «گریز از مرکز API 610» با کلاس S یا D اعمال می‌شود.
B7: کلاس مواد API 610 | D7: D2 | F7: از دیتاشیت (مثلاً S6، D1، I2). اگر نمی‌دانید «نامشخص».
B8: قیمت واحد پایه | D8: 260000 | F8: قیمت یک دستگاه در منبع قدیمی، به همان ارزی که در منبع آمده.
B9: ارز قیمت پایه | D9: EUR | F9: EUR / USD / IRR
B10: سال پایه (شمسی) | D10: 1393 | F10: سال تاریخ قیمت/استعلام منبع (نه سال انتشار گزارش).
B11: نرخ تسعیر منبع (ریال به ازای یورو) — اختیاری | F11: فقط برای قیمت ریالی. اگر منبع ریال را از یورو ساخته، همان نرخ را بنویسید (گچساران ۴ = ۴۵۵٬۶۹۲؛ پازنان ۱۴۰۴ = ۶۹۵٬۲۹۹). خالی = نرخ جدول Indices.
B12: سال هدف (شمسی) | D12: 1405 | F12: سالی که قیمت را برای آن می‌خواهید.
B13: نرخ یورو هدف (ریال) — اختیاری | F13: خالی = نرخ سال هدف در Indices. برای نرخ روز یا مرکز مبادله اینجا بنویسید.
B14: تعداد | D14: 2 | F14: تعداد دستگاه (مثلاً A/B = ۲).
B15: هزینه گمرک/حمل/ترخیص (٪ از قیمت) | D15: 0 | F15: برای کالای وارداتی؛ برای ساخت داخل صفر. مثال: CSV پمپ‌ها ۶٪.
B16: اعمال کف قیمت | D16: خودکار | F16: خودکار = طبق نوع و کلاس؛ یا اجباری بله/خیر.
B18: ب) مراحل محاسبه (خودکار)
B19: مرحله | D19: مقدار | F19: توضیح
B20: ۱. نرخ تبدیل ارز پایه به یورو | D20: =IF(D9="EUR",1,IF(D9="USD",INDEX(Indices!$E$51:$E$71,MATCH(D10,Indices!$A$51:$A$71,0)),IF(D11<>"",D11,INDEX(Indices!$G$51:$G$71,MATCH(D10,Indices!$A$51:$A$71,0))))) -> 1 | F20: یورو=۱؛ دلار=نرخ یورو/دلار سال پایه؛ ریال=نرخ تسعیر منبع یا نرخ سال پایه
B21: ۲. قیمت پایه به یورو | D21: =D8/D20 -> 260000 | F21: لنگر یورویی قیمت
B22: ۳. شاخص قیمت پمپ در سال پایه | D22: =INDEX(Indices!$C$51:$C$71,MATCH(D10,Indices!$A$51:$A$71,0)) -> 91.347 | F22: Eurostat C28.13 (۲۰۲۱=۱۰۰)
B23: ۴. شاخص قیمت پمپ در سال هدف | D23: =INDEX(Indices!$C$51:$C$71,MATCH(D12,Indices!$A$51:$A$71,0)) -> 125.8845 | F23: برای ۱۴۰۵ به بعد پیش‌بینی است
B24: ۵. ضریب تعدیل یورویی | D24: =D23/D22 -> 1.3780913 | F24: رشد قیمت پمپ به یورو بین دو سال
B25: ۶. قیمت یورویی تعدیل‌شده | D25: =D21*D24 -> 358303.73
B26: ۷. مشمول کف قیمت؟ | D26: =IF(D16="بله","بله",IF(D16="خیر","خیر",IF(AND(D6="گریز از مرکز API 610",OR(LEFT(D7,1)="S",LEFT(D7,1)="D")),"بله","خیر"))) -> بله | F26: پمپ کوچک API بازار امروز ارزان‌تر از این حد ندارد
B27: ۸. کف قیمت در سال هدف (یورو) | D27: =Val_EUR_Pumps!$E$16*D23/INDEX(Indices!$C$51:$C$71,MATCH(1404,Indices!$A$51:$A$71,0)) -> 25500 | F27: ۲۵٬۰۰۰ یورو در سطح ۱۴۰۴ × رشد شاخص
B28: ۹. قیمت یورویی نهایی (واحد) | D28: =IF(D26="بله",MAX(D25,D27),D25) -> 358303.73
B29: ۱۰. نرخ یورو سال هدف (ریال) | D29: =IF(D13<>"",D13,INDEX(Indices!$G$51:$G$71,MATCH(D12,Indices!$A$51:$A$71,0))) -> 2875000 | F29: دستی یا از Indices
B30: ۱۱. قیمت ریالی واحد (بدون گمرک) | D30: =D28*D29 -> 1.0301232e+12
B31: ۱۲. گمرک/حمل/ترخیص (ریال، واحد) | D31: =D30*D15 -> 0
B33: ج) نتیجه
B34: قیمت واحد (ریال) | D34: =D30+D31 -> 1.0301232e+12
B35: قیمت کل (ریال) | D35: =D34*D14 -> 2.0602465e+12
B36: قیمت کل (تومان) | D36: =D35/10 -> 2.0602465e+11
B37: قیمت کل (یورو) | D37: =D28*(1+D15)*D14 -> 716607.46
B38: قیمت کل (دلار) | D38: =D37*INDEX(Indices!$E$51:$E$71,MATCH(D12,Indices!$A$51:$A$71,0)) -> 824098.58
B40: هشدار: | D40: =IF(D10>D12,"سال پایه بعد از سال هدف است. ","")&IF(D6="آتش‌نشانی","پمپ آتش‌نشانی: دامنه کار (پمپ تنها یا پکیج NFPA 20) را مشخص کنید؛ پراکندگی استعلام‌ها بسیار زیاد است. ","")&IF(D6="پکیج تزریق مواد","پکیج تزریق: روش روی ۱۱ پکیج پازنان آزموده شده (خطای حدود ±۱۰٪). ","")&IF(D12>=1405,"شاخص پمپ برای ۱۴۰۵ پیش‌بینی است (رشد در Indices!C4). ","")&IF(AND(D9="IRR",D11=""),"قیمت ریالی بدون نرخ تسعیر منبع: نرخ تقریبی Indices استفاده شد. ","") -> شاخص پمپ برای ۱۴۰۵ پیش‌بینی است (رشد در Indices!C4).
B43: د) محاسبه چندقلمی (سال هدف، نرخ یورو هدف و درصد گمرک از بخش الف خوانده می‌شوند)
B44: Tag/شرح | C44: نوع پمپ | D44: کلاس | E44: قیمت واحد پایه | F44: ارز | G44: سال پایه | H44: نرخ تسعیر منبع (اختیاری) | I44: تعداد | J44: کف قیمت | K44: یورو پایه | L44: ضریب PPI | M44: یورو نهایی (واحد) | N44: ریال واحد | O44: ریال کل
B45: KPL P-111 A/B/C | C45: گریز از مرکز API 610 | D45: D1 | E45: 55000 | F45: EUR | G45: 1394 | I45: 3 | J45: خودکار | K45: =IF(E45="","",E45/IF(F45="EUR",1,IF(F45="USD",INDEX(Indices!$E$51:$E$71,MATCH(G45,Indices!$A$51:$A$71,0)),IF(H45<>"",H45,INDEX(Indices!$G$51:$G$71,MATCH(G45,Indices!$A$51:$A$71,0)))))) -> 55000 | L45: =IF(E45="","",INDEX(Indices!$C$51:$C$71,MATCH($D$12,Indices!$A$51:$A$71,0))/INDEX(Indices!$C$51:$C$71,MATCH(G45,Indices!$A$51:$A$71,0))) -> 1.3676112 | M45: =IF(E45="","",IF(OR(J45="بله",AND(J45<>"خیر",C45="گریز از مرکز API 610",OR(LEFT(D45,1)="S",LEFT(D45,1)="D"))),MAX(K45*L45,$D$27),K45*L45)) -> 75218.613 | N45: =IF(E45="","",M45*$D$29*(1+$D$15)) -> 2.1625351e+11 | O45: =IF(E45="","",N45*I45) -> 6.4876054e+11
B46: Gachsaran P-103 | C46: گریز از مرکز API 610 | D46: S6 | E46: 13215061212 | F46: IRR | G46: 1402 | H46: 455692 | I46: 1 | J46: خودکار | K46: =IF(E46="","",E46/IF(F46="EUR",1,IF(F46="USD",INDEX(Indices!$E$51:$E$71,MATCH(G46,Indices!$A$51:$A$71,0)),IF(H46<>"",H46,INDEX(Indices!$G$51:$G$71,MATCH(G46,Indices!$A$51:$A$71,0)))))) -> 28999.985 | L46: =IF(E46="","",INDEX(Indices!$C$51:$C$71,MATCH($D$12,Indices!$A$51:$A$71,0))/INDEX(Indices!$C$51:$C$71,MATCH(G46,Indices!$A$51:$A$71,0))) -> 1.0556264 | M46: =IF(E46="","",IF(OR(J46="بله",AND(J46<>"خیر",C46="گریز از مرکز API 610",OR(LEFT(D46,1)="S",LEFT(D46,1)="D"))),MAX(K46*L46,$D$27),K46*L46)) -> 30613.15 | N46: =IF(E46="","",M46*$D$29*(1+$D$15)) -> 8.8012806e+10 | O46: =IF(E46="","",N46*I46) -> 8.8012806e+10
...

Sheet راهنما
A1: راهنمای فایل: هر شیت چه می‌کند و هر نرخ به چه کار می‌آید
A3: ترتیب استفاده
A5: شیت‌ها
A6: ماشین_حساب | B6: محاسبه قیمت یک پمپ (با نمایش گام‌به‌گام) و جدول ۲۰ قلمی. ورودی‌ها زرد، نتیجه سبز.
A7: Summary | B7: جدول مقایسه ۷ روش تعدیل روی پمپ‌های یورویی و ۴ روش روی پکیج‌های ریالی، روش پیشنهادی، محدودیت‌ها و جمع بانک پمپ ۱۴۰۵. همه اعداد فرمول و متصل به شیت‌های دیگرند.
A8: Indices | B8: تنها محل نرخ‌ها و شاخص‌ها. جدول ۱: شاخص قیمت پمپ اروپا و آمریکا (میلادی). جدول ۲: سبد فلزی پمپ. جدول ۳: سری شمسی (شاخص پمپ شمسی، دلار، یورو/دلار، نرخ یورو، تورم ریالی و ارزی). تغییر هر عدد اینجا همه فایل را به‌روز می‌کند.
A9: Val_EUR_Pumps | B9: آزمون اصلی: ۱۸ پمپ پازنان ۲ با قیمت ۱۳۹۳ و استعلام واقعی ۱۴۰۴ (آریا سپهر کیهان، پمپیران، کالای پمپ). برای هر روش: پیش‌بینی، نسبت پیش‌بینی/واقعی و خطای مطلق؛ پایین شیت آمار خطا. ستون «در آمار؟» پمپ‌های آتش‌نشانی را کنار می‌گذارد؛ ستون «مشمول کف؟» تعیین می‌کند کف قیمت اعمال شود یا نه.
A10: Val_IRR_Packages | B10: آزمون مسیر ریالی: ۱۱ پکیج تزریق پازنان (قیمت ریالی ۱۳۹۳). مقایسه CPI، ضریب پازنان، مدل فعلی شما و روش پیشنهادی با استعلام ریالی واقعی و میانگین همه استعلام‌ها. پایین شیت: نرخ دلاری که روش پیشنهادی را دقیقاً منطبق می‌کند (آزمون حساسیت).
A11: Drivers | B11: تفکیک اثر عوامل ۱۳۹۳ تا ۱۴۰۳: نرخ یورو، PPI پمپ، CPI، فلزات؛ و جدول/نمودار سالانه «شاخص ریالی پمپ» در برابر CPI.
A12: Pump_Bank_Escalated | B12: ۱۱۱ ردیف پمپ مدل شما (KPL، پازنان، گچساران، CSV) با روش پیشنهادی به سال هدف (D3) + ستون مقایسه با خروجی مدل فعلی. سطرهای اشتباه‌طبقه‌بندی‌شده (جرثقیل، فیلتر، IGF، مخزن) حذف شده‌اند.
A13: Model_Issues | B13: ۱۰ ایراد یافت‌شده در مدل فعلی با محل، اثر و اصلاح.
A14: Sources | B14: لینک منابع شاخص‌ها و نرخ‌ها و فایل‌های مرجع.
A15: نرخ‌ها و ضرایب: چه هستند و چرا
A16: شاخص PPI پمپ اروپا (Eurostat C28.13) | B16: شاخص رسمی قیمت تولیدکننده پمپ و کمپرسور در منطقه یورو. موتور اصلی تعدیل است چون استعلام‌ها (حتی سازنده داخلی) به یورو داده می‌شوند. ۱۳۹۳→۱۴۰۴ ≈ ۱٫۳۵ برابر. اثر فولاد، نیکل، مس، دستمزد و انرژی سازنده داخلش هست.
A17: سهم سال شمسی (۰٫۷۹) | B17: تبدیل شاخص میلادی به شمسی: سال شمسی Y حدود ۹٫۵ ماه در سال میلادی Y+621 است. شاخص شمسی = ۰٫۷۹×میلادی(Y+621) + ۰٫۲۱×میلادی(Y+622).
A18: رشد پیش‌بینی (۲٪) و روش «فلزی» | B18: برای سال‌هایی که شاخص رسمی هنوز منتشر نشده (۲۰۲۶ به بعد). «روند» = ۲٪ ثابت؛ «فلزی» = ترکیب ۷۰٪ روند + ۳۰٪ تغییر سبد فلزی. فلزات فقط همین‌جا وارد می‌شوند تا دوباره‌شماری نشود.
A19: سبد فلزی پمپ (فولاد ۶۰٪، مس ۲۵٪، نیکل ۱۲٪، مولیبدن ۳٪) | B19: برای nowcast و تحلیل حساسیت. نشان می‌دهد اثر مستقیم فلزات در ۱۰ سال فقط حدود ۵٪ قیمت بوده است.
A20: PPI پمپ آمریکا (BLS) | B20: فقط برای مقایسه (روش M5). چون قیمت‌ها به یورو است، شاخص اروپا مبناست.
A21: دلار آزاد و یورو/دلار (Indices ستون D و E) | B21: برای تبدیل قیمت ریالی و دلاری به یورو در سال پایه و برگرداندن یورو به ریال در سال هدف. از Params مدل شما آمده و تخمینی است؛ ۱۴۰۵ = ۲٬۵۰۰٬۰۰۰ (عدد خودتان).
A22: نرخ یورو جایگزین ۱۳۹۳ = ۴۰٬۵۳۱ | B22: از شیت Inflation مارون ۳. همان نرخی است که قیمت‌های ریالی آن دوره با آن ساخته شده‌اند، پس برای برگرداندن آن‌ها به یورو درست‌ترین است.
A23: نرخ تسعیر منبع | B23: قاعده طلایی: ریال را با همان نرخی به یورو برگردانید که منبع با آن ساخته (گچساران ۴: ۴۲۰٬۰۰۰×۱٫۰۸۵ = ۴۵۵٬۶۹۲؛ پازنان ۱۴۰۴: ۶۵۸٬۵۳۳×۱٫۰۵۶ = ۶۹۵٬۲۹۹). اگر نه، خطای نرخ ارز وارد قیمت می‌شود.
A24: تورم ریالی (CPI) و تورم ارزی مارون ۳ | B24: فقط برای مقایسه و روش‌های قدیمی (M1، R1). برای پمپ CPI استفاده نمی‌شود چون در آزمون نصف قیمت واقعی را داد. تورم ریالی ۱۴۰۵ (۲۰٪) در منبع غیرواقعی است.
A25: ضرایب پازنان (۱٫۵۵ یورویی، ۱۶٫۲۶ ریالی) | B25: ضرایبی که مشاور پازنان برای اقلام بدون استعلام به کار برده (از فایل لینک‌شده Basic INFO). ۱۶٫۲۶ همان CPI است. فقط برای مقایسه (M2، R2).
A26: کف قیمت ۲۵٬۰۰۰ یورو (سطح ۱۴۰۴) | B26: پمپ گریز از مرکز API 610 با کلاس S یا D امروز ارزان‌تر از این حد عرضه نمی‌شود (پمپیران برای پمپ‌های کوچک ۳۰٬۰۰۰ داده). با شاخص به سال هدف می‌رود. پمپ چدنی I2، جابه‌جایی مثبت، آتش‌نشانی و پکیج کف ندارند. نتیجه بین ۲۲٬۵۰۰ تا ۳۰٬۰۰۰ تقریباً ثابت است.
A27: نرخ دلار اسفند ۱۴۰۳ = ۹۳۰٬۰۰۰ و یورو/دلار ۱٫۰۴ | B27: فقط در آزمون ریالی، برای تاریخ استعلام‌های پازنان. تقریبی است؛ آزمون حساسیت در Val_IRR_Packages.
A28: معیارهای خطا
A29: سوگیری میانه | B29: میانه (پیش‌بینی÷واقعی)−۱. منفی = کم‌برآورد سیستماتیک.
A30: MdAPE / MAPE | B30: میانه / میانگین قدر مطلق خطای تک‌قلم. MdAPE حساسیت کمتری به اقلام عجیب دارد.
A31: جمع پیش‌بینی/واقعی | B31: دقت روی جمع پروژه (وزنی با تعداد و مبلغ). مهم‌ترین معیار برای بودجه.
A32: رنگ‌ها | B32: آبی = ورودی؛ زرد = فرض کلیدی/ورودی کاربر؛ سیاه = فرمول؛ سبز = پیوند از شیت دیگر یا نتیجه؛ صورتی = مقدار پیش‌بینی‌شده.

Sheet Summary
A1: روش تعدیل قیمت پمپ‌های نمک‌زدایی — نتیجه صحت‌سنجی
A2: داده آزمون: همان Tagهای پازنان ۲ با قیمت ۱۳۹۳ و استعلام واقعی ۱۴۰۴ (۱۴ پمپ یورویی + ۱۱ پکیج ریالی). اعداد این صفحه همه فرمول‌اند و با تغییر ورودی‌ها به‌روز می‌شوند.
A4: الف) پمپ‌ها — قیمت یورویی (۱۴ پمپ، بدون آتش‌نشانی)
A5: کد | B5: روش | C5: ضریب ۱۳۹۳→۱۴۰۴ | D5: سوگیری میانه | E5: MdAPE | F5: MAPE | G5: خطای ≤۲۵٪ (از ۱۴) | H5: جمع پیش‌بینی/واقعی
A6: M0 | B6: =Val_EUR_Pumps!B6 -> بدون تعدیل (یورو ثابت) | C6: =IF(ISNUMBER(Val_EUR_Pumps!E6),Val_EUR_Pumps!E6,"~1.27 (هر سطر)") -> 1 | D6: =Val_EUR_Pumps!D39 -> -0.37365644 | E6: =Val_EUR_Pumps!E39 -> 0.37365644 | F6: =Val_EUR_Pumps!F39 -> 0.37234734 | G6: =Val_EUR_Pumps!G39 -> 3 | H6: =Val_EUR_Pumps!H39 -> 0.73446193
A7: M1 | B7: =Val_EUR_Pumps!B7 -> تورم ارزی مارون ۳ (۱۳۹۴ تا ۱۴۰۳) | C7: =IF(ISNUMBER(Val_EUR_Pumps!E7),Val_EUR_Pumps!E7,"~1.27 (هر سطر)") -> 1.3810889 | D7: =Val_EUR_Pumps!D40 -> -0.13496388 | E7: =Val_EUR_Pumps!E40 -> 0.21998303 | F7: =Val_EUR_Pumps!F40 -> 0.26138111 | G7: =Val_EUR_Pumps!G40 -> 8 | H7: =Val_EUR_Pumps!H40 -> 1.0143572
A8: M2 | B8: =Val_EUR_Pumps!B8 -> ضریب یورویی پازنان (Basic INFO!C138) | C8: =IF(ISNUMBER(Val_EUR_Pumps!E8),Val_EUR_Pumps!E8,"~1.27 (هر سطر)") -> 1.5520762 | D8: =Val_EUR_Pumps!D41 -> -0.027867046 | E8: =Val_EUR_Pumps!E41 -> 0.17359989 | F8: =Val_EUR_Pumps!F41 -> 0.25805632 | G8: =Val_EUR_Pumps!G41 -> 8 | H8: =Val_EUR_Pumps!H41 -> 1.1399409
A9: M3 | B9: =Val_EUR_Pumps!B9 -> مدل فلزی فعلی شما (ضریب هر سطر) | C9: =IF(ISNUMBER(Val_EUR_Pumps!E9),Val_EUR_Pumps!E9,"~1.27 (هر سطر)") -> ~1.27 (هر سطر) | D9: =Val_EUR_Pumps!D42 -> -0.20406498 | E9: =Val_EUR_Pumps!E42 -> 0.28204029 | F9: =Val_EUR_Pumps!F42 -> 0.2859887 | G9: =Val_EUR_Pumps!G42 -> 6 | H9: =Val_EUR_Pumps!H42 -> 0.93570194
A10: M4 | B10: =Val_EUR_Pumps!B10 -> PPI پمپ منطقه یورو (Eurostat C28.13) | C10: =IF(ISNUMBER(Val_EUR_Pumps!E10),Val_EUR_Pumps!E10,"~1.27 (هر سطر)") -> 1.3454191 | D10: =Val_EUR_Pumps!D43 -> -0.1573054 | E10: =Val_EUR_Pumps!E43 -> 0.24012874 | F10: =Val_EUR_Pumps!F43 -> 0.26877251 | G10: =Val_EUR_Pumps!G43 -> 8 | H10: =Val_EUR_Pumps!H43 -> 0.98815912
A11: M5 | B11: =Val_EUR_Pumps!B11 -> PPI پمپ آمریکا تبدیل‌شده به یورو | C11: =IF(ISNUMBER(Val_EUR_Pumps!E11),Val_EUR_Pumps!E11,"~1.27 (هر سطر)") -> 1.5903823 | D11: =Val_EUR_Pumps!D44 -> -0.0038742953 | E11: =Val_EUR_Pumps!E44 -> 0.17535235 | F11: =Val_EUR_Pumps!F44 -> 0.26442528 | G11: =Val_EUR_Pumps!G44 -> 9 | H11: =Val_EUR_Pumps!H44 -> 1.1680752
A12: M6 | B12: =Val_EUR_Pumps!B12 -> پیشنهادی: PPI پمپ یورو + کف قیمت پمپ API (S/D) | C12: =IF(ISNUMBER(Val_EUR_Pumps!E12),Val_EUR_Pumps!E12,"~1.27 (هر سطر)") -> 1.3454191 | D12: =Val_EUR_Pumps!D45 -> -0.070297462 | E12: =Val_EUR_Pumps!E45 -> 0.13071961 | F12: =Val_EUR_Pumps!F45 -> 0.2084972 | G12: =Val_EUR_Pumps!G45 -> 10 | H12: =Val_EUR_Pumps!H45 -> 1.0097808
A14: ب) پکیج‌های تزریق — قیمت ریالی (۱۱ قلم)
A15: کد | B15: روش | C15: میانه پیش/استعلام ریالی | D15: جمع پیش/استعلام ریالی | E15: میانه پیش/میانگین همه استعلام‌ها | F15: جمع پیش/میانگین همه
A16: R1 | B16: تورم ریالی (CPI مارون ۳) | C16: =Val_IRR_Packages!N28 -> 0.46217203 | D16: =Val_IRR_Packages!N29 -> 0.47716293 | E16: =Val_IRR_Packages!R28 -> 0.55026843 | F16: =Val_IRR_Packages!R29 -> 0.57186268
A17: R2 | B17: ضریب ریالی پازنان (۱۶٫۲۶) | C17: =Val_IRR_Packages!O28 -> 0.45894076 | D17: =Val_IRR_Packages!O29 -> 0.47382685 | E17: =Val_IRR_Packages!S28 -> 0.54642123 | F17: =Val_IRR_Packages!S29 -> 0.56786451
A18: R3 | B18: مدل فلزی فعلی شما | C18: =Val_IRR_Packages!P28 -> 0.82899546 | D18: =Val_IRR_Packages!P29 -> 0.85544587 | E18: =Val_IRR_Packages!T28 -> 0.9870135 | F18: =Val_IRR_Packages!T29 -> 1.0252213
A19: R4 | B19: پیشنهادی: یورو × PPI × نرخ ارز | C19: =Val_IRR_Packages!Q28 -> 0.90622297 | D19: =Val_IRR_Packages!Q29 -> 0.93561699 | E19: =Val_IRR_Packages!U28 -> 1.0789616 | F19: =Val_IRR_Packages!U29 -> 1.1213035
A21: ج) روش پیشنهادی برای پمپ‌ها
A22: ۱. لنگر یورو: قیمت پایه را با «نرخ تسعیر همان منبع» در تاریخ همان منبع به یورو برگردانید (قیمت ریالی پازنان ۹۳ ÷ ۴۰٬۵۳۱؛ گچساران ÷ ۴۵۵٬۶۹۳).
A23: ۲. تعدیل در یورو با شاخص PPI پمپ و کمپرسور منطقه یورو (Eurostat C28.13)؛ ۱۳۹۳→۱۴۰۴ ≈ ۱٫۳۵ (حدود ۳٪ در سال).
A24: ۳. کف قیمت برای پمپ گریز از مرکز API 610 با کلاس مواد S یا D: حداقل ۲۵٬۰۰۰ یورو در سطح ۱۴۰۴ (با همان شاخص تعدیل شود). پمپ‌های I2 چدنی، جابه‌جایی مثبت و آتش‌نشانی کف ندارند.
A25: ۴. تبدیل به ریال با نرخ یوروی تاریخ هدف، از همان نوع نرخ (آزاد یا مرکز مبادله) که در کل پروژه ثابت است؛ هزینه ترخیص/حمل جدا.
A26: ۵. تورم ریالی (CPI) برای پمپ و پکیج پمپ استفاده نشود؛ فلزات فقط برای پیش‌بینی سال‌های بدون PPI (۲۰۲۶ به بعد) و تحلیل حساسیت.
A27: فرمول: ریال(هدف) = MAX[ قیمت پایه ÷ نرخ تسعیر منبع × PPI(هدف)/PPI(پایه) ، کف × PPI(هدف)/PPI(۱۴۰۴) ] × نرخ یورو(هدف)
A29: د) محدودیت‌ها
A30: • فقط یک زوج داده واقعی (پازنان ۲) با همان Tag در دو زمان موجود است؛ ۱۴ پمپ و ۱۱ پکیج. کف قیمت روی همین داده تنظیم شده و باید با استعلام‌های بعدی بازبینی شود.
A31: • پراکندگی استعلام دو فروشنده برای یک پمپ (میانه ~۱٫۳ برابر، بیشینه ۴ برابر) سقف دقت تک‌قلم را تعیین می‌کند؛ دقت روی جمع پروژه (±۵٪) بسیار بهتر از تک‌قلم (±۲۰٪) است.
A32: • نرخ‌های ارز سالانه Indices تخمینی‌اند (از Params مدل شما). برای آزمون ریالی نرخ اسفند ۱۴۰۳ (۹۳۰٬۰۰۰ ریال/دلار) تقریبی است؛ حساسیت در شیت Val_IRR_Packages.
A33: • PPI منطقه یورو برای ۲۰۲۶ و ۲۰۲۷ هنوز منتشر نشده و با رشد ۲٪ (یا روش فلزی) پیش‌بینی شده است.
A35: ه) جمع بانک پمپ‌ها در سال هدف (شیت Pump_Bank_Escalated)
A36: روش پیشنهادی (ریال) | D36: =Pump_Bank_Escalated!P123 -> 4.1598964e+13
A37: مدل فعلی شما (ریال، همان اقلام) | D37: =Pump_Bank_Escalated!Q123 -> 3.5640785e+13
A38: اختلاف | D38: =Pump_Bank_Escalated!R123 -> 0.16717308
A40: راهنما: سلول‌های آبی ورودی‌اند و زرد فرض‌های کلیدی. برای تغییر سال هدف به Pump_Bank_Escalated!D3 و برای نرخ ارز به Indices بروید.

Sheet Indices
A1: شاخص‌ها و نرخ‌ها (ورودی‌های مدل تعدیل پمپ)
A2: متن آبی = ورودی قابل ویرایش؛ زرد = فرض کلیدی؛ سیاه = فرمول. منابع در شیت Sources.
A3: سهم سال شمسی از سال میلادی هم‌شماره (Y+621) | C3: 0.79 | D3: فروردین تا دی = ~۹٫۵ ماه از ۱۲ ماه در سال میلادی Y+621
A4: رشد پیش‌بینی شاخص پمپ (روند) برای سال‌های بدون داده | C4: 0.02 | D4: میانگین رشد سالانه EA C2813 در ۲۰۱۵ تا ۲۰۲۱ حدود ۱٫۴٪ و ۲۰۲۴ تا ۲۰۲۵ حدود ۱٪ بوده؛ ۲٪ فرض محافظه‌کارانه است
A5: روش پیش‌بینی ۲۰۲۶ (روند / فلزی) | C5: روند | D5: «فلزی»: رشد ۲۰۲۶ = (۱−سهم فلز)×رشد روند + سهم فلز×تغییر سبد فلزی پمپ (۱۴۰۴→۱۴۰۵، جدول پایین)
A6: سهم فلزات در قیمت پمپ (برای nowcast) | C6: 0.3
A8: جدول ۱: شاخص قیمت تولیدکننده پمپ (میلادی)
A9: سال میلادی | B9: EA20 PPI C28.13 پمپ و کمپرسور (2021=100) | C9: رشد سالانه | D9: وضعیت | E9: US PPI پمپ (NAICS 333914، ژانویه، Dec1983=100)
A10: 2005 | B10: 74.8 | D10: Eurostat sts_inppd_a (imputed)
A11: 2006 | B11: 76.5 | C11: =B11/B10-1 -> 0.022727273 | D11: Eurostat sts_inppd_a (imputed)
A12: 2007 | B12: 79.8 | C12: =B12/B11-1 -> 0.043137255 | D12: Eurostat sts_inppd_a (imputed)
A13: 2008 | B13: 81.5 | C13: =B13/B12-1 -> 0.021303258 | D13: Eurostat sts_inppd_a (imputed)
A14: 2009 | B14: 83.7 | C14: =B14/B13-1 -> 0.026993865 | D14: Eurostat sts_inppd_a (imputed)
A15: 2010 | B15: 84.4 | C15: =B15/B14-1 -> 0.0083632019 | D15: Eurostat sts_inppd_a (imputed) | E15: 226.2
A16: 2011 | B16: 86.2 | C16: =B16/B15-1 -> 0.021327014 | D16: Eurostat sts_inppd_a (imputed) | E16: 229.2
A17: 2012 | B17: 88.4 | C17: =B17/B16-1 -> 0.025522042 | D17: Eurostat sts_inppd_a (imputed) | E17: 235.4
A18: 2013 | B18: 89.9 | C18: =B18/B17-1 -> 0.016968326 | D18: Eurostat sts_inppd_a (imputed) | E18: 239.5
A19: 2014 | B19: 91.2 | C19: =B19/B18-1 -> 0.014460512 | D19: Eurostat sts_inppd_a (imputed) | E19: 245.1
A20: 2015 | B20: 91.9 | C20: =B20/B19-1 -> 0.0076754386 | D20: Eurostat sts_inppd_a (imputed) | E20: 250.7
A21: 2016 | B21: 92.6 | C21: =B21/B20-1 -> 0.007616975 | D21: Eurostat sts_inppd_a (imputed) | E21: 255.9
A22: 2017 | B22: 93.6 | C22: =B22/B21-1 -> 0.010799136 | D22: Eurostat sts_inppd_a (imputed) | E22: 256.9
A23: 2018 | B23: 94.6 | C23: =B23/B22-1 -> 0.010683761 | D23: Eurostat sts_inppd_a | E23: 266.4
A24: 2019 | B24: 96.4 | C24: =B24/B23-1 -> 0.019027484 | D24: Eurostat sts_inppd_a | E24: 274.9
A25: 2020 | B25: 97.8 | C25: =B25/B24-1 -> 0.014522822 | D25: Eurostat sts_inppd_a | E25: 276
A26: 2021 | B26: 100 | C26: =B26/B25-1 -> 0.022494888 | D26: Eurostat sts_inppd_a | E26: 279.4
... A30: 2025 | B30: 122.9 | C30: =B30/B29-1 -> 0.0098603122 | D30: Eurostat sts_inppd_a | E30: 382.901
A31: 2026 | B31: =B30*(1+IF($C$5="فلزی",(1-$C$6)*$C$4+$C$6*$H$45,$C$4)) -> 125.358 | C31: =B31/B30-1 -> 0.02 | D31: پیش‌بینی (داده رسمی هنوز منتشر نشده) | E31: 399.843
A32: 2027 | B32: =B31*(1+$C$4) -> 127.86516 | C32: =B32/B31-1 -> 0.02 | D32: پیش‌بینی
A36: جدول ۲: سبد فلزی پمپ (قیمت‌ها از شیت MetalPrices مدل شما، دلار بر تن؛ بخشی تخمینی)
A37: فلز | B37: وزن در سبد پمپ | C37: ۱۳۹۳ | D37: ۱۴۰۳ | E37: ۱۴۰۴ | F37: ۱۴۰۵ | G37: نسبت ۱۴۰۴/۱۳۹۳ | H37: نسبت ۱۴۰۵/۱۴۰۴
A38: فولاد (HRC/Plate) | B38: 0.6 | C38: 560 | D38: 600 | E38: 560 | F38: 600 | G38: =E38/C38 -> 1 | H38: =F38/E38 -> 1.0714286
A39: نیکل | B39: 0.12 | C39: 16893 | D39: 16814 | E39: 15162 | F39: 17800 | G39: =E39/C39 -> 0.89753152 | H39: =F39/E39 -> 1.1739876
A40: مولیبدن | B40: 0.03 | C40: 24000 | D40: 46000 | E40: 52000 | F40: 66000 | G40: =E40/C40 -> 2.1666667 | H40: =F40/E40 -> 1.2692308
A41: مس (سیم‌پیچ موتور) | B41: 0.25 | C41: 6863 | D41: 9142 | E41: 9921 | F41: 13200 | G41: =E41/C41 -> 1.4455777 | H41: =F41/E41 -> 1.330511
A42: جمع وزن | B42: =SUM(B38:B41) -> 1
A44: تغییر سبد فلزی (دلاری) ۱۳۹۳→۱۴۰۴ | G44: =SUMPRODUCT(B38:B41,G38:G41)-1 -> 0.13409822
A45: تغییر سبد فلزی (دلاری) ۱۴۰۴→۱۴۰۵ (برای nowcast ۲۰۲۶) | H45: =SUMPRODUCT(B38:B41,H38:H41)-1 -> 0.15444034
A46: وزن‌ها برآورد مهندسی است (پوسته/پروانه/شفت + سیم‌پیچ مسی الکتروموتور). اعداد فلزات از MetalPrices مدل شما کپی شده و برای ۱۴۰۵ تخمینی است.
A49: جدول ۳: سری سالانه شمسی (شاخص پمپ، نرخ ارز، تورم)
A50: سال شمسی | B50: سال میلادی | C50: شاخص پمپ EA (شمسی) | D50: دلار آزاد (ریال، میانگین تقریبی) | E50: یورو/دلار | F50: نرخ یورو جایگزین (ریال) | G50: نرخ مؤثر یورو (ریال) | H50: تورم ریالی سالانه | I50: شاخص تجمعی ریالی (۱۳۸۵=۱) | J50: تورم ارزی سالانه (مارون ۳) | K50: شاخص تجمعی ارزی | L50: شاخص ریالیِ پمپ = یورو×PPI (۱۳۸۵=۱) | M50: وضعیت داده
...

Sheet Val_EUR_Pumps
A1: اعتبارسنجی ۱: پمپ‌های پازنان ۲ — قیمت یورویی ۱۳۹۳ (بهمن، Rev.R02 فوریه ۲۰۱۵) در برابر استعلام‌های واقعی ۱۴۰۴ (فوریه تا مه ۲۰۲۵)
A2: همان Tag و همان مشخصات؛ «واقعی» = میانگین استعلام‌های فروشندگان (همه به یورو). سطرهایی که قیمت ۱۴۰۴ آن‌ها مشتق از ضریب است (P-163, P-210, P-211) حذف شده‌اند.
A4: ضرایب روش‌ها (۱۳۹۳ → ۲۰۲۵)
A5: کد | B5: روش | E5: ضریب | F5: منبع
A6: M0 | B6: بدون تعدیل (یورو ثابت) | E6: =1 -> 1 | F6: مرجع
A7: M1 | B7: تورم ارزی مارون ۳ (۱۳۹۴ تا ۱۴۰۳) | E7: =INDEX(Indices!$K$51:$K$71,MATCH(1403,Indices!$A$51:$A$71,0))/INDEX(Indices!$K$51:$K$71,MATCH(1393,Indices!$A$51:$A$71,0)) -> 1.3810889 | F7: شیت Inflation مارون ۳
A8: M2 | B8: ضریب یورویی پازنان (Basic INFO!C138) | E8: 1.5520762 | F8: فایل لینک‌شده PZN-Summary-140401 Rev.03
A9: M3 | B9: مدل فلزی فعلی شما (ضریب هر سطر) | E9: هر سطر | F9: خروجی ستون AH شیت Equipment مدل (پس از محاسبه مجدد)
A10: M4 | B10: PPI پمپ منطقه یورو (Eurostat C28.13) | E10: =INDEX(Indices!$B$10:$B$32,MATCH(2025,Indices!$A$10:$A$32,0))/INDEX(Indices!$C$51:$C$71,MATCH(1393,Indices!$A$51:$A$71,0)) -> 1.3454191 | F10: Eurostat
A11: M5 | B11: PPI پمپ آمریکا تبدیل‌شده به یورو | E11: =(INDEX(Indices!$E$10:$E$32,MATCH(2025,Indices!$A$10:$A$32,0))/INDEX(Indices!$E$10:$E$32,MATCH(2015,Indices!$A$10:$A$32,0)))*E14/E15 -> 1.5903823 | F11: BLS/FRED
A12: M6 | B12: پیشنهادی: PPI پمپ یورو + کف قیمت پمپ API (S/D) | E12: =E10 -> 1.3454191 | F12: M4 + کف
B14: یورو/دلار بهمن ۱۳۹۳ (فوریه ۲۰۱۵) | E14: 1.135
B15: یورو/دلار فوریه تا مه ۲۰۲۵ (میانگین تقریبی) | E15: 1.09
B16: کف قیمت پمپ گریز از مرکز API 610 کلاس S/D (یورو، سطح ۱۴۰۴) | E16: 25000 | F16: فقط پمپ‌های گریز از مرکز با کلاس مواد S یا D (نه I2 چدنی، نه جابه‌جایی مثبت، نه آتش‌نشانی). نتیجه بین ۲۲٬۵۰۰ تا ۳۰٬۰۰۰ تقریباً ثابت است (پمپیران برای پمپ‌های کوچک API عدد ثابت ۳۰٬۰۰۰ داده)؛ با داده جدید بازبینی شود
A17: Tag | B17: سرویس | C17: نوع | D17: کلاس مواد API 610 | E17: تعداد | F17: قیمت ۱۳۹۳ (یورو) | G17: آریا سپهر کیهان | H17: پمپیران | I17: کالای پمپ | J17: میانگین استعلام (واقعی) | K17: بیشینه/کمینه استعلام | L17: در آمار؟ | M17: مشمول کف؟ | N17: نسبت واقعی/قدیم | O17: M0 پیش‌بینی | P17: M0 پیش/واقعی | Q17: M0 |خطا| | R17: M1 پیش‌بینی | S17: M1 پیش/واقعی | T17: M1 |خطا| | U17: M2 پیش‌بینی | V17: M2 پیش/واقعی | W17: M2 |خطا| | X17: M3 پیش‌بینی | Y17: M3 پیش/واقعی | Z17: M3 |خطا| | AA17: M4 پیش‌بینی | AB17: M4 پیش/واقعی | AC17: M4 |خطا| | AD17: M5 پیش‌بینی | AE17: M5 پیش/واقعی | AF17: M5 |خطا| | AG17: M6 پیش‌بینی | AH17: M6 پیش/واقعی | AI17: M6 |خطا| | AJ17: پراکندگی (کمکی)
A18: P-111 A/B | B18: Off Spec. Crude Pumps | C18: Centrifugal (VS6) | D18: D1 | E18: 2 | F18: 75000 | G18: 43000 | H18: 180000 | J18: =AVERAGE(G18:I18) -> 111500 | K18: =MAX(G18:I18)/MIN(G18:I18) -> 4.1860465 | L18: Y | M18: Y | N18: =J18/F18 -> 1.4866667 | O18: =F18*$E$6 -> 75000 | P18: =IF($L18="Y",O18/$J18,"") -> 0.67264574 | Q18: =IF($L18="Y",ABS(P18-1),"") -> 0.32735426 | R18: =F18*$E$7 -> 103581.66 | S18: =IF($L18="Y",R18/$J18,"") -> 0.92898354 | T18: =IF($L18="Y",ABS(S18-1),"") -> 0.071016459 | U18: =F18*$E$8 -> 116405.72 | V18: =IF($L18="Y",U18/$J18,"") -> 1.0439975 | W18: =IF($L18="Y",ABS(V18-1),"") -> 0.043997466 | X18: =F18*1.27425462793664 -> 95569.097 | Y18: =IF($L18="Y",X18/$J18,"") -> 0.85712195 | Z18: =IF($L18="Y",ABS(Y18-1),"") -> 0.14287805 | AA18: =F18*$E$10 -> 100906.43 | AB18: =IF($L18="Y",AA18/$J18,"") -> 0.90499044 | AC18: =IF($L18="Y",ABS(AB18-1),"") -> 0.095009563 | AD18: =F18*$E$11 -> 119278.67 | AE18: =IF($L18="Y",AD18/$J18,"") -> 1.0697639 | AF18: =IF($L18="Y",ABS(AE18-1),"") -> 0.06976387 | AG18: =IF(M18="Y",MAX(F18*$E$12,$E$16),F18*$E$12) -> 100906.43 | AH18: =IF($L18="Y",AG18/$J18,"") -> 0.90499044 | AI18: =IF($L18="Y",ABS(AH18-1),"") -> 0.095009563 | AJ18: =IF(AND(L18="Y",COUNT(G18:I18)>=2),K18,"") -> 4.1860465
A19: P-122 A/B | B19: Deaerated Water Pumps | C19: Centrifugal (Horizontal) | D19: I2 | E19: 2 | F19: 10000 | G19: 14100 | H19: 16000 | J19: =AVERAGE(G19:I19) -> 15050 | K19: =MAX(G19:I19)/MIN(G19:I19) -> 1.1347518 | L19: Y | M19: N | N19: =J19/F19 -> 1.505 | O19: =F19*$E$6 -> 10000 | P19: =IF($L19="Y",O19/$J19,"") -> 0.66445183 | Q19: =IF($L19="Y",ABS(P19-1),"") -> 0.33554817 | R19: =F19*$E$7 -> 13810.889 | S19: =IF($L19="Y",R19/$J19,"") -> 0.91766702 | T19: =IF($L19="Y",ABS(S19-1),"") -> 0.08233298 | U19: =F19*$E$8 -> 15520.762 | V19: =IF($L19="Y",U19/$J19,"") -> 1.0312799 | W19: =IF($L19="Y",ABS(V19-1),"") -> 0.031279889 | X19: =F19*1.2649857956038 -> 12649.858 | Y19: =IF($L19="Y",X19/$J19,"") -> 0.84052212 | Z19: =IF($L19="Y",ABS(Y19-1),"") -> 0.15947788 | AA19: =F19*$E$10 -> 13454.191 | AB19: =IF($L19="Y",AA19/$J19,"") -> 0.89396619 | AC19: =IF($L19="Y",ABS(AB19-1),"") -> 0.10603381 | AD19: =F19*$E$11 -> 15903.823 | AE19: =IF($L19="Y",AD19/$J19,"") -> 1.0567324 | AF19: =IF($L19="Y",ABS(AE19-1),"") -> 0.056732417 | AG19: =IF(M19="Y",MAX(F19*$E$12,$E$16),F19*$E$12) -> 13454.191 | AH19: =IF($L19="Y",AG19/$J19,"") -> 0.89396619 | AI19: =IF($L19="Y",ABS(AH19-1),"") -> 0.10603381 | AJ19: =IF(AND(L19="Y",COUNT(G19:I19)>=2),K19,"") -> 1.1347518
A20: P-124 | B20: Dilution Water Pump | C20: Centrifugal (OH2) | D20: I2 | E20: 1 | F20: 15000 | G20: 28500 | H20: 16000 | J20: =AVERAGE(G20:I20) -> 22250 | K20: =MAX(G20:I20)/MIN(G20:I20) -> 1.78125 | L20: Y | M20: N | N20: =J20/F20 -> 1.4833333 | O20: =F20*$E$6 -> 15000 | P20: =IF($L20="Y",O20/$J20,"") -> 0.6741573 | Q20: =IF($L20="Y",ABS(P20-1),"") -> 0.3258427 | R20: =F20*$E$7 -> 20716.333 | S20: =IF($L20="Y",R20/$J20,"") -> 0.93107114 | T20: =IF($L20="Y",ABS(S20-1),"") -> 0.068928855 | U20: =F20*$E$8 -> 23281.143 | V20: =IF($L20="Y",U20/$J20,"") -> 1.0463435 | W20: =IF($L20="Y",ABS(V20-1),"") -> 0.046343528 | X20: =F20*1.2649857956038 -> 18974.787 | Y20: =IF($L20="Y",X20/$J20,"") -> 0.85279941 | Z20: =IF($L20="Y",ABS(Y20-1),"") -> 0.14720059 | AA20: =F20*$E$10 -> 20181.287 | AB20: =IF($L20="Y",AA20/$J20,"") -> 0.90702412 | AC20: =IF($L20="Y",ABS(AB20-1),"") -> 0.092975877 | AD20: =F20*$E$11 -> 23855.734 | AE20: =IF($L20="Y",AD20/$J20,"") -> 1.0721678 | AF20: =IF($L20="Y",ABS(AE20-1),"") -> 0.072167834 | AG20: =IF(M20="Y",MAX(F20*$E$12,$E$16),F20*$E$12) -> 20181.287 | AH20: =IF($L20="Y",AG20/$J20,"") -> 0.90702412 | AI20: =IF($L20="Y",ABS(AH20-1),"") -> 0.092975877 | AJ20: =IF(AND(L20="Y",COUNT(G20:I20)>=2),K20,"") -> 1.78125
A21: P-125 A/B | B21: Dilution Water Pumps | C21: Centrifugal (OH2) | D21: I2 | E21: 2 | F21: 12000 | G21: 27000 | H21: 16000 | J21: =AVERAGE(G21:I21) -> 21500 | K21: =MAX(G21:I21)/MIN(G21:I21) -> 1.6875 | L21: Y | M21: N | N21: =J21/F21 -> 1.7916667 | O21: =F21*$E$6 -> 12000 | P21: =IF($L21="Y",O21/$J21,"") -> 0.55813953 | Q21: =IF($L21="Y",ABS(P21-1),"") -> 0.44186047 | R21: =F21*$E$7 -> 16573.066 | S21: =IF($L21="Y",R21/$J21,"") -> 0.7708403 | T21: =IF($L21="Y",ABS(S21-1),"") -> 0.2291597 | U21: =F21*$E$8 -> 18624.915 | V21: =IF($L21="Y",U21/$J21,"") -> 0.86627511 | W21: =IF($L21="Y",ABS(V21-1),"") -> 0.13372489 | X21: =F21*1.2649857956038 -> 15179.83 | Y21: =IF($L21="Y",X21/$J21,"") -> 0.70603858 | Z21: =IF($L21="Y",ABS(Y21-1),"") -> 0.29396142 | AA21: =F21*$E$10 -> 16145.029 | AB21: =IF($L21="Y",AA21/$J21,"") -> 0.7509316 | AC21: =IF($L21="Y",ABS(AB21-1),"") -> 0.2490684 | AD21: =F21*$E$11 -> 19084.587 | AE21: =IF($L21="Y",AD21/$J21,"") -> 0.88765523 | AF21: =IF($L21="Y",ABS(AE21-1),"") -> 0.11234477 | AG21: =IF(M21="Y",MAX(F21*$E$12,$E$16),F21*$E$12) -> 16145.029 | AH21: =IF($L21="Y",AG21/$J21,"") -> 0.7509316 | AI21: =IF($L21="Y",ABS(AH21-1),"") -> 0.2490684 | AJ21: =IF(AND(L21="Y",COUNT(G21:I21)>=2),K21,"") -> 1.6875
A22: P-136 A/B | B22: Disposal Water InjectionPumps | C22: Centrifugal (BB3) | D22: D2 | E22: 2 | F22: 260000 | G22: 335000 | H22: 300000 | J22: =AVERAGE(G22:I22) -> 317500 | K22: =MAX(G22:I22)/MIN(G22:I22) -> 1.1166667 | L22: Y | M22: Y | N22: =J22/F22 -> 1.2211538 | O22: =F22*$E$6 -> 260000 | P22: =IF($L22="Y",O22/$J22,"") -> 0.81889764 | Q22: =IF($L22="Y",ABS(P22-1),"") -> 0.18110236 | R22: =F22*$E$7 -> 359083.1 | S22: =IF($L22="Y",R22/$J22,"") -> 1.1309704 | T22: =IF($L22="Y",ABS(S22-1),"") -> 0.13097041 | U22: =F22*$E$8 -> 403539.82 | V22: =IF($L22="Y",U22/$J22,"") -> 1.2709916 | W22: =IF($L22="Y",ABS(V22-1),"") -> 0.27099156 | X22: =F22*1.27425462793664 -> 331306.2 | Y22: =IF($L22="Y",X22/$J22,"") -> 1.0434841 | Z22: =IF($L22="Y",ABS(Y22-1),"") -> 0.043484105 | AA22: =F22*$E$10 -> 349808.97 | AB22: =IF($L22="Y",AA22/$J22,"") -> 1.1017605 | AC22: =IF($L22="Y",ABS(AB22-1),"") -> 0.10176054 | AD22: =F22*$E$11 -> 413499.39 | AE22: =IF($L22="Y",AD22/$J22,"") -> 1.3023603 | AF22: =IF($L22="Y",ABS(AE22-1),"") -> 0.3023603 | AG22: =IF(M22="Y",MAX(F22*$E$12,$E$16),F22*$E$12) -> 349808.97 | AH22: =IF($L22="Y",AG22/$J22,"") -> 1.1017605 | AI22: =IF($L22="Y",ABS(AH22-1),"") -> 0.10176054 | AJ22: =IF(AND(L22="Y",COUNT(G22:I22)>=2),K22,"") -> 1.1166667
A23: P-137 A/B | B23: Dirty Oil Pumps | C23: P.D.-Rotary (Ext. Gear) | D23: D1 | E23: 2 | F23: 10000 | G23: 30000 | J23: =AVERAGE(G23:I23) -> 30000 | K23: =MAX(G23:I23)/MIN(G23:I23) -> 1 | L23: Y | M23: N | N23: =J23/F23 -> 3 | O23: =F23*$E$6 -> 10000 | P23: =IF($L23="Y",O23/$J23,"") -> 0.33333333 | Q23: =IF($L23="Y",ABS(P23-1),"") -> 0.66666667 | R23: =F23*$E$7 -> 13810.889 | S23: =IF($L23="Y",R23/$J23,"") -> 0.46036295 | T23: =IF($L23="Y",ABS(S23-1),"") -> 0.53963705 | U23: =F23*$E$8 -> 15520.762 | V23: =IF($L23="Y",U23/$J23,"") -> 0.51735874 | W23: =IF($L23="Y",ABS(V23-1),"") -> 0.48264126 | X23: =F23*1.27499556885319 -> 12749.956 | Y23: =IF($L23="Y",X23/$J23,"") -> 0.42499852 | Z23: =IF($L23="Y",ABS(Y23-1),"") -> 0.57500148 | AA23: =F23*$E$10 -> 13454.191 | AB23: =IF($L23="Y",AA23/$J23,"") -> 0.44847304 | AC23: =IF($L23="Y",ABS(AB23-1),"") -> 0.55152696 | AD23: =F23*$E$11 -> 15903.823 | AE23: =IF($L23="Y",AD23/$J23,"") -> 0.53012743 | AF23: =IF($L23="Y",ABS(AE23-1),"") -> 0.46987257 | AG23: =IF(M23="Y",MAX(F23*$E$12,$E$16),F23*$E$12) -> 13454.191 | AH23: =IF($L23="Y",AG23/$J23,"") -> 0.44847304 | AI23: =IF($L23="Y",ABS(AH23-1),"") -> 0.55152696 | AJ23: =IF(AND(L23="Y",COUNT(G23:I23)>=2),K23,"")
A24: P-138 A/B | B24: Evaporation Pond Water Return Pumps | C24: Centrifugal (OH2) | D24: D2 | E24: 2 | F24: 35000 | G24: 28000 | H24: 30000 | J24: =AVERAGE(G24:I24) -> 29000 | K24: =MAX(G24:I24)/MIN(G24:I24) -> 1.0714286 | L24: Y | M24: Y | N24: =J24/F24 -> 0.82857143 | O24: =F24*$E$6 -> 35000 | P24: =IF($L24="Y",O24/$J24,"") -> 1.2068966 | Q24: =IF($L24="Y",ABS(P24-1),"") -> 0.20689655 | R24: =F24*$E$7 -> 48338.11 | S24: =IF($L24="Y",R24/$J24,"") -> 1.6668314 | T24: =IF($L24="Y",ABS(S24-1),"") -> 0.66683139 | U24: =F24*$E$8 -> 54322.668 | V24: =IF($L24="Y",U24/$J24,"") -> 1.8731955 | W24: =IF($L24="Y",ABS(V24-1),"") -> 0.87319545 | X24: =F24*1.27425462793664 -> 44598.912 | Y24: =IF($L24="Y",X24/$J24,"") -> 1.5378935 | Z24: =IF($L24="Y",ABS(Y24-1),"") -> 0.53789352 | AA24: =F24*$E$10 -> 47089.669 | AB24: =IF($L24="Y",AA24/$J24,"") -> 1.6237817 | AC24: =IF($L24="Y",ABS(AB24-1),"") -> 0.62378169 | AD24: =F24*$E$11 -> 55663.38 | AE24: =IF($L24="Y",AD24/$J24,"") -> 1.9194269 | AF24: =IF($L24="Y",ABS(AE24-1),"") -> 0.9194269 | AG24: =IF(M24="Y",MAX(F24*$E$12,$E$16),F24*$E$12) -> 47089.669 | AH24: =IF($L24="Y",AG24/$J24,"") -> 1.6237817 | AI24: =IF($L24="Y",ABS(AH24-1),"") -> 0.62378169 | AJ24: =IF(AND(L24="Y",COUNT(G24:I24)>=2),K24,"") -> 1.0714286
A25: P-139 A/B/C | B25: Disposal Water InjectionPumps | C25: Centrifugal (BB3) | D25: D2 | E25: 3 | F25: 180000 | G25: 225000 | H25: 270000 | J25: =AVERAGE(G25:I25) -> 247500 | K25: =MAX(G25:I25)/MIN(G25:I25) -> 1.2 | L25: Y | M25: Y | N25: =J25/F25 -> 1.375 | O25: =F25*$E$6 -> 180000 | P25: =IF($L25="Y",O25/$J25,"") -> 0.72727273 | Q25: =IF($L25="Y",ABS(P25-1),"") -> 0.27272727 | R25: =F25*$E$7 -> 248596 | S25: =IF($L25="Y",R25/$J25,"") -> 1.0044283 | T25: =IF($L25="Y",ABS(S25-1),"") -> 0.0044282653 | U25: =F25*$E$8 -> 279373.72 | V25: =IF($L25="Y",U25/$J25,"") -> 1.1287827 | W25: =IF($L25="Y",ABS(V25-1),"") -> 0.12878271 | X25: =F25*1.27425462793664 -> 229365.83 | Y25: =IF($L25="Y",X25/$J25,"") -> 0.92673064 | Z25: =IF($L25="Y",ABS(Y25-1),"") -> 0.073269362 | AA25: =F25*$E$10 -> 242175.44 | AB25: =IF($L25="Y",AA25/$J25,"") -> 0.97848663 | AC25: =IF($L25="Y",ABS(AB25-1),"") -> 0.02151337 | AD25: =F25*$E$11 -> 286268.81 | AE25: =IF($L25="Y",AD25/$J25,"") -> 1.1566417 | AF25: =IF($L25="Y",ABS(AE25-1),"") -> 0.15664166 | AG25: =IF(M25="Y",MAX(F25*$E$12,$E$16),F25*$E$12) -> 242175.44 | AH25: =IF($L25="Y",AG25/$J25,"") -> 0.97848663 | AI25: =IF($L25="Y",ABS(AH25-1),"") -> 0.02151337 | AJ25: =IF(AND(L25="Y",COUNT(G25:I25)>=2),K25,"") -> 1.2
A26: P-151 A/B | B26: Flare K.O. Drum Pumps | C26: Centrifugal (OH2) | D26: S6 | E26: 2 | F26: 15000 | G26: 21000 | H26: 30000 | J26: =AVERAGE(G26:I26) -> 25500 | K26: =MAX(G26:I26)/MIN(G26:I26) -> 1.4285714 | L26: Y | M26: Y | N26: =J26/F26 -> 1.7 | O26: =F26*$E$6 -> 15000 | P26: =IF($L26="Y",O26/$J26,"") -> 0.58823529 | Q26: =IF($L26="Y",ABS(P26-1),"") -> 0.41176471 | R26: =F26*$E$7 -> 20716.333 | S26: =IF($L26="Y",R26/$J26,"") -> 0.81240521 | T26: =IF($L26="Y",ABS(S26-1),"") -> 0.18759479 | U26: =F26*$E$8 -> 23281.143 | V26: =IF($L26="Y",U26/$J26,"") -> 0.91298602 | W26: =IF($L26="Y",ABS(V26-1),"") -> 0.087013981 | X26: =F26*1.27729147398551 -> 19159.372 | Y26: =IF($L26="Y",X26/$J26,"") -> 0.75134793 | Z26: =IF($L26="Y",ABS(Y26-1),"") -> 0.24865207 | AA26: =F26*$E$10 -> 20181.287 | AB26: =IF($L26="Y",AA26/$J26,"") -> 0.79142301 | AC26: =IF($L26="Y",ABS(AB26-1),"") -> 0.20857699 | AD26: =F26*$E$11 -> 23855.734 | AE26: =IF($L26="Y",AD26/$J26,"") -> 0.93551899 | AF26: =IF($L26="Y",ABS(AE26-1),"") -> 0.064481007 | AG26: =IF(M26="Y",MAX(F26*$E$12,$E$16),F26*$E$12) -> 25000 | AH26: =IF($L26="Y",AG26/$J26,"") -> 0.98039216 | AI26: =IF($L26="Y",ABS(AH26-1),"") -> 0.019607843 | AJ26: =IF(AND(L26="Y",COUNT(G26:I26)>=2),K26,"") -> 1.4285714
A27: P-161 A/B | B27: Closed Drain Drum Pumps | C27: Centrifugal (OH2) | D27: D2 | E27: 2 | F27: 32000 | G27: 32000 | H27: 30000 | J27: =AVERAGE(G27:I27) -> 31000 | K27: =MAX(G27:I27)/MIN(G27:I27) -> 1.0666667 | L27: Y | M27: Y | N27: =J27/F27 -> 0.96875 | O27: =F27*$E$6 -> 32000 | P27: =IF($L27="Y",O27/$J27,"") -> 1.0322581 | Q27: =IF($L27="Y",ABS(P27-1),"") -> 0.032258065 | R27: =F27*$E$7 -> 44194.844 | S27: =IF($L27="Y",R27/$J27,"") -> 1.4256401 | T27: =IF($L27="Y",ABS(S27-1),"") -> 0.42564012 | U27: =F27*$E$8 -> 49666.439 | V27: =IF($L27="Y",U27/$J27,"") -> 1.6021432 | W27: =IF($L27="Y",ABS(V27-1),"") -> 0.60214321 | X27: =F27*1.27425462793664 -> 40776.148 | Y27: =IF($L27="Y",X27/$J27,"") -> 1.3153596 | Z27: =IF($L27="Y",ABS(Y27-1),"") -> 0.31535962 | AA27: =F27*$E$10 -> 43053.412 | AB27: =IF($L27="Y",AA27/$J27,"") -> 1.3888197 | AC27: =IF($L27="Y",ABS(AB27-1),"") -> 0.38881973 | AD27: =F27*$E$11 -> 50892.233 | AE27: =IF($L27="Y",AD27/$J27,"") -> 1.6416849 | AF27: =IF($L27="Y",ABS(AE27-1),"") -> 0.64168494 | AG27: =IF(M27="Y",MAX(F27*$E$12,$E$16),F27*$E$12) -> 43053.412 | AH27: =IF($L27="Y",AG27/$J27,"") -> 1.3888197 | AI27: =IF($L27="Y",ABS(AH27-1),"") -> 0.38881973 | AJ27: =IF(AND(L27="Y",COUNT(G27:I27)>=2),K27,"") -> 1.0666667
A28: P-162 | B28: C. D. Drum / Flare K.O. Drum Sump Pump | C28: Centrifugal (VS4) | D28: S6 | E28: 1 | F28: 15000 | G28: 24000 | H28: 45000 | J28: =AVERAGE(G28:I28) -> 34500 | K28: =MAX(G28:I28)/MIN(G28:I28) -> 1.875 | L28: Y | M28: Y | N28: =J28/F28 -> 2.3 | O28: =F28*$E$6 -> 15000 | P28: =IF($L28="Y",O28/$J28,"") -> 0.43478261 | Q28: =IF($L28="Y",ABS(P28-1),"") -> 0.56521739 | R28: =F28*$E$7 -> 20716.333 | S28: =IF($L28="Y",R28/$J28,"") -> 0.60047342 | T28: =IF($L28="Y",ABS(S28-1),"") -> 0.39952658 | U28: =F28*$E$8 -> 23281.143 | V28: =IF($L28="Y",U28/$J28,"") -> 0.67481575 | W28: =IF($L28="Y",ABS(V28-1),"") -> 0.32518425 | X28: =F28*1.27729147398551 -> 19159.372 | Y28: =IF($L28="Y",X28/$J28,"") -> 0.55534412 | Z28: =IF($L28="Y",ABS(Y28-1),"") -> 0.44465588 | AA28: =F28*$E$10 -> 20181.287 | AB28: =IF($L28="Y",AA28/$J28,"") -> 0.58496483 | AC28: =IF($L28="Y",ABS(AB28-1),"") -> 0.41503517 | AD28: =F28*$E$11 -> 23855.734 | AE28: =IF($L28="Y",AD28/$J28,"") -> 0.69147056 | AF28: =IF($L28="Y",ABS(AE28-1),"") -> 0.30852944 | AG28: =IF(M28="Y",MAX(F28*$E$12,$E$16),F28*$E$12) -> 25000 | AH28: =IF($L28="Y",AG28/$J28,"") -> 0.72463768 | AI28: =IF($L28="Y",ABS(AH28-1),"") -> 0.27536232 | AJ28: =IF(AND(L28="Y",COUNT(G28:I28)>=2),K28,"") -> 1.875
A29: P-164 A/B | B29: O.W.S. Water Pumps | C29: Centrifugal (OH2) | D29: D2 | E29: 2 | F29: 15000 | G29: 29200 | H29: 30000 | J29: =AVERAGE(G29:I29) -> 29600 | K29: =MAX(G29:I29)/MIN(G29:I29) -> 1.0273973 | L29: Y | M29: Y | N29: =J29/F29 -> 1.9733333 | O29: =F29*$E$6 -> 15000 | P29: =IF($L29="Y",O29/$J29,"") -> 0.50675676 | Q29: =IF($L29="Y",ABS(P29-1),"") -> 0.49324324 | R29: =F29*$E$7 -> 20716.333 | S29: =IF($L29="Y",R29/$J29,"") -> 0.69987611 | T29: =IF($L29="Y",ABS(S29-1),"") -> 0.30012389 | U29: =F29*$E$8 -> 23281.143 | V29: =IF($L29="Y",U29/$J29,"") -> 0.78652512 | W29: =IF($L29="Y",ABS(V29-1),"") -> 0.21347488 | X29: =F29*1.27425462793664 -> 19113.819 | Y29: =IF($L29="Y",X29/$J29,"") -> 0.64573714 | Z29: =IF($L29="Y",ABS(Y29-1),"") -> 0.35426286 | AA29: =F29*$E$10 -> 20181.287 | AB29: =IF($L29="Y",AA29/$J29,"") -> 0.68180023 | AC29: =IF($L29="Y",ABS(AB29-1),"") -> 0.31819977 | AD29: =F29*$E$11 -> 23855.734 | AE29: =IF($L29="Y",AD29/$J29,"") -> 0.80593697 | AF29: =IF($L29="Y",ABS(AE29-1),"") -> 0.19406303 | AG29: =IF(M29="Y",MAX(F29*$E$12,$E$16),F29*$E$12) -> 25000 | AH29: =IF($L29="Y",AG29/$J29,"") -> 0.84459459 | AI29: =IF($L29="Y",ABS(AH29-1),"") -> 0.15540541 | AJ29: =IF(AND(L29="Y",COUNT(G29:I29)>=2),K29,"") -> 1.0273973
A30: P-165 A/B | B30: Oily Water Basin Pumps | C30: Centrifugal (OH2) | D30: S6 | E30: 2 | F30: 15000 | G30: 22500 | H30: 30000 | J30: =AVERAGE(G30:I30) -> 26250 | K30: =MAX(G30:I30)/MIN(G30:I30) -> 1.3333333 | L30: Y | M30: Y | N30: =J30/F30 -> 1.75 | O30: =F30*$E$6 -> 15000 | P30: =IF($L30="Y",O30/$J30,"") -> 0.57142857 | Q30: =IF($L30="Y",ABS(P30-1),"") -> 0.42857143 | R30: =F30*$E$7 -> 20716.333 | S30: =IF($L30="Y",R30/$J30,"") -> 0.78919364 | T30: =IF($L30="Y",ABS(S30-1),"") -> 0.21080636 | U30: =F30*$E$8 -> 23281.143 | V30: =IF($L30="Y",U30/$J30,"") -> 0.8869007 | W30: =IF($L30="Y",ABS(V30-1),"") -> 0.1130993 | X30: =F30*1.27729147398551 -> 19159.372 | Y30: =IF($L30="Y",X30/$J30,"") -> 0.72988084 | Z30: =IF($L30="Y",ABS(Y30-1),"") -> 0.27011916 | AA30: =F30*$E$10 -> 20181.287 | AB30: =IF($L30="Y",AA30/$J30,"") -> 0.76881092 | AC30: =IF($L30="Y",ABS(AB30-1),"") -> 0.23118908 | AD30: =F30*$E$11 -> 23855.734 | AE30: =IF($L30="Y",AD30/$J30,"") -> 0.90878988 | AF30: =IF($L30="Y",ABS(AE30-1),"") -> 0.091210121 | AG30: =IF(M30="Y",MAX(F30*$E$12,$E$16),F30*$E$12) -> 25000 | AH30: =IF($L30="Y",AG30/$J30,"") -> 0.95238095 | AI30: =IF($L30="Y",ABS(AH30-1),"") -> 0.047619048 | AJ30: =IF(AND(L30="Y",COUNT(G30:I30)>=2),K30,"") -> 1.3333333
A31: P-171 | B31: Fuel Oil Pump | C31: Centrifugal (Horizontal) | D31: S1 | E31: 1 | F31: 10000 | G31: 12000 | H31: 30000 | J31: =AVERAGE(G31:I31) -> 21000 | K31: =MAX(G31:I31)/MIN(G31:I31) -> 2.5 | L31: Y | M31: Y | N31: =J31/F31 -> 2.1 | O31: =F31*$E$6 -> 10000 | P31: =IF($L31="Y",O31/$J31,"") -> 0.47619048 | Q31: =IF($L31="Y",ABS(P31-1),"") -> 0.52380952 | R31: =F31*$E$7 -> 13810.889 | S31: =IF($L31="Y",R31/$J31,"") -> 0.65766136 | T31: =IF($L31="Y",ABS(S31-1),"") -> 0.34233864 | U31: =F31*$E$8 -> 15520.762 | V31: =IF($L31="Y",U31/$J31,"") -> 0.73908392 | W31: =IF($L31="Y",ABS(V31-1),"") -> 0.26091608 | X31: =F31*1.2649857956038 -> 12649.858 | Y31: =IF($L31="Y",X31/$J31,"") -> 0.60237419 | Z31: =IF($L31="Y",ABS(Y31-1),"") -> 0.39762581 | AA31: =F31*$E$10 -> 13454.191 | AB31: =IF($L31="Y",AA31/$J31,"") -> 0.64067577 | AC31: =IF($L31="Y",ABS(AB31-1),"") -> 0.35932423 | AD31: =F31*$E$11 -> 15903.823 | AE31: =IF($L31="Y",AD31/$J31,"") -> 0.7573249 | AF31: =IF($L31="Y",ABS(AE31-1),"") -> 0.2426751 | AG31: =IF(M31="Y",MAX(F31*$E$12,$E$16),F31*$E$12) -> 25000 | AH31: =IF($L31="Y",AG31/$J31,"") -> 1.1904762 | AI31: =IF($L31="Y",ABS(AH31-1),"") -> 0.19047619 | AJ31: =IF(AND(L31="Y",COUNT(G31:I31)>=2),K31,"") -> 2.5
A32: P-191 | B32: Fire Water Loading Pump | C32: Centrifugal (Horizontal) | D32: I2 | E32: 1 | F32: 6500 | G32: 19000 | H32: 13000 | J32: =AVERAGE(G32:I32) -> 16000 | K32: =MAX(G32:I32)/MIN(G32:I32) -> 1.4615385 | L32: N | M32: N | N32: =J32/F32 -> 2.4615385 | O32: =F32*$E$6 -> 6500 | P32: =IF($L32="Y",O32/$J32,"") | Q32: =IF($L32="Y",ABS(P32-1),"") | R32: =F32*$E$7 -> 8977.0776 | S32: =IF($L32="Y",R32/$J32,"") | T32: =IF($L32="Y",ABS(S32-1),"") | U32: =F32*$E$8 -> 10088.496 | V32: =IF($L32="Y",U32/$J32,"") | W32: =IF($L32="Y",ABS(V32-1),"") | X32: =F32*1.28661751025058 -> 8363.0138 | Y32: =IF($L32="Y",X32/$J32,"") | Z32: =IF($L32="Y",ABS(Y32-1),"") | AA32: =F32*$E$10 -> 8745.2243 | AB32: =IF($L32="Y",AA32/$J32,"") | AC32: =IF($L32="Y",ABS(AB32-1),"") | AD32: =F32*$E$11 -> 10337.485 | AE32: =IF($L32="Y",AD32/$J32,"") | AF32: =IF($L32="Y",ABS(AE32-1),"") | AG32: =IF(M32="Y",MAX(F32*$E$12,$E$16),F32*$E$12) -> 8745.2243 | AH32: =IF($L32="Y",AG32/$J32,"") | AI32: =IF($L32="Y",ABS(AH32-1),"") | AJ32: =IF(AND(L32="Y",COUNT(G32:I32)>=2),K32,"")
A33: P-192 | B33: Fire Water Pump-Elect. Motor Driven | C33: Centrifugal (Horizontal, | D33: I2 | E33: 1 | F33: 80000 | G33: 200000 | H33: 30000 | I33: 698980.33 | J33: =AVERAGE(G33:I33) -> 309660.11 | K33: =MAX(G33:I33)/MIN(G33:I33) -> 23.299344 | L33: N | M33: N | N33: =J33/F33 -> 3.8707514 | O33: =F33*$E$6 -> 80000 | P33: =IF($L33="Y",O33/$J33,"") | Q33: =IF($L33="Y",ABS(P33-1),"") | R33: =F33*$E$7 -> 110487.11 | S33: =IF($L33="Y",R33/$J33,"") | T33: =IF($L33="Y",ABS(S33-1),"") | U33: =F33*$E$8 -> 124166.1 | V33: =IF($L33="Y",U33/$J33,"") | W33: =IF($L33="Y",ABS(V33-1),"") | X33: =F33*1.28661751025058 -> 102929.4 | Y33: =IF($L33="Y",X33/$J33,"") | Z33: =IF($L33="Y",ABS(Y33-1),"") | AA33: =F33*$E$10 -> 107633.53 | AB33: =IF($L33="Y",AA33/$J33,"") | AC33: =IF($L33="Y",ABS(AB33-1),"") | AD33: =F33*$E$11 -> 127230.58 | AE33: =IF($L33="Y",AD33/$J33,"") | AF33: =IF($L33="Y",ABS(AE33-1),"") | AG33: =IF(M33="Y",MAX(F33*$E$12,$E$16),F33*$E$12) -> 107633.53 | AH33: =IF($L33="Y",AG33/$J33,"") | AI33: =IF($L33="Y",ABS(AH33-1),"") | AJ33: =IF(AND(L33="Y",COUNT(G33:I33)>=2),K33,"")
A34: P-193 | B34: Fire Water Pump-Diesel Engine Driven | C34: Centrifugal (Horizontal, | D34: I2 | E34: 1 | F34: 100000 | G34: 225000 | H34: 120000 | I34: 263921.27 | J34: =AVERAGE(G34:I34) -> 202973.76 | K34: =MAX(G34:I34)/MIN(G34:I34) -> 2.1993439 | L34: N | M34: N | N34: =J34/F34 -> 2.0297376 | O34: =F34*$E$6 -> 100000 | P34: =IF($L34="Y",O34/$J34,"") | Q34: =IF($L34="Y",ABS(P34-1),"") | R34: =F34*$E$7 -> 138108.89 | S34: =IF($L34="Y",R34/$J34,"") | T34: =IF($L34="Y",ABS(S34-1),"") | U34: =F34*$E$8 -> 155207.62 | V34: =IF($L34="Y",U34/$J34,"") | W34: =IF($L34="Y",ABS(V34-1),"") | X34: =F34*1.28661751025058 -> 128661.75 | Y34: =IF($L34="Y",X34/$J34,"") | Z34: =IF($L34="Y",ABS(Y34-1),"") | AA34: =F34*$E$10 -> 134541.91 | AB34: =IF($L34="Y",AA34/$J34,"") | AC34: =IF($L34="Y",ABS(AB34-1),"") | AD34: =F34*$E$11 -> 159038.23 | AE34: =IF($L34="Y",AD34/$J34,"") | AF34: =IF($L34="Y",ABS(AE34-1),"") | AG34: =IF(M34="Y",MAX(F34*$E$12,$E$16),F34*$E$12) -> 134541.91 | AH34: =IF($L34="Y",AG34/$J34,"") | AI34: =IF($L34="Y",ABS(AH34-1),"") | AJ34: =IF(AND(L34="Y",COUNT(G34:I34)>=2),K34,"")
A35: P-194 A/B | B35: Fire Water Jockey Pumps | C35: Centrifugal | D35: I2 | E35: 2 | F35: 15000 | G35: 19000 | H35: 21000 | I35: 40424.2 | J35: =AVERAGE(G35:I35) -> 26808.067 | K35: =MAX(G35:I35)/MIN(G35:I35) -> 2.1275895 | L35: N | M35: N | N35: =J35/F35 -> 1.7872044 | O35: =F35*$E$6 -> 15000 | P35: =IF($L35="Y",O35/$J35,"") | Q35: =IF($L35="Y",ABS(P35-1),"") | R35: =F35*$E$7 -> 20716.333 | S35: =IF($L35="Y",R35/$J35,"") | T35: =IF($L35="Y",ABS(S35-1),"") | U35: =F35*$E$8 -> 23281.143 | V35: =IF($L35="Y",U35/$J35,"") | W35: =IF($L35="Y",ABS(V35-1),"") | X35: =F35*1.28661751025058 -> 19299.263 | Y35: =IF($L35="Y",X35/$J35,"") | Z35: =IF($L35="Y",ABS(Y35-1),"") | AA35: =F35*$E$10 -> 20181.287 | AB35: =IF($L35="Y",AA35/$J35,"") | AC35: =IF($L35="Y",ABS(AB35-1),"") | AD35: =F35*$E$11 -> 23855.734 | AE35: =IF($L35="Y",AD35/$J35,"") | AF35: =IF($L35="Y",ABS(AE35-1),"") | AG35: =IF(M35="Y",MAX(F35*$E$12,$E$16),F35*$E$12) -> 20181.287 | AH35: =IF($L35="Y",AG35/$J35,"") | AI35: =IF($L35="Y",ABS(AH35-1),"") | AJ35: =IF(AND(L35="Y",COUNT(G35:I35)>=2),K35,"")
A37: آمار خطا (فقط سطرهای «در آمار = Y»)
A38: کد | B38: روش | C38: تعداد | D38: میانه پیش/واقعی −۱ (سوگیری) | E38: میانه |خطا| (MdAPE) | F38: میانگین |خطا| (MAPE) | G38: تعداد با خطای ≤۲۵٪ | H38: جمع پیش‌بینی/جمع واقعی (وزنی با تعداد)
A39: M0 | B39: =B6 -> بدون تعدیل (یورو ثابت) | C39: =COUNT(P18:P35) -> 14 | D39: =MEDIAN(P18:P35)-1 -> -0.37365644 | E39: =MEDIAN(Q18:Q35) -> 0.37365644 | F39: =AVERAGE(Q18:Q35) -> 0.37234734 | G39: =COUNTIF(Q18:Q35,"<=0.25") -> 3 | H39: =SUMPRODUCT(($L$18:$L$35="Y")*$E$18:$E$35*O18:O35)/SUMPRODUCT(($L$18:$L$35="Y")*$E$18:$E$35*$J$18:$J$35) -> 0.73446193
A40: M1 | B40: =B7 -> تورم ارزی مارون ۳ (۱۳۹۴ تا ۱۴۰۳) | C40: =COUNT(S18:S35) -> 14 | D40: =MEDIAN(S18:S35)-1 -> -0.13496388 | E40: =MEDIAN(T18:T35) -> 0.21998303 | F40: =AVERAGE(T18:T35) -> 0.26138111 | G40: =COUNTIF(T18:T35,"<=0.25") -> 8 | H40: =SUMPRODUCT(($L$18:$L$35="Y")*$E$18:$E$35*R18:R35)/SUMPRODUCT(($L$18:$L$35="Y")*$E$18:$E$35*$J$18:$J$35) -> 1.0143572
A41: M2 | B41: =B8 -> ضریب یورویی پازنان (Basic INFO!C138) | C41: =COUNT(V18:V35) -> 14 | D41: =MEDIAN(V18:V35)-1 -> -0.027867046 | E41: =MEDIAN(W18:W35) -> 0.17359989 | F41: =AVERAGE(W18:W35) -> 0.25805632 | G41: =COUNTIF(W18:W35,"<=0.25") -> 8 | H41: =SUMPRODUCT(($L$18:$L$35="Y")*$E$18:$E$35*U18:U35)/SUMPRODUCT(($L$18:$L$35="Y")*$E$18:$E$35*$J$18:$J$35) -> 1.1399409
A42: M3 | B42: =B9 -> مدل فلزی فعلی شما (ضریب هر سطر) | C42: =COUNT(Y18:Y35) -> 14 | D42: =MEDIAN(Y18:Y35)-1 -> -0.20406498 | E42: =MEDIAN(Z18:Z35) -> 0.28204029 | F42: =AVERAGE(Z18:Z35) -> 0.2859887 | G42: =COUNTIF(Z18:Z35,"<=0.25") -> 6 | H42: =SUMPRODUCT(($L$18:$L$35="Y")*$E$18:$E$35*X18:X35)/SUMPRODUCT(($L$18:$L$35="Y")*$E$18:$E$35*$J$18:$J$35) -> 0.93570194
A43: M4 | B43: =B10 -> PPI پمپ منطقه یورو (Eurostat C28.13) | C43: =COUNT(AB18:AB35) -> 14 | D43: =MEDIAN(AB18:AB35)-1 -> -0.1573054 | E43: =MEDIAN(AC18:AC35) -> 0.24012874 | F43: =AVERAGE(AC18:AC35) -> 0.26877251 | G43: =COUNTIF(AC18:AC35,"<=0.25") -> 8 | H43: =SUMPRODUCT(($L$18:$L$35="Y")*$E$18:$E$35*AA18:AA35)/SUMPRODUCT(($L$18:$L$35="Y")*$E$18:$E$35*$J$18:$J$35) -> 0.98815912
...

Sheet Val_IRR_Packages
A1: اعتبارسنجی ۲: پکیج‌های تزریق مواد شیمیایی پازنان ۲ — قیمت ریالی ۱۳۹۳ در برابر استعلام ۱۴۰۴
A2: این سطرها آزمون مسیر «ریالی» است: آیا قیمت ریالی قدیم را باید با تورم ریالی (CPI) بالا برد یا با نرخ ارز؟ «واقعی الف» = تنها استعلام کاملاً ریالی (کندر صنعت پارتیان، اسفند ۱۴۰۳)؛ «واقعی ب» = میانگین همه استعلام‌ها (ریالی، دلاری، یورویی) که پازنان با نرخ ۶۵۸٬۵۳۳ ریال/دلار تبدیل کرده است.
A4: ورودی‌ها
A5: نرخ یورو پایه (بهمن ۱۳۹۳، فایل مارون ۳) | E5: =INDEX(Indices!$G$51:$G$71,MATCH(1393,Indices!$A$51:$A$71,0)) -> 40530.8 | F5: Indices
A6: دلار آزاد در تاریخ استعلام (اسفند ۱۴۰۳، تقریبی) | E6: 930000 | F6: تقریبی؛ ۲ اردیبهشت ۱۴۰۴ حدود ۷۹۰٬۰۰۰ و اوایل ۲۰۲۵ حدود ۸۱۷٬۵۰۰ بوده — با نرخ روز استعلام جایگزین شود
A7: یورو/دلار در تاریخ استعلام | E7: 1.04 | F7: فوریه ۲۰۲۵
A8: نرخ یورو هدف (ریال) | E8: =E6*E7 -> 967200 | F8: فرمول
A9: شاخص پمپ EA (۱۳۹۳→۲۰۲۵) | E9: =Val_EUR_Pumps!E10 -> 1.3454191 | F9: Val_EUR_Pumps
A10: ضریب تورم ریالی ۱۳۹۴ تا ۱۴۰۳ (مارون ۳) | E10: =INDEX(Indices!$I$51:$I$71,MATCH(1403,Indices!$A$51:$A$71,0))/INDEX(Indices!$I$51:$I$71,MATCH(1393,Indices!$A$51:$A$71,0)) -> 16.374095 | F10: Indices
A11: ضریب ریالی پازنان (Basic INFO!E127) | E11: 16.259615 | F11: فایل لینک‌شده PZN-Summary؛ عملاً همان CPI
A12: نرخ تسعیر پازنان (ریال/یورو) | E12: =658533*1.05582863728925 -> 695298 | F12: Basic INFO!C101 × C103 (نرخ مرکز مبادله)
A15: Tag | B15: سرویس | C15: تعداد | D15: قیمت ۱۳۹۳ (ریال) | E15: معادل یورویی ۱۳۹۳ | F15: واقعی الف: استعلام ریالی | G15: واقعی ب: میانگین همه (پازنان) | H15: نسبت واقعی الف/قدیم | I15: نسبت واقعی ب/قدیم | J15: R1 تورم ریالی (CPI) | K15: R2 ضریب ریالی پازنان | L15: R3 مدل فلزی فعلی | M15: R4 پیشنهادی: یورو×PPI×نرخ ارز | N15: R1/الف | O15: R2/الف | P15: R3/الف | Q15: R4/الف | R15: R1/ب | S15: R2/ب | T15: R3/ب | U15: R4/ب
A16: PK-180 | B16: Anti Scale Injection Package | C16: 1 | D16: 1750000000 | E16: =D16/$E$5 -> 43177.041 | F16: 62000000000 | G16: 4.9878867e+10 | H16: =F16/D16 -> 35.428571 | I16: =G16/D16 -> 28.50221 | J16: =D16*$E$10 -> 2.8654666e+10 | K16: =D16*$E$11 -> 2.8454327e+10 | L16: =D16*29.3701248418824 -> 5.1397718e+10 | M16: =E16*$E$9*$E$8 -> 5.6185824e+10 | N16: =J16/$F16 -> 0.46217203 | O16: =K16/$F16 -> 0.45894076 | P16: =L16/$F16 -> 0.82899546 | Q16: =M16/$F16 -> 0.90622297 | R16: =J16/$G16 -> 0.57448509 | S16: =K16/$G16 -> 0.57046859 | T16: =L16/$G16 -> 1.0304508 | U16: =M16/$G16 -> 1.1264455
A17: PK-181 | B17: Demulsifier Injection Package | C17: 1 | D17: 3000000000 | E17: =D17/$E$5 -> 74017.784 | F17: 86500000000 | G17: 7.3692915e+10 | H17: =F17/D17 -> 28.833333 | I17: =G17/D17 -> 24.564305 | J17: =D17*$E$10 -> 4.9122284e+10 | K17: =D17*$E$11 -> 4.8778846e+10 | L17: =D17*29.3701248418824 -> 8.8110375e+10 | M17: =E17*$E$9*$E$8 -> 9.6318555e+10 | N17: =J17/$F17 -> 0.56788768 | O17: =K17/$F17 -> 0.5639173 | P17: =L17/$F17 -> 1.018617 | Q17: =M17/$F17 -> 1.1135093 | R17: =J17/$G17 -> 0.66658083 | S17: =K17/$G17 -> 0.66192044 | T17: =L17/$G17 -> 1.1956424 | U17: =M17/$G17 -> 1.307026
A18: PK-182 | B18: Reverse Demulsifier Injection Package | C18: 1 | D18: 1750000000 | E18: =D18/$E$5 -> 43177.041 | F18: 62000000000 | G18: 5.0976422e+10 | H18: =F18/D18 -> 35.428571 | I18: =G18/D18 -> 29.129384 | J18: =D18*$E$10 -> 2.8654666e+10 | K18: =D18*$E$11 -> 2.8454327e+10 | L18: =D18*29.3701248418824 -> 5.1397718e+10 | M18: =E18*$E$9*$E$8 -> 5.6185824e+10 | N18: =J18/$F18 -> 0.46217203 | O18: =K18/$F18 -> 0.45894076 | P18: =L18/$F18 -> 0.82899546 | Q18: =M18/$F18 -> 0.90622297 | R18: =J18/$G18 -> 0.56211606 | S18: =K18/$G18 -> 0.55818603 | T18: =L18/$G18 -> 1.0082645 | U18: =M18/$G18 -> 1.1021924
A19: PK-183 | B19: Biocide Injection Package | C19: 1 | D19: 1900000000 | E19: =D19/$E$5 -> 46877.93 | F19: 62000000000 | G19: 5.2073977e+10 | H19: =F19/D19 -> 32.631579 | I19: =G19/D19 -> 27.407357 | J19: =D19*$E$10 -> 3.111078e+10 | K19: =D19*$E$11 -> 3.0893269e+10 | L19: =D19*29.3701248418824 -> 5.5803237e+10 | M19: =E19*$E$9*$E$8 -> 6.1001752e+10 | N19: =J19/$F19 -> 0.50178677 | O19: =K19/$F19 -> 0.49827854 | P19: =L19/$F19 -> 0.90005221 | Q19: =M19/$F19 -> 0.98389922 | R19: =J19/$G19 -> 0.59743429 | S19: =K19/$G19 -> 0.59325734 | T19: =L19/$G19 -> 1.0716147 | U19: =M19/$G19 -> 1.1714441
A20: PK-184 | B20: Oxygen Scavenger Injection Package | C20: 1 | D20: 1350000000 | E20: =D20/$E$5 -> 33308.003 | F20: 50500000000 | G20: 4.0488071e+10 | H20: =F20/D20 -> 37.407407 | I20: =G20/D20 -> 29.991164 | J20: =D20*$E$10 -> 2.2105028e+10 | K20: =D20*$E$11 -> 2.1950481e+10 | L20: =D20*29.2979785279696 -> 3.9552271e+10 | M20: =E20*$E$9*$E$8 -> 4.334335e+10 | N20: =J20/$F20 -> 0.43772332 | O20: =K20/$F20 -> 0.43466299 | P20: =L20/$F20 -> 0.78321329 | Q20: =M20/$F20 -> 0.85828416 | R20: =J20/$G20 -> 0.54596396 | S20: =K20/$G20 -> 0.54214686 | T20: =L20/$G20 -> 0.97688701 | U20: =M20/$G20 -> 1.0705215
A21: PK-185 | B21: Anti Scale Injection Package | C21: 1 | D21: 1750000000 | E21: =D21/$E$5 -> 43177.041 | F21: 62000000000 | G21: 5.2073977e+10 | H21: =F21/D21 -> 35.428571 | I21: =G21/D21 -> 29.756558 | J21: =D21*$E$10 -> 2.8654666e+10 | K21: =D21*$E$11 -> 2.8454327e+10 | L21: =D21*29.3701248418824 -> 5.1397718e+10 | M21: =E21*$E$9*$E$8 -> 5.6185824e+10 | N21: =J21/$F21 -> 0.46217203 | O21: =K21/$F21 -> 0.45894076 | P21: =L21/$F21 -> 0.82899546 | Q21: =M21/$F21 -> 0.90622297 | R21: =J21/$G21 -> 0.55026843 | S21: =K21/$G21 -> 0.54642123 | T21: =L21/$G21 -> 0.9870135 | U21: =M21/$G21 -> 1.0789616
A22: PK-186 | B22: Corrosion Inhibitor Injection Package | C22: 1 | D22: 1750000000 | E22: =D22/$E$5 -> 43177.041 | F22: 62000000000 | G22: 5.2073977e+10 | H22: =F22/D22 -> 35.428571 | I22: =G22/D22 -> 29.756558 | J22: =D22*$E$10 -> 2.8654666e+10 | K22: =D22*$E$11 -> 2.8454327e+10 | L22: =D22*29.3701248418824 -> 5.1397718e+10 | M22: =E22*$E$9*$E$8 -> 5.6185824e+10 | N22: =J22/$F22 -> 0.46217203 | O22: =K22/$F22 -> 0.45894076 | P22: =L22/$F22 -> 0.82899546 | Q22: =M22/$F22 -> 0.90622297 | R22: =J22/$G22 -> 0.55026843 | S22: =K22/$G22 -> 0.54642123 | T22: =L22/$G22 -> 0.9870135 | U22: =M22/$G22 -> 1.0789616
A23: PK-187 | B23: Anti Scale Injection Package | C23: 1 | D23: 1750000000 | E23: =D23/$E$5 -> 43177.041 | F23: 62000000000 | G23: 5.2073977e+10 | H23: =F23/D23 -> 35.428571 | I23: =G23/D23 -> 29.756558 | J23: =D23*$E$10 -> 2.8654666e+10 | K23: =D23*$E$11 -> 2.8454327e+10 | L23: =D23*29.3701248418824 -> 5.1397718e+10 | M23: =E23*$E$9*$E$8 -> 5.6185824e+10 | N23: =J23/$F23 -> 0.46217203 | O23: =K23/$F23 -> 0.45894076 | P23: =L23/$F23 -> 0.82899546 | Q23: =M23/$F23 -> 0.90622297 | R23: =J23/$G23 -> 0.55026843 | S23: =K23/$G23 -> 0.54642123 | T23: =L23/$G23 -> 0.9870135 | U23: =M23/$G23 -> 1.0789616
A24: PK-188 | B24: Oxygen Scavenger Injection Package | C24: 1 | D24: 1400000000 | E24: =D24/$E$5 -> 34541.633 | F24: 50500000000 | G24: 4.3780736e+10 | H24: =F24/D24 -> 36.071429 | I24: =G24/D24 -> 31.271955 | J24: =D24*$E$10 -> 2.2923733e+10 | K24: =D24*$E$11 -> 2.2763462e+10 | L24: =D24*29.2979785279696 -> 4.101717e+10 | M24: =E24*$E$9*$E$8 -> 4.4948659e+10 | N24: =J24/$F24 -> 0.4539353 | O24: =K24/$F24 -> 0.45076161 | P24: =L24/$F24 -> 0.81222119 | Q24: =M24/$F24 -> 0.89007246 | R24: =J24/$G24 -> 0.52360317 | S24: =K24/$G24 -> 0.51994241 | T24: =L24/$G24 -> 0.93687711 | U24: =M24/$G24 -> 1.0266766
A25: PK-189 | B25: Oxygen Scavenger Injection Package | C25: 1 | D25: 1350000000 | E25: =D25/$E$5 -> 33308.003 | F25: 50500000000 | G25: 4.0488071e+10 | H25: =F25/D25 -> 37.407407 | I25: =G25/D25 -> 29.991164 | J25: =D25*$E$10 -> 2.2105028e+10 | K25: =D25*$E$11 -> 2.1950481e+10 | L25: =D25*29.2979785279696 -> 3.9552271e+10 | M25: =E25*$E$9*$E$8 -> 4.334335e+10 | N25: =J25/$F25 -> 0.43772332 | O25: =K25/$F25 -> 0.43466299 | P25: =L25/$F25 -> 0.78321329 | Q25: =M25/$F25 -> 0.85828416 | R25: =J25/$G25 -> 0.54596396 | S25: =K25/$G25 -> 0.54214686 | T25: =L25/$G25 -> 0.97688701 | U25: =M25/$G25 -> 1.0705215
A26: PK-212 | B26: Demulsifier Injection Package | C26: 1 | D26: 1900000000 | E26: =D26/$E$5 -> 46877.93 | F26: 64300000000 | G26: 5.5035754e+10 | H26: =F26/D26 -> 33.842105 | I26: =G26/D26 -> 28.966186 | J26: =D26*$E$10 -> 3.111078e+10 | K26: =D26*$E$11 -> 3.0893269e+10 | L26: =D26*29.3701248418824 -> 5.5803237e+10 | M26: =E26*$E$9*$E$8 -> 6.1001752e+10 | N26: =J26/$F26 -> 0.48383795 | O26: =K26/$F26 -> 0.4804552 | P26: =L26/$F26 -> 0.8678575 | Q26: =M26/$F26 -> 0.94870532 | R26: =J26/$G26 -> 0.56528307 | S26: =K26/$G26 -> 0.5613309 | T26: =L26/$G26 -> 1.0139452 | U26: =M26/$G26 -> 1.1084022
A28: میانه نسبت‌ها | H28: =MEDIAN(H16:H26) -> 35.428571 | I28: =MEDIAN(I16:I26) -> 29.756558 | N28: =MEDIAN(N16:N26) -> 0.46217203 | O28: =MEDIAN(O16:O26) -> 0.45894076 | P28: =MEDIAN(P16:P26) -> 0.82899546 | Q28: =MEDIAN(Q16:Q26) -> 0.90622297 | R28: =MEDIAN(R16:R26) -> 0.55026843 | S28: =MEDIAN(S16:S26) -> 0.54642123 | T28: =MEDIAN(T16:T26) -> 0.9870135 | U28: =MEDIAN(U16:U26) -> 1.0789616
A29: جمع پیش‌بینی / جمع واقعی | N29: =SUMPRODUCT($C$16:$C$26,J16:J26)/SUMPRODUCT($C$16:$C$26,$F$16:$F$26) -> 0.47716293 | O29: =SUMPRODUCT($C$16:$C$26,K16:K26)/SUMPRODUCT($C$16:$C$26,$F$16:$F$26) -> 0.47382685 | P29: =SUMPRODUCT($C$16:$C$26,L16:L26)/SUMPRODUCT($C$16:$C$26,$F$16:$F$26) -> 0.85544587 | Q29: =SUMPRODUCT($C$16:$C$26,M16:M26)/SUMPRODUCT($C$16:$C$26,$F$16:$F$26) -> 0.93561699 | R29: =SUMPRODUCT($C$16:$C$26,J16:J26)/SUMPRODUCT($C$16:$C$26,$G$16:$G$26) -> 0.57186268 | S29: =SUMPRODUCT($C$16:$C$26,K16:K26)/SUMPRODUCT($C$16:$C$26,$G$16:$G$26) -> 0.56786451 | T29: =SUMPRODUCT($C$16:$C$26,L16:L26)/SUMPRODUCT($C$16:$C$26,$G$16:$G$26) -> 1.0252213 | U29: =SUMPRODUCT($C$16:$C$26,M16:M26)/SUMPRODUCT($C$16:$C$26,$G$16:$G$26) -> 1.1213035
A31: آزمون حساسیت: نرخ دلار لازم برای اینکه روش R4 دقیقاً میانه «واقعی الف» را بدهد | M31: =$E$6*MEDIAN(H16:H26)/(($E$9*$E$8)/$E$5) -> 1026237.5 | N31: ریال/دلار
A32: نتیجه: مسیر تورم ریالی (R1، R2) قیمت را حدود نصف واقعیت برآورد می‌کند؛ چون از ۱۳۹۳ تا ۱۴۰۳ دلار ~۲۸ برابر ولی CPI ~۱۶ برابر شده و قیمت پمپ و پکیج (حتی سازنده داخلی) به ارز گره خورده است.
A33: نکته: هر سه فروشنده (یکی ریالی، یکی دلاری، یکی یورویی) سازنده داخلی‌اند؛ یعنی «ساخت داخل» به معنای «ریالی» نیست.

Sheet Drivers
A1: تفکیک اثر عوامل: تورم ارزی، تورم ریالی، نرخ ارز و فلزات (۱۳۹۳ → ۱۴۰۳/۱۴۰۴)
A3: عامل | B3: ضریب ۱۳۹۳→هدف | C3: توضیح
A4: نرخ یورو (ریال) — بهمن ۱۳۹۳ تا اسفند ۱۴۰۳ | B4: =Val_IRR_Packages!E8/Val_IRR_Packages!E5 -> 23.863334 | C4: کاهش ارزش ریال؛ بزرگ‌ترین عامل
A5: شاخص قیمت پمپ به یورو (EA PPI C28.13) | B5: =Val_EUR_Pumps!E10 -> 1.3454191 | C5: تورم ارزیِ خاصِ صنعت پمپ؛ اثر فلزات، دستمزد و انرژی سازنده در آن نهفته است
A6: حاصل‌ضرب: «شاخص ریالیِ پمپ» | B6: =B4*B5 -> 32.106185 | C6: پیش‌بینی روش پیشنهادی برای قیمت ریالی
A7: تورم ریالی تجمعی (CPI، مارون ۳) | B7: =Val_IRR_Packages!E10 -> 16.374095 | C7: مسیر CPI
A8: مشاهده‌شده: میانه استعلام ریالی/قیمت قدیم | B8: =Val_IRR_Packages!H28 -> 35.428571 | C8: پکیج‌های تزریق، واقعی الف
A9: مشاهده‌شده: پمپ‌ها، میانه نسبت یورویی واقعی/قدیم | B9: =MEDIAN(Val_EUR_Pumps!N18:N35) -> 1.7686022 | C9: در یورو؛ شامل اثر کف قیمت پمپ‌های کوچک
A10: مشاهده‌شده: پمپ‌ها، جمع واقعی/جمع قدیم (بدون آتش‌نشانی) | B10: =SUMPRODUCT((Val_EUR_Pumps!L18:L35="Y")*Val_EUR_Pumps!E18:E35*Val_EUR_Pumps!J18:J35)/SUMPRODUCT((Val_EUR_Pumps!L18:L35="Y")*Val_EUR_Pumps!E18:E35*Val_EUR_Pumps!F18:F35) -> 1.361541 | C10: در یورو، وزنی با مبلغ
A11: سبد فلزی پمپ به دلار (۱۳۹۳→۱۴۰۴) | B11: =1+Indices!G44 -> 1.1340982 | C11: فولاد ثابت، نیکل −۱۰٪، مولیبدن ×۲٫۲، مس +۴۵٪
A12: سبد فلزی پمپ به یورو | B12: =B11*Val_EUR_Pumps!E14/Val_EUR_Pumps!E15 -> 1.1809188 | C12: با تبدیل یورو/دلار
A13: سهم مستقیم فلز در رشد قیمت (فرض سهم فلز) | B13: =Indices!C6*(B12-1) -> 0.054275636 | C13: سهم فلز × تغییر سبد فلزی؛ در برابر کل رشد ~۳۵٪
A15: برداشت:
A16: ۱) قیمت ریالی پمپ ≈ قیمت یورویی × نرخ یورو. ضریب «یورو × PPI» (حدود ۳۰ تا ۳۲) با مشاهده (۳۰ تا ۳۵) می‌خواند؛ CPI (حدود ۱۶) نصف واقعیت است.
A17: ۲) در خود یورو، رشد قیمت پمپ طی ۱۰ سال حدود ۳۵٪ (۳٪ در سال) بوده که دو سوم آن در ۲۰۲۲ و ۲۰۲۳ رخ داده است.
A18: ۳) اثر مستقیم فلزات کوچک است (چند درصد) و خودش داخل PPI لحاظ شده؛ اضافه‌کردن جداگانه شاخص فلزی روی PPI دوباره‌شماری است.
A19: ۴) فلزات فقط برای «پیش‌بینی» سال‌هایی که هنوز PPI رسمی ندارند (۲۰۲۶ به بعد) و برای تحلیل حساسیت (شوک نیکل/مس برای پمپ‌های دوپلکس) کاربرد دارند.
A22: مقایسه سالانه: شاخص ریالیِ پمپ (یورو×PPI) در برابر شاخص تورم ریالی (۱۳۹۳ = ۱)
A23: سال شمسی | B23: شاخص پمپ به یورو | C23: نرخ یورو | D23: شاخص ریالی پمپ | E23: شاخص CPI | F23: نسبت پمپ/CPI
A24: 1393 | B24: =INDEX(Indices!$C$51:$C$71,MATCH(A24,Indices!$A$51:$A$71,0))/INDEX(Indices!$C$51:$C$71,MATCH(1393,Indices!$A$51:$A$71,0)) -> 1 | C24: =INDEX(Indices!$G$51:$G$71,MATCH(A24,Indices!$A$51:$A$71,0))/INDEX(Indices!$G$51:$G$71,MATCH(1393,Indices!$A$51:$A$71,0)) -> 1 | D24: =B24*C24 -> 1 | E24: =INDEX(Indices!$I$51:$I$71,MATCH(A24,Indices!$A$51:$A$71,0))/INDEX(Indices!$I$51:$I$71,MATCH(1393,Indices!$A$51:$A$71,0)) -> 1 | F24: =D24/E24 -> 1
